[META]
version=2.0
spawnSunlight=True
spawnDarkness=True
spawnWater=False
spawnLava=False
underFill=False
randomRotation=True
dig=True
tree=False
branch=False
needsFoundation=True
rarity=30
collisionPercentage=5
spawnElevationMin=0
spawnElevationMax=200
branchLimit=6
spawnInBiome=All
[DATA]
0,0,0:1
0,1,0:1
0,2,0:1
0,3,0:1
0,4,0:1
0,5,0:1
0,6,0:1
0,7,0:1
0,8,0:1
0,9,0:1
0,10,0:1
0,11,0:1
0,12,0:1
0,13,0:1
0,0,1:1
0,1,1:1
0,2,1:1
0,3,1:1
0,4,1:1
0,5,1:1
0,6,1:1
0,7,1:1
0,8,1:1
0,9,1:1
0,10,1:1
0,11,1:1
0,12,1:1
0,13,1:1
0,14,1:1
0,15,1:1
0,16,1:1
0,0,2:3
0,1,2:3
0,2,2:3
0,3,2:3
0,4,2:3
0,5,2:1
0,6,2:1
0,7,2:1
0,8,2:1
0,9,2:1
0,10,2:1
0,11,2:1
0,12,2:3
0,13,2:1
0,14,2:3
0,15,2:3
0,16,2:1
0,0,3:3
0,1,3:2
0,2,3:3
0,3,3:3
0,4,3:3
0,5,3:3
0,6,3:3
0,7,3:3
0,8,3:3
0,9,3:3
0,10,3:3
0,11,3:3
0,12,3:3
0,13,3:3
0,14,3:3
0,15,3:3
0,16,3:3
0,0,4:44.5
0,2,4:1
0,3,4:1
0,4,4:1
0,5,4:1
0,6,4:1
0,7,4:1
0,8,4:1
0,9,4:1
0,10,4:1
0,11,4:1
0,12,4:1
0,13,4:1
0,14,4:1
0,15,4:43.5
0,16,4:43
0,14,5:1
1,0,0:1
1,1,0:1
1,2,0:1
1,3,0:15
1,4,0:15
1,5,0:1
1,6,0:1
1,7,0:1
1,8,0:1
1,9,0:1
1,10,0:1
1,11,0:1
1,12,0:1
1,13,0:1
1,14,0:1
1,15,0:1
1,16,0:1
1,0,1:3
1,1,1:1
1,2,1:1
1,3,1:1
1,4,1:15
1,5,1:1
1,6,1:1
1,7,1:1
1,8,1:1
1,9,1:1
1,10,1:1
1,11,1:1
1,12,1:1
1,13,1:1
1,14,1:1
1,15,1:1
1,16,1:1
1,0,2:3
1,1,2:3
1,2,2:3
1,3,2:3
1,4,2:3
1,5,2:3
1,7,2:1
1,8,2:3
1,9,2:1
1,10,2:1
1,11,2:1
1,12,2:1
1,13,2:1
1,14,2:3
1,15,2:3
1,16,2:3
1,0,3:3
1,1,3:2
1,2,3:3
1,3,3:3
1,4,3:3
1,5,3:3
1,6,3:50.4
1,7,3:3
1,8,3:3
1,9,3:3
1,10,3:3
1,11,3:3
1,12,3:3
1,13,3:3
1,14,3:3
1,15,3:3
1,16,3:3
1,0,4:44.5
1,2,4:2
1,3,4:2
1,4,4:2
1,5,4:2
1,6,4:2
1,7,4:2
1,8,4:2
1,9,4:2
1,10,4:2
1,11,4:2
1,12,4:2
1,13,4:2
1,14,4:2
1,15,4:3
1,16,4:2
1,2,5:44.5
1,3,5:44.5
1,12,5:44.5
1,13,5:44.5
1,15,5:1
1,16,5:44.5
2,0,0:1
2,1,0:1
2,2,0:1
2,3,0:15
2,4,0:15
2,5,0:1
2,6,0:1
2,7,0:1
2,8,0:1
2,9,0:1
2,10,0:1
2,11,0:1
2,12,0:1
2,13,0:1
2,14,0:1
2,15,0:1
2,16,0:1
2,0,1:3
2,1,1:1
2,2,1:1
2,3,1:1
2,4,1:1
2,5,1:1
2,6,1:1
2,7,1:1
2,8,1:1
2,9,1:1
2,10,1:1
2,11,1:1
2,12,1:1
2,13,1:1
2,14,1:1
2,15,1:1
2,16,1:1
2,0,2:3
2,1,2:3
2,2,2:3
2,3,2:3
2,4,2:3
2,5,2:3
2,7,2:3
2,9,2:3
2,10,2:3
2,11,2:1
2,12,2:3
2,13,2:1
2,14,2:3
2,15,2:3
2,16,2:3
2,0,3:3
2,1,3:2
2,2,3:3
2,3,3:3
2,4,3:3
2,5,3:3
2,7,3:3
2,9,3:3
2,10,3:2
2,11,3:2
2,12,3:2
2,13,3:2
2,14,3:3
2,15,3:3
2,16,3:3
2,0,4:44.5
2,2,4:3
2,3,4:3
2,4,4:2
2,5,4:2
2,6,4:2
2,7,4:2
2,9,4:2
2,14,4:3
2,15,4:3
2,16,4:3
2,1,5:44.5
2,2,5:17.1
2,3,5:17.1
2,4,5:44.5
2,5,5:44.5
2,6,5:44.5
2,7,5:44.5
2,8,5:44.5
2,9,5:44.5
2,10,5:44.5
2,11,5:44.5
2,12,5:17.1
2,13,5:17.1
2,14,5:2
2,15,5:1
2,16,5:44.5
2,2,6:17.1
2,3,6:17.1
2,12,6:17.1
2,13,6:17.1
2,14,6:44.5
2,2,7:17.1
2,3,7:17.1
2,12,7:17.1
2,13,7:17.1
2,2,8:17.1
2,3,8:17.1
2,12,8:17.1
2,13,8:17.1
2,2,9:44.2
2,3,9:44.2
2,4,9:44.2
2,5,9:44.2
2,6,9:44.2
2,7,9:44.2
2,8,9:44.2
2,9,9:44.2
2,10,9:44.2
2,11,9:44.2
2,12,9:44.2
2,13,9:44.2
2,4,10:44.2
2,5,10:44.2
2,6,10:44.2
2,7,10:44.2
2,8,10:44.2
2,9,10:44.2
2,10,10:44.2
2,11,10:44.2
2,5,11:44.2
2,6,11:44.2
2,7,11:44.2
2,8,11:44.2
2,9,11:44.2
2,10,11:44.2
2,6,12:44.2
2,7,12:44.2
2,8,12:44.2
2,9,12:44.2
3,0,0:1
3,1,0:1
3,2,0:1
3,3,0:1
3,4,0:1
3,5,0:1
3,6,0:1
3,7,0:1
3,8,0:1
3,9,0:1
3,10,0:1
3,11,0:1
3,12,0:1
3,13,0:1
3,14,0:1
3,15,0:1
3,16,0:1
3,0,1:3
3,1,1:3
3,2,1:1
3,3,1:1
3,4,1:1
3,5,1:1
3,6,1:1
3,7,1:1
3,8,1:1
3,9,1:1
3,10,1:1
3,11,1:1
3,12,1:1
3,13,1:1
3,14,1:1
3,15,1:1
3,16,1:1
3,0,2:3
3,1,2:3
3,2,2:1
3,3,2:3
3,4,2:3
3,5,2:3
3,7,2:3
3,9,2:3
3,10,2:3
3,11,2:3
3,12,2:1
3,13,2:3
3,14,2:1
3,15,2:3
3,16,2:3
3,0,3:3
3,1,3:2
3,2,3:3
3,3,3:3
3,4,3:3
3,5,3:3
3,7,3:3
3,9,3:3
3,10,3:3
3,11,3:3
3,12,3:3
3,13,3:3
3,14,3:3
3,15,3:3
3,16,3:3
3,0,4:44.5
3,2,4:3
3,3,4:3
3,4,4:98
3,5,4:98
3,6,4:98
3,7,4:98
3,8,4:98
3,9,4:98
3,10,4:98
3,11,4:98
3,12,4:3
3,13,4:3
3,14,4:3
3,15,4:3
3,16,4:3
3,1,5:44.5
3,2,5:17.1
3,3,5:98
3,4,5:20
3,5,5:20
3,6,5:20
3,8,5:20
3,9,5:20
3,10,5:20
3,11,5:20
3,12,5:98
3,13,5:17.1
3,14,5:2
3,15,5:1
3,16,5:44.5
3,2,6:17.1
3,3,6:5
3,4,6:20
3,5,6:20
3,6,6:20
3,8,6:20
3,9,6:20
3,10,6:20
3,11,6:20
3,12,6:5
3,13,6:17.1
3,14,6:44.5
3,2,7:17.1
3,3,7:5
3,4,7:5
3,5,7:5
3,6,7:5
3,8,7:5
3,9,7:5
3,10,7:5
3,11,7:5
3,12,7:5
3,13,7:17.1
3,2,8:17.1
3,3,8:5
3,4,8:5
3,5,8:20
3,6,8:20
3,7,8:20
3,8,8:20
3,9,8:20
3,10,8:20
3,11,8:5
3,12,8:5
3,13,8:17.1
3,2,9:44.2
3,3,9:44.2
3,4,9:5
3,5,9:5
3,6,9:20
3,7,9:20
3,8,9:20
3,9,9:20
3,10,9:5
3,11,9:5
3,12,9:44.2
3,13,9:44.2
3,4,10:44.2
3,5,10:5
3,6,10:5
3,7,10:20
3,8,10:20
3,9,10:5
3,10,10:5
3,11,10:44.2
3,5,11:44.2
3,6,11:5
3,7,11:5
3,8,11:5
3,9,11:5
3,10,11:44.2
3,6,12:44.2
3,7,12:5
3,8,12:5
3,9,12:44.2
3,7,13:44.2
3,8,13:44.2
4,0,0:1
4,1,0:1
4,2,0:1
4,3,0:1
4,4,0:1
4,5,0:1
4,6,0:1
4,7,0:1
4,8,0:1
4,9,0:1
4,10,0:1
4,11,0:1
4,12,0:1
4,13,0:1
4,14,0:1
4,15,0:1
4,16,0:1
4,0,1:3
4,1,1:3
4,2,1:3
4,3,1:1
4,4,1:1
4,5,1:1
4,6,1:1
4,7,1:1
4,8,1:1
4,9,1:1
4,10,1:3
4,11,1:1
4,12,1:1
4,13,1:1
4,14,1:1
4,15,1:1
4,16,1:1
4,0,2:3
4,1,2:3
4,2,2:3
4,3,2:3
4,4,2:3
4,5,2:3
4,7,2:3
4,9,2:1
4,10,2:3
4,11,2:3
4,12,2:3
4,13,2:3
4,14,2:3
4,15,2:1
4,16,2:3
4,0,3:3
4,1,3:2
4,2,3:3
4,3,3:3
4,4,3:3
4,5,3:3
4,7,3:3
4,9,3:3
4,10,3:3
4,11,3:3
4,12,3:3
4,13,3:3
4,14,3:3
4,15,3:3
4,16,3:3
4,0,4:44.5
4,2,4:2
4,3,4:3
4,4,4:5
4,5,4:5
4,6,4:5
4,8,4:54.5
4,9,4:5
4,10,4:5
4,11,4:5
4,12,4:98
4,13,4:3
4,14,4:3
4,15,4:3
4,16,4:3
4,2,5:44.5
4,3,5:98
4,4,5:61.3
4,9,5:54.5
4,10,5:54.5
4,11,5:58
4,12,5:20
4,13,5:2
4,14,5:2
4,15,5:1
4,16,5:44.5
4,3,6:20
4,12,6:20
4,13,6:44.5
4,3,7:20
4,5,7:50.1
4,10,7:50.1
4,12,7:5
4,3,8:5
4,12,8:5
4,2,9:44.2
4,3,9:44.2
4,4,9:5
4,11,9:5
4,12,9:44.2
4,13,9:44.2
4,4,10:44.2
4,5,10:5
4,10,10:5
4,11,10:44.2
4,5,11:44.2
4,6,11:5
4,9,11:5
4,10,11:44.2
4,6,12:44.2
4,7,12:5
4,8,12:5
4,9,12:44.2
4,7,13:44.2
4,8,13:44.2
5,0,0:1
5,1,0:1
5,2,0:1
5,3,0:1
5,4,0:1
5,5,0:1
5,6,0:1
5,7,0:1
5,8,0:1
5,9,0:1
5,10,0:1
5,11,0:1
5,12,0:1
5,13,0:1
5,14,0:1
5,15,0:1
5,16,0:1
5,0,1:3
5,1,1:3
5,2,1:3
5,3,1:1
5,4,1:1
5,5,1:1
5,6,1:1
5,7,1:1
5,8,1:1
5,9,1:1
5,10,1:3
5,11,1:3
5,12,1:1
5,13,1:3
5,14,1:1
5,15,1:1
5,16,1:1
5,0,2:3
5,1,2:3
5,2,2:3
5,3,2:1
5,4,2:3
5,5,2:3
5,6,2:3
5,7,2:3
5,9,2:3
5,10,2:3
5,11,2:3
5,12,2:3
5,13,2:3
5,14,2:3
5,15,2:3
5,16,2:3
5,0,3:3
5,1,3:2
5,2,3:3
5,3,3:3
5,4,3:3
5,5,3:3
5,6,3:3
5,8,3:50.4
5,9,3:3
5,10,3:3
5,11,3:3
5,12,3:3
5,13,3:3
5,14,3:3
5,15,3:3
5,16,3:3
5,0,4:44.5
5,2,4:2
5,3,4:3
5,12,4:98
5,13,4:3
5,14,4:3
5,15,4:3
5,16,4:3
5,2,5:44.5
5,3,5:98
5,12,5:20
5,13,5:2
5,14,5:2
5,15,5:1
5,16,5:44.5
5,3,6:20
5,12,6:20
5,13,6:44.5
5,3,7:20
5,12,7:5
5,3,8:5
5,12,8:5
5,2,9:44.2
5,3,9:44.2
5,4,9:5
5,11,9:5
5,12,9:44.2
5,13,9:44.2
5,4,10:44.2
5,5,10:5
5,10,10:5
5,11,10:44.2
5,5,11:44.2
5,6,11:5
5,9,11:5
5,10,11:44.2
5,6,12:44.2
5,7,12:5
5,8,12:5
5,9,12:44.2
5,7,13:44.2
5,8,13:44.2
6,0,0:1
6,1,0:1
6,2,0:1
6,3,0:1
6,4,0:1
6,5,0:1
6,6,0:1
6,7,0:1
6,8,0:1
6,9,0:1
6,10,0:1
6,11,0:1
6,12,0:1
6,13,0:1
6,14,0:1
6,15,0:1
6,16,0:1
6,0,1:3
6,1,1:3
6,2,1:3
6,3,1:3
6,4,1:1
6,6,1:1
6,7,1:1
6,8,1:1
6,9,1:1
6,10,1:1
6,11,1:1
6,12,1:3
6,13,1:3
6,14,1:3
6,15,1:1
6,16,1:1
6,0,2:3
6,1,2:3
6,2,2:3
6,3,2:3
6,4,2:3
6,5,2:3
6,6,2:3
6,7,2:3
6,8,2:3
6,9,2:3
6,10,2:3
6,11,2:3
6,12,2:3
6,13,2:3
6,14,2:3
6,15,2:3
6,16,2:1
6,0,3:3
6,1,3:2
6,2,3:3
6,3,3:3
6,4,3:3
6,5,3:3
6,6,3:3
6,7,3:3
6,8,3:3
6,9,3:3
6,10,3:3
6,11,3:3
6,12,3:3
6,13,3:3
6,14,3:3
6,15,3:3
6,16,3:3
6,0,4:44.5
6,2,4:3
6,3,4:5
6,12,4:98
6,13,4:3
6,14,4:3
6,15,4:3
6,16,4:3
6,1,5:44.5
6,2,5:17.1
6,12,5:20
6,13,5:2
6,14,5:2
6,15,5:1
6,16,5:44.5
6,2,6:17.1
6,12,6:20
6,13,6:44.5
6,2,7:17.1
6,12,7:5
6,2,8:17.1
6,12,8:5
6,2,9:44.2
6,3,9:44.2
6,4,9:5
6,11,9:5
6,12,9:44.2
6,13,9:44.2
6,4,10:44.2
6,5,10:5
6,10,10:5
6,11,10:44.2
6,5,11:44.2
6,6,11:5
6,9,11:5
6,10,11:44.2
6,6,12:44.2
6,7,12:5
6,8,12:5
6,9,12:44.2
6,7,13:44.2
6,8,13:44.2
7,0,0:1
7,1,0:1
7,2,0:1
7,3,0:1
7,7,0:1
7,8,0:1
7,9,0:1
7,10,0:1
7,11,0:1
7,12,0:1
7,13,0:1
7,14,0:1
7,15,0:1
7,16,0:1
7,0,1:3
7,1,1:3
7,2,1:3
7,3,1:3
7,7,1:1
7,8,1:1
7,9,1:1
7,10,1:1
7,11,1:1
7,12,1:3
7,13,1:3
7,14,1:3
7,15,1:3
7,16,1:1
7,0,2:3
7,1,2:3
7,2,2:3
7,3,2:3
7,4,2:3
7,7,2:3
7,8,2:3
7,9,2:3
7,10,2:3
7,11,2:3
7,12,2:3
7,13,2:3
7,14,2:3
7,15,2:3
7,16,2:3
7,0,3:3
7,1,3:2
7,2,3:3
7,3,3:3
7,4,3:3
7,5,3:3
7,6,3:3
7,7,3:3
7,8,3:3
7,9,3:3
7,10,3:3
7,11,3:3
7,12,3:3
7,13,3:3
7,14,3:3
7,15,3:3
7,16,3:3
7,0,4:44.5
7,2,4:3
7,3,4:5
7,12,4:98
7,13,4:3
7,14,4:3
7,15,4:3
7,16,4:3
7,2,5:17.1
7,12,5:20
7,13,5:2
7,14,5:2
7,15,5:1
7,16,5:44.5
7,2,6:17.1
7,12,6:20
7,13,6:44.5
7,2,7:17.1
7,12,7:5
7,2,8:17.1
7,12,8:5
7,2,9:44.2
7,3,9:44.2
7,4,9:5
7,11,9:5
7,12,9:44.2
7,13,9:44.2
7,4,10:44.2
7,5,10:5
7,10,10:5
7,11,10:44.2
7,5,11:44.2
7,6,11:5
7,9,11:5
7,10,11:44.2
7,6,12:44.2
7,7,12:5
7,8,12:5
7,9,12:44.2
7,7,13:44.2
7,8,13:44.2
8,0,0:1
8,1,0:1
8,2,0:1
8,3,0:1
8,7,0:1
8,8,0:1
8,9,0:1
8,10,0:1
8,11,0:1
8,12,0:1
8,13,0:1
8,14,0:1
8,15,0:1
8,16,0:1
8,0,1:3
8,1,1:3
8,2,1:3
8,3,1:3
8,7,1:1
8,8,1:1
8,9,1:1
8,10,1:1
8,11,1:1
8,12,1:3
8,13,1:3
8,14,1:3
8,15,1:3
8,16,1:3
8,0,2:3
8,1,2:3
8,2,2:3
8,3,2:3
8,6,2:3
8,7,2:3
8,8,2:3
8,9,2:3
8,10,2:3
8,11,2:3
8,12,2:3
8,13,2:3
8,14,2:3
8,15,2:3
8,16,2:3
8,0,3:3
8,1,3:2
8,2,3:3
8,3,3:3
8,4,3:3
8,5,3:3
8,6,3:3
8,7,3:3
8,8,3:3
8,9,3:3
8,10,3:3
8,11,3:3
8,12,3:3
8,13,3:3
8,14,3:3
8,15,3:3
8,16,3:3
8,0,4:44.5
8,2,4:2
8,3,4:5
8,12,4:98
8,13,4:3
8,14,4:3
8,15,4:3
8,16,4:3
8,2,5:44.5
8,3,5:5
8,12,5:20
8,13,5:3
8,14,5:2
8,15,5:1
8,16,5:44.5
8,3,6:20
8,12,6:20
8,13,6:44.5
8,3,7:20
8,12,7:5
8,3,8:5
8,12,8:5
8,2,9:44.2
8,3,9:44.2
8,4,9:5
8,11,9:5
8,12,9:44.2
8,13,9:44.2
8,4,10:44.2
8,5,10:5
8,10,10:5
8,11,10:44.2
8,5,11:44.2
8,6,11:5
8,9,11:5
8,10,11:44.2
8,6,12:44.2
8,7,12:5
8,8,12:5
8,9,12:44.2
8,7,13:44.2
8,8,13:44.2
9,1,0:1
9,6,0:1
9,7,0:1
9,8,0:1
9,9,0:1
9,10,0:15
9,11,0:15
9,12,0:1
9,13,0:1
9,14,0:1
9,15,0:1
9,16,0:1
9,0,1:3
9,1,1:3
9,6,1:1
9,7,1:1
9,8,1:1
9,9,1:1
9,10,1:1
9,11,1:3
9,12,1:3
9,13,1:3
9,14,1:3
9,15,1:3
9,16,1:3
9,0,2:3
9,1,2:3
9,2,2:3
9,3,2:3
9,4,2:3
9,5,2:3
9,6,2:3
9,7,2:3
9,8,2:3
9,9,2:3
9,10,2:3
9,11,2:3
9,12,2:3
9,13,2:3
9,14,2:3
9,15,2:3
9,16,2:3
9,0,3:3
9,1,3:2
9,2,3:3
9,3,3:3
9,4,3:3
9,5,3:3
9,6,3:3
9,7,3:3
9,8,3:3
9,9,3:3
9,10,3:3
9,11,3:3
9,12,3:3
9,13,3:3
9,14,3:3
9,15,3:3
9,16,3:3
9,0,4:44.5
9,2,4:2
9,3,4:5
9,12,4:98
9,13,4:3
9,14,4:3
9,15,4:3
9,16,4:3
9,2,5:44.5
9,3,5:5
9,12,5:20
9,13,5:2
9,14,5:2
9,15,5:1
9,16,5:44.5
9,3,6:20
9,12,6:20
9,13,6:44.5
9,3,7:20
9,12,7:5
9,3,8:5
9,12,8:5
9,2,9:44.2
9,3,9:44.2
9,4,9:5
9,11,9:5
9,12,9:44.2
9,13,9:44.2
9,4,10:44.2
9,5,10:5
9,10,10:5
9,11,10:44.2
9,5,11:44.2
9,6,11:5
9,9,11:5
9,10,11:44.2
9,6,12:44.2
9,7,12:5
9,8,12:5
9,9,12:44.2
9,7,13:44.2
9,8,13:44.2
10,4,0:1
10,5,0:1
10,6,0:1
10,7,0:1
10,8,0:1
10,9,0:1
10,10,0:15
10,11,0:15
10,12,0:1
10,13,0:1
10,14,0:1
10,15,0:1
10,16,0:1
10,0,1:3
10,1,1:3
10,4,1:1
10,5,1:1
10,6,1:1
10,7,1:1
10,8,1:1
10,9,1:3
10,10,1:1
10,11,1:1
10,12,1:3
10,13,1:3
10,14,1:3
10,15,1:3
10,16,1:3
10,0,2:3
10,1,2:3
10,2,2:3
10,3,2:3
10,4,2:3
10,5,2:3
10,6,2:3
10,7,2:3
10,8,2:3
10,9,2:3
10,10,2:3
10,11,2:3
10,12,2:3
10,13,2:3
10,14,2:3
10,15,2:3
10,16,2:3
10,0,3:3
10,1,3:2
10,2,3:3
10,3,3:3
10,4,3:3
10,5,3:3
10,6,3:3
10,7,3:3
10,8,3:3
10,9,3:3
10,10,3:3
10,11,3:3
10,12,3:3
10,13,3:3
10,14,3:3
10,15,3:3
10,16,3:3
10,0,4:44.5
10,2,4:2
10,3,4:5
10,12,4:98
10,13,4:3
10,14,4:3
10,15,4:3
10,16,4:3
10,2,5:44.5
10,3,5:5
10,12,5:20
10,13,5:2
10,14,5:2
10,15,5:1
10,16,5:44.5
10,3,6:20
10,12,6:20
10,13,6:44.5
10,3,7:20
10,12,7:5
10,3,8:5
10,12,8:5
10,2,9:44.2
10,3,9:44.2
10,4,9:5
10,11,9:5
10,12,9:44.2
10,13,9:44.2
10,4,10:44.2
10,5,10:5
10,10,10:5
10,11,10:44.2
10,5,11:44.2
10,6,11:5
10,9,11:5
10,10,11:44.2
10,6,12:44.2
10,7,12:5
10,8,12:5
10,9,12:44.2
10,7,13:44.2
10,8,13:44.2
11,1,0:1
11,4,0:1
11,5,0:1
11,6,0:1
11,7,0:1
11,8,0:1
11,9,0:1
11,10,0:1
11,11,0:1
11,12,0:1
11,13,0:1
11,14,0:1
11,15,0:1
11,16,0:1
11,0,1:3
11,1,1:3
11,4,1:1
11,5,1:1
11,6,1:1
11,7,1:1
11,8,1:1
11,9,1:3
11,10,1:1
11,11,1:1
11,12,1:3
11,13,1:3
11,14,1:3
11,15,1:3
11,16,1:3
11,0,2:3
11,1,2:3
11,2,2:3
11,4,2:3
11,5,2:3
11,6,2:1
11,7,2:3
11,8,2:3
11,9,2:3
11,10,2:3
11,11,2:3
11,12,2:3
11,13,2:3
11,14,2:3
11,15,2:3
11,16,2:3
11,0,3:3
11,1,3:2
11,2,3:3
11,3,3:3
11,4,3:3
11,5,3:3
11,6,3:3
11,7,3:3
11,8,3:3
11,9,3:3
11,10,3:3
11,11,3:3
11,12,3:3
11,13,3:3
11,14,3:3
11,15,3:3
11,16,3:3
11,0,4:44.5
11,2,4:3
11,3,4:5
11,12,4:98
11,13,4:3
11,14,4:3
11,15,4:3
11,16,4:3
11,1,5:44.5
11,2,5:17.1
11,12,5:20
11,13,5:2
11,14,5:2
11,15,5:1
11,16,5:44.5
11,2,6:17.1
11,12,6:20
11,13,6:44.5
11,2,7:17.1
11,12,7:5
11,2,8:17.1
11,12,8:5
11,2,9:44.2
11,3,9:44.2
11,4,9:5
11,11,9:5
11,12,9:44.2
11,13,9:44.2
11,4,10:44.2
11,5,10:5
11,10,10:5
11,11,10:44.2
11,5,11:44.2
11,6,11:5
11,9,11:5
11,10,11:44.2
11,6,12:44.2
11,7,12:5
11,8,12:5
11,9,12:44.2
11,7,13:44.2
11,8,13:44.2
12,0,0:1
12,1,0:1
12,2,0:1
12,3,0:1
12,4,0:1
12,5,0:1
12,6,0:1
12,7,0:1
12,8,0:1
12,9,0:1
12,10,0:1
12,11,0:1
12,12,0:1
12,13,0:1
12,14,0:1
12,15,0:1
12,16,0:1
12,0,1:3
12,1,1:3
12,2,1:3
12,3,1:1
12,4,1:1
12,5,1:1
12,6,1:1
12,7,1:1
12,8,1:1
12,9,1:1
12,10,1:1
12,11,1:1
12,12,1:3
12,13,1:3
12,14,1:3
12,15,1:3
12,16,1:3
12,0,2:3
12,1,2:3
12,2,2:3
12,3,2:1
12,4,2:3
12,5,2:3
12,6,2:3
12,7,2:3
12,8,2:3
12,9,2:3
12,10,2:3
12,11,2:3
12,12,2:3
12,13,2:3
12,14,2:3
12,15,2:3
12,16,2:3
12,0,3:3
12,1,3:2
12,2,3:3
12,3,3:3
12,4,3:3
12,5,3:3
12,6,3:3
12,7,3:3
12,8,3:3
12,9,3:3
12,10,3:3
12,11,3:3
12,12,3:3
12,13,3:3
12,14,3:3
12,15,3:3
12,16,3:3
12,0,4:44.5
12,2,4:3
12,3,4:5
12,12,4:98
12,13,4:3
12,14,4:3
12,15,4:3
12,16,4:3
12,1,5:44.5
12,2,5:17.1
12,12,5:20
12,13,5:3
12,14,5:2
12,15,5:1
12,16,5:44.5
12,2,6:17.1
12,12,6:20
12,13,6:44.5
12,2,7:17.1
12,12,7:5
12,2,8:17.1
12,12,8:5
12,1,9:44.2
12,2,9:44.2
12,3,9:44.2
12,4,9:5
12,11,9:5
12,12,9:44.2
12,13,9:44.2
12,4,10:44.2
12,5,10:5
12,10,10:5
12,11,10:44.2
12,5,11:44.2
12,6,11:5
12,9,11:5
12,10,11:44.2
12,6,12:44.2
12,7,12:5
12,8,12:5
12,9,12:44.2
12,7,13:44.2
12,8,13:44.2
13,0,0:1
13,1,0:1
13,2,0:1
13,3,0:1
13,4,0:1
13,5,0:1
13,6,0:1
13,7,0:1
13,8,0:1
13,9,0:1
13,10,0:1
13,11,0:1
13,12,0:1
13,13,0:1
13,14,0:1
13,15,0:1
13,16,0:1
13,0,1:3
13,1,1:1
13,2,1:1
13,3,1:1
13,4,1:1
13,5,1:1
13,6,1:1
13,7,1:1
13,8,1:1
13,9,1:1
13,10,1:1
13,11,1:1
13,12,1:3
13,13,1:3
13,14,1:3
13,15,1:3
13,16,1:3
13,0,2:3
13,1,2:3
13,2,2:3
13,3,2:3
13,4,2:3
13,5,2:3
13,6,2:3
13,7,2:3
13,8,2:3
13,9,2:3
13,10,2:3
13,11,2:3
13,12,2:3
13,13,2:3
13,14,2:3
13,15,2:3
13,16,2:3
13,0,3:3
13,1,3:2
13,2,3:3
13,3,3:3
13,4,3:3
13,5,3:3
13,6,3:3
13,7,3:3
13,8,3:3
13,9,3:3
13,10,3:3
13,11,3:3
13,12,3:3
13,13,3:3
13,14,3:3
13,15,3:3
13,16,3:3
13,0,4:44.5
13,2,4:2
13,3,4:5
13,12,4:98
13,13,4:3
13,14,4:3
13,15,4:3
13,16,4:3
13,2,5:44.5
13,3,5:5
13,12,5:20
13,13,5:2
13,14,5:2
13,15,5:1
13,16,5:44.5
13,3,6:5
13,12,6:20
13,3,7:5
13,12,7:5
13,3,8:5
13,12,8:5
13,1,9:44.2
13,2,9:5
13,3,9:5
13,4,9:5
13,11,9:5
13,12,9:44.2
13,13,9:44.2
13,1,10:44.2
13,2,10:44.2
13,3,10:44.2
13,4,10:44.2
13,5,10:5
13,10,10:5
13,11,10:44.2
13,5,11:44.2
13,6,11:5
13,9,11:5
13,10,11:44.2
13,6,12:44.2
13,7,12:5
13,8,12:5
13,9,12:44.2
13,7,13:44.2
13,8,13:44.2
14,0,0:1
14,1,0:1
14,2,0:1
14,3,0:1
14,4,0:1
14,5,0:1
14,6,0:1
14,7,0:1
14,8,0:1
14,9,0:1
14,10,0:1
14,11,0:1
14,12,0:1
14,13,0:1
14,14,0:1
14,15,0:1
14,16,0:1
14,0,1:1
14,1,1:1
14,2,1:1
14,3,1:1
14,4,1:1
14,5,1:1
14,6,1:1
14,7,1:1
14,8,1:1
14,9,1:16
14,10,1:16
14,11,1:1
14,12,1:3
14,13,1:3
14,14,1:3
14,15,1:3
14,16,1:3
14,0,2:3
14,1,2:3
14,2,2:3
14,3,2:3
14,4,2:3
14,5,2:3
14,6,2:3
14,7,2:3
14,8,2:3
14,9,2:3
14,10,2:3
14,11,2:3
14,12,2:3
14,13,2:3
14,14,2:3
14,15,2:3
14,16,2:3
14,0,3:3
14,1,3:2
14,2,3:3
14,3,3:3
14,4,3:3
14,5,3:3
14,6,3:3
14,7,3:3
14,8,3:3
14,9,3:3
14,10,3:3
14,11,3:3
14,12,3:3
14,13,3:3
14,14,3:3
14,15,3:3
14,16,3:3
14,0,4:44.5
14,2,4:2
14,3,4:98
14,12,4:98
14,13,4:3
14,14,4:3
14,15,4:3
14,16,4:3
14,2,5:44.5
14,3,5:20
14,12,5:20
14,13,5:2
14,14,5:2
14,15,5:1
14,16,5:44.5
14,3,6:20
14,12,6:20
14,13,6:44.5
14,3,7:20
14,12,7:5
14,3,8:20
14,12,8:5
14,3,9:20
14,11,9:5
14,12,9:44.2
14,13,9:44.2
14,1,10:44.2
14,2,10:5
14,3,10:5
14,4,10:5
14,5,10:5
14,10,10:5
14,11,10:44.2
14,1,11:44.2
14,2,11:44.2
14,3,11:44.2
14,4,11:44.2
14,5,11:44.2
14,6,11:5
14,9,11:5
14,10,11:44.2
14,6,12:44.2
14,7,12:5
14,8,12:5
14,9,12:44.2
14,7,13:44.2
14,8,13:44.2
15,0,0:1
15,1,0:1
15,2,0:1
15,3,0:1
15,4,0:1
15,5,0:1
15,6,0:1
15,7,0:1
15,8,0:1
15,9,0:1
15,10,0:1
15,11,0:1
15,12,0:1
15,13,0:1
15,14,0:1
15,15,0:1
15,16,0:1
15,0,1:1
15,1,1:1
15,2,1:1
15,3,1:1
15,4,1:1
15,5,1:1
15,6,1:1
15,7,1:1
15,8,1:1
15,9,1:16
15,10,1:16
15,11,1:1
15,12,1:1
15,13,1:3
15,14,1:1
15,15,1:3
15,16,1:3
15,0,2:3
15,1,2:3
15,2,2:1
15,3,2:3
15,4,2:3
15,5,2:3
15,6,2:3
15,7,2:1
15,8,2:3
15,9,2:3
15,10,2:3
15,11,2:3
15,12,2:3
15,13,2:3
15,14,2:3
15,15,2:3
15,16,2:3
15,0,3:3
15,1,3:3
15,2,3:3
15,3,3:3
15,4,3:3
15,5,3:3
15,6,3:3
15,7,3:1
15,8,3:3
15,9,3:3
15,10,3:3
15,11,3:3
15,12,3:3
15,13,3:3
15,14,3:3
15,15,3:3
15,16,3:3
15,0,4:44.5
15,1,4:44.5
15,2,4:1
15,3,4:98
15,12,4:98
15,13,4:3
15,14,4:3
15,15,4:3
15,16,4:3
15,2,5:98
15,3,5:98
15,12,5:20
15,13,5:2
15,14,5:2
15,15,5:1
15,16,5:44.5
15,2,6:98
15,3,6:98
15,12,6:20
15,13,6:44.5
15,2,7:98
15,3,7:98
15,4,7:50.3
15,11,7:50.4
15,12,7:5
15,3,8:20
15,12,8:5
15,3,9:20
15,11,9:5
15,12,9:44.2
15,13,9:44.2
15,3,10:20
15,10,10:5
15,11,10:44.2
15,1,11:44.2
15,2,11:5
15,3,11:5
15,4,11:5
15,5,11:5
15,6,11:5
15,9,11:5
15,10,11:44.2
15,1,12:44.2
15,2,12:44.2
15,3,12:44.2
15,4,12:44.2
15,5,12:44.2
15,6,12:44.2
15,7,12:5
15,8,12:5
15,9,12:44.2
15,7,13:44.2
15,8,13:44.2
16,0,0:1
16,1,0:1
16,2,0:1
16,3,0:1
16,4,0:1
16,5,0:1
16,6,0:1
16,7,0:1
16,8,0:1
16,9,0:1
16,10,0:1
16,11,0:1
16,12,0:1
16,13,0:3
16,14,0:3
16,15,0:3
16,16,0:3
16,0,1:1
16,1,1:1
16,2,1:1
16,3,1:1
16,4,1:1
16,5,1:1
16,6,1:1
16,7,1:1
16,8,1:1
16,9,1:16
16,10,1:16
16,11,1:1
16,12,1:1
16,13,1:3
16,14,1:3
16,15,1:3
16,16,1:3
16,0,2:3
16,1,2:3
16,2,2:3
16,3,2:1
16,4,2:3
16,5,2:3
16,6,2:1
16,7,2:3
16,8,2:3
16,9,2:3
16,10,2:3
16,11,2:3
16,12,2:3
16,13,2:3
16,14,2:3
16,15,2:3
16,16,2:3
16,0,3:3
16,1,3:3
16,2,3:3
16,3,3:3
16,4,3:3
16,5,3:3
16,6,3:3
16,7,3:3
16,8,3:3
16,9,3:3
16,10,3:3
16,11,3:3
16,12,3:3
16,13,3:3
16,14,3:3
16,15,3:3
16,16,3:3
16,0,4:44
16,1,4:44
16,2,4:98
16,12,4:98
16,13,4:3
16,14,4:3
16,15,4:3
16,16,4:3
16,2,5:64.7
16,12,5:20
16,13,5:2
16,14,5:2
16,15,5:1
16,16,5:44.5
16,2,6:64.15
16,12,6:20
16,13,6:44.5
16,1,7:68.2
16,2,7:98
16,3,7:98
16,12,7:5
16,3,8:20
16,12,8:5
16,3,9:20
16,11,9:5
16,12,9:44.2
16,13,9:44.2
16,3,10:20
16,10,10:5
16,11,10:44.2
16,3,11:20
16,9,11:5
16,10,11:44.2
16,1,12:44.2
16,2,12:5
16,3,12:5
16,4,12:5
16,5,12:5
16,6,12:5
16,7,12:5
16,8,12:5
16,9,12:44.2
16,7,13:44.2
16,8,13:44.2
17,0,0:1
17,1,0:1
17,2,0:1
17,3,0:1
17,4,0:1
17,5,0:1
17,6,0:1
17,7,0:1
17,8,0:1
17,9,0:1
17,10,0:1
17,11,0:1
17,12,0:3
17,13,0:3
17,14,0:3
17,15,0:3
17,16,0:3
17,0,1:1
17,1,1:1
17,2,1:1
17,3,1:1
17,4,1:1
17,5,1:1
17,6,1:1
17,7,1:1
17,8,1:1
17,9,1:1
17,10,1:1
17,11,1:3
17,12,1:3
17,13,1:3
17,14,1:3
17,15,1:3
17,16,1:3
17,0,2:3
17,1,2:3
17,2,2:3
17,3,2:3
17,4,2:3
17,5,2:3
17,6,2:1
17,7,2:3
17,8,2:3
17,9,2:3
17,10,2:3
17,11,2:3
17,12,2:3
17,13,2:3
17,14,2:3
17,15,2:3
17,16,2:3
17,0,3:3
17,1,3:3
17,2,3:3
17,3,3:3
17,4,3:3
17,5,3:3
17,6,3:3
17,7,3:3
17,8,3:3
17,9,3:3
17,10,3:3
17,11,3:3
17,12,3:3
17,13,3:3
17,14,3:3
17,15,3:3
17,16,3:3
17,0,4:44
17,1,4:44
17,2,4:98
17,12,4:98
17,13,4:3
17,14,4:3
17,15,4:3
17,16,4:3
17,2,5:64.2
17,12,5:20
17,13,5:2
17,14,5:2
17,15,5:1
17,16,5:44.5
17,2,6:64.10
17,12,6:20
17,13,6:44.5
17,2,7:98
17,3,7:98
17,12,7:5
17,3,8:20
17,12,8:5
17,3,9:20
17,11,9:5
17,12,9:44.2
17,13,9:44.2
17,3,10:20
17,10,10:5
17,11,10:44.2
17,3,11:20
17,9,11:5
17,10,11:44.2
17,1,12:44.2
17,2,12:5
17,3,12:5
17,4,12:5
17,5,12:5
17,6,12:5
17,7,12:5
17,8,12:5
17,9,12:44.2
17,7,13:44.2
17,8,13:44.2
18,0,0:1
18,1,0:1
18,2,0:1
18,3,0:1
18,4,0:1
18,5,0:1
18,6,0:3
18,7,0:1
18,8,0:1
18,9,0:1
18,10,0:1
18,11,0:1
18,12,0:3
18,13,0:3
18,14,0:3
18,15,0:3
18,16,0:3
18,0,1:1
18,1,1:1
18,2,1:1
18,3,1:1
18,4,1:1
18,5,1:1
18,6,1:1
18,7,1:1
18,8,1:1
18,9,1:1
18,10,1:1
18,11,1:3
18,12,1:3
18,13,1:3
18,14,1:3
18,15,1:3
18,16,1:3
18,0,2:3
18,1,2:3
18,2,2:3
18,3,2:3
18,4,2:3
18,5,2:3
18,6,2:1
18,7,2:3
18,8,2:3
18,9,2:3
18,10,2:3
18,11,2:3
18,12,2:3
18,13,2:3
18,14,2:3
18,15,2:3
18,16,2:3
18,0,3:3
18,1,3:3
18,2,3:3
18,3,3:3
18,4,3:3
18,5,3:3
18,6,3:3
18,7,3:3
18,8,3:3
18,9,3:3
18,10,3:3
18,11,3:3
18,12,3:3
18,13,3:3
18,14,3:3
18,15,3:3
18,16,3:3
18,0,4:44.5
18,1,4:44.5
18,2,4:1
18,3,4:98
18,12,4:98
18,13,4:3
18,14,4:3
18,15,4:3
18,16,4:3
18,2,5:98
18,3,5:98
18,12,5:20
18,13,5:2
18,14,5:2
18,15,5:1
18,16,5:44.5
18,2,6:98
18,3,6:98
18,12,6:5
18,2,7:98
18,3,7:98
18,4,7:50.3
18,12,7:5
18,3,8:20
18,12,8:5
18,3,9:20
18,11,9:5
18,12,9:44.2
18,13,9:44.2
18,3,10:20
18,10,10:5
18,11,10:44.2
18,1,11:44.2
18,2,11:5
18,3,11:5
18,4,11:5
18,5,11:5
18,6,11:5
18,9,11:5
18,10,11:44.2
18,1,12:44.2
18,2,12:44.2
18,3,12:44.2
18,4,12:44.2
18,5,12:44.2
18,6,12:44.2
18,7,12:5
18,8,12:5
18,9,12:44.2
18,7,13:44.2
18,8,13:44.2
19,0,0:1
19,1,0:1
19,2,0:1
19,3,0:1
19,4,0:1
19,5,0:1
19,6,0:3
19,7,0:3
19,8,0:3
19,9,0:1
19,10,0:1
19,11,0:1
19,12,0:1
19,13,0:3
19,14,0:3
19,15,0:3
19,16,0:3
19,0,1:1
19,1,1:1
19,2,1:1
19,3,1:1
19,4,1:1
19,5,1:1
19,6,1:1
19,7,1:1
19,8,1:1
19,9,1:1
19,10,1:1
19,11,1:1
19,12,1:1
19,13,1:3
19,14,1:3
19,15,1:3
19,16,1:3
19,0,2:3
19,1,2:3
19,2,2:3
19,3,2:3
19,4,2:3
19,5,2:3
19,6,2:1
19,7,2:3
19,8,2:3
19,9,2:3
19,10,2:3
19,11,2:3
19,12,2:3
19,13,2:3
19,14,2:3
19,15,2:3
19,16,2:3
19,0,3:3
19,1,3:2
19,2,3:3
19,3,3:3
19,4,3:3
19,5,3:3
19,6,3:3
19,7,3:3
19,8,3:3
19,9,3:3
19,10,3:3
19,11,3:3
19,12,3:3
19,13,3:3
19,14,3:3
19,15,3:3
19,16,3:3
19,0,4:44.5
19,1,4:89
19,2,4:2
19,3,4:98
19,12,4:98
19,13,4:3
19,14,4:3
19,15,4:3
19,16,4:3
19,2,5:44.5
19,12,5:20
19,13,5:3
19,14,5:2
19,15,5:1
19,16,5:44.5
19,12,6:20
19,13,6:44.5
19,12,7:5
19,3,8:20
19,12,8:5
19,3,9:20
19,11,9:5
19,12,9:44.2
19,13,9:44.2
19,1,10:44.2
19,2,10:5
19,3,10:5
19,4,10:5
19,5,10:5
19,10,10:5
19,11,10:44.2
19,1,11:44.2
19,2,11:44.2
19,3,11:44.2
19,4,11:44.2
19,5,11:44.2
19,6,11:5
19,9,11:5
19,10,11:44.2
19,6,12:44.2
19,7,12:5
19,8,12:5
19,9,12:44.2
19,7,13:44.2
19,8,13:44.2
20,0,0:1
20,1,0:1
20,2,0:1
20,3,0:1
20,4,0:1
20,5,0:1
20,6,0:1
20,7,0:3
20,8,0:3
20,9,0:1
20,10,0:1
20,11,0:1
20,12,0:1
20,13,0:1
20,14,0:1
20,15,0:1
20,16,0:1
20,0,1:1
20,1,1:1
20,2,1:1
20,3,1:1
20,4,1:1
20,5,1:1
20,6,1:1
20,7,1:1
20,8,1:1
20,9,1:1
20,10,1:1
20,11,1:1
20,12,1:1
20,13,1:1
20,14,1:1
20,15,1:3
20,16,1:1
20,0,2:3
20,1,2:1
20,2,2:3
20,3,2:3
20,4,2:3
20,5,2:3
20,6,2:3
20,7,2:3
20,8,2:3
20,9,2:3
20,10,2:3
20,11,2:3
20,12,2:3
20,13,2:3
20,14,2:3
20,15,2:3
20,16,2:3
20,0,3:3
20,1,3:2
20,2,3:3
20,3,3:3
20,4,3:3
20,5,3:3
20,6,3:3
20,7,3:3
20,8,3:3
20,9,3:3
20,10,3:3
20,11,3:3
20,12,3:3
20,13,3:3
20,14,3:3
20,15,3:3
20,16,3:3
20,0,4:44.5
20,1,4:89
20,2,4:2
20,3,4:98
20,12,4:98
20,13,4:3
20,14,4:3
20,15,4:3
20,16,4:3
20,2,5:44.5
20,3,5:5
20,12,5:20
20,13,5:2
20,14,5:2
20,15,5:1
20,16,5:44.5
20,3,6:5
20,13,6:44.5
20,3,7:5
20,12,7:5
20,3,8:5
20,12,8:5
20,1,9:44.2
20,2,9:5
20,3,9:5
20,4,9:5
20,11,9:5
20,12,9:44.2
20,13,9:44.2
20,1,10:44.2
20,2,10:44.2
20,3,10:44.2
20,4,10:44.2
20,5,10:5
20,10,10:5
20,11,10:44.2
20,5,11:44.2
20,6,11:5
20,9,11:5
20,10,11:44.2
20,6,12:44.2
20,7,12:5
20,8,12:5
20,9,12:44.2
20,7,13:44.2
20,8,13:44.2
21,0,0:1
21,1,0:1
21,2,0:1
21,4,0:1
21,5,0:1
21,6,0:1
21,7,0:3
21,8,0:3
21,9,0:1
21,10,0:1
21,11,0:1
21,12,0:1
21,13,0:1
21,14,0:1
21,15,0:1
21,16,0:1
21,0,1:1
21,1,1:1
21,2,1:1
21,4,1:1
21,5,1:1
21,6,1:1
21,7,1:1
21,8,1:1
21,9,1:1
21,10,1:1
21,11,1:1
21,12,1:1
21,13,1:1
21,14,1:1
21,15,1:1
21,16,1:3
21,0,2:3
21,1,2:3
21,2,2:1
21,4,2:1
21,5,2:3
21,6,2:3
21,7,2:3
21,8,2:3
21,9,2:3
21,10,2:3
21,11,2:3
21,12,2:3
21,13,2:3
21,14,2:3
21,15,2:3
21,16,2:3
21,0,3:3
21,1,3:2
21,2,3:3
21,4,3:1
21,5,3:3
21,6,3:3
21,7,3:3
21,8,3:3
21,9,3:3
21,10,3:3
21,11,3:3
21,12,3:3
21,13,3:3
21,14,3:3
21,15,3:3
21,16,3:3
21,0,4:44.5
21,1,4:89
21,2,4:3
21,3,4:98
21,12,4:98
21,13,4:3
21,14,4:3
21,15,4:3
21,16,4:3
21,1,5:44.5
21,2,5:17.1
21,12,5:20
21,13,5:2
21,14,5:2
21,15,5:1
21,16,5:44.5
21,2,6:17.1
21,13,6:44.5
21,2,7:17.1
21,12,7:5
21,2,8:17.1
21,12,8:5
21,1,9:44.2
21,2,9:44.2
21,3,9:44.2
21,4,9:5
21,11,9:5
21,12,9:44.2
21,13,9:44.2
21,4,10:44.2
21,5,10:5
21,10,10:5
21,11,10:44.2
21,5,11:44.2
21,6,11:5
21,9,11:5
21,10,11:44.2
21,6,12:44.2
21,7,12:5
21,8,12:5
21,9,12:44.2
21,7,13:44.2
21,8,13:44.2
22,0,0:1
22,1,0:1
22,2,0:1
22,4,0:1
22,5,0:1
22,6,0:1
22,7,0:1
22,8,0:1
22,9,0:1
22,10,0:1
22,11,0:1
22,12,0:1
22,13,0:1
22,14,0:1
22,15,0:1
22,16,0:1
22,0,1:1
22,1,1:1
22,2,1:1
22,4,1:1
22,5,1:1
22,6,1:1
22,7,1:1
22,8,1:1
22,9,1:1
22,10,1:1
22,11,1:1
22,12,1:1
22,13,1:1
22,14,1:1
22,15,1:1
22,16,1:1
22,0,2:3
22,1,2:3
22,2,2:1
22,4,2:1
22,5,2:3
22,6,2:3
22,7,2:3
22,8,2:3
22,9,2:3
22,10,2:3
22,11,2:3
22,12,2:3
22,13,2:3
22,14,2:3
22,15,2:3
22,16,2:3
22,0,3:3
22,1,3:2
22,2,3:3
22,4,3:1
22,5,3:3
22,6,3:3
22,7,3:3
22,8,3:3
22,9,3:3
22,10,3:3
22,11,3:3
22,12,3:3
22,13,3:3
22,14,3:3
22,15,3:3
22,16,3:3
22,0,4:44.5
22,1,4:89
22,2,4:3
22,3,4:98
22,12,4:98
22,13,4:3
22,14,4:3
22,15,4:3
22,16,4:3
22,2,5:17.1
22,12,5:20
22,13,5:3
22,14,5:2
22,15,5:1
22,16,5:44.5
22,2,6:17.1
22,13,6:44.5
22,2,7:17.1
22,12,7:5
22,2,8:17.1
22,12,8:5
22,2,9:44.2
22,3,9:44.2
22,4,9:5
22,11,9:5
22,12,9:44.2
22,13,9:44.2
22,4,10:44.2
22,5,10:5
22,10,10:5
22,11,10:44.2
22,5,11:44.2
22,6,11:5
22,9,11:5
22,10,11:44.2
22,6,12:44.2
22,7,12:5
22,8,12:5
22,9,12:44.2
22,7,13:44.2
22,8,13:44.2
23,0,0:1
23,1,0:1
23,2,0:1
23,3,0:1
23,4,0:1
23,5,0:1
23,6,0:1
23,7,0:1
23,8,0:1
23,9,0:1
23,10,0:1
23,11,0:1
23,12,0:1
23,13,0:1
23,14,0:1
23,15,0:1
23,16,0:1
23,0,1:1
23,1,1:1
23,2,1:1
23,3,1:1
23,4,1:1
23,5,1:1
23,6,1:1
23,7,1:1
23,8,1:1
23,9,1:1
23,10,1:1
23,11,1:1
23,12,1:1
23,13,1:1
23,14,1:1
23,15,1:1
23,16,1:1
23,0,2:1
23,1,2:1
23,2,2:3
23,3,2:1
23,4,2:1
23,5,2:3
23,6,2:3
23,7,2:3
23,8,2:3
23,9,2:3
23,10,2:3
23,11,2:3
23,12,2:3
23,13,2:3
23,14,2:3
23,15,2:3
23,16,2:3
23,0,3:1
23,1,3:2
23,2,3:3
23,3,3:1
23,4,3:1
23,5,3:3
23,6,3:3
23,7,3:3
23,8,3:3
23,9,3:3
23,10,3:3
23,11,3:3
23,12,3:3
23,13,3:3
23,14,3:3
23,15,3:3
23,16,3:3
23,0,4:44.5
23,1,4:89
23,2,4:2
23,3,4:98
23,12,4:98
23,13,4:3
23,14,4:3
23,15,4:3
23,16,4:3
23,2,5:44.5
23,3,5:5
23,13,5:2
23,14,5:2
23,15,5:1
23,16,5:44.5
23,3,6:20
23,13,6:44.5
23,3,7:20
23,12,7:5
23,3,8:5
23,12,8:5
23,2,9:44.2
23,3,9:44.2
23,4,9:5
23,11,9:5
23,12,9:44.2
23,13,9:44.2
23,4,10:44.2
23,5,10:5
23,10,10:5
23,11,10:44.2
23,5,11:44.2
23,6,11:5
23,9,11:5
23,10,11:44.2
23,6,12:44.2
23,7,12:5
23,8,12:5
23,9,12:44.2
23,7,13:44.2
23,8,13:44.2
24,0,0:1
24,1,0:1
24,2,0:1
24,3,0:1
24,4,0:1
24,5,0:1
24,6,0:1
24,7,0:1
24,8,0:1
24,9,0:1
24,10,0:1
24,11,0:1
24,12,0:1
24,13,0:1
24,14,0:1
24,15,0:1
24,16,0:1
24,0,1:1
24,1,1:1
24,2,1:1
24,3,1:1
24,4,1:1
24,5,1:1
24,6,1:1
24,7,1:1
24,8,1:1
24,9,1:1
24,10,1:1
24,11,1:1
24,12,1:1
24,13,1:1
24,14,1:3
24,15,1:3
24,16,1:3
24,0,2:1
24,1,2:1
24,2,2:3
24,3,2:3
24,4,2:1
24,5,2:3
24,6,2:1
24,7,2:3
24,8,2:3
24,9,2:3
24,10,2:3
24,11,2:3
24,12,2:3
24,13,2:3
24,14,2:3
24,15,2:3
24,16,2:3
24,0,3:3
24,1,3:2
24,2,3:3
24,3,3:3
24,4,3:3
24,5,3:3
24,6,3:1
24,7,3:3
24,8,3:3
24,9,3:3
24,10,3:3
24,11,3:3
24,12,3:3
24,13,3:3
24,14,3:3
24,15,3:3
24,16,3:3
24,0,4:44.5
24,1,4:89
24,2,4:2
24,3,4:98
24,12,4:98
24,13,4:3
24,14,4:3
24,15,4:3
24,16,4:3
24,2,5:44.5
24,3,5:5
24,13,5:2
24,14,5:2
24,15,5:1
24,16,5:44.5
24,13,6:44.5
24,3,7:4
24,12,7:5
24,3,8:5
24,12,8:5
24,2,9:44.2
24,3,9:44.2
24,4,9:5
24,11,9:5
24,12,9:44.2
24,13,9:44.2
24,4,10:44.2
24,5,10:5
24,10,10:5
24,11,10:44.2
24,5,11:44.2
24,6,11:5
24,9,11:5
24,10,11:44.2
24,6,12:44.2
24,7,12:5
24,8,12:5
24,9,12:44.2
24,7,13:44.2
24,8,13:44.2
25,0,0:1
25,1,0:1
25,2,0:1
25,3,0:1
25,4,0:1
25,5,0:1
25,6,0:1
25,7,0:1
25,8,0:1
25,9,0:1
25,10,0:1
25,11,0:1
25,12,0:1
25,13,0:1
25,14,0:1
25,15,0:1
25,16,0:1
25,0,1:1
25,1,1:1
25,2,1:1
25,3,1:1
25,4,1:1
25,5,1:1
25,6,1:1
25,7,1:1
25,8,1:1
25,9,1:1
25,10,1:1
25,11,1:1
25,12,1:1
25,13,1:1
25,14,1:1
25,15,1:1
25,16,1:1
25,0,2:1
25,1,2:1
25,2,2:3
25,3,2:3
25,4,2:3
25,5,2:1
25,6,2:1
25,7,2:3
25,8,2:3
25,9,2:3
25,10,2:3
25,11,2:3
25,12,2:3
25,13,2:3
25,14,2:1
25,15,2:1
25,16,2:1
25,0,3:3
25,1,3:2
25,2,3:3
25,3,3:3
25,4,3:3
25,5,3:3
25,6,3:1
25,7,3:3
25,8,3:3
25,9,3:3
25,10,3:3
25,11,3:3
25,12,3:3
25,13,3:3
25,14,3:3
25,15,3:3
25,16,3:3
25,0,4:44.5
25,1,4:89
25,2,4:2
25,3,4:98
25,12,4:98
25,13,4:3
25,14,4:3
25,15,4:3
25,16,4:3
25,2,5:44.5
25,3,5:5
25,12,5:20
25,13,5:2
25,14,5:2
25,15,5:1
25,16,5:44.5
25,3,6:20
25,12,6:20
25,13,6:44.5
25,3,7:20
25,12,7:5
25,3,8:5
25,12,8:5
25,2,9:44.2
25,3,9:44.2
25,4,9:5
25,11,9:5
25,12,9:44.2
25,13,9:44.2
25,4,10:44.2
25,5,10:5
25,10,10:5
25,11,10:44.2
25,5,11:44.2
25,6,11:5
25,9,11:5
25,10,11:44.2
25,6,12:44.2
25,7,12:5
25,8,12:5
25,9,12:44.2
25,7,13:44.2
25,8,13:44.2
26,0,0:1
26,1,0:1
26,2,0:1
26,3,0:1
26,4,0:1
26,5,0:1
26,6,0:1
26,7,0:1
26,8,0:1
26,9,0:1
26,10,0:1
26,11,0:1
26,12,0:1
26,13,0:1
26,14,0:1
26,15,0:1
26,16,0:1
26,0,1:1
26,1,1:1
26,2,1:1
26,3,1:1
26,4,1:1
26,5,1:1
26,6,1:1
26,7,1:1
26,8,1:1
26,9,1:1
26,10,1:1
26,11,1:1
26,12,1:1
26,13,1:1
26,14,1:1
26,15,1:1
26,16,1:1
26,0,2:1
26,1,2:3
26,2,2:1
26,3,2:1
26,4,2:1
26,5,2:1
26,6,2:1
26,7,2:1
26,8,2:1
26,9,2:1
26,10,2:3
26,11,2:3
26,12,2:3
26,13,2:3
26,14,2:1
26,15,2:1
26,16,2:1
26,0,3:3
26,1,3:2
26,2,3:3
26,3,3:3
26,4,3:3
26,5,3:1
26,6,3:1
26,7,3:3
26,8,3:3
26,9,3:3
26,11,3:3
26,12,3:3
26,13,3:3
26,14,3:3
26,15,3:3
26,16,3:3
26,0,4:44.5
26,1,4:89
26,2,4:3
26,3,4:98
26,12,4:98
26,13,4:3
26,14,4:3
26,15,4:3
26,16,4:3
26,1,5:44.5
26,2,5:17.1
26,12,5:20
26,13,5:2
26,14,5:2
26,15,5:1
26,16,5:44.5
26,2,6:17.1
26,12,6:20
26,13,6:44.5
26,2,7:17.1
26,12,7:5
26,2,8:17.1
26,12,8:5
26,2,9:44.2
26,3,9:44.2
26,4,9:5
26,11,9:5
26,12,9:44.2
26,13,9:44.2
26,4,10:44.2
26,5,10:5
26,10,10:5
26,11,10:44.2
26,5,11:44.2
26,6,11:5
26,9,11:5
26,10,11:44.2
26,6,12:44.2
26,7,12:5
26,8,12:5
26,9,12:44.2
26,7,13:44.2
26,8,13:44.2
27,0,0:1
27,1,0:1
27,2,0:1
27,3,0:1
27,4,0:1
27,5,0:1
27,6,0:1
27,7,0:1
27,8,0:3
27,9,0:3
27,10,0:1
27,11,0:1
27,12,0:1
27,13,0:1
27,14,0:1
27,15,0:1
27,16,0:1
27,0,1:1
27,1,1:1
27,2,1:1
27,3,1:1
27,4,1:1
27,5,1:1
27,6,1:1
27,7,1:1
27,8,1:1
27,9,1:1
27,10,1:1
27,11,1:1
27,12,1:1
27,13,1:1
27,14,1:1
27,15,1:1
27,16,1:1
27,0,2:1
27,1,2:3
27,2,2:1
27,3,2:1
27,4,2:1
27,5,2:1
27,6,2:1
27,7,2:1
27,8,2:1
27,9,2:1
27,10,2:1
27,11,2:1
27,12,2:1
27,13,2:1
27,14,2:1
27,15,2:1
27,16,2:1
27,0,3:3
27,1,3:2
27,2,3:3
27,3,3:3
27,4,3:3
27,5,3:3
27,6,3:3
27,7,3:3
27,8,3:3
27,9,3:3
27,10,3:3
27,11,3:3
27,12,3:3
27,13,3:3
27,14,3:3
27,15,3:3
27,16,3:3
27,0,4:44.5
27,1,4:89
27,2,4:3
27,3,4:98
27,12,4:98
27,13,4:3
27,14,4:3
27,15,4:3
27,16,4:3
27,1,5:44.5
27,2,5:17.1
27,12,5:20
27,13,5:2
27,14,5:2
27,15,5:1
27,16,5:44.5
27,2,6:17.1
27,12,6:20
27,13,6:44.5
27,2,7:17.1
27,12,7:5
27,2,8:17.1
27,12,8:5
27,2,9:44.2
27,3,9:44.2
27,4,9:5
27,11,9:5
27,12,9:44.2
27,13,9:44.2
27,4,10:44.2
27,5,10:5
27,10,10:5
27,11,10:44.2
27,5,11:44.2
27,6,11:5
27,9,11:5
27,10,11:44.2
27,6,12:44.2
27,7,12:5
27,8,12:5
27,9,12:44.2
27,7,13:44.2
27,8,13:44.2
28,0,0:1
28,1,0:1
28,2,0:1
28,3,0:1
28,4,0:1
28,5,0:1
28,6,0:1
28,7,0:3
28,8,0:3
28,9,0:3
28,10,0:1
28,11,0:1
28,12,0:1
28,13,0:1
28,14,0:1
28,15,0:1
28,16,0:1
28,0,1:1
28,1,1:1
28,2,1:1
28,3,1:1
28,4,1:1
28,5,1:1
28,6,1:1
28,7,1:1
28,8,1:1
28,9,1:1
28,10,1:1
28,11,1:1
28,12,1:1
28,13,1:1
28,14,1:1
28,15,1:1
28,16,1:1
28,0,2:1
28,1,2:1
28,2,2:3
28,3,2:1
28,4,2:1
28,5,2:1
28,6,2:1
28,7,2:1
28,8,2:1
28,9,2:1
28,10,2:1
28,11,2:1
28,12,2:1
28,13,2:1
28,15,2:1
28,16,2:1
28,0,3:3
28,1,3:2
28,2,3:3
28,3,3:3
28,4,3:3
28,5,3:3
28,6,3:3
28,7,3:3
28,8,3:3
28,9,3:3
28,10,3:3
28,11,3:3
28,12,3:3
28,13,3:3
28,14,3:3
28,15,3:3
28,16,3:3
28,0,4:44.5
28,1,4:89
28,2,4:2
28,3,4:98
28,4,4:5
28,11,4:5
28,12,4:98
28,13,4:3
28,14,4:3
28,15,4:3
28,16,4:3
28,2,5:44.5
28,3,5:5
28,12,5:20
28,13,5:2
28,14,5:2
28,15,5:1
28,16,5:44.5
28,3,6:20
28,12,6:20
28,13,6:44.5
28,3,7:20
28,12,7:5
28,3,8:5
28,12,8:5
28,2,9:44.2
28,3,9:44.2
28,4,9:5
28,11,9:5
28,12,9:44.2
28,13,9:44.2
28,4,10:44.2
28,5,10:5
28,10,10:5
28,11,10:44.2
28,5,11:44.2
28,6,11:5
28,9,11:5
28,10,11:44.2
28,6,12:44.2
28,7,12:5
28,8,12:5
28,9,12:44.2
28,7,13:44.2
28,8,13:44.2
29,0,0:1
29,1,0:1
29,2,0:1
29,3,0:1
29,4,0:1
29,5,0:1
29,6,0:1
29,7,0:3
29,8,0:3
29,9,0:3
29,10,0:1
29,11,0:1
29,12,0:1
29,13,0:1
29,14,0:1
29,15,0:1
29,16,0:1
29,0,1:1
29,1,1:1
29,2,1:1
29,3,1:1
29,4,1:1
29,5,1:1
29,6,1:1
29,7,1:1
29,8,1:1
29,9,1:1
29,10,1:1
29,11,1:1
29,12,1:1
29,13,1:1
29,14,1:1
29,15,1:1
29,16,1:1
29,0,2:1
29,1,2:3
29,2,2:3
29,3,2:1
29,4,2:1
29,5,2:1
29,6,2:1
29,7,2:1
29,8,2:1
29,9,2:1
29,10,2:1
29,11,2:1
29,12,2:1
29,13,2:1
29,15,2:1
29,16,2:1
29,0,3:3
29,1,3:2
29,2,3:3
29,3,3:3
29,4,3:3
29,5,3:3
29,6,3:1
29,7,3:3
29,8,3:3
29,9,3:3
29,10,3:3
29,11,3:3
29,12,3:3
29,13,3:3
29,14,3:3
29,15,3:3
29,16,3:3
29,0,4:44.5
29,1,4:89
29,2,4:2
29,3,4:98
29,4,4:5
29,5,4:5
29,6,4:5
29,7,4:5
29,8,4:5
29,9,4:5
29,10,4:5
29,11,4:5
29,12,4:98
29,13,4:3
29,14,4:3
29,15,4:3
29,16,4:3
29,2,5:44.5
29,3,5:5
29,12,5:20
29,13,5:2
29,14,5:2
29,15,5:1
29,16,5:44.5
29,3,6:20
29,12,6:20
29,13,6:44.5
29,3,7:20
29,5,7:50.2
29,10,7:50.2
29,12,7:5
29,3,8:5
29,12,8:5
29,2,9:44.2
29,3,9:44.2
29,4,9:5
29,11,9:5
29,12,9:44.2
29,13,9:44.2
29,4,10:44.2
29,5,10:5
29,10,10:5
29,11,10:44.2
29,5,11:44.2
29,6,11:5
29,9,11:5
29,10,11:44.2
29,6,12:44.2
29,7,12:5
29,8,12:5
29,9,12:44.2
29,7,13:44.2
29,8,13:44.2
30,0,0:1
30,1,0:1
30,2,0:1
30,3,0:1
30,4,0:1
30,5,0:1
30,6,0:1
30,7,0:3
30,8,0:3
30,9,0:3
30,10,0:3
30,11,0:1
30,12,0:1
30,13,0:4
30,0,1:3
30,1,1:3
30,2,1:1
30,3,1:1
30,4,1:1
30,5,1:1
30,6,1:1
30,7,1:1
30,8,1:3
30,9,1:3
30,10,1:1
30,11,1:1
30,12,1:1
30,14,1:1
30,0,2:3
30,1,2:3
30,2,2:3
30,3,2:1
30,4,2:1
30,5,2:1
30,6,2:1
30,7,2:1
30,8,2:1
30,9,2:1
30,10,2:1
30,11,2:1
30,12,2:1
30,0,3:3
30,1,3:2
30,2,3:3
30,3,3:3
30,4,3:3
30,5,3:3
30,6,3:3
30,7,3:3
30,8,3:3
30,9,3:3
30,10,3:1
30,11,3:1
30,12,3:1
30,13,3:3
30,14,3:3
30,15,3:3
30,16,3:3
30,0,4:44.5
30,1,4:89
30,2,4:3
30,3,4:98
30,4,4:98
30,5,4:98
30,6,4:98
30,7,4:98
30,8,4:98
30,9,4:98
30,10,4:98
30,11,4:98
30,12,4:3
30,13,4:3
30,14,4:3
30,15,4:3
30,16,4:3
30,1,5:44.5
30,2,5:17.1
30,3,5:98
30,4,5:20
30,5,5:20
30,6,5:20
30,7,5:20
30,8,5:20
30,9,5:20
30,10,5:20
30,11,5:20
30,12,5:98
30,13,5:3
30,14,5:3
30,15,5:1
30,16,5:44.5
30,2,6:17.1
30,3,6:5
30,4,6:20
30,5,6:20
30,6,6:20
30,7,6:20
30,8,6:20
30,9,6:20
30,10,6:20
30,11,6:20
30,12,6:5
30,13,6:17.1
30,14,6:44.5
30,2,7:17.1
30,3,7:5
30,4,7:5
30,5,7:5
30,6,7:5
30,7,7:5
30,8,7:5
30,9,7:5
30,10,7:5
30,11,7:5
30,12,7:5
30,13,7:17.1
30,2,8:17.1
30,3,8:5
30,4,8:5
30,5,8:20
30,6,8:20
30,7,8:20
30,8,8:20
30,9,8:20
30,10,8:20
30,11,8:5
30,12,8:5
30,13,8:17.1
30,2,9:44.2
30,3,9:44.2
30,4,9:5
30,5,9:5
30,6,9:20
30,7,9:20
30,8,9:20
30,9,9:20
30,10,9:5
30,11,9:5
30,12,9:44.2
30,13,9:44.2
30,4,10:44.2
30,5,10:5
30,6,10:5
30,7,10:20
30,8,10:20
30,9,10:5
30,10,10:5
30,11,10:44.2
30,5,11:44.2
30,6,11:5
30,7,11:5
30,8,11:5
30,9,11:5
30,10,11:44.2
30,6,12:44.2
30,7,12:5
30,8,12:5
30,9,12:44.2
30,7,13:44.2
30,8,13:44.2
31,0,0:3
31,1,0:3
31,2,0:1
31,3,0:1
31,4,0:1
31,5,0:1
31,6,0:1
31,7,0:3
31,8,0:3
31,9,0:3
31,10,0:3
31,11,0:1
31,12,0:1
31,13,0:1
31,0,1:3
31,1,1:3
31,2,1:3
31,3,1:1
31,4,1:1
31,5,1:1
31,6,1:1
31,7,1:1
31,8,1:3
31,9,1:3
31,10,1:1
31,11,1:1
31,12,1:1
31,0,2:3
31,1,2:3
31,2,2:3
31,3,2:3
31,4,2:1
31,5,2:1
31,6,2:1
31,7,2:1
31,8,2:1
31,9,2:1
31,10,2:1
31,11,2:1
31,12,2:1
31,14,2:1
31,15,2:1
31,0,3:3
31,1,3:2
31,2,3:3
31,3,3:3
31,4,3:1
31,5,3:3
31,6,3:3
31,7,3:3
31,8,3:1
31,9,3:1
31,10,3:1
31,11,3:1
31,12,3:1
31,13,3:3
31,14,3:3
31,15,3:3
31,16,3:3
31,0,4:44.5
31,1,4:89
31,2,4:3
31,3,4:3
31,4,4:2
31,5,4:2
31,6,4:2
31,7,4:2
31,8,4:2
31,9,4:2
31,10,4:2
31,11,4:2
31,12,4:3
31,13,4:3
31,14,4:3
31,15,4:3
31,16,4:3
31,1,5:44.5
31,2,5:17.1
31,3,5:17.1
31,4,5:44.5
31,5,5:44.5
31,6,5:44.5
31,7,5:44.5
31,8,5:44.5
31,9,5:44.5
31,10,5:44.5
31,11,5:44.5
31,12,5:17.1
31,13,5:3
31,14,5:2
31,15,5:1
31,16,5:44.5
31,2,6:17.1
31,3,6:17.1
31,12,6:17.1
31,13,6:17.1
31,14,6:44.5
31,2,7:17.1
31,3,7:17.1
31,12,7:17.1
31,13,7:17.1
31,2,8:17.1
31,3,8:17.1
31,12,8:17.1
31,13,8:17.1
31,2,9:44.2
31,3,9:44.2
31,4,9:44.2
31,5,9:44.2
31,6,9:44.2
31,7,9:44.2
31,8,9:44.2
31,9,9:44.2
31,10,9:44.2
31,11,9:44.2
31,12,9:44.2
31,13,9:44.2
31,4,10:44.2
31,5,10:44.2
31,6,10:44.2
31,7,10:44.2
31,8,10:44.2
31,9,10:44.2
31,10,10:44.2
31,11,10:44.2
31,5,11:44.2
31,6,11:44.2
31,7,11:44.2
31,8,11:44.2
31,9,11:44.2
31,10,11:44.2
31,6,12:44.2
31,7,12:44.2
31,8,12:44.2
31,9,12:44.2
32,0,0:3
32,1,0:3
32,2,0:3
32,3,0:1
32,4,0:1
32,5,0:1
32,6,0:1
32,7,0:3
32,8,0:3
32,9,0:3
32,10,0:3
32,11,0:1
32,12,0:1
32,13,0:1
32,14,0:1
32,15,0:1
32,16,0:1
32,0,1:3
32,1,1:3
32,2,1:3
32,3,1:3
32,4,1:1
32,5,1:1
32,6,1:1
32,7,1:1
32,8,1:3
32,9,1:3
32,10,1:1
32,11,1:1
32,12,1:58
32,0,2:3
32,1,2:3
32,2,2:3
32,3,2:3
32,4,2:1
32,5,2:1
32,6,2:1
32,7,2:1
32,8,2:1
32,9,2:1
32,10,2:1
32,11,2:1
32,14,2:1
32,15,2:1
32,16,2:1
32,0,3:3
32,1,3:2
32,2,3:3
32,3,3:3
32,4,3:1
32,5,3:1
32,6,3:3
32,7,3:3
32,8,3:1
32,9,3:1
32,10,3:1
32,11,3:1
32,12,3:1
32,13,3:3
32,14,3:3
32,15,3:3
32,16,3:3
32,0,4:44.5
32,1,4:89
32,2,4:2
32,3,4:2
32,4,4:2
32,5,4:2
32,6,4:2
32,7,4:2
32,8,4:2
32,9,4:2
32,10,4:2
32,11,4:2
32,12,4:2
32,13,4:3
32,14,4:3
32,15,4:3
32,16,4:3
32,13,5:2
32,14,5:2
32,15,5:1
32,16,5:44.5
