[META]
version=2.0
spawnSunlight=True
spawnDarkness=True
spawnWater=False
spawnLava=False
underFill=False
randomRotation=True
dig=True
tree=False
branch=False
needsFoundation=True
rarity=30
collisionPercentage=5
spawnElevationMin=0
spawnElevationMax=200
branchLimit=6
spawnInBiome=All
[DATA]
0,0,0:24
0,1,0:24
0,2,0:24
0,3,0:24
0,4,0:24
0,5,0:24
0,6,0:24
0,7,0:24
0,8,0:24
0,9,0:24
0,10,0:24
0,11,0:24
0,12,0:24
0,13,0:24
0,14,0:24
0,15,0:24
0,16,0:24
0,17,0:24
0,18,0:24
0,19,0:24
0,20,0:24
0,21,0:24
0,22,0:24
0,23,0:24
0,24,0:24
0,25,0:24
0,26,0:24
0,27,0:24
0,28,0:24
0,29,0:24
0,30,0:24
0,31,0:24
0,32,0:24
0,33,0:24
0,34,0:24
0,35,0:24
0,36,0:24
0,37,0:24
0,38,0:24
0,39,0:24
0,40,0:24
0,41,0:24
0,42,0:24
0,43,0:24
0,44,0:24
0,45,0:24
0,46,0:24
0,47,0:24
0,48,0:24
0,49,0:24
0,50,0:24
0,51,0:24
0,52,0:24
0,53,0:24
0,54,0:24
0,55,0:24
0,56,0:24
0,57,0:24
0,58,0:24
0,59,0:24
0,60,0:24
0,61,0:24
0,62,0:24
0,63,0:24
0,64,0:24
0,65,0:24
0,66,0:98
0,67,0:98
0,68,0:98
0,69,0:98
0,70,0:98
0,71,0:98
0,72,0:98
0,73,0:98
0,74,0:98
0,75,0:98
0,76,0:98
0,77,0:98
0,78,0:98
0,79,0:98
0,80,0:98
0,81,0:98
0,82,0:98
0,83,0:98
0,84,0:98
0,85,0:98
0,86,0:98
0,87,0:98
0,88,0:98
0,89,0:98
0,90,0:98
0,91,0:98
0,92,0:98
0,93,0:98
0,94,0:98
0,95,0:98
0,96,0:98
0,97,0:98
0,98,0:98
0,99,0:98
0,100,0:98
0,101,0:98
0,102,0:98
0,103,0:98
0,104,0:98
0,105,0:98
0,106,0:98
0,107,0:98
0,108,0:98
0,109,0:98
0,110,0:98
0,111,0:98
0,112,0:98
0,113,0:98
0,114,0:98
0,115,0:98
0,116,0:98
0,117,0:98
0,118,0:98
0,119,0:98
0,120,0:98
0,121,0:98
0,122,0:98
0,123,0:98
0,124,0:98
0,125,0:98
0,126,0:98
0,127,0:98
0,128,0:98
0,129,0:98
0,130,0:98
0,131,0:98
0,132,0:98
0,133,0:98
0,134,0:98
0,135,0:98
0,136,0:98
0,137,0:98
0,138,0:98
0,139,0:98
0,140,0:98
0,141,0:98
0,142,0:98
0,143,0:98
0,144,0:98
0,145,0:98
0,146,0:98
0,147,0:98
0,148,0:98
0,149,0:98
0,150,0:98
0,151,0:98
0,152,0:98
0,153,0:98
0,154,0:98
0,155,0:98
0,156,0:98
0,157,0:98
0,158,0:98
0,159,0:98
0,160,0:98
0,161,0:98
0,162,0:98
0,163,0:98
0,164,0:98
0,165,0:98
0,166,0:98
0,167,0:98
0,168,0:98
0,169,0:98
0,170,0:98
0,171,0:98
0,172,0:98
0,173,0:98
0,174,0:98
0,175,0:98
0,176,0:98
0,177,0:98
0,178,0:98
0,179,0:98
0,180,0:98
0,181,0:98
0,182,0:98
0,183,0:98
0,184,0:98
0,185,0:98
0,186,0:98
0,187,0:98
0,188,0:98
0,189,0:98
0,190,0:98
0,191,0:98
0,192,0:98
0,193,0:98
0,194,0:98
0,195,0:98
0,196,0:24
0,197,0:24
0,198,0:24
0,199,0:24
0,200,0:24
0,201,0:24
0,202,0:24
0,203,0:24
0,204,0:24
0,205,0:24
0,206,0:24
0,207,0:24
0,208,0:24
0,209,0:24
0,210,0:24
0,211,0:24
0,212,0:24
0,213,0:24
0,214,0:24
0,215,0:24
0,216,0:24
0,217,0:24
0,218,0:24
0,219,0:24
0,220,0:24
0,221,0:24
0,222,0:24
0,223,0:24
0,224,0:24
0,225,0:24
0,226,0:24
0,227,0:24
0,228,0:24
0,229,0:24
0,230,0:24
0,231,0:24
0,232,0:24
0,233,0:24
0,234,0:24
0,235,0:24
0,236,0:24
0,237,0:24
0,238,0:24
0,239,0:24
0,240,0:24
0,241,0:24
0,242,0:24
0,243,0:24
0,244,0:24
0,245,0:24
0,246,0:24
0,247,0:24
0,248,0:24
0,249,0:24
0,250,0:24
0,251,0:24
0,252,0:24
0,253,0:24
0,254,0:24
0,255,0:24
0,256,0:24
0,257,0:24
0,258,0:24
0,259,0:24
1,0,0:24
1,1,0:24
1,2,0:24
1,3,0:24
1,4,0:24
1,5,0:24
1,6,0:24
1,7,0:24
1,8,0:24
1,9,0:24
1,10,0:24
1,11,0:24
1,12,0:24
1,13,0:24
1,14,0:24
1,15,0:24
1,16,0:24
1,17,0:24
1,18,0:24
1,19,0:24
1,20,0:24
1,21,0:24
1,22,0:24
1,23,0:24
1,24,0:24
1,25,0:24
1,26,0:24
1,27,0:24
1,28,0:24
1,29,0:24
1,30,0:24
1,31,0:24
1,32,0:24
1,33,0:24
1,34,0:24
1,35,0:24
1,36,0:24
1,37,0:24
1,38,0:24
1,39,0:24
1,40,0:24
1,41,0:24
1,42,0:24
1,43,0:24
1,44,0:24
1,45,0:24
1,46,0:24
1,47,0:24
1,48,0:24
1,49,0:24
1,50,0:24
1,51,0:24
1,52,0:24
1,53,0:24
1,54,0:24
1,55,0:24
1,56,0:24
1,57,0:24
1,58,0:24
1,59,0:24
1,60,0:24
1,61,0:24
1,62,0:24
1,63,0:24
1,64,0:24
1,65,0:24
1,66,0:98
1,67,0:98
1,68,0:98
1,69,0:98
1,70,0:98
1,71,0:98
1,72,0:98
1,73,0:98
1,74,0:98
1,75,0:98
1,76,0:98
1,77,0:98
1,78,0:98
1,79,0:98
1,80,0:98
1,81,0:98
1,82,0:98
1,83,0:98
1,84,0:98
1,85,0:98
1,86,0:98
1,87,0:98
1,88,0:98
1,89,0:98
1,90,0:98
1,91,0:98
1,92,0:98
1,93,0:98
1,94,0:98
1,95,0:98
1,96,0:98
1,97,0:98
1,98,0:98
1,99,0:98
1,100,0:98
1,101,0:98
1,102,0:98
1,103,0:98
1,104,0:98
1,105,0:98
1,106,0:98
1,107,0:98
1,108,0:98
1,109,0:98
1,110,0:98
1,111,0:98
1,112,0:98
1,113,0:98
1,114,0:98
1,115,0:98
1,116,0:98
1,117,0:98
1,118,0:98
1,119,0:98
1,120,0:98
1,121,0:98
1,122,0:98
1,123,0:98
1,124,0:98
1,125,0:98
1,126,0:98
1,127,0:98
1,128,0:98
1,129,0:98
1,130,0:98
1,131,0:98
1,132,0:98
1,133,0:98
1,134,0:98
1,135,0:98
1,136,0:98
1,137,0:98
1,138,0:98
1,139,0:98
1,140,0:98
1,141,0:98
1,142,0:98
1,143,0:98
1,144,0:98
1,145,0:98
1,146,0:98
1,147,0:98
1,148,0:98
1,149,0:98
1,150,0:98
1,151,0:98
1,152,0:98
1,153,0:98
1,154,0:98
1,155,0:98
1,156,0:98
1,157,0:98
1,158,0:98
1,159,0:98
1,160,0:98
1,161,0:98
1,162,0:98
1,163,0:98
1,164,0:98
1,165,0:98
1,166,0:98
1,167,0:98
1,168,0:98
1,169,0:98
1,170,0:98
1,171,0:98
1,172,0:98
1,173,0:98
1,174,0:98
1,175,0:98
1,176,0:98
1,177,0:98
1,178,0:98
1,179,0:98
1,180,0:98
1,181,0:98
1,182,0:98
1,183,0:98
1,184,0:98
1,185,0:98
1,186,0:98
1,187,0:98
1,188,0:98
1,189,0:98
1,190,0:98
1,191,0:98
1,192,0:98
1,193,0:98
1,194,0:98
1,195,0:98
1,196,0:24
1,197,0:24
1,198,0:24
1,199,0:24
1,200,0:24
1,201,0:24
1,202,0:24
1,203,0:24
1,204,0:24
1,205,0:24
1,206,0:24
1,207,0:24
1,208,0:24
1,209,0:24
1,210,0:24
1,211,0:24
1,212,0:24
1,213,0:24
1,214,0:24
1,215,0:24
1,216,0:24
1,217,0:24
1,218,0:24
1,219,0:24
1,220,0:24
1,221,0:24
1,222,0:24
1,223,0:24
1,224,0:24
1,225,0:24
1,226,0:24
1,227,0:24
1,228,0:24
1,229,0:24
1,230,0:24
1,231,0:24
1,232,0:24
1,233,0:24
1,234,0:24
1,235,0:24
1,236,0:24
1,237,0:24
1,238,0:24
1,239,0:24
1,240,0:24
1,241,0:24
1,242,0:24
1,243,0:24
1,244,0:24
1,245,0:24
1,246,0:24
1,247,0:24
1,248,0:24
1,249,0:24
1,250,0:24
1,251,0:24
1,252,0:24
1,253,0:24
1,254,0:24
1,255,0:24
1,256,0:24
1,257,0:24
1,258,0:24
1,259,0:24
2,0,0:24
2,1,0:24
2,2,0:24
2,3,0:24
2,4,0:24
2,5,0:24
2,6,0:24
2,7,0:24
2,8,0:24
2,9,0:24
2,10,0:24
2,11,0:24
2,12,0:24
2,13,0:24
2,14,0:24
2,15,0:24
2,16,0:24
2,17,0:24
2,18,0:24
2,19,0:24
2,20,0:24
2,21,0:24
2,22,0:24
2,23,0:24
2,24,0:24
2,25,0:24
2,26,0:24
2,27,0:24
2,28,0:24
2,29,0:24
2,30,0:24
2,31,0:24
2,32,0:24
2,33,0:24
2,34,0:24
2,35,0:24
2,36,0:24
2,37,0:24
2,38,0:24
2,39,0:24
2,40,0:24
2,41,0:24
2,42,0:24
2,43,0:24
2,44,0:24
2,45,0:24
2,46,0:24
2,47,0:24
2,48,0:24
2,49,0:24
2,50,0:24
2,51,0:24
2,52,0:24
2,53,0:24
2,54,0:24
2,55,0:24
2,56,0:24
2,57,0:24
2,58,0:24
2,59,0:24
2,60,0:24
2,61,0:24
2,62,0:24
2,63,0:24
2,64,0:24
2,65,0:24
2,66,0:98
2,67,0:98
2,68,0:98
2,69,0:98
2,70,0:98
2,71,0:98
2,72,0:98
2,73,0:98
2,74,0:98
2,75,0:98
2,76,0:98
2,77,0:98
2,78,0:98
2,79,0:98
2,80,0:98
2,81,0:98
2,82,0:98
2,83,0:98
2,84,0:98
2,85,0:98
2,86,0:98
2,87,0:98
2,88,0:98
2,89,0:98
2,90,0:98
2,91,0:98
2,92,0:98
2,93,0:98
2,94,0:98
2,95,0:98
2,96,0:98
2,97,0:98
2,98,0:98
2,99,0:98
2,100,0:98
2,101,0:98
2,102,0:98
2,103,0:98
2,104,0:98
2,105,0:98
2,106,0:98
2,107,0:98
2,108,0:98
2,109,0:98
2,110,0:98
2,111,0:98
2,112,0:98
2,113,0:98
2,114,0:98
2,115,0:98
2,116,0:98
2,117,0:98
2,118,0:98
2,119,0:98
2,120,0:98
2,121,0:98
2,122,0:98
2,123,0:98
2,124,0:98
2,125,0:98
2,126,0:98
2,127,0:98
2,128,0:98
2,129,0:98
2,130,0:98
2,131,0:98
2,132,0:98
2,133,0:98
2,134,0:98
2,135,0:98
2,136,0:98
2,137,0:98
2,138,0:98
2,139,0:98
2,140,0:98
2,141,0:98
2,142,0:98
2,143,0:98
2,144,0:98
2,145,0:98
2,146,0:98
2,147,0:98
2,148,0:98
2,149,0:98
2,150,0:98
2,151,0:98
2,152,0:98
2,153,0:98
2,154,0:98
2,155,0:98
2,156,0:98
2,157,0:98
2,158,0:98
2,159,0:98
2,160,0:98
2,161,0:98
2,162,0:98
2,163,0:98
2,164,0:98
2,165,0:98
2,166,0:98
2,167,0:98
2,168,0:98
2,169,0:98
2,170,0:98
2,171,0:98
2,172,0:98
2,173,0:98
2,174,0:98
2,175,0:98
2,176,0:98
2,177,0:98
2,178,0:98
2,179,0:98
2,180,0:98
2,181,0:98
2,182,0:98
2,183,0:98
2,184,0:98
2,185,0:98
2,186,0:98
2,187,0:98
2,188,0:98
2,189,0:98
2,190,0:98
2,191,0:98
2,192,0:98
2,193,0:98
2,194,0:98
2,195,0:98
2,196,0:24
2,197,0:24
2,198,0:24
2,199,0:24
2,200,0:24
2,201,0:24
2,202,0:24
2,203,0:24
2,204,0:24
2,205,0:24
2,206,0:24
2,207,0:24
2,208,0:24
2,209,0:24
2,210,0:24
2,211,0:24
2,212,0:24
2,213,0:24
2,214,0:24
2,215,0:24
2,216,0:24
2,217,0:24
2,218,0:24
2,219,0:24
2,220,0:24
2,221,0:24
2,222,0:24
2,223,0:24
2,224,0:24
2,225,0:24
2,226,0:24
2,227,0:24
2,228,0:24
2,229,0:24
2,230,0:24
2,231,0:24
2,232,0:24
2,233,0:24
2,234,0:24
2,235,0:24
2,236,0:24
2,237,0:24
2,238,0:24
2,239,0:24
2,240,0:24
2,241,0:24
2,242,0:24
2,243,0:24
2,244,0:24
2,245,0:24
2,246,0:24
2,247,0:24
2,248,0:24
2,249,0:24
2,250,0:24
2,251,0:24
2,252,0:24
2,253,0:24
2,254,0:24
2,255,0:24
2,256,0:24
2,257,0:24
2,258,0:24
2,259,0:24
3,0,0:24
3,1,0:24
3,2,0:24
3,3,0:24
3,4,0:24
3,5,0:24
3,6,0:24
3,7,0:24
3,8,0:24
3,9,0:24
3,10,0:24
3,11,0:24
3,12,0:24
3,13,0:24
3,14,0:24
3,15,0:24
3,16,0:24
3,17,0:24
3,18,0:24
3,19,0:24
3,20,0:24
3,21,0:24
3,22,0:24
3,23,0:24
3,24,0:24
3,25,0:24
3,26,0:24
3,27,0:24
3,28,0:24
3,29,0:24
3,30,0:24
3,31,0:24
3,32,0:24
3,33,0:24
3,34,0:24
3,35,0:24
3,36,0:24
3,37,0:24
3,38,0:24
3,39,0:24
3,40,0:24
3,41,0:24
3,42,0:24
3,43,0:24
3,44,0:24
3,45,0:24
3,46,0:24
3,47,0:24
3,48,0:24
3,49,0:24
3,50,0:24
3,51,0:24
3,52,0:24
3,53,0:24
3,54,0:24
3,55,0:24
3,56,0:24
3,57,0:24
3,58,0:24
3,59,0:24
3,60,0:24
3,61,0:24
3,62,0:24
3,63,0:24
3,64,0:24
3,65,0:24
3,66,0:98
3,67,0:98
3,68,0:98
3,69,0:98
3,70,0:98
3,71,0:98
3,72,0:98
3,73,0:98
3,74,0:98
3,75,0:98
3,76,0:98
3,77,0:98
3,78,0:98
3,79,0:98
3,80,0:98
3,81,0:98
3,82,0:98
3,83,0:98
3,84,0:98
3,85,0:98
3,86,0:98
3,87,0:98
3,88,0:98
3,89,0:98
3,90,0:98
3,91,0:98
3,92,0:98
3,93,0:98
3,94,0:98
3,95,0:98
3,96,0:98
3,97,0:98
3,98,0:98
3,99,0:98
3,100,0:98
3,101,0:98
3,102,0:98
3,103,0:98
3,104,0:98
3,105,0:98
3,106,0:98
3,107,0:98
3,108,0:98
3,109,0:98
3,110,0:98
3,111,0:98
3,112,0:98
3,113,0:98
3,114,0:98
3,115,0:98
3,116,0:98
3,117,0:98
3,118,0:98
3,119,0:98
3,120,0:98
3,121,0:98
3,122,0:98
3,123,0:98
3,124,0:98
3,125,0:98
3,126,0:98
3,127,0:98
3,128,0:98
3,129,0:98
3,130,0:98
3,131,0:98
3,132,0:98
3,133,0:98
3,134,0:98
3,135,0:98
3,136,0:98
3,137,0:98
3,138,0:98
3,139,0:98
3,140,0:98
3,141,0:98
3,142,0:98
3,143,0:98
3,144,0:98
3,145,0:98
3,146,0:98
3,147,0:98
3,148,0:98
3,149,0:98
3,150,0:98
3,151,0:98
3,152,0:98
3,153,0:98
3,154,0:98
3,155,0:98
3,156,0:98
3,157,0:98
3,158,0:98
3,159,0:98
3,160,0:98
3,161,0:98
3,162,0:98
3,163,0:98
3,164,0:98
3,165,0:98
3,166,0:98
3,167,0:98
3,168,0:98
3,169,0:98
3,170,0:98
3,171,0:98
3,172,0:98
3,173,0:98
3,174,0:98
3,175,0:98
3,176,0:98
3,177,0:98
3,178,0:98
3,179,0:98
3,180,0:98
3,181,0:98
3,182,0:98
3,183,0:98
3,184,0:98
3,185,0:98
3,186,0:98
3,187,0:98
3,188,0:98
3,189,0:98
3,190,0:98
3,191,0:98
3,192,0:98
3,193,0:98
3,194,0:98
3,195,0:98
3,196,0:24
3,197,0:24
3,198,0:24
3,199,0:24
3,200,0:24
3,201,0:24
3,202,0:24
3,203,0:24
3,204,0:24
3,205,0:24
3,206,0:24
3,207,0:24
3,208,0:24
3,209,0:24
3,210,0:24
3,211,0:24
3,212,0:24
3,213,0:24
3,214,0:24
3,215,0:24
3,216,0:24
3,217,0:24
3,218,0:24
3,219,0:24
3,220,0:24
3,221,0:24
3,222,0:24
3,223,0:24
3,224,0:24
3,225,0:24
3,226,0:24
3,227,0:24
3,228,0:24
3,229,0:24
3,230,0:24
3,231,0:24
3,232,0:24
3,233,0:24
3,234,0:24
3,235,0:24
3,236,0:24
3,237,0:24
3,238,0:24
3,239,0:24
3,240,0:24
3,241,0:24
3,242,0:24
3,243,0:24
3,244,0:24
3,245,0:24
3,246,0:24
3,247,0:24
3,248,0:24
3,249,0:24
3,250,0:24
3,251,0:24
3,252,0:24
3,253,0:24
3,254,0:24
3,255,0:24
3,256,0:24
3,257,0:24
3,258,0:24
3,259,0:24
4,0,0:24
4,1,0:24
4,2,0:24
4,3,0:24
4,4,0:24
4,5,0:24
4,6,0:24
4,7,0:24
4,8,0:24
4,9,0:24
4,10,0:24
4,11,0:24
4,12,0:24
4,13,0:24
4,14,0:24
4,15,0:24
4,16,0:24
4,17,0:24
4,18,0:24
4,19,0:24
4,20,0:24
4,21,0:24
4,22,0:24
4,23,0:24
4,24,0:24
4,25,0:24
4,26,0:24
4,27,0:24
4,28,0:24
4,29,0:24
4,30,0:24
4,31,0:24
4,32,0:24
4,33,0:24
4,34,0:24
4,35,0:24
4,36,0:24
4,37,0:24
4,38,0:24
4,39,0:24
4,40,0:24
4,41,0:24
4,42,0:24
4,43,0:24
4,44,0:24
4,45,0:24
4,46,0:24
4,47,0:24
4,48,0:24
4,49,0:24
4,50,0:24
4,51,0:24
4,52,0:24
4,53,0:24
4,54,0:24
4,55,0:24
4,56,0:24
4,57,0:24
4,58,0:24
4,59,0:24
4,60,0:24
4,61,0:24
4,62,0:24
4,63,0:24
4,64,0:24
4,65,0:24
4,66,0:98
4,67,0:98
4,68,0:98
4,69,0:98
4,70,0:98
4,71,0:98
4,72,0:98
4,73,0:98
4,74,0:98
4,75,0:98
4,76,0:98
4,77,0:98
4,78,0:98
4,79,0:98
4,80,0:98
4,81,0:98
4,82,0:98
4,83,0:98
4,84,0:98
4,85,0:98
4,86,0:98
4,87,0:98
4,88,0:98
4,89,0:98
4,90,0:98
4,91,0:98
4,92,0:98
4,93,0:98
4,94,0:98
4,95,0:98
4,96,0:98
4,97,0:98
4,98,0:98
4,99,0:98
4,100,0:98
4,101,0:98
4,102,0:98
4,103,0:98
4,104,0:98
4,105,0:98
4,106,0:98
4,107,0:98
4,108,0:98
4,109,0:98
4,110,0:98
4,111,0:98
4,112,0:98
4,113,0:98
4,114,0:98
4,115,0:98
4,116,0:98
4,117,0:98
4,118,0:98
4,119,0:98
4,120,0:98
4,121,0:98
4,122,0:98
4,123,0:98
4,124,0:98
4,125,0:98
4,126,0:98
4,127,0:98
4,128,0:98
4,129,0:98
4,130,0:98
4,131,0:98
4,132,0:98
4,133,0:98
4,134,0:98
4,135,0:98
4,136,0:98
4,137,0:98
4,138,0:98
4,139,0:98
4,140,0:98
4,141,0:98
4,142,0:98
4,143,0:98
4,144,0:98
4,145,0:98
4,146,0:98
4,147,0:98
4,148,0:98
4,149,0:98
4,150,0:98
4,151,0:98
4,152,0:98
4,153,0:98
4,154,0:98
4,155,0:98
4,156,0:98
4,157,0:98
4,158,0:98
4,159,0:98
4,160,0:98
4,161,0:98
4,162,0:98
4,163,0:98
4,164,0:98
4,165,0:98
4,166,0:98
4,167,0:98
4,168,0:98
4,169,0:98
4,170,0:98
4,171,0:98
4,172,0:98
4,173,0:98
4,174,0:98
4,175,0:98
4,176,0:98
4,177,0:98
4,178,0:98
4,179,0:98
4,180,0:98
4,181,0:98
4,182,0:98
4,183,0:98
4,184,0:98
4,185,0:98
4,186,0:98
4,187,0:98
4,188,0:98
4,189,0:98
4,190,0:98
4,191,0:98
4,192,0:98
4,193,0:98
4,194,0:98
4,195,0:98
4,196,0:24
4,197,0:24
4,198,0:24
4,199,0:24
4,200,0:24
4,201,0:24
4,202,0:24
4,203,0:24
4,204,0:24
4,205,0:24
4,206,0:24
4,207,0:24
4,208,0:24
4,209,0:24
4,210,0:24
4,211,0:24
4,212,0:24
4,213,0:24
4,214,0:24
4,215,0:24
4,216,0:24
4,217,0:24
4,218,0:24
4,219,0:24
4,220,0:24
4,221,0:24
4,222,0:24
4,223,0:24
4,224,0:24
4,225,0:24
4,226,0:24
4,227,0:24
4,228,0:24
4,229,0:24
4,230,0:24
4,231,0:24
4,232,0:24
4,233,0:24
4,234,0:24
4,235,0:24
4,236,0:24
4,237,0:24
4,238,0:24
4,239,0:24
4,240,0:24
4,241,0:24
4,242,0:24
4,243,0:24
4,244,0:24
4,245,0:24
4,246,0:24
4,247,0:24
4,248,0:24
4,249,0:24
4,250,0:24
4,251,0:24
4,252,0:24
4,253,0:24
4,254,0:24
4,255,0:24
4,256,0:24
4,257,0:24
4,258,0:24
4,259,0:24
4,120,1:4
4,141,1:4
4,120,2:4
4,141,2:4
4,120,3:4
4,141,3:4
4,120,4:4
4,141,4:4
4,120,5:4
4,141,5:4
4,120,6:4
4,141,6:4
4,120,7:4
4,141,7:4
4,120,8:4
4,141,8:4
4,120,9:4
4,141,9:4
4,120,10:4
4,141,10:4
4,120,11:4
4,141,11:4
5,0,0:24
5,1,0:24
5,2,0:24
5,3,0:24
5,4,0:24
5,5,0:24
5,6,0:24
5,7,0:24
5,8,0:24
5,9,0:24
5,10,0:24
5,11,0:24
5,12,0:24
5,13,0:24
5,14,0:24
5,15,0:24
5,16,0:24
5,17,0:24
5,18,0:24
5,19,0:24
5,20,0:24
5,21,0:24
5,22,0:24
5,23,0:24
5,24,0:24
5,25,0:24
5,26,0:24
5,27,0:24
5,28,0:24
5,29,0:24
5,30,0:24
5,31,0:24
5,32,0:24
5,33,0:24
5,34,0:24
5,35,0:24
5,36,0:24
5,37,0:24
5,38,0:24
5,39,0:24
5,40,0:24
5,41,0:24
5,42,0:24
5,43,0:24
5,44,0:24
5,45,0:24
5,46,0:24
5,47,0:24
5,48,0:24
5,49,0:24
5,50,0:24
5,51,0:24
5,52,0:24
5,53,0:24
5,54,0:24
5,55,0:24
5,56,0:24
5,57,0:24
5,58,0:24
5,59,0:24
5,60,0:24
5,61,0:24
5,62,0:24
5,63,0:24
5,64,0:24
5,65,0:24
5,66,0:98
5,67,0:98
5,68,0:98
5,69,0:98
5,70,0:98
5,71,0:98
5,72,0:98
5,73,0:98
5,74,0:98
5,75,0:98
5,76,0:98
5,77,0:98
5,78,0:98
5,79,0:98
5,80,0:98
5,81,0:98
5,82,0:98
5,83,0:98
5,84,0:98
5,85,0:98
5,86,0:98
5,87,0:98
5,88,0:98
5,89,0:98
5,90,0:98
5,91,0:98
5,92,0:98
5,93,0:98
5,94,0:98
5,95,0:98
5,96,0:98
5,97,0:98
5,98,0:98
5,99,0:98
5,100,0:98
5,101,0:98
5,102,0:98
5,103,0:98
5,104,0:98
5,105,0:98
5,106,0:98
5,107,0:98
5,108,0:98
5,109,0:98
5,110,0:98
5,111,0:98
5,112,0:98
5,113,0:98
5,114,0:98
5,115,0:98
5,116,0:98
5,117,0:98
5,118,0:98
5,119,0:98
5,120,0:98
5,121,0:98
5,122,0:98
5,123,0:98
5,124,0:98
5,125,0:98
5,126,0:98
5,127,0:98
5,128,0:98
5,129,0:98
5,130,0:98
5,131,0:98
5,132,0:98
5,133,0:98
5,134,0:98
5,135,0:98
5,136,0:98
5,137,0:98
5,138,0:98
5,139,0:98
5,140,0:98
5,141,0:98
5,142,0:98
5,143,0:98
5,144,0:98
5,145,0:98
5,146,0:98
5,147,0:98
5,148,0:98
5,149,0:98
5,150,0:98
5,151,0:98
5,152,0:98
5,153,0:98
5,154,0:98
5,155,0:98
5,156,0:98
5,157,0:98
5,158,0:98
5,159,0:98
5,160,0:98
5,161,0:98
5,162,0:98
5,163,0:98
5,164,0:98
5,165,0:98
5,166,0:98
5,167,0:98
5,168,0:98
5,169,0:98
5,170,0:98
5,171,0:98
5,172,0:98
5,173,0:98
5,174,0:98
5,175,0:98
5,176,0:98
5,177,0:98
5,178,0:98
5,179,0:98
5,180,0:98
5,181,0:98
5,182,0:98
5,183,0:98
5,184,0:98
5,185,0:98
5,186,0:98
5,187,0:98
5,188,0:98
5,189,0:98
5,190,0:98
5,191,0:98
5,192,0:98
5,193,0:98
5,194,0:98
5,195,0:98
5,196,0:24
5,197,0:24
5,198,0:24
5,199,0:24
5,200,0:24
5,201,0:24
5,202,0:24
5,203,0:24
5,204,0:24
5,205,0:24
5,206,0:24
5,207,0:24
5,208,0:24
5,209,0:24
5,210,0:24
5,211,0:24
5,212,0:24
5,213,0:24
5,214,0:24
5,215,0:24
5,216,0:24
5,217,0:24
5,218,0:24
5,219,0:24
5,220,0:24
5,221,0:24
5,222,0:24
5,223,0:24
5,224,0:24
5,225,0:24
5,226,0:24
5,227,0:24
5,228,0:24
5,229,0:24
5,230,0:24
5,231,0:24
5,232,0:24
5,233,0:24
5,234,0:24
5,235,0:24
5,236,0:24
5,237,0:24
5,238,0:24
5,239,0:24
5,240,0:24
5,241,0:24
5,242,0:24
5,243,0:24
5,244,0:24
5,245,0:24
5,246,0:24
5,247,0:24
5,248,0:24
5,249,0:24
5,250,0:24
5,251,0:24
5,252,0:24
5,253,0:24
5,254,0:24
5,255,0:24
5,256,0:24
5,257,0:24
5,258,0:24
5,259,0:24
5,119,1:4
5,120,1:4
5,121,1:4
5,140,1:4
5,141,1:4
5,142,1:4
5,119,2:4
5,120,2:4
5,121,2:4
5,140,2:4
5,141,2:4
5,142,2:4
5,119,3:4
5,120,3:4
5,121,3:4
5,140,3:4
5,141,3:4
5,142,3:4
5,119,4:4
5,120,4:4
5,121,4:4
5,140,4:4
5,141,4:4
5,142,4:4
5,119,5:4
5,120,5:4
5,121,5:4
5,140,5:4
5,141,5:4
5,142,5:4
5,119,6:4
5,120,6:4
5,121,6:4
5,140,6:4
5,141,6:4
5,142,6:4
5,119,7:4
5,120,7:4
5,121,7:4
5,140,7:4
5,141,7:4
5,142,7:4
5,119,8:4
5,120,8:4
5,121,8:4
5,140,8:4
5,141,8:4
5,142,8:4
5,119,9:4
5,120,9:4
5,121,9:4
5,140,9:4
5,141,9:4
5,142,9:4
5,119,10:4
5,120,10:4
5,121,10:4
5,140,10:4
5,141,10:4
5,142,10:4
5,119,11:4
5,120,11:4
5,121,11:4
5,140,11:4
5,141,11:4
5,142,11:4
5,120,12:43.3
5,121,12:4
5,122,12:67.7
5,139,12:67.6
5,140,12:4
5,141,12:43.3
5,120,13:43.3
5,121,13:4
5,122,13:4
5,139,13:4
5,140,13:4
5,141,13:43.3
5,121,14:43.3
5,122,14:4
5,123,14:67.7
5,138,14:67.6
5,139,14:4
5,140,14:43.3
5,121,15:44.3
5,122,15:43.3
5,123,15:4
5,138,15:4
5,139,15:43.3
5,140,15:44.3
5,122,16:44.3
5,123,16:4
5,124,16:67.7
5,137,16:67.6
5,138,16:4
5,139,16:44.3
5,123,17:44.3
5,124,17:4
5,125,17:67.7
5,136,17:67.6
5,137,17:4
5,138,17:44.3
5,124,18:44.3
5,125,18:43.3
5,126,18:67.7
5,135,18:67.6
5,136,18:43.3
5,137,18:44.3
5,125,19:44.3
5,126,19:43.3
5,127,19:4
5,134,19:4
5,135,19:43.3
5,136,19:44.3
5,127,20:44.3
5,128,20:43.3
5,129,20:44.11
5,130,20:44.11
5,131,20:44.11
5,132,20:44.11
5,133,20:43.3
5,134,20:44.3
5,118,21:109.4
5,119,21:109.4
5,120,21:109.4
5,121,21:109.4
5,122,21:109.4
5,123,21:109.4
5,124,21:109.4
5,125,21:109.4
5,126,21:109.4
5,127,21:109.4
5,128,21:109.4
5,129,21:109.4
5,130,21:109.4
5,131,21:109.4
5,132,21:109.4
5,133,21:109.4
5,134,21:109.4
5,135,21:109.4
5,136,21:109.4
5,137,21:109.4
5,138,21:109.4
5,139,21:109.4
5,140,21:109.4
5,141,21:109.4
5,142,21:109.4
5,143,21:109.4
6,0,0:24
6,1,0:24
6,2,0:24
6,3,0:24
6,4,0:24
6,5,0:24
6,6,0:24
6,7,0:24
6,8,0:24
6,9,0:24
6,10,0:24
6,11,0:24
6,12,0:24
6,13,0:24
6,14,0:24
6,15,0:24
6,16,0:24
6,17,0:24
6,18,0:24
6,19,0:24
6,20,0:24
6,21,0:24
6,22,0:24
6,23,0:24
6,24,0:24
6,25,0:24
6,26,0:24
6,27,0:24
6,28,0:24
6,29,0:24
6,30,0:24
6,31,0:24
6,32,0:24
6,33,0:24
6,34,0:24
6,35,0:24
6,36,0:24
6,37,0:24
6,38,0:24
6,39,0:24
6,40,0:24
6,41,0:24
6,42,0:24
6,43,0:24
6,44,0:24
6,45,0:24
6,46,0:24
6,47,0:24
6,48,0:24
6,49,0:24
6,50,0:24
6,51,0:24
6,52,0:24
6,53,0:24
6,54,0:24
6,55,0:24
6,56,0:24
6,57,0:24
6,58,0:24
6,59,0:24
6,60,0:24
6,61,0:24
6,62,0:24
6,63,0:24
6,64,0:24
6,65,0:24
6,66,0:98
6,67,0:98
6,68,0:98
6,69,0:98
6,70,0:98
6,71,0:98
6,72,0:98
6,73,0:98
6,74,0:98
6,75,0:98
6,76,0:98
6,77,0:98
6,78,0:98
6,79,0:98
6,80,0:98
6,81,0:98
6,82,0:98
6,83,0:98
6,84,0:98
6,85,0:98
6,86,0:98
6,87,0:98
6,88,0:98
6,89,0:98
6,90,0:98
6,91,0:98
6,92,0:98
6,93,0:98
6,94,0:98
6,95,0:98
6,96,0:98
6,97,0:98
6,98,0:98
6,99,0:98
6,100,0:98
6,101,0:98
6,102,0:98
6,103,0:98
6,104,0:98
6,105,0:98
6,106,0:98
6,107,0:98
6,108,0:98
6,109,0:98
6,110,0:98
6,111,0:98
6,112,0:98
6,113,0:98
6,114,0:98
6,115,0:98
6,116,0:98
6,117,0:98
6,118,0:98
6,119,0:98
6,120,0:98
6,121,0:98
6,122,0:98
6,123,0:98
6,124,0:98
6,125,0:98
6,126,0:98
6,127,0:98
6,128,0:98
6,129,0:98
6,130,0:98
6,131,0:98
6,132,0:98
6,133,0:98
6,134,0:98
6,135,0:98
6,136,0:98
6,137,0:98
6,138,0:98
6,139,0:98
6,140,0:98
6,141,0:98
6,142,0:98
6,143,0:98
6,144,0:98
6,145,0:98
6,146,0:98
6,147,0:98
6,148,0:98
6,149,0:98
6,150,0:98
6,151,0:98
6,152,0:98
6,153,0:98
6,154,0:98
6,155,0:98
6,156,0:98
6,157,0:98
6,158,0:98
6,159,0:98
6,160,0:98
6,161,0:98
6,162,0:98
6,163,0:98
6,164,0:98
6,165,0:98
6,166,0:98
6,167,0:98
6,168,0:98
6,169,0:98
6,170,0:98
6,171,0:98
6,172,0:98
6,173,0:98
6,174,0:98
6,175,0:98
6,176,0:98
6,177,0:98
6,178,0:98
6,179,0:98
6,180,0:98
6,181,0:98
6,182,0:98
6,183,0:98
6,184,0:98
6,185,0:98
6,186,0:98
6,187,0:98
6,188,0:98
6,189,0:98
6,190,0:98
6,191,0:98
6,192,0:98
6,193,0:98
6,194,0:98
6,195,0:98
6,196,0:24
6,197,0:24
6,198,0:24
6,199,0:24
6,200,0:24
6,201,0:24
6,202,0:24
6,203,0:24
6,204,0:24
6,205,0:24
6,206,0:24
6,207,0:24
6,208,0:24
6,209,0:24
6,210,0:24
6,211,0:24
6,212,0:24
6,213,0:24
6,214,0:24
6,215,0:24
6,216,0:24
6,217,0:24
6,218,0:24
6,219,0:24
6,220,0:24
6,221,0:24
6,222,0:24
6,223,0:24
6,224,0:24
6,225,0:24
6,226,0:24
6,227,0:24
6,228,0:24
6,229,0:24
6,230,0:24
6,231,0:24
6,232,0:24
6,233,0:24
6,234,0:24
6,235,0:24
6,236,0:24
6,237,0:24
6,238,0:24
6,239,0:24
6,240,0:24
6,241,0:24
6,242,0:24
6,243,0:24
6,244,0:24
6,245,0:24
6,246,0:24
6,247,0:24
6,248,0:24
6,249,0:24
6,250,0:24
6,251,0:24
6,252,0:24
6,253,0:24
6,254,0:24
6,255,0:24
6,256,0:24
6,257,0:24
6,258,0:24
6,259,0:24
6,118,1:4
6,119,1:170
6,120,1:170
6,121,1:17.1
6,122,1:17.1
6,139,1:17.1
6,140,1:170.4
6,141,1:170
6,142,1:170
6,143,1:4
6,118,2:17.1
6,120,2:170
6,121,2:17.1
6,122,2:17.1
6,139,2:17.1
6,140,2:170
6,142,2:170
6,143,2:17.1
6,118,3:98
6,121,3:17.1
6,122,3:17.1
6,139,3:17.1
6,143,3:98
6,118,4:98
6,121,4:17.1
6,122,4:17.1
6,139,4:17.1
6,143,4:98
6,118,5:98
6,121,5:17.1
6,122,5:17.1
6,139,5:17.1
6,143,5:98
6,118,6:17.1
6,121,6:17.1
6,122,6:17.1
6,139,6:17.1
6,143,6:17.1
6,118,7:98
6,121,7:17.1
6,122,7:17.1
6,139,7:17.1
6,143,7:98
6,118,8:24.1
6,121,8:17.1
6,122,8:17.1
6,139,8:17.1
6,143,8:24.1
6,118,9:98
6,121,9:17.1
6,122,9:17.1
6,139,9:17.1
6,143,9:98
6,118,10:17.1
6,121,10:17.1
6,122,10:17.1
6,139,10:17.1
6,143,10:17.1
6,118,11:17.1
6,121,11:17.1
6,122,11:17.1
6,139,11:17.1
6,142,11:30
6,143,11:17.1
6,91,12:109.4
6,92,12:109.4
6,93,12:109.4
6,94,12:109.4
6,118,12:17.1
6,119,12:98
6,122,12:17.1
6,139,12:17.9
6,142,12:98
6,143,12:17.1
6,167,12:109.4
6,168,12:109.4
6,169,12:109.4
6,170,12:109.4
6,118,13:17.1
6,119,13:98
6,122,13:17.1
6,123,13:17.9
6,138,13:17.1
6,141,13:98
6,142,13:98
6,143,13:17.1
6,118,14:17.1
6,119,14:98
6,120,14:98
6,123,14:17.1
6,138,14:17.9
6,139,14:98
6,140,14:98
6,141,14:98
6,142,14:98
6,143,14:17.1
6,118,15:17.1
6,119,15:98
6,120,15:67
6,121,15:67
6,123,15:17.1
6,124,15:17.9
6,137,15:17.9
6,138,15:17.1
6,139,15:98
6,140,15:67
6,141,15:67
6,142,15:98
6,143,15:17.1
6,118,16:17.1
6,119,16:98
6,122,16:98
6,124,16:17.1
6,137,16:17.1
6,138,16:98
6,139,16:98
6,142,16:98
6,143,16:17.1
6,118,17:17.1
6,119,17:98
6,120,17:67.4
6,121,17:67.4
6,122,17:98
6,123,17:98
6,125,17:17.1
6,136,17:17.9
6,137,17:98
6,138,17:98
6,139,17:98
6,140,17:67.4
6,141,17:67.4
6,142,17:98
6,143,17:17.1
6,118,18:17.1
6,119,18:98
6,120,18:98
6,121,18:98
6,122,18:98
6,123,18:98
6,124,18:98
6,125,18:162.1
6,126,18:17.1
6,135,18:17.9
6,136,18:98
6,137,18:98
6,138,18:98
6,139,18:98
6,140,18:98
6,141,18:98
6,142,18:98
6,143,18:17.1
6,118,19:162.1
6,119,19:162.1
6,120,19:162.1
6,121,19:162.1
6,122,19:162.1
6,123,19:162.1
6,124,19:162.1
6,125,19:162.1
6,126,19:162.1
6,127,19:17.1
6,128,19:17.9
6,129,19:17.9
6,130,19:17.9
6,131,19:17.9
6,132,19:17.9
6,133,19:17.9
6,134,19:17.9
6,135,19:162.1
6,136,19:162.1
6,137,19:162.1
6,138,19:162.1
6,139,19:162.1
6,140,19:162.1
6,141,19:162.1
6,142,19:162.1
6,143,19:162.1
6,118,20:98
6,119,20:98
6,120,20:98
6,121,20:98
6,122,20:98
6,123,20:98
6,124,20:98
6,125,20:98
6,126,20:98
6,127,20:98
6,128,20:98
6,129,20:98
6,130,20:98
6,131,20:98
6,132,20:98
6,133,20:98
6,134,20:98
6,135,20:98
6,136,20:98
6,137,20:98
6,138,20:98
6,139,20:98
6,140,20:98
6,141,20:98
6,142,20:98
6,143,20:98
6,117,21:109.4
6,118,21:98
6,119,21:98
6,120,21:98
6,121,21:98
6,122,21:98
6,123,21:98
6,124,21:98
6,125,21:98
6,126,21:98
6,127,21:98
6,128,21:98
6,129,21:98
6,130,21:98
6,131,21:98
6,132,21:98
6,133,21:98
6,134,21:98
6,135,21:98
6,136,21:98
6,137,21:98
6,138,21:98
6,139,21:98
6,140,21:98
6,141,21:98
6,142,21:98
6,143,21:98
6,144,21:109.7
6,118,22:98
6,120,22:98
6,122,22:98
6,124,22:98
6,126,22:98
6,128,22:98
6,130,22:98
6,132,22:98
6,134,22:98
6,136,22:98
6,138,22:98
6,140,22:98
6,142,22:98
7,0,0:24
7,1,0:24
7,2,0:24
7,3,0:24
7,4,0:24
7,5,0:24
7,6,0:24
7,7,0:24
7,8,0:24
7,9,0:24
7,10,0:24
7,11,0:24
7,12,0:24
7,13,0:24
7,14,0:24
7,15,0:24
7,16,0:24
7,17,0:24
7,18,0:24
7,19,0:24
7,20,0:24
7,21,0:24
7,22,0:24
7,23,0:24
7,24,0:24
7,25,0:24
7,26,0:24
7,27,0:24
7,28,0:24
7,29,0:24
7,30,0:24
7,31,0:24
7,32,0:24
7,33,0:24
7,34,0:24
7,35,0:24
7,36,0:24
7,37,0:24
7,38,0:24
7,39,0:24
7,40,0:24
7,41,0:24
7,42,0:24
7,43,0:24
7,44,0:24
7,45,0:24
7,46,0:24
7,47,0:24
7,48,0:24
7,49,0:24
7,50,0:24
7,51,0:24
7,52,0:24
7,53,0:24
7,54,0:24
7,55,0:24
7,56,0:24
7,57,0:24
7,58,0:24
7,59,0:24
7,60,0:24
7,61,0:24
7,62,0:24
7,63,0:24
7,64,0:24
7,65,0:24
7,66,0:24
7,67,0:24
7,68,0:24
7,69,0:24
7,70,0:24
7,71,0:24
7,72,0:24
7,73,0:24
7,74,0:98
7,75,0:98
7,76,0:98
7,77,0:98
7,78,0:98
7,79,0:98
7,80,0:98
7,81,0:98
7,82,0:98
7,83,0:98
7,84,0:98
7,85,0:98
7,86,0:98
7,87,0:98
7,88,0:98
7,89,0:98
7,90,0:98
7,91,0:98
7,92,0:98
7,93,0:98
7,94,0:98
7,95,0:98
7,96,0:98
7,97,0:98
7,98,0:98
7,99,0:98
7,100,0:98
7,101,0:98
7,102,0:98
7,103,0:98
7,104,0:98
7,105,0:98
7,106,0:98
7,107,0:98
7,108,0:98
7,109,0:98
7,110,0:98
7,111,0:98
7,112,0:98
7,113,0:98
7,114,0:98
7,115,0:98
7,116,0:98
7,117,0:98
7,118,0:98
7,119,0:98
7,120,0:98
7,121,0:98
7,122,0:98
7,123,0:98
7,124,0:98
7,125,0:98
7,126,0:98
7,127,0:98
7,128,0:98
7,129,0:98
7,130,0:98
7,131,0:98
7,132,0:98
7,133,0:98
7,134,0:98
7,135,0:98
7,136,0:98
7,137,0:98
7,138,0:98
7,139,0:98
7,140,0:98
7,141,0:98
7,142,0:98
7,143,0:98
7,144,0:98
7,145,0:98
7,146,0:98
7,147,0:98
7,148,0:98
7,149,0:98
7,150,0:98
7,151,0:98
7,152,0:98
7,153,0:98
7,154,0:98
7,155,0:98
7,156,0:98
7,157,0:98
7,158,0:98
7,159,0:98
7,160,0:98
7,161,0:98
7,162,0:98
7,163,0:98
7,164,0:98
7,165,0:98
7,166,0:98
7,167,0:98
7,168,0:98
7,169,0:98
7,170,0:98
7,171,0:98
7,172,0:98
7,173,0:98
7,174,0:98
7,175,0:98
7,176,0:98
7,177,0:98
7,178,0:98
7,179,0:98
7,180,0:98
7,181,0:98
7,182,0:98
7,183,0:98
7,184,0:98
7,185,0:98
7,186,0:98
7,187,0:98
7,188,0:24
7,189,0:24
7,190,0:24
7,191,0:24
7,192,0:24
7,193,0:24
7,194,0:24
7,195,0:24
7,196,0:24
7,197,0:24
7,198,0:24
7,199,0:24
7,200,0:24
7,201,0:24
7,202,0:24
7,203,0:24
7,204,0:24
7,205,0:24
7,206,0:24
7,207,0:24
7,208,0:24
7,209,0:24
7,210,0:24
7,211,0:24
7,212,0:24
7,213,0:24
7,214,0:24
7,215,0:24
7,216,0:24
7,217,0:24
7,218,0:24
7,219,0:24
7,220,0:24
7,221,0:24
7,222,0:24
7,223,0:24
7,224,0:24
7,225,0:24
7,226,0:24
7,227,0:24
7,228,0:24
7,229,0:24
7,230,0:24
7,231,0:24
7,232,0:24
7,233,0:24
7,234,0:24
7,235,0:24
7,236,0:24
7,237,0:24
7,238,0:24
7,239,0:24
7,240,0:24
7,241,0:24
7,242,0:24
7,243,0:24
7,244,0:24
7,245,0:24
7,246,0:24
7,247,0:24
7,248,0:24
7,249,0:24
7,250,0:24
7,251,0:24
7,252,0:24
7,253,0:24
7,254,0:24
7,255,0:24
7,256,0:24
7,257,0:24
7,258,0:24
7,259,0:24
7,90,1:162.1
7,91,1:44
7,92,1:44
7,93,1:44
7,94,1:44
7,95,1:162.1
7,117,1:4
7,120,1:170
7,122,1:98
7,139,1:98
7,140,1:170
7,143,1:33.5
7,144,1:4
7,166,1:162.1
7,167,1:44
7,168,1:44
7,169,1:44
7,170,1:44
7,171,1:162.1
7,90,2:162.1
7,95,2:162.1
7,117,2:17.1
7,122,2:98
7,139,2:98
7,144,2:17.1
7,166,2:162.1
7,171,2:162.1
7,90,3:162.1
7,95,3:162.1
7,117,3:17.1
7,122,3:98
7,139,3:98
7,144,3:17.1
7,166,3:162.1
7,171,3:162.1
7,90,4:162.1
7,95,4:162.1
7,117,4:17.1
7,122,4:98
7,139,4:98
7,144,4:17.1
7,166,4:162.1
7,171,4:162.1
7,90,5:162.1
7,91,5:162.9
7,92,5:162.9
7,93,5:162.9
7,94,5:162.9
7,95,5:162.1
7,117,5:17.1
7,122,5:98
7,139,5:98
7,144,5:17.1
7,166,5:162.1
7,167,5:162.9
7,168,5:162.9
7,169,5:162.9
7,170,5:162.9
7,171,5:162.1
7,90,6:162.1
7,95,6:162.1
7,117,6:17.1
7,122,6:98
7,139,6:98
7,144,6:17.1
7,166,6:162.1
7,171,6:162.1
7,90,7:162.1
7,95,7:162.1
7,117,7:17.1
7,122,7:98
7,139,7:98
7,144,7:17.1
7,166,7:162.1
7,171,7:162.1
7,90,8:162.1
7,95,8:162.1
7,117,8:24.1
7,122,8:98
7,139,8:98
7,144,8:24.1
7,166,8:162.1
7,171,8:162.1
7,90,9:162.1
7,95,9:162.1
7,117,9:98
7,122,9:98
7,139,9:98
7,144,9:98
7,166,9:162.1
7,171,9:162.1
7,90,10:162.1
7,91,10:162.9
7,92,10:162.9
7,93,10:162.9
7,94,10:162.9
7,95,10:162.1
7,117,10:17.1
7,122,10:98
7,124,10:77.2
7,126,10:77.2
7,128,10:77.2
7,130,10:77.2
7,131,10:77.2
7,133,10:77.2
7,135,10:77.2
7,137,10:77.2
7,139,10:98
7,144,10:17.1
7,166,10:162.1
7,167,10:162.9
7,168,10:162.9
7,169,10:162.9
7,170,10:162.9
7,171,10:162.1
7,91,11:43.5
7,92,11:43.5
7,93,11:43.5
7,94,11:43.5
7,117,11:17.1
7,122,11:98
7,139,11:98
7,144,11:17.1
7,167,11:43.5
7,168,11:43.5
7,169,11:43.5
7,170,11:43.5
7,89,12:109.6
7,90,12:109.4
7,91,12:98
7,92,12:98
7,93,12:98
7,94,12:98
7,95,12:109.4
7,96,12:109.7
7,117,12:17.1
7,122,12:98
7,139,12:98
7,144,12:17.1
7,165,12:109.6
7,166,12:109.4
7,167,12:98
7,168,12:98
7,169,12:98
7,170,12:98
7,171,12:109.4
7,172,12:109.7
7,117,13:17.1
7,123,13:98
7,138,13:98
7,144,13:17.1
7,117,14:17.1
7,123,14:98
7,138,14:98
7,144,14:17.1
7,117,15:17.1
7,124,15:98
7,125,15:77.2
7,127,15:77.2
7,129,15:77.2
7,132,15:77.2
7,134,15:77.2
7,136,15:77.2
7,137,15:98
7,144,15:17.1
7,117,16:17.1
7,124,16:98
7,137,16:98
7,144,16:17.1
7,117,17:17.1
7,125,17:98
7,136,17:98
7,144,17:17.1
7,117,18:17.1
7,126,18:98
7,135,18:98
7,144,18:17.1
7,117,19:162.1
7,127,19:98
7,128,19:98
7,129,19:98
7,130,19:98
7,131,19:98
7,132,19:98
7,133,19:98
7,134,19:98
7,144,19:162.1
7,117,20:98
7,144,20:98
7,116,21:109.4
7,117,21:98
7,118,21:98
7,119,21:98
7,120,21:98
7,121,21:98
7,122,21:98
7,123,21:98
7,124,21:98
7,125,21:98
7,126,21:98
7,127,21:98
7,128,21:98
7,129,21:98
7,130,21:98
7,131,21:98
7,132,21:98
7,133,21:98
7,134,21:98
7,135,21:98
7,136,21:98
7,137,21:98
7,138,21:98
7,139,21:98
7,140,21:98
7,141,21:98
7,142,21:98
7,143,21:98
7,144,21:98
7,145,21:109.7
7,144,22:98
8,0,0:24
8,1,0:24
8,2,0:24
8,3,0:24
8,4,0:24
8,5,0:24
8,6,0:24
8,7,0:24
8,8,0:24
8,9,0:24
8,10,0:24
8,11,0:24
8,12,0:24
8,13,0:24
8,14,0:24
8,15,0:24
8,16,0:24
8,17,0:24
8,18,0:24
8,19,0:24
8,20,0:24
8,21,0:24
8,22,0:24
8,23,0:24
8,24,0:24
8,25,0:24
8,26,0:24
8,27,0:24
8,28,0:24
8,29,0:24
8,30,0:24
8,31,0:24
8,32,0:24
8,33,0:24
8,34,0:24
8,35,0:24
8,36,0:24
8,37,0:24
8,38,0:24
8,39,0:24
8,40,0:24
8,41,0:24
8,42,0:24
8,43,0:24
8,44,0:24
8,45,0:24
8,46,0:24
8,47,0:24
8,48,0:24
8,49,0:24
8,50,0:24
8,51,0:24
8,52,0:24
8,53,0:24
8,54,0:24
8,55,0:24
8,56,0:24
8,57,0:24
8,58,0:24
8,59,0:24
8,60,0:24
8,61,0:24
8,62,0:24
8,63,0:24
8,64,0:24
8,65,0:24
8,66,0:24
8,67,0:24
8,68,0:24
8,69,0:24
8,70,0:24
8,71,0:24
8,72,0:24
8,73,0:24
8,74,0:98
8,75,0:98
8,76,0:98
8,77,0:98
8,78,0:98
8,79,0:98
8,80,0:98
8,81,0:98
8,82,0:98
8,83,0:98
8,84,0:98
8,85,0:98
8,86,0:98
8,87,0:98
8,88,0:98
8,89,0:98
8,90,0:98
8,91,0:98
8,92,0:98
8,93,0:98
8,94,0:98
8,95,0:98
8,96,0:98
8,97,0:98
8,98,0:98
8,99,0:98
8,100,0:98
8,101,0:98
8,102,0:98
8,103,0:98
8,104,0:98
8,105,0:98
8,106,0:98
8,107,0:98
8,108,0:98
8,109,0:98
8,110,0:98
8,111,0:98
8,112,0:98
8,113,0:98
8,114,0:98
8,115,0:98
8,116,0:98
8,117,0:98
8,118,0:98
8,119,0:98
8,120,0:98
8,121,0:98
8,122,0:98
8,123,0:98
8,124,0:98
8,125,0:98
8,126,0:98
8,127,0:98
8,128,0:13
8,129,0:98
8,130,0:98
8,131,0:98.2
8,132,0:4
8,133,0:4
8,134,0:98
8,135,0:98
8,136,0:98
8,137,0:98
8,138,0:98
8,139,0:98
8,140,0:98
8,141,0:98
8,142,0:98
8,143,0:98
8,144,0:98
8,145,0:98
8,146,0:98
8,147,0:98
8,148,0:98
8,149,0:98
8,150,0:98
8,151,0:98
8,152,0:98
8,153,0:98
8,154,0:98
8,155,0:98
8,156,0:98
8,157,0:98
8,158,0:98
8,159,0:98
8,160,0:98
8,161,0:98
8,162,0:98
8,163,0:98
8,164,0:98
8,165,0:98
8,166,0:98
8,167,0:98
8,168,0:98
8,169,0:98
8,170,0:98
8,171,0:98
8,172,0:98
8,173,0:98
8,174,0:98
8,175,0:98
8,176,0:98
8,177,0:98
8,178,0:98
8,179,0:98
8,180,0:98
8,181,0:98
8,182,0:98
8,183,0:98
8,184,0:98
8,185,0:98
8,186,0:98
8,187,0:98
8,188,0:24
8,189,0:24
8,190,0:24
8,191,0:24
8,192,0:24
8,193,0:24
8,194,0:24
8,195,0:24
8,196,0:24
8,197,0:24
8,198,0:24
8,199,0:24
8,200,0:24
8,201,0:24
8,202,0:24
8,203,0:24
8,204,0:24
8,205,0:24
8,206,0:24
8,207,0:24
8,208,0:24
8,209,0:24
8,210,0:24
8,211,0:24
8,212,0:24
8,213,0:24
8,214,0:24
8,215,0:24
8,216,0:24
8,217,0:24
8,218,0:24
8,219,0:24
8,220,0:24
8,221,0:24
8,222,0:24
8,223,0:24
8,224,0:24
8,225,0:24
8,226,0:24
8,227,0:24
8,228,0:24
8,229,0:24
8,230,0:24
8,231,0:24
8,232,0:24
8,233,0:24
8,234,0:24
8,235,0:24
8,236,0:24
8,237,0:24
8,238,0:24
8,239,0:24
8,240,0:24
8,241,0:24
8,242,0:24
8,243,0:24
8,244,0:24
8,245,0:24
8,246,0:24
8,247,0:24
8,248,0:24
8,249,0:24
8,250,0:24
8,251,0:24
8,252,0:24
8,253,0:24
8,254,0:24
8,255,0:24
8,256,0:24
8,257,0:24
8,258,0:24
8,259,0:24
8,90,1:4
8,91,1:4
8,92,1:4
8,93,1:4
8,94,1:4
8,95,1:4
8,116,1:4
8,117,1:118
8,121,1:162.1
8,140,1:162.1
8,145,1:4
8,166,1:4
8,167,1:4
8,168,1:4
8,169,1:4
8,170,1:4
8,171,1:4
8,90,2:162.1
8,91,2:128
8,92,2:128
8,93,2:128
8,94,2:128
8,95,2:162.1
8,116,2:17.1
8,121,2:162.1
8,140,2:162.1
8,145,2:17.1
8,166,2:162.1
8,167,2:128
8,168,2:128
8,169,2:128
8,170,2:128
8,171,2:162.1
8,90,3:162.1
8,91,3:128.4
8,92,3:128.4
8,93,3:128.4
8,94,3:128.4
8,95,3:162.1
8,116,3:98
8,121,3:162.1
8,140,3:162.1
8,145,3:98
8,166,3:162.1
8,167,3:128.4
8,168,3:128.4
8,169,3:128.4
8,170,3:128.4
8,171,3:162.1
8,90,4:162.1
8,91,4:43
8,92,4:4
8,93,4:4
8,94,4:43
8,95,4:162.1
8,116,4:98
8,121,4:162.1
8,140,4:162.1
8,145,4:98
8,166,4:162.1
8,167,4:43
8,168,4:4
8,169,4:4
8,170,4:43
8,171,4:162.1
8,87,5:44.9
8,88,5:44.9
8,89,5:44.9
8,90,5:162.1
8,91,5:162.9
8,92,5:162.9
8,93,5:162.9
8,94,5:162.9
8,95,5:162.1
8,96,5:44.9
8,97,5:44.9
8,98,5:44.9
8,116,5:98
8,121,5:162.1
8,140,5:162.1
8,145,5:98
8,163,5:44.9
8,164,5:44.9
8,165,5:44.9
8,166,5:162.1
8,167,5:162.9
8,168,5:162.9
8,169,5:162.9
8,170,5:162.9
8,171,5:162.1
8,172,5:44.9
8,173,5:44.9
8,174,5:44.9
8,90,6:162.1
8,91,6:43
8,92,6:4
8,93,6:4
8,94,6:43
8,95,6:162.1
8,116,6:17.1
8,121,6:162.1
8,140,6:162.1
8,145,6:17.1
8,166,6:162.1
8,167,6:43
8,168,6:4
8,169,6:4
8,170,6:43
8,171,6:162.1
8,87,7:44.9
8,88,7:44.9
8,89,7:44.9
8,90,7:162.1
8,91,7:128
8,92,7:128
8,93,7:128
8,94,7:128
8,95,7:162.1
8,96,7:44.9
8,97,7:44.9
8,98,7:44.9
8,116,7:98
8,121,7:162.1
8,140,7:162.1
8,145,7:98
8,163,7:44.9
8,164,7:44.9
8,165,7:44.9
8,166,7:162.1
8,167,7:128
8,168,7:128
8,169,7:128
8,170,7:128
8,171,7:162.1
8,172,7:44.9
8,173,7:44.9
8,174,7:44.9
8,90,8:162.1
8,91,8:128.4
8,92,8:128.4
8,93,8:128.4
8,94,8:128.4
8,95,8:162.1
8,116,8:24.1
8,121,8:162.1
8,140,8:162.1
8,145,8:24.1
8,166,8:162.1
8,167,8:128.4
8,168,8:128.4
8,169,8:128.4
8,170,8:128.4
8,171,8:162.1
8,88,9:44.8
8,89,9:44.8
8,90,9:162.1
8,91,9:162.9
8,92,9:162.9
8,93,9:162.9
8,94,9:162.9
8,95,9:162.1
8,96,9:44.8
8,97,9:44.8
8,116,9:98
8,121,9:162.1
8,140,9:162.1
8,145,9:98
8,164,9:44.8
8,165,9:44.8
8,166,9:162.1
8,167,9:162.9
8,168,9:162.9
8,169,9:162.9
8,170,9:162.9
8,171,9:162.1
8,172,9:44.8
8,173,9:44.8
8,90,10:162.1
8,91,10:162.9
8,92,10:162.9
8,93,10:162.9
8,94,10:162.9
8,95,10:162.1
8,116,10:17.1
8,121,10:162.1
8,122,10:5.5
8,123,10:5.5
8,124,10:5.5
8,125,10:5.5
8,126,10:5.5
8,127,10:5.5
8,128,10:5.5
8,129,10:5.5
8,130,10:5.5
8,131,10:5.5
8,132,10:5.5
8,133,10:5.5
8,134,10:5.5
8,135,10:5.5
8,136,10:5.5
8,137,10:5.5
8,138,10:5.5
8,139,10:5.5
8,140,10:162.1
8,145,10:17.1
8,166,10:162.1
8,167,10:162.9
8,168,10:162.9
8,169,10:162.9
8,170,10:162.9
8,171,10:162.1
8,90,11:43.5
8,95,11:43.5
8,116,11:17.1
8,121,11:162.1
8,122,11:5.5
8,130,11:164
8,131,11:164
8,139,11:5.5
8,140,11:162.1
8,145,11:17.1
8,166,11:43.5
8,171,11:43.5
8,86,12:109.6
8,87,12:109.4
8,88,12:109.4
8,89,12:109.4
8,90,12:98
8,91,12:162.5
8,92,12:162.5
8,93,12:162.5
8,94,12:162.5
8,95,12:98
8,96,12:109.7
8,97,12:109.4
8,98,12:109.4
8,99,12:109.7
8,114,12:109.6
8,115,12:109.4
8,116,12:17.1
8,121,12:162.1
8,122,12:5.5
8,130,12:77.2
8,131,12:77.2
8,139,12:5.5
8,140,12:162.1
8,145,12:17.1
8,146,12:109.4
8,147,12:109.7
8,162,12:109.6
8,163,12:109.4
8,164,12:109.4
8,165,12:109.6
8,166,12:98
8,167,12:162.5
8,168,12:162.5
8,169,12:162.5
8,170,12:162.5
8,171,12:98
8,172,12:109.4
8,173,12:109.4
8,174,12:109.4
8,175,12:109.7
8,90,13:85
8,92,13:85
8,93,13:85
8,95,13:85
8,115,13:109
8,116,13:17.1
8,121,13:162.1
8,122,13:162.9
8,123,13:5.5
8,130,13:77.2
8,131,13:77.2
8,138,13:5.5
8,139,13:162.1
8,140,13:162.9
8,145,13:17.1
8,146,13:109
8,166,13:85
8,168,13:85
8,169,13:85
8,171,13:85
8,90,14:85
8,95,14:85
8,116,14:17.1
8,122,14:162.1
8,123,14:5.5
8,130,14:164.4
8,131,14:164.4
8,138,14:5.5
8,139,14:162.1
8,145,14:17.1
8,166,14:85
8,171,14:85
8,90,15:85
8,95,15:85
8,116,15:17.1
8,122,15:162.1
8,123,15:162.9
8,124,15:5.5
8,125,15:5.5
8,126,15:5.5
8,127,15:5.5
8,128,15:5.5
8,129,15:5.5
8,130,15:5.5
8,131,15:5.5
8,132,15:5.5
8,133,15:5.5
8,134,15:5.5
8,135,15:5.5
8,136,15:5.5
8,137,15:5.5
8,138,15:162.1
8,139,15:162.9
8,145,15:17.1
8,166,15:85
8,171,15:85
8,45,16:109
8,46,16:109
8,47,16:109
8,48,16:109
8,49,16:109
8,50,16:109
8,51,16:109
8,52,16:109
8,53,16:109
8,54,16:109
8,55,16:109
8,90,16:85
8,95,16:85
8,116,16:17.1
8,123,16:162.1
8,130,16:164
8,131,16:164
8,138,16:162.1
8,145,16:17.1
8,166,16:85
8,171,16:85
8,206,16:109
8,207,16:109
8,208,16:109
8,209,16:109
8,210,16:109
8,211,16:109
8,212,16:109
8,213,16:109
8,214,16:109
8,215,16:109
8,216,16:109
8,116,17:17.1
8,123,17:162.1
8,124,17:162.9
8,130,17:77.2
8,131,17:77.2
8,137,17:162.1
8,138,17:162.9
8,145,17:17.1
8,116,18:17.1
8,124,18:162.1
8,125,18:162.9
8,136,18:162.1
8,137,18:162.9
8,145,18:17.1
8,116,19:162.1
8,125,19:162.1
8,126,19:162.9
8,130,19:77.2
8,131,19:77.2
8,135,19:162.1
8,136,19:162.9
8,145,19:162.1
8,116,20:98
8,126,20:162.1
8,127,20:162.9
8,128,20:162.9
8,129,20:162.9
8,130,20:162.9
8,131,20:162.9
8,132,20:162.9
8,133,20:162.9
8,134,20:162.9
8,135,20:162.9
8,145,20:98
8,115,21:109.4
8,116,21:98
8,117,21:98
8,118,21:98
8,119,21:98
8,120,21:98
8,121,21:98
8,122,21:98
8,123,21:98
8,124,21:98
8,125,21:98
8,126,21:98
8,127,21:98
8,128,21:98
8,129,21:98
8,130,21:98
8,131,21:98
8,132,21:98
8,133,21:98
8,134,21:98
8,135,21:98
8,136,21:98
8,137,21:98
8,138,21:98
8,139,21:98
8,140,21:98
8,141,21:98
8,142,21:98
8,143,21:98
8,144,21:98
8,145,21:98
8,146,21:109.7
8,116,22:98
9,0,0:24
9,1,0:24
9,2,0:24
9,3,0:24
9,4,0:24
9,5,0:24
9,6,0:24
9,7,0:24
9,8,0:24
9,9,0:24
9,10,0:24
9,11,0:24
9,12,0:24
9,13,0:24
9,14,0:24
9,15,0:24
9,16,0:98
9,17,0:98
9,18,0:24
9,19,0:24
9,20,0:24
9,21,0:24
9,22,0:24
9,23,0:24
9,24,0:24
9,25,0:24
9,26,0:24
9,27,0:24
9,28,0:24
9,29,0:24
9,30,0:24
9,31,0:24
9,32,0:24
9,33,0:24
9,34,0:24
9,35,0:24
9,36,0:24
9,37,0:24
9,38,0:24
9,39,0:24
9,40,0:24
9,41,0:24
9,42,0:24
9,43,0:24
9,44,0:24
9,45,0:24
9,46,0:24
9,47,0:24
9,48,0:24
9,49,0:24
9,50,0:24
9,51,0:24
9,52,0:24
9,53,0:24
9,54,0:24
9,55,0:24
9,56,0:24
9,57,0:24
9,58,0:24
9,59,0:24
9,60,0:24
9,61,0:24
9,62,0:24
9,63,0:24
9,64,0:24
9,65,0:24
9,66,0:24
9,67,0:24
9,68,0:24
9,69,0:24
9,70,0:24
9,71,0:24
9,72,0:24
9,73,0:24
9,74,0:98
9,75,0:98
9,76,0:98
9,77,0:98
9,78,0:98
9,79,0:98
9,80,0:98
9,81,0:98
9,82,0:98
9,83,0:98
9,84,0:98
9,85,0:98
9,86,0:98
9,87,0:98
9,88,0:98
9,89,0:98
9,90,0:98
9,91,0:98
9,92,0:98
9,93,0:98
9,94,0:98
9,95,0:98
9,96,0:98
9,97,0:98
9,98,0:98
9,99,0:98
9,100,0:98
9,101,0:98
9,102,0:98
9,103,0:98
9,104,0:98
9,105,0:98
9,106,0:98
9,107,0:98
9,108,0:98
9,109,0:98
9,110,0:98
9,111,0:98
9,112,0:98
9,113,0:98
9,114,0:98
9,115,0:98
9,116,0:98
9,117,0:98
9,118,0:98
9,119,0:98
9,120,0:98
9,121,0:98
9,122,0:98
9,123,0:98
9,124,0:98
9,125,0:4
9,126,0:13
9,127,0:98
9,128,0:98
9,129,0:98.2
9,130,0:13
9,131,0:98
9,132,0:98
9,133,0:98.2
9,134,0:98
9,135,0:4
9,136,0:98
9,137,0:13
9,138,0:98
9,139,0:98
9,140,0:98
9,141,0:98
9,142,0:98
9,143,0:98.2
9,144,0:98
9,145,0:98
9,146,0:98
9,147,0:98
9,148,0:98
9,149,0:98
9,150,0:98
9,151,0:98
9,152,0:98
9,153,0:98
9,154,0:98
9,155,0:98
9,156,0:98
9,157,0:98
9,158,0:98
9,159,0:98
9,160,0:98
9,161,0:98
9,162,0:98
9,163,0:98
9,164,0:98
9,165,0:98
9,166,0:98
9,167,0:98
9,168,0:98
9,169,0:98
9,170,0:98
9,171,0:98
9,172,0:98
9,173,0:98
9,174,0:98
9,175,0:98
9,176,0:98
9,177,0:98
9,178,0:98
9,179,0:98
9,180,0:98
9,181,0:98
9,182,0:98
9,183,0:98
9,184,0:98
9,185,0:98
9,186,0:98
9,187,0:98
9,188,0:24
9,189,0:24
9,190,0:24
9,191,0:24
9,192,0:24
9,193,0:24
9,194,0:24
9,195,0:24
9,196,0:24
9,197,0:24
9,198,0:24
9,199,0:24
9,200,0:24
9,201,0:24
9,202,0:24
9,203,0:24
9,204,0:24
9,205,0:24
9,206,0:24
9,207,0:24
9,208,0:24
9,209,0:24
9,210,0:24
9,211,0:24
9,212,0:24
9,213,0:24
9,214,0:24
9,215,0:24
9,216,0:24
9,217,0:24
9,218,0:24
9,219,0:24
9,220,0:24
9,221,0:24
9,222,0:24
9,223,0:24
9,224,0:24
9,225,0:24
9,226,0:24
9,227,0:24
9,228,0:24
9,229,0:24
9,230,0:24
9,231,0:24
9,232,0:24
9,233,0:24
9,234,0:24
9,235,0:24
9,236,0:24
9,237,0:24
9,238,0:24
9,239,0:24
9,240,0:24
9,241,0:24
9,242,0:24
9,243,0:24
9,244,0:98
9,245,0:98
9,246,0:24
9,247,0:24
9,248,0:24
9,249,0:24
9,250,0:24
9,251,0:24
9,252,0:24
9,253,0:24
9,254,0:24
9,255,0:24
9,256,0:24
9,257,0:24
9,258,0:24
9,259,0:24
9,12,1:109
9,13,1:109
9,14,1:109
9,15,1:98
9,18,1:98
9,19,1:109
9,20,1:109
9,46,1:17.1
9,54,1:17.1
9,87,1:4
9,88,1:4
9,89,1:4
9,90,1:162.1
9,91,1:162.1
9,92,1:162.1
9,93,1:162.1
9,94,1:162.1
9,95,1:162.1
9,96,1:4
9,97,1:4
9,98,1:4
9,115,1:4
9,116,1:33.3
9,121,1:162.1
9,140,1:162.1
9,145,1:118
9,146,1:4
9,163,1:4
9,164,1:4
9,165,1:4
9,166,1:162.1
9,167,1:162.1
9,168,1:162.1
9,169,1:162.1
9,170,1:162.1
9,171,1:162.1
9,172,1:4
9,173,1:4
9,174,1:4
9,207,1:17.1
9,215,1:17.1
9,241,1:109
9,242,1:109
9,243,1:98
9,246,1:98
9,247,1:109
9,248,1:109
9,249,1:109
9,15,2:101
9,18,2:101
9,46,2:17.1
9,54,2:17.1
9,87,2:162.1
9,88,2:24.2
9,89,2:162.1
9,96,2:162.1
9,97,2:24.2
9,98,2:162.1
9,115,2:162.1
9,121,2:162.1
9,140,2:162.1
9,146,2:162.1
9,163,2:162.1
9,164,2:24.2
9,165,2:162.1
9,172,2:162.1
9,173,2:24.2
9,174,2:162.1
9,207,2:17.1
9,215,2:17.1
9,243,2:101
9,246,2:101
9,15,3:98
9,18,3:98
9,46,3:17.1
9,47,3:109.4
9,48,3:109.4
9,49,3:109.4
9,50,3:109.4
9,51,3:109.4
9,52,3:109.4
9,53,3:109.4
9,54,3:17.1
9,87,3:162.1
9,88,3:24.1
9,89,3:162.1
9,96,3:162.1
9,97,3:24.1
9,98,3:162.1
9,115,3:162.1
9,121,3:162.1
9,140,3:162.1
9,146,3:162.1
9,163,3:162.1
9,164,3:24.1
9,165,3:162.1
9,172,3:162.1
9,173,3:24.1
9,174,3:162.1
9,207,3:17.1
9,208,3:109.4
9,209,3:109.4
9,210,3:109.4
9,211,3:109.4
9,212,3:109.4
9,213,3:109.4
9,214,3:109.4
9,215,3:17.1
9,243,3:98
9,246,3:98
9,15,4:98
9,16,4:67.4
9,17,4:67.4
9,18,4:98
9,46,4:17.1
9,47,4:98
9,49,4:98
9,51,4:98
9,53,4:98
9,54,4:17.1
9,87,4:162.1
9,88,4:24.2
9,89,4:162.1
9,96,4:162.1
9,97,4:24.2
9,98,4:162.1
9,115,4:162.1
9,121,4:162.1
9,140,4:162.1
9,146,4:162.1
9,163,4:162.1
9,164,4:24.2
9,165,4:162.1
9,172,4:162.1
9,173,4:24.2
9,174,4:162.1
9,207,4:17.1
9,208,4:98
9,210,4:98
9,212,4:98
9,214,4:98
9,215,4:17.1
9,243,4:98
9,244,4:67.4
9,245,4:67.4
9,246,4:98
9,15,5:98
9,16,5:98
9,17,5:98
9,18,5:98
9,46,5:17.1
9,47,5:98
9,49,5:98
9,51,5:98
9,53,5:98
9,54,5:17.1
9,85,5:44.9
9,86,5:44.9
9,87,5:24.2
9,88,5:24.2
9,89,5:24.2
9,95,5:44.13
9,96,5:24.2
9,97,5:24.2
9,98,5:24.2
9,99,5:44.9
9,100,5:44.9
9,115,5:162.1
9,121,5:162.1
9,140,5:162.1
9,146,5:162.1
9,161,5:44.9
9,162,5:44.9
9,163,5:24.2
9,164,5:24.2
9,165,5:24.2
9,166,5:44.13
9,172,5:24.2
9,173,5:24.2
9,174,5:24.2
9,175,5:44.9
9,176,5:44.9
9,207,5:17.1
9,208,5:98
9,210,5:98
9,212,5:98
9,214,5:98
9,215,5:17.1
9,243,5:98
9,244,5:98
9,245,5:98
9,246,5:98
9,14,6:109.6
9,15,6:4
9,16,6:4
9,17,6:4
9,18,6:4
9,19,6:109.7
9,46,6:17.1
9,47,6:98
9,48,6:98
9,49,6:98
9,50,6:98
9,51,6:98
9,52,6:98
9,53,6:98
9,54,6:17.1
9,87,6:162.1
9,88,6:114
9,89,6:114
9,93,6:44.13
9,94,6:44.5
9,96,6:114
9,97,6:114
9,98,6:162.1
9,115,6:162.1
9,121,6:162.1
9,140,6:162.1
9,146,6:162.1
9,163,6:162.1
9,164,6:114
9,165,6:114
9,167,6:44.5
9,168,6:44.13
9,172,6:114
9,173,6:114
9,174,6:162.1
9,207,6:17.1
9,208,6:98
9,209,6:98
9,210,6:98
9,211,6:98
9,212,6:98
9,213,6:98
9,214,6:98
9,215,6:17.1
9,242,6:109.6
9,243,6:4
9,244,6:4
9,245,6:4
9,246,6:4
9,247,6:109.7
9,14,7:98
9,15,7:67
9,16,7:4
9,17,7:4
9,18,7:67
9,19,7:98
9,46,7:17.1
9,47,7:44.1
9,48,7:44.1
9,49,7:44.1
9,50,7:44.1
9,51,7:44.1
9,52,7:44.1
9,53,7:44.1
9,54,7:17.1
9,85,7:44.9
9,86,7:44.9
9,87,7:162.1
9,88,7:114.4
9,89,7:114.4
9,91,7:44.13
9,92,7:44.5
9,96,7:114.4
9,97,7:114.4
9,98,7:162.1
9,99,7:44.9
9,100,7:44.9
9,115,7:162.1
9,121,7:162.1
9,140,7:162.1
9,146,7:162.1
9,161,7:44.9
9,162,7:44.9
9,163,7:162.1
9,164,7:114.4
9,165,7:114.4
9,169,7:44.5
9,170,7:44.13
9,172,7:114.4
9,173,7:114.4
9,174,7:162.1
9,175,7:44.9
9,176,7:44.9
9,207,7:17.1
9,208,7:44.1
9,209,7:44.1
9,210,7:44.1
9,211,7:44.1
9,212,7:44.1
9,213,7:44.1
9,214,7:44.1
9,215,7:17.1
9,242,7:98
9,243,7:67
9,244,7:4
9,245,7:4
9,246,7:67
9,247,7:98
9,14,8:98
9,16,8:4
9,17,8:4
9,19,8:98
9,46,8:17.1
9,47,8:44.9
9,48,8:44.9
9,49,8:44.9
9,50,8:44.9
9,51,8:44.9
9,52,8:44.9
9,53,8:44.9
9,54,8:17.1
9,87,8:162.1
9,88,8:4
9,89,8:4
9,90,8:44.5
9,96,8:4
9,97,8:4
9,98,8:162.1
9,115,8:24.1
9,121,8:162.1
9,140,8:162.1
9,146,8:24.1
9,163,8:162.1
9,164,8:4
9,165,8:4
9,171,8:44.5
9,172,8:4
9,173,8:4
9,174,8:162.1
9,207,8:17.1
9,208,8:44.9
9,209,8:44.9
9,210,8:44.9
9,211,8:44.9
9,212,8:44.9
9,213,8:44.9
9,214,8:44.9
9,215,8:17.1
9,242,8:98
9,244,8:4
9,245,8:4
9,247,8:98
9,14,9:109.6
9,16,9:4
9,17,9:4
9,19,9:109.7
9,46,9:17.1
9,47,9:44.1
9,48,9:44.9
9,49,9:44.1
9,50,9:85
9,51,9:44.1
9,52,9:44.9
9,53,9:44.1
9,54,9:17.1
9,86,9:44.8
9,87,9:162.1
9,88,9:43
9,89,9:43
9,96,9:43
9,97,9:43
9,98,9:162.1
9,99,9:44.8
9,115,9:98
9,121,9:162.1
9,140,9:162.1
9,146,9:98
9,162,9:44.8
9,163,9:162.1
9,164,9:43
9,165,9:43
9,172,9:43
9,173,9:43
9,174,9:162.1
9,175,9:44.8
9,207,9:17.1
9,208,9:44.1
9,209,9:44.9
9,210,9:44.1
9,211,9:85
9,212,9:44.1
9,213,9:44.9
9,214,9:44.1
9,215,9:17.1
9,242,9:109.6
9,244,9:4
9,245,9:4
9,247,9:109.7
9,14,10:98
9,15,10:17.1
9,16,10:24.2
9,17,10:24.2
9,18,10:17.1
9,19,10:98
9,46,10:17.1
9,47,10:85
9,48,10:98
9,50,10:85
9,52,10:98
9,53,10:85
9,54,10:17.1
9,87,10:162.1
9,88,10:162.1
9,89,10:162.1
9,92,10:85
9,93,10:85
9,96,10:162.1
9,97,10:162.1
9,98,10:162.1
9,115,10:162.1
9,121,10:162.1
9,122,10:5.5
9,123,10:29
9,124,10:29
9,125,10:29
9,126,10:29
9,127,10:29
9,128,10:29
9,129,10:29
9,130,10:5.5
9,131,10:5.5
9,132,10:29
9,133,10:29
9,134,10:29
9,135,10:29
9,136,10:29
9,137,10:29
9,138,10:29
9,139,10:5.5
9,140,10:162.1
9,146,10:162.1
9,163,10:162.1
9,164,10:162.1
9,165,10:162.1
9,168,10:85
9,169,10:85
9,172,10:162.1
9,173,10:162.1
9,174,10:162.1
9,207,10:17.1
9,208,10:85
9,209,10:98
9,211,10:85
9,213,10:98
9,214,10:85
9,215,10:17.1
9,242,10:98
9,243,10:17.1
9,244,10:24.2
9,245,10:24.2
9,246,10:17.1
9,247,10:98
9,14,11:98
9,15,11:17.1
9,16,11:24.2
9,17,11:24.2
9,18,11:17.1
9,19,11:98
9,46,11:17.1
9,47,11:44.9
9,48,11:98
9,49,11:44.9
9,50,11:44.9
9,51,11:44.9
9,52,11:98
9,53,11:44.9
9,54,11:17.1
9,87,11:43.5
9,88,11:43.5
9,89,11:43.5
9,92,11:50.5
9,93,11:50.5
9,96,11:43.5
9,97,11:43.5
9,98,11:43.5
9,115,11:98
9,121,11:162.1
9,122,11:5.5
9,123,11:101
9,124,11:101
9,125,11:101
9,126,11:101
9,127,11:101
9,128,11:101
9,129,11:101
9,130,11:5.5
9,131,11:5.5
9,132,11:101
9,133,11:101
9,134,11:101
9,135,11:101
9,136,11:101
9,137,11:101
9,138,11:101
9,139,11:5.5
9,140,11:162.1
9,146,11:98
9,163,11:43.5
9,164,11:43.5
9,165,11:43.5
9,168,11:50.5
9,169,11:50.5
9,172,11:43.5
9,173,11:43.5
9,174,11:43.5
9,207,11:17.1
9,208,11:44.9
9,209,11:98
9,210,11:44.9
9,211,11:44.9
9,212,11:44.9
9,213,11:98
9,214,11:44.9
9,215,11:17.1
9,242,11:98
9,243,11:17.1
9,244,11:24.2
9,245,11:24.2
9,246,11:17.1
9,247,11:98
9,13,12:109.6
9,14,12:98
9,15,12:4
9,16,12:4
9,17,12:4
9,18,12:4
9,19,12:98
9,20,12:109.7
9,46,12:17.1
9,47,12:98
9,48,12:98
9,49,12:98
9,50,12:98
9,51,12:98
9,52,12:98
9,53,12:98
9,54,12:17.1
9,84,12:109.6
9,85,12:109.4
9,86,12:109.4
9,87,12:98
9,88,12:98
9,89,12:98
9,90,12:162.9
9,91,12:44.5
9,92,12:44.5
9,93,12:44.5
9,94,12:44.5
9,95,12:162.9
9,96,12:98
9,97,12:98
9,98,12:98
9,99,12:109.7
9,100,12:109.4
9,101,12:109.7
9,113,12:109.4
9,114,12:109.6
9,115,12:98
9,116,12:30
9,121,12:162.1
9,122,12:5.5
9,123,12:101
9,124,12:101
9,125,12:101
9,126,12:101
9,127,12:101
9,128,12:101
9,129,12:101
9,130,12:5.5
9,131,12:5.5
9,132,12:101
9,133,12:101
9,134,12:101
9,135,12:101
9,136,12:101
9,137,12:101
9,138,12:101
9,139,12:5.5
9,140,12:162.1
9,146,12:98
9,147,12:109.7
9,148,12:109.4
9,160,12:109.6
9,161,12:109.4
9,162,12:109.6
9,163,12:98
9,164,12:98
9,165,12:98
9,166,12:162.9
9,167,12:44.5
9,168,12:44.5
9,169,12:44.5
9,170,12:44.5
9,171,12:162.9
9,172,12:98
9,173,12:98
9,174,12:98
9,175,12:109.4
9,176,12:109.4
9,177,12:109.7
9,207,12:17.1
9,208,12:98
9,209,12:98
9,210,12:98
9,211,12:98
9,212,12:98
9,213,12:98
9,214,12:98
9,215,12:17.1
9,241,12:109.6
9,242,12:98
9,243,12:4
9,244,12:4
9,245,12:4
9,246,12:4
9,247,12:98
9,248,12:109.7
9,14,13:109.2
9,15,13:109.3
9,17,13:109.2
9,18,13:109.3
9,46,13:17.1
9,48,13:109.2
9,49,13:109.3
9,51,13:109.2
9,52,13:109.3
9,54,13:17.1
9,90,13:162.1
9,91,13:128
9,92,13:128
9,93,13:128
9,94,13:128
9,95,13:162.1
9,114,13:109.2
9,115,13:24.2
9,116,13:17.5
9,121,13:162.1
9,122,13:162.9
9,123,13:5.5
9,124,13:101
9,125,13:101
9,126,13:101
9,127,13:101
9,128,13:101
9,129,13:101
9,130,13:5.5
9,131,13:5.5
9,132,13:101
9,133,13:101
9,134,13:101
9,135,13:101
9,136,13:101
9,137,13:101
9,138,13:5.5
9,139,13:162.1
9,140,13:162.9
9,145,13:17.5
9,146,13:24.2
9,147,13:109.3
9,166,13:162.1
9,167,13:128
9,168,13:128
9,169,13:128
9,170,13:128
9,171,13:162.1
9,207,13:17.1
9,209,13:109.2
9,210,13:109.3
9,212,13:109.2
9,213,13:109.3
9,215,13:17.1
9,243,13:109.2
9,244,13:109.3
9,246,13:109.2
9,247,13:109.3
9,46,14:17.1
9,54,14:17.1
9,90,14:162.1
9,91,14:128.4
9,92,14:128.4
9,93,14:128.4
9,94,14:128.4
9,95,14:162.1
9,115,14:24.2
9,122,14:162.1
9,123,14:5.5
9,124,14:101
9,125,14:101
9,126,14:101
9,127,14:101
9,128,14:101
9,129,14:101
9,130,14:5.5
9,131,14:5.5
9,132,14:101
9,133,14:101
9,134,14:101
9,135,14:101
9,136,14:101
9,137,14:101
9,138,14:5.5
9,139,14:162.1
9,146,14:24.2
9,166,14:162.1
9,167,14:128.4
9,168,14:128.4
9,169,14:128.4
9,170,14:128.4
9,171,14:162.1
9,207,14:17.1
9,215,14:17.1
9,46,15:17.1
9,54,15:17.1
9,90,15:162.1
9,91,15:44.13
9,92,15:44.13
9,93,15:44.13
9,94,15:44.13
9,95,15:162.1
9,115,15:24.2
9,122,15:162.1
9,123,15:162.9
9,124,15:5.5
9,125,15:101
9,126,15:101
9,127,15:101
9,128,15:101
9,129,15:101
9,130,15:5.5
9,131,15:5.5
9,132,15:101
9,133,15:101
9,134,15:101
9,135,15:101
9,136,15:101
9,137,15:5.5
9,138,15:162.1
9,139,15:162.9
9,146,15:24.2
9,166,15:162.1
9,167,15:44.13
9,168,15:44.13
9,169,15:44.13
9,170,15:44.13
9,171,15:162.1
9,207,15:17.1
9,215,15:17.1
9,11,16:109.2
9,12,16:109
9,13,16:109
9,14,16:109
9,15,16:109
9,16,16:109
9,17,16:109
9,18,16:109
9,19,16:109
9,20,16:109
9,21,16:109
9,45,16:109.2
9,46,16:17.1
9,54,16:17.1
9,55,16:109.3
9,90,16:162.1
9,95,16:162.1
9,115,16:98
9,123,16:162.1
9,124,16:5.5
9,125,16:101
9,126,16:101
9,127,16:101
9,128,16:101
9,129,16:101
9,130,16:5.5
9,131,16:5.5
9,132,16:101
9,133,16:101
9,134,16:101
9,135,16:101
9,136,16:101
9,137,16:5.5
9,138,16:162.1
9,146,16:98
9,166,16:162.1
9,171,16:162.1
9,206,16:109.2
9,207,16:17.1
9,215,16:17.1
9,216,16:109.3
9,240,16:109
9,241,16:109
9,242,16:109
9,243,16:109
9,244,16:109
9,245,16:109
9,246,16:109
9,247,16:109
9,248,16:109
9,249,16:109
9,250,16:109.3
9,46,17:109.2
9,47,17:109
9,48,17:109
9,49,17:109
9,50,17:109
9,51,17:109
9,52,17:109
9,53,17:109
9,54,17:109
9,90,17:162.1
9,91,17:44.13
9,92,17:44.13
9,93,17:44.13
9,94,17:44.13
9,95,17:162.1
9,115,17:98
9,123,17:162.1
9,124,17:162.9
9,125,17:5.5
9,126,17:101
9,127,17:101
9,128,17:101
9,129,17:101
9,130,17:5.5
9,131,17:5.5
9,132,17:101
9,133,17:101
9,134,17:101
9,135,17:101
9,136,17:5.5
9,137,17:162.1
9,138,17:162.9
9,146,17:98
9,166,17:162.1
9,167,17:44.13
9,168,17:44.13
9,169,17:44.13
9,170,17:44.13
9,171,17:162.1
9,207,17:109
9,208,17:109
9,209,17:109
9,210,17:109
9,211,17:109
9,212,17:109
9,213,17:109
9,214,17:109
9,215,17:109.3
9,90,18:162.1
9,95,18:162.1
9,115,18:162.1
9,124,18:162.1
9,125,18:162.9
9,126,18:5.5
9,127,18:101
9,128,18:101
9,129,18:101
9,130,18:5.5
9,131,18:5.5
9,132,18:101
9,133,18:101
9,134,18:101
9,135,18:5.5
9,136,18:162.1
9,137,18:162.9
9,146,18:162.1
9,166,18:162.1
9,171,18:162.1
9,90,19:109.2
9,91,19:44.13
9,94,19:44.13
9,95,19:109.3
9,115,19:98
9,125,19:162.1
9,126,19:162.9
9,127,19:5.5
9,128,19:5.5
9,129,19:5.5
9,130,19:5.5
9,131,19:5.5
9,132,19:5.5
9,133,19:5.5
9,134,19:5.5
9,135,19:162.1
9,136,19:162.9
9,146,19:98
9,166,19:109.2
9,167,19:44.13
9,170,19:44.13
9,171,19:109.3
9,92,20:44.5
9,93,20:44.5
9,115,20:98
9,126,20:162.1
9,127,20:162.9
9,128,20:162.9
9,129,20:162.9
9,130,20:162.9
9,131,20:162.9
9,132,20:162.9
9,133,20:162.9
9,134,20:162.9
9,135,20:162.9
9,146,20:98
9,168,20:44.5
9,169,20:44.5
9,114,21:109.4
9,115,21:98
9,116,21:98
9,117,21:98
9,118,21:98
9,119,21:98
9,120,21:98
9,121,21:98
9,122,21:98
9,123,21:98
9,124,21:98
9,125,21:98
9,126,21:98
9,127,21:98
9,128,21:98
9,129,21:98
9,130,21:98
9,131,21:98
9,132,21:98
9,133,21:98
9,134,21:98
9,135,21:98
9,136,21:98
9,137,21:98
9,138,21:98
9,139,21:98
9,140,21:98
9,141,21:98
9,142,21:98
9,143,21:98
9,144,21:98
9,145,21:98
9,146,21:98
9,147,21:109.7
9,146,22:98
10,0,0:24
10,1,0:24
10,2,0:24
10,3,0:24
10,4,0:24
10,5,0:24
10,6,0:24
10,7,0:24
10,8,0:24
10,9,0:24
10,10,0:24
10,11,0:24
10,12,0:24
10,13,0:24
10,14,0:24
10,15,0:98
10,16,0:98
10,17,0:98
10,18,0:98
10,19,0:24
10,20,0:24
10,21,0:98
10,22,0:98
10,23,0:98
10,24,0:98
10,25,0:98
10,26,0:98
10,27,0:98
10,28,0:98
10,29,0:98
10,30,0:98
10,31,0:98
10,32,0:98
10,33,0:98
10,34,0:98
10,35,0:98
10,36,0:98
10,37,0:98
10,38,0:98
10,39,0:98
10,40,0:98
10,41,0:98
10,42,0:98
10,43,0:98
10,44,0:98
10,45,0:98
10,46,0:24
10,47,0:24
10,48,0:24
10,49,0:24
10,50,0:24
10,51,0:24
10,52,0:24
10,53,0:24
10,54,0:24
10,55,0:98
10,56,0:98
10,57,0:98
10,58,0:98
10,59,0:98
10,60,0:98
10,61,0:98
10,62,0:98
10,63,0:98
10,64,0:98
10,65,0:98
10,66,0:98
10,67,0:98
10,68,0:98
10,69,0:98
10,70,0:98
10,71,0:98
10,72,0:98
10,73,0:98
10,74,0:98
10,75,0:98
10,76,0:98
10,77,0:98
10,78,0:98
10,79,0:98
10,80,0:98
10,81,0:98
10,82,0:98
10,83,0:98
10,84,0:98
10,85,0:98
10,86,0:98
10,87,0:98
10,88,0:98
10,89,0:98
10,90,0:98
10,91,0:98
10,92,0:98
10,93,0:98
10,94,0:98
10,95,0:98
10,96,0:98
10,97,0:98
10,98,0:98
10,99,0:98
10,100,0:98
10,101,0:98
10,102,0:98
10,103,0:98
10,104,0:98
10,105,0:98
10,106,0:98
10,107,0:98
10,108,0:98
10,109,0:98
10,110,0:98
10,111,0:98
10,112,0:98
10,113,0:98
10,114,0:98
10,115,0:98
10,116,0:98
10,117,0:98
10,118,0:98
10,119,0:98
10,120,0:98
10,121,0:98
10,122,0:98
10,123,0:98
10,124,0:13
10,125,0:98
10,126,0:98
10,127,0:98.2
10,128,0:98
10,129,0:4
10,130,0:4
10,131,0:98
10,132,0:4
10,133,0:98
10,134,0:13
10,135,0:98
10,136,0:98
10,137,0:4
10,138,0:98
10,139,0:98
10,140,0:98
10,141,0:98
10,142,0:98
10,143,0:98
10,144,0:98
10,145,0:98.2
10,146,0:98
10,147,0:98
10,148,0:98
10,149,0:98
10,150,0:98
10,151,0:98
10,152,0:98
10,153,0:98
10,154,0:98
10,155,0:98
10,156,0:98
10,157,0:98
10,158,0:98
10,159,0:98
10,160,0:98
10,161,0:98
10,162,0:98
10,163,0:98
10,164,0:98
10,165,0:98
10,166,0:98
10,167,0:98
10,168,0:98
10,169,0:98
10,170,0:98
10,171,0:98
10,172,0:98
10,173,0:98
10,174,0:98
10,175,0:98
10,176,0:98
10,177,0:98
10,178,0:98
10,179,0:98
10,180,0:98
10,181,0:98
10,182,0:98
10,183,0:98
10,184,0:98
10,185,0:98
10,186,0:98
10,187,0:98
10,188,0:98
10,189,0:98
10,190,0:98
10,191,0:98
10,192,0:98
10,193,0:98
10,194,0:98
10,195,0:98
10,196,0:98
10,197,0:98
10,198,0:98
10,199,0:98
10,200,0:98
10,201,0:98
10,202,0:98
10,203,0:98
10,204,0:98
10,205,0:98
10,206,0:98
10,207,0:24
10,208,0:24
10,209,0:24
10,210,0:24
10,211,0:24
10,212,0:24
10,213,0:24
10,214,0:24
10,215,0:24
10,216,0:98
10,217,0:98
10,218,0:98
10,219,0:98
10,220,0:98
10,221,0:98
10,222,0:98
10,223,0:98
10,224,0:98
10,225,0:98
10,226,0:98
10,227,0:98
10,228,0:98
10,229,0:98
10,230,0:98
10,231,0:98
10,232,0:98
10,233,0:98
10,234,0:98
10,235,0:98
10,236,0:98
10,237,0:98
10,238,0:98
10,239,0:98
10,240,0:98
10,241,0:24
10,242,0:24
10,243,0:98
10,244,0:98
10,245,0:98
10,246,0:98
10,247,0:24
10,248,0:24
10,249,0:24
10,250,0:24
10,251,0:24
10,252,0:24
10,253,0:24
10,254,0:24
10,255,0:24
10,256,0:24
10,257,0:24
10,258,0:24
10,259,0:24
10,12,1:17.1
10,13,1:17.1
10,14,1:98
10,15,1:98
10,18,1:98
10,19,1:17.1
10,20,1:17.1
10,46,1:17.1
10,47,1:98
10,48,1:98
10,49,1:98
10,50,1:98
10,51,1:98
10,52,1:98
10,53,1:98
10,54,1:17.1
10,85,1:4
10,86,1:4
10,87,1:162.1
10,88,1:162.1
10,89,1:162.1
10,90,1:24.1
10,91,1:24.1
10,92,1:24.1
10,93,1:24.1
10,94,1:24.1
10,95,1:24.1
10,96,1:162.1
10,97,1:162.1
10,98,1:162.1
10,99,1:4
10,100,1:4
10,114,1:4
10,115,1:98
10,116,1:33.1
10,121,1:162.1
10,140,1:162.1
10,141,1:33.1
10,146,1:98
10,147,1:4
10,161,1:4
10,162,1:4
10,163,1:162.1
10,164,1:162.1
10,165,1:162.1
10,166,1:24.1
10,167,1:24.1
10,168,1:24.1
10,169,1:24.1
10,170,1:24.1
10,171,1:24.1
10,172,1:162.1
10,173,1:162.1
10,174,1:162.1
10,175,1:4
10,176,1:4
10,207,1:17.1
10,208,1:98
10,209,1:98
10,210,1:98
10,211,1:98
10,212,1:98
10,213,1:98
10,214,1:98
10,215,1:17.1
10,241,1:17.1
10,242,1:17.1
10,243,1:98
10,246,1:98
10,247,1:98
10,248,1:17.1
10,249,1:17.1
10,12,2:17.1
10,13,2:17.1
10,14,2:98
10,15,2:98
10,18,2:98
10,19,2:17.1
10,20,2:17.1
10,46,2:17.1
10,48,2:98
10,50,2:98
10,52,2:98
10,54,2:17.1
10,85,2:162.1
10,86,2:24.2
10,99,2:24.2
10,100,2:162.1
10,114,2:24.2
10,115,2:98
10,121,2:162.1
10,140,2:162.1
10,146,2:98
10,147,2:24.2
10,161,2:162.1
10,162,2:24.2
10,175,2:24.2
10,176,2:162.1
10,207,2:17.1
10,209,2:98
10,211,2:98
10,213,2:98
10,215,2:17.1
10,241,2:17.1
10,242,2:17.1
10,243,2:98
10,246,2:98
10,247,2:98
10,248,2:17.1
10,249,2:17.1
10,12,3:17.1
10,13,3:17.1
10,14,3:98
10,15,3:98
10,18,3:98
10,19,3:17.1
10,20,3:17.1
10,46,3:17.1
10,47,3:98
10,48,3:98
10,49,3:98
10,50,3:98
10,51,3:98
10,52,3:98
10,53,3:98
10,54,3:17.1
10,85,3:162.1
10,86,3:24.1
10,99,3:24.1
10,100,3:162.1
10,114,3:24.2
10,115,3:98
10,121,3:162.1
10,140,3:162.1
10,146,3:98
10,147,3:24.2
10,161,3:162.1
10,162,3:24.1
10,175,3:24.1
10,176,3:162.1
10,207,3:17.1
10,208,3:98
10,209,3:98
10,210,3:98
10,211,3:98
10,212,3:98
10,213,3:98
10,214,3:98
10,215,3:17.1
10,241,3:17.1
10,242,3:17.1
10,243,3:98
10,246,3:98
10,247,3:98
10,248,3:17.1
10,249,3:17.1
10,12,4:17.1
10,13,4:17.1
10,14,4:98
10,15,4:98
10,16,4:98
10,17,4:98
10,18,4:98
10,19,4:17.1
10,20,4:17.1
10,46,4:17.1
10,54,4:17.1
10,85,4:162.1
10,86,4:24.2
10,88,4:85
10,97,4:44.13
10,98,4:44.5
10,99,4:24.2
10,100,4:162.1
10,114,4:4
10,115,4:98
10,121,4:162.1
10,140,4:162.1
10,146,4:98
10,147,4:4
10,161,4:162.1
10,162,4:24.2
10,163,4:44.5
10,164,4:44.13
10,173,4:85
10,175,4:24.2
10,176,4:162.1
10,207,4:17.1
10,215,4:17.1
10,241,4:17.1
10,242,4:17.1
10,243,4:98
10,244,4:98
10,245,4:98
10,246,4:98
10,247,4:98
10,248,4:17.1
10,249,4:17.1
10,12,5:17.1
10,13,5:17.1
10,14,5:98
10,15,5:98
10,16,5:98
10,17,5:98
10,18,5:98
10,19,5:17.1
10,20,5:17.1
10,46,5:17.1
10,54,5:17.1
10,84,5:44.9
10,85,5:24.2
10,86,5:24.2
10,88,5:50.5
10,95,5:44.13
10,96,5:44.5
10,99,5:24.2
10,100,5:24.2
10,101,5:44.9
10,114,5:24.2
10,115,5:98
10,121,5:162.1
10,140,5:162.1
10,146,5:98
10,147,5:24.2
10,160,5:44.9
10,161,5:24.2
10,162,5:24.2
10,165,5:44.5
10,166,5:44.13
10,173,5:50.5
10,175,5:24.2
10,176,5:24.2
10,177,5:44.9
10,207,5:17.1
10,215,5:17.1
10,241,5:17.1
10,242,5:17.1
10,243,5:98
10,244,5:98
10,245,5:98
10,246,5:98
10,247,5:98
10,248,5:17.1
10,249,5:17.1
10,12,6:17.1
10,13,6:17.1
10,14,6:98
10,15,6:4
10,16,6:4
10,17,6:4
10,18,6:4
10,19,6:17.1
10,20,6:17.1
10,46,6:17.1
10,47,6:4
10,48,6:4
10,49,6:4
10,50,6:4
10,51,6:4
10,52,6:4
10,53,6:4
10,54,6:17.1
10,85,6:162.1
10,86,6:114
10,93,6:44.13
10,94,6:44.5
10,99,6:114
10,100,6:162.1
10,114,6:109.2
10,115,6:98
10,121,6:162.1
10,140,6:162.1
10,146,6:98
10,147,6:109.3
10,161,6:162.1
10,162,6:114
10,167,6:44.5
10,168,6:44.13
10,175,6:114
10,176,6:162.1
10,207,6:17.1
10,208,6:4
10,209,6:4
10,210,6:4
10,211,6:4
10,212,6:4
10,213,6:4
10,214,6:4
10,215,6:17.1
10,241,6:17.1
10,242,6:17.1
10,243,6:4
10,244,6:4
10,245,6:4
10,246,6:4
10,247,6:98
10,248,6:17.1
10,249,6:17.1
10,12,7:17.1
10,13,7:17.1
10,14,7:98
10,19,7:17.1
10,20,7:17.1
10,46,7:17.1
10,47,7:17.9
10,48,7:17.9
10,49,7:17.9
10,50,7:17.9
10,51,7:17.9
10,52,7:17.9
10,53,7:17.9
10,54,7:17.1
10,84,7:44.9
10,85,7:162.1
10,86,7:114.4
10,91,7:44.13
10,92,7:44.5
10,99,7:114.4
10,100,7:162.1
10,101,7:44.9
10,114,7:109.6
10,115,7:98
10,121,7:162.1
10,140,7:162.1
10,146,7:98
10,147,7:109.7
10,160,7:44.9
10,161,7:162.1
10,162,7:114.4
10,169,7:44.5
10,170,7:44.13
10,175,7:114.4
10,176,7:162.1
10,177,7:44.9
10,207,7:17.1
10,208,7:17.9
10,209,7:17.9
10,210,7:17.9
10,211,7:17.9
10,212,7:17.9
10,213,7:17.9
10,214,7:17.9
10,215,7:17.1
10,241,7:17.1
10,242,7:17.1
10,247,7:98
10,248,7:17.1
10,249,7:17.1
10,12,8:17.1
10,13,8:17.1
10,14,8:98
10,19,8:17.1
10,20,8:17.1
10,46,8:17.1
10,47,8:98
10,48,8:98
10,49,8:98
10,50,8:98
10,51,8:98
10,52,8:98
10,53,8:98
10,54,8:17.1
10,85,8:162.1
10,86,8:4
10,89,8:44.13
10,90,8:44.5
10,99,8:4
10,100,8:162.1
10,114,8:24.1
10,115,8:98
10,121,8:162.1
10,140,8:162.1
10,146,8:98
10,147,8:24.1
10,161,8:162.1
10,162,8:4
10,171,8:44.5
10,172,8:44.13
10,175,8:4
10,176,8:162.1
10,207,8:17.1
10,208,8:98
10,209,8:98
10,210,8:98
10,211,8:98
10,212,8:98
10,213,8:98
10,214,8:98
10,215,8:17.1
10,241,8:17.1
10,242,8:17.1
10,247,8:98
10,248,8:17.1
10,249,8:17.1
10,12,9:17.1
10,13,9:17.1
10,14,9:98
10,19,9:17.1
10,20,9:17.1
10,46,9:17.1
10,47,9:98
10,48,9:98
10,49,9:98
10,50,9:98
10,51,9:98
10,52,9:98
10,53,9:98
10,54,9:17.1
10,84,9:44.8
10,85,9:162.1
10,86,9:43
10,87,9:44.13
10,88,9:44.5
10,99,9:43
10,100,9:162.1
10,101,9:44.8
10,114,9:98
10,115,9:98
10,121,9:162.1
10,140,9:162.1
10,146,9:98
10,147,9:98
10,160,9:44.8
10,161,9:162.1
10,162,9:43
10,173,9:44.5
10,174,9:44.13
10,175,9:43
10,176,9:162.1
10,177,9:44.8
10,207,9:17.1
10,208,9:98
10,209,9:98
10,210,9:98
10,211,9:98
10,212,9:98
10,213,9:98
10,214,9:98
10,215,9:17.1
10,241,9:17.1
10,242,9:17.1
10,247,9:98
10,248,9:17.1
10,249,9:17.1
10,12,10:17.1
10,13,10:17.1
10,14,10:98
10,19,10:17.1
10,20,10:17.1
10,46,10:17.1
10,47,10:17.1
10,48,10:17.1
10,49,10:17.1
10,50,10:17.1
10,51,10:17.1
10,52,10:17.1
10,53,10:17.1
10,54,10:17.1
10,85,10:162.1
10,86,10:162.1
10,99,10:162.1
10,100,10:162.1
10,114,10:162.1
10,115,10:98
10,121,10:162.1
10,122,10:5.5
10,123,10:5.5
10,124,10:5.5
10,125,10:5.5
10,126,10:5.5
10,127,10:5.5
10,128,10:5.5
10,129,10:5.5
10,130,10:5.5
10,131,10:5.5
10,132,10:5.5
10,133,10:5.5
10,134,10:5.5
10,135,10:5.5
10,136,10:5.5
10,137,10:5.5
10,138,10:5.5
10,139,10:5.5
10,140,10:162.1
10,146,10:98
10,147,10:162.1
10,161,10:162.1
10,162,10:162.1
10,175,10:162.1
10,176,10:162.1
10,207,10:17.1
10,208,10:17.1
10,209,10:17.1
10,210,10:17.1
10,211,10:17.1
10,212,10:17.1
10,213,10:17.1
10,214,10:17.1
10,215,10:17.1
10,241,10:17.1
10,242,10:17.1
10,247,10:98
10,248,10:17.1
10,249,10:17.1
10,12,11:17.1
10,13,11:17.1
10,14,11:98
10,19,11:17.1
10,20,11:17.1
10,46,11:17.1
10,47,11:17.1
10,48,11:17.1
10,49,11:17.1
10,50,11:17.1
10,51,11:17.1
10,52,11:17.1
10,53,11:17.1
10,54,11:17.1
10,85,11:43.5
10,86,11:43.5
10,99,11:43.5
10,100,11:43.5
10,114,11:98
10,115,11:98
10,121,11:162.1
10,122,11:5.5
10,130,11:164.1
10,131,11:164.1
10,139,11:5.5
10,140,11:162.1
10,146,11:98
10,147,11:98
10,161,11:43.5
10,162,11:43.5
10,175,11:43.5
10,176,11:43.5
10,207,11:17.1
10,208,11:17.1
10,209,11:17.1
10,210,11:17.1
10,211,11:17.1
10,212,11:17.1
10,213,11:17.1
10,214,11:17.1
10,215,11:17.1
10,241,11:17.1
10,242,11:17.1
10,247,11:98
10,248,11:17.1
10,249,11:17.1
10,12,12:17.1
10,13,12:17.1
10,14,12:98
10,15,12:4
10,16,12:4
10,17,12:4
10,18,12:4
10,19,12:17.1
10,20,12:17.1
10,21,12:109.4
10,22,12:109.4
10,23,12:109.4
10,24,12:109.4
10,25,12:109.4
10,26,12:109.4
10,27,12:109.4
10,28,12:109.4
10,29,12:109.4
10,30,12:109.4
10,31,12:109.4
10,32,12:109.4
10,33,12:109.4
10,34,12:109.4
10,35,12:109.4
10,36,12:109.4
10,37,12:109.4
10,38,12:109.4
10,39,12:109.4
10,40,12:109.4
10,41,12:109.4
10,42,12:109.4
10,43,12:109.4
10,44,12:109.4
10,45,12:109.4
10,46,12:17.1
10,47,12:98
10,48,12:98
10,49,12:98
10,50,12:98
10,51,12:98
10,52,12:98
10,53,12:98
10,54,12:17.1
10,55,12:109.4
10,56,12:109.4
10,57,12:109.4
10,58,12:109.4
10,59,12:109.4
10,60,12:109.4
10,61,12:109.4
10,62,12:109.4
10,63,12:109.4
10,64,12:109.4
10,65,12:109.4
10,66,12:109.4
10,67,12:109.4
10,68,12:109.4
10,69,12:109.4
10,70,12:109.4
10,71,12:109.4
10,72,12:109.4
10,73,12:109.4
10,74,12:109.4
10,75,12:109.4
10,76,12:109.4
10,77,12:109.4
10,78,12:109.4
10,79,12:109.4
10,80,12:109.4
10,81,12:109.4
10,82,12:109.4
10,83,12:109.6
10,84,12:109.4
10,85,12:98
10,86,12:98
10,87,12:162.5
10,89,12:162.5
10,90,12:162.5
10,91,12:44.5
10,92,12:44.5
10,93,12:44.5
10,94,12:44.5
10,95,12:162.5
10,96,12:162.5
10,97,12:162.5
10,98,12:162.5
10,99,12:98
10,100,12:98
10,101,12:109.7
10,102,12:109.4
10,112,12:109.4
10,113,12:109.6
10,114,12:98
10,115,12:44.13
10,121,12:162.1
10,122,12:5.5
10,130,12:77.1
10,131,12:77.1
10,139,12:5.5
10,140,12:162.1
10,146,12:44.13
10,147,12:98
10,148,12:109.7
10,149,12:109.4
10,159,12:109.4
10,160,12:109.6
10,161,12:98
10,162,12:98
10,163,12:162.5
10,164,12:162.5
10,165,12:162.5
10,166,12:162.5
10,167,12:44.5
10,168,12:44.5
10,169,12:44.5
10,170,12:44.5
10,171,12:162.5
10,172,12:162.5
10,174,12:162.5
10,175,12:98
10,176,12:98
10,177,12:109.4
10,178,12:109.7
10,179,12:109.4
10,180,12:109.4
10,181,12:109.4
10,182,12:109.4
10,183,12:109.4
10,184,12:109.4
10,185,12:109.4
10,186,12:109.4
10,187,12:109.4
10,188,12:109.4
10,189,12:109.4
10,190,12:109.4
10,191,12:109.4
10,192,12:109.4
10,193,12:109.4
10,194,12:109.4
10,195,12:109.4
10,196,12:109.4
10,197,12:109.4
10,198,12:109.4
10,199,12:109.4
10,200,12:109.4
10,201,12:109.4
10,202,12:109.4
10,203,12:109.4
10,204,12:109.4
10,205,12:109.4
10,206,12:109.4
10,207,12:17.1
10,208,12:98
10,209,12:98
10,210,12:98
10,211,12:98
10,212,12:98
10,213,12:98
10,214,12:98
10,215,12:17.1
10,216,12:109.4
10,217,12:109.4
10,218,12:109.4
10,219,12:109.4
10,220,12:109.4
10,221,12:109.4
10,222,12:109.4
10,223,12:109.4
10,224,12:109.4
10,225,12:109.4
10,226,12:109.4
10,227,12:109.4
10,228,12:109.4
10,229,12:109.4
10,230,12:109.4
10,231,12:109.4
10,232,12:109.4
10,233,12:109.4
10,234,12:109.4
10,235,12:109.4
10,236,12:109.4
10,237,12:109.4
10,238,12:109.4
10,239,12:109.4
10,240,12:109.4
10,241,12:17.1
10,242,12:17.1
10,243,12:4
10,244,12:4
10,245,12:4
10,246,12:4
10,247,12:98
10,248,12:17.1
10,249,12:17.1
10,12,13:17.1
10,13,13:17.1
10,19,13:17.1
10,20,13:17.1
10,22,13:109.2
10,23,13:109.3
10,25,13:109.2
10,26,13:109.3
10,28,13:109.2
10,29,13:109.3
10,31,13:109.2
10,32,13:109.3
10,34,13:109.2
10,35,13:109.3
10,37,13:109.2
10,38,13:109.3
10,40,13:109.2
10,41,13:109.3
10,43,13:109.2
10,44,13:109.3
10,46,13:17.1
10,54,13:17.1
10,57,13:109.2
10,58,13:109.3
10,60,13:109.2
10,61,13:109.3
10,63,13:109.2
10,64,13:109.3
10,66,13:109.2
10,67,13:109.3
10,69,13:109.2
10,70,13:109.3
10,72,13:109.2
10,73,13:109.3
10,75,13:109.2
10,76,13:109.3
10,78,13:109.2
10,79,13:109.3
10,81,13:109.2
10,82,13:109.3
10,86,13:128.2
10,87,13:128
10,88,13:128
10,89,13:128
10,90,13:162.1
10,95,13:162.1
10,96,13:128
10,97,13:128
10,98,13:128
10,99,13:128
10,113,13:109
10,114,13:17.1
10,116,13:17.5
10,121,13:162.1
10,122,13:162.9
10,123,13:5.5
10,130,13:77.1
10,131,13:77.1
10,138,13:5.5
10,139,13:162.1
10,140,13:162.9
10,145,13:17.5
10,147,13:17.1
10,148,13:109
10,162,13:128
10,163,13:128
10,164,13:128
10,165,13:128
10,166,13:162.1
10,171,13:162.1
10,172,13:128
10,173,13:128
10,174,13:128
10,175,13:128.3
10,179,13:109.2
10,180,13:109.3
10,182,13:109.2
10,183,13:109.3
10,185,13:109.2
10,186,13:109.3
10,188,13:109.2
10,189,13:109.3
10,191,13:109.2
10,192,13:109.3
10,194,13:109.2
10,195,13:109.3
10,197,13:109.2
10,198,13:109.3
10,200,13:109.2
10,201,13:109.3
10,203,13:109.2
10,204,13:109.3
10,207,13:17.1
10,215,13:17.1
10,217,13:109.2
10,218,13:109.3
10,220,13:109.2
10,221,13:109.3
10,223,13:109.2
10,224,13:109.3
10,226,13:109.2
10,227,13:109.3
10,229,13:109.2
10,230,13:109.3
10,232,13:109.2
10,233,13:109.3
10,235,13:109.2
10,236,13:109.3
10,238,13:109.2
10,239,13:109.3
10,241,13:17.1
10,242,13:17.1
10,248,13:17.1
10,249,13:17.1
10,12,14:17.1
10,13,14:17.1
10,19,14:17.1
10,20,14:17.1
10,46,14:17.1
10,54,14:17.1
10,86,14:128.6
10,87,14:128.4
10,88,14:128.4
10,89,14:128.4
10,90,14:162.1
10,91,14:109.5
10,92,14:109.5
10,93,14:109.5
10,94,14:109.5
10,95,14:162.1
10,96,14:128.4
10,97,14:128.4
10,98,14:128.4
10,99,14:128.7
10,122,14:162.1
10,123,14:5.5
10,130,14:164.5
10,131,14:164.5
10,138,14:5.5
10,139,14:162.1
10,162,14:128.6
10,163,14:128.4
10,164,14:128.4
10,165,14:128.4
10,166,14:162.1
10,167,14:109.5
10,168,14:109.5
10,169,14:109.5
10,170,14:109.5
10,171,14:162.1
10,172,14:128.4
10,173,14:128.4
10,174,14:128.4
10,175,14:128.7
10,207,14:17.1
10,215,14:17.1
10,241,14:17.1
10,242,14:17.1
10,248,14:17.1
10,249,14:17.1
10,12,15:17.1
10,13,15:17.1
10,19,15:17.1
10,20,15:17.1
10,46,15:17.1
10,54,15:17.1
10,87,15:44.13
10,88,15:44.13
10,89,15:44.13
10,90,15:162.1
10,91,15:98
10,92,15:98
10,93,15:98
10,94,15:98
10,95,15:162.1
10,96,15:44.13
10,97,15:44.13
10,98,15:44.13
10,114,15:17.1
10,122,15:162.1
10,123,15:162.9
10,124,15:5.5
10,125,15:5.5
10,126,15:5.5
10,127,15:5.5
10,128,15:5.5
10,129,15:5.5
10,130,15:5.5
10,131,15:5.5
10,132,15:5.5
10,133,15:5.5
10,134,15:5.5
10,135,15:5.5
10,136,15:5.5
10,137,15:5.5
10,138,15:162.1
10,139,15:162.9
10,147,15:17.1
10,163,15:44.13
10,164,15:44.13
10,165,15:44.13
10,166,15:162.1
10,167,15:98
10,168,15:98
10,169,15:98
10,170,15:98
10,171,15:162.1
10,172,15:44.13
10,173,15:44.13
10,174,15:44.13
10,207,15:17.1
10,215,15:17.1
10,241,15:17.1
10,242,15:17.1
10,248,15:17.1
10,249,15:17.1
10,11,16:109.2
10,12,16:17.1
10,13,16:17.1
10,19,16:17.1
10,20,16:17.1
10,21,16:109.3
10,45,16:109.2
10,46,16:17.1
10,54,16:17.1
10,55,16:109.3
10,90,16:162.1
10,91,16:162.1
10,92,16:162.1
10,93,16:162.1
10,94,16:162.1
10,95,16:162.1
10,114,16:98
10,123,16:162.1
10,130,16:164.1
10,131,16:164.1
10,138,16:162.1
10,147,16:98
10,166,16:162.1
10,167,16:162.1
10,168,16:162.1
10,169,16:162.1
10,170,16:162.1
10,171,16:162.1
10,206,16:109.2
10,207,16:17.1
10,215,16:17.1
10,216,16:109.3
10,240,16:109.2
10,241,16:17.1
10,242,16:17.1
10,248,16:17.1
10,249,16:17.1
10,250,16:109.3
10,12,17:109.2
10,13,17:109
10,14,17:109
10,15,17:109
10,16,17:109
10,17,17:109
10,18,17:109
10,19,17:109
10,20,17:109.3
10,46,17:109.2
10,54,17:109.3
10,87,17:44.13
10,88,17:44.13
10,89,17:44.13
10,90,17:43.5
10,91,17:43.5
10,92,17:43.5
10,93,17:43.5
10,94,17:43.5
10,95,17:43.5
10,96,17:44.13
10,97,17:44.13
10,98,17:44.13
10,114,17:98
10,123,17:162.1
10,124,17:162.9
10,130,17:77.1
10,131,17:77.1
10,137,17:162.1
10,138,17:162.9
10,147,17:98
10,163,17:44.13
10,164,17:44.13
10,165,17:44.13
10,166,17:43.5
10,167,17:43.5
10,168,17:43.5
10,169,17:43.5
10,170,17:43.5
10,171,17:43.5
10,172,17:44.13
10,173,17:44.13
10,174,17:44.13
10,207,17:109.2
10,215,17:109.3
10,241,17:109.2
10,242,17:109
10,243,17:109
10,244,17:109
10,245,17:109
10,246,17:109
10,247,17:109
10,248,17:109
10,249,17:109.3
10,47,18:109
10,48,18:109
10,49,18:109
10,50,18:109
10,51,18:109
10,52,18:109
10,53,18:109.3
10,114,18:162.1
10,124,18:162.1
10,125,18:162.9
10,136,18:162.1
10,137,18:162.9
10,147,18:162.1
10,208,18:109.2
10,209,18:109
10,210,18:109
10,211,18:109
10,212,18:109
10,213,18:109
10,214,18:109
10,114,19:98
10,125,19:162.1
10,126,19:162.9
10,130,19:77.1
10,131,19:77.1
10,135,19:162.1
10,136,19:162.9
10,147,19:98
10,114,20:98
10,126,20:162.1
10,127,20:162.9
10,128,20:162.9
10,129,20:162.9
10,130,20:162.9
10,131,20:162.9
10,132,20:162.9
10,133,20:162.9
10,134,20:162.9
10,135,20:162.9
10,147,20:98
10,113,21:109.4
10,114,21:98
10,115,21:98
10,116,21:98
10,117,21:98
10,118,21:98
10,119,21:98
10,120,21:98
10,121,21:98
10,122,21:98
10,123,21:98
10,124,21:98
10,125,21:98
10,126,21:98
10,127,21:98
10,128,21:98
10,129,21:98
10,130,21:98
10,131,21:98
10,132,21:98
10,133,21:98
10,134,21:98
10,135,21:98
10,136,21:98
10,137,21:98
10,138,21:98
10,139,21:98
10,140,21:98
10,141,21:98
10,142,21:98
10,143,21:98
10,144,21:98
10,145,21:98
10,146,21:98
10,147,21:98
10,148,21:109.7
10,114,22:98
10,90,29:109.4
10,91,29:109.4
10,92,29:109.4
10,93,29:109.4
10,94,29:109.4
10,95,29:109.7
10,166,29:109.6
10,167,29:109.4
10,168,29:109.4
10,169,29:109.4
10,170,29:109.4
10,171,29:109.4
11,0,0:24
11,1,0:24
11,2,0:24
11,3,0:24
11,4,0:24
11,5,0:24
11,6,0:24
11,7,0:24
11,8,0:24
11,9,0:24
11,10,0:24
11,11,0:24
11,12,0:98
11,13,0:24
11,14,0:98
11,15,0:98
11,16,0:98
11,17,0:98
11,18,0:98
11,19,0:24
11,20,0:24
11,21,0:24
11,22,0:24
11,23,0:24
11,24,0:24
11,25,0:24
11,26,0:24
11,27,0:24
11,28,0:24
11,29,0:24
11,30,0:24
11,31,0:24
11,32,0:24
11,33,0:24
11,34,0:24
11,35,0:24
11,36,0:24
11,37,0:24
11,38,0:24
11,39,0:98
11,40,0:98
11,41,0:98
11,42,0:98
11,43,0:98
11,44,0:98
11,45,0:98
11,46,0:98
11,47,0:98
11,48,0:98
11,49,0:98
11,50,0:98
11,51,0:98
11,52,0:98
11,53,0:98
11,54,0:98
11,55,0:24
11,56,0:24
11,57,0:24
11,58,0:24
11,59,0:24
11,60,0:24
11,61,0:24
11,62,0:24
11,63,0:24
11,64,0:24
11,65,0:24
11,66,0:24
11,67,0:24
11,68,0:24
11,69,0:24
11,70,0:24
11,71,0:24
11,72,0:24
11,73,0:24
11,74,0:98
11,75,0:98
11,76,0:98
11,77,0:98
11,78,0:98
11,79,0:98
11,80,0:98
11,81,0:98
11,82,0:98
11,83,0:98
11,84,0:98
11,85,0:98
11,86,0:98
11,87,0:98
11,88,0:98
11,89,0:98
11,90,0:98
11,91,0:98
11,92,0:98
11,93,0:98
11,94,0:98
11,95,0:98
11,96,0:98
11,97,0:98
11,98,0:98
11,99,0:98
11,100,0:98
11,101,0:98
11,102,0:98
11,103,0:98
11,104,0:98
11,105,0:98
11,106,0:98
11,107,0:98
11,108,0:98
11,109,0:98
11,110,0:98
11,111,0:98
11,112,0:98
11,113,0:98
11,114,0:98
11,115,0:98
11,116,0:98
11,117,0:98
11,118,0:98
11,119,0:98
11,120,0:98
11,121,0:98
11,122,0:98
11,123,0:98
11,124,0:98
11,125,0:98
11,126,0:13
11,127,0:4
11,128,0:98
11,129,0:98
11,130,0:98
11,131,0:4
11,132,0:98
11,133,0:98
11,134,0:98
11,135,0:13
11,136,0:98.2
11,137,0:98
11,138,0:98
11,139,0:98
11,140,0:98
11,141,0:98
11,142,0:98
11,143,0:98.2
11,144,0:98
11,145,0:98
11,146,0:98
11,147,0:98
11,148,0:98
11,149,0:98
11,150,0:98
11,151,0:98
11,152,0:98
11,153,0:98
11,154,0:98
11,155,0:98
11,156,0:98
11,157,0:98
11,158,0:98
11,159,0:98
11,160,0:98
11,161,0:98
11,162,0:98
11,163,0:98
11,164,0:98
11,165,0:98
11,166,0:98
11,167,0:98
11,168,0:98
11,169,0:98
11,170,0:98
11,171,0:98
11,172,0:98
11,173,0:98
11,174,0:98
11,175,0:98
11,176,0:98
11,177,0:98
11,178,0:98
11,179,0:98
11,180,0:98
11,181,0:98
11,182,0:98
11,183,0:98
11,184,0:98
11,185,0:98
11,186,0:98
11,187,0:98
11,188,0:24
11,189,0:24
11,190,0:24
11,191,0:24
11,192,0:24
11,193,0:24
11,194,0:24
11,195,0:24
11,196,0:24
11,197,0:24
11,198,0:24
11,199,0:24
11,200,0:24
11,201,0:24
11,202,0:24
11,203,0:24
11,204,0:24
11,205,0:24
11,206,0:24
11,207,0:98
11,208,0:98
11,209,0:98
11,210,0:98
11,211,0:98
11,212,0:98
11,213,0:98
11,214,0:98
11,215,0:98
11,216,0:98
11,217,0:98
11,218,0:98
11,219,0:98
11,220,0:98
11,221,0:98
11,222,0:98
11,223,0:24
11,224,0:24
11,225,0:24
11,226,0:24
11,227,0:24
11,228,0:24
11,229,0:24
11,230,0:24
11,231,0:24
11,232,0:24
11,233,0:24
11,234,0:24
11,235,0:24
11,236,0:24
11,237,0:24
11,238,0:24
11,239,0:24
11,240,0:24
11,241,0:24
11,242,0:24
11,243,0:98
11,244,0:98
11,245,0:98
11,246,0:98
11,247,0:98
11,248,0:24
11,249,0:98
11,250,0:24
11,251,0:24
11,252,0:24
11,253,0:24
11,254,0:24
11,255,0:24
11,256,0:24
11,257,0:24
11,258,0:24
11,259,0:24
11,12,1:109.2
11,13,1:98
11,19,1:98
11,20,1:98
11,21,1:44
11,22,1:44
11,23,1:44
11,24,1:44
11,25,1:44
11,26,1:44
11,27,1:44
11,28,1:44
11,29,1:44
11,30,1:44
11,31,1:44
11,32,1:44
11,33,1:44
11,34,1:44
11,35,1:44
11,36,1:44
11,37,1:44
11,38,1:44
11,39,1:44
11,40,1:44
11,41,1:44
11,42,1:44
11,43,1:44
11,44,1:44
11,45,1:44
11,46,1:98
11,54,1:98
11,55,1:44
11,56,1:44
11,57,1:44
11,58,1:44
11,59,1:44
11,60,1:44
11,61,1:44
11,62,1:44
11,63,1:44
11,64,1:44
11,65,1:44
11,66,1:44
11,67,1:44
11,68,1:44
11,69,1:44
11,70,1:44
11,71,1:44
11,72,1:44
11,73,1:44
11,74,1:44
11,75,1:44
11,76,1:44
11,77,1:44
11,78,1:44
11,79,1:44
11,80,1:44
11,81,1:44
11,82,1:44
11,83,1:44
11,84,1:4
11,85,1:162.1
11,86,1:162.1
11,87,1:24.1
11,88,1:24.1
11,89,1:24.1
11,90,1:98
11,91,1:98
11,92,1:98
11,93,1:98
11,94,1:98
11,95,1:98
11,96,1:24.1
11,97,1:24.1
11,98,1:24.1
11,99,1:162.1
11,100,1:162.1
11,101,1:4
11,113,1:4
11,114,1:98
11,120,1:98
11,121,1:98
11,122,1:98
11,139,1:98
11,140,1:98
11,141,1:98
11,146,1:54.2
11,147,1:98
11,148,1:4
11,160,1:4
11,161,1:162.1
11,162,1:162.1
11,163,1:24.1
11,164,1:24.1
11,165,1:24.1
11,166,1:98
11,167,1:98
11,168,1:98
11,169,1:98
11,170,1:98
11,171,1:98
11,172,1:24.1
11,173,1:24.1
11,174,1:24.1
11,175,1:162.1
11,176,1:162.1
11,177,1:4
11,178,1:44
11,179,1:44
11,180,1:44
11,181,1:44
11,182,1:44
11,183,1:44
11,184,1:44
11,185,1:44
11,186,1:44
11,187,1:44
11,188,1:44
11,189,1:44
11,190,1:44
11,191,1:44
11,192,1:44
11,193,1:44
11,194,1:44
11,195,1:44
11,196,1:44
11,197,1:44
11,198,1:44
11,199,1:44
11,200,1:44
11,201,1:44
11,202,1:44
11,203,1:44
11,204,1:44
11,205,1:44
11,206,1:44
11,207,1:98
11,214,1:65.2
11,215,1:98
11,216,1:44
11,217,1:44
11,218,1:44
11,219,1:44
11,220,1:44
11,221,1:44
11,222,1:44
11,223,1:44
11,224,1:44
11,225,1:44
11,226,1:44
11,227,1:44
11,228,1:44
11,229,1:44
11,230,1:44
11,231,1:44
11,232,1:44
11,233,1:44
11,234,1:44
11,235,1:44
11,236,1:44
11,237,1:44
11,238,1:44
11,239,1:44
11,240,1:44
11,241,1:98
11,242,1:98
11,248,1:98
11,249,1:109.3
11,20,2:98
11,46,2:98
11,54,2:98
11,84,2:24.2
11,101,2:24.2
11,113,2:162.1
11,114,2:98
11,120,2:98
11,121,2:98
11,122,2:98
11,139,2:98
11,140,2:98
11,141,2:98
11,147,2:98
11,148,2:162.1
11,160,2:24.2
11,177,2:24.2
11,207,2:98
11,214,2:65.2
11,215,2:98
11,241,2:98
11,12,3:109.6
11,13,3:98
11,19,3:98
11,20,3:109.7
11,21,3:128.4
11,22,3:128.4
11,23,3:128.4
11,24,3:128.4
11,25,3:128.4
11,26,3:128.4
11,27,3:128.4
11,28,3:128.4
11,29,3:128.4
11,30,3:128.4
11,31,3:128.4
11,32,3:128.4
11,33,3:128.4
11,34,3:128.4
11,35,3:128.4
11,36,3:128.4
11,37,3:128.4
11,38,3:128.4
11,39,3:128.4
11,40,3:128.4
11,41,3:128.4
11,42,3:128.4
11,43,3:128.4
11,44,3:128.4
11,45,3:128.4
11,46,3:98
11,54,3:98
11,55,3:128.4
11,56,3:128.4
11,57,3:128.4
11,58,3:128.4
11,59,3:128.4
11,60,3:128.4
11,61,3:128.4
11,62,3:128.4
11,63,3:128.4
11,64,3:128.4
11,65,3:128.4
11,66,3:128.4
11,67,3:128.4
11,68,3:128.4
11,69,3:128.4
11,70,3:128.4
11,71,3:128.4
11,72,3:128.4
11,73,3:128.4
11,74,3:128.4
11,75,3:128.4
11,76,3:128.4
11,77,3:128.4
11,78,3:128.4
11,79,3:128.4
11,80,3:128.4
11,81,3:128.4
11,82,3:128.4
11,84,3:24.1
11,99,3:44.13
11,100,3:44.5
11,101,3:24.1
11,113,3:162.1
11,114,3:98
11,120,3:98
11,121,3:98
11,122,3:98
11,139,3:98
11,140,3:98
11,141,3:98
11,147,3:98
11,148,3:162.1
11,160,3:24.1
11,161,3:44.5
11,162,3:44.13
11,177,3:24.1
11,179,3:128.4
11,180,3:128.4
11,181,3:128.4
11,182,3:128.4
11,183,3:128.4
11,184,3:128.4
11,185,3:128.4
11,186,3:128.4
11,187,3:128.4
11,188,3:128.4
11,189,3:128.4
11,190,3:128.4
11,191,3:128.4
11,192,3:128.4
11,193,3:128.4
11,194,3:128.4
11,195,3:128.4
11,196,3:128.4
11,197,3:128.4
11,198,3:128.4
11,199,3:128.4
11,200,3:128.4
11,201,3:128.4
11,202,3:128.4
11,203,3:128.4
11,204,3:128.4
11,205,3:128.4
11,206,3:128.4
11,207,3:98
11,214,3:65.2
11,215,3:98
11,216,3:128.4
11,217,3:128.4
11,218,3:128.4
11,219,3:128.4
11,220,3:128.4
11,221,3:128.4
11,222,3:128.4
11,223,3:128.4
11,224,3:128.4
11,225,3:128.4
11,226,3:128.4
11,227,3:128.4
11,228,3:128.4
11,229,3:128.4
11,230,3:128.4
11,231,3:128.4
11,232,3:128.4
11,233,3:128.4
11,234,3:128.4
11,235,3:128.4
11,236,3:128.4
11,237,3:128.4
11,238,3:128.4
11,239,3:128.4
11,240,3:128.4
11,241,3:109.6
11,242,3:98
11,248,3:98
11,249,3:109.7
11,12,4:98
11,19,4:4
11,20,4:98
11,46,4:98
11,54,4:98
11,84,4:24.2
11,97,4:44.13
11,98,4:44.5
11,101,4:24.2
11,113,4:162.1
11,114,4:98
11,120,4:98
11,121,4:98
11,122,4:98
11,139,4:98
11,140,4:98
11,141,4:98
11,147,4:98
11,148,4:162.1
11,160,4:24.2
11,163,4:44.5
11,164,4:44.13
11,177,4:24.2
11,207,4:98
11,214,4:65.2
11,215,4:98
11,241,4:98
11,242,4:4
11,249,4:98
11,12,5:98
11,19,5:4
11,20,5:98
11,46,5:98
11,54,5:98
11,83,5:44.9
11,84,5:24.2
11,95,5:44.13
11,96,5:44.5
11,101,5:24.2
11,102,5:44.9
11,113,5:162.1
11,114,5:98
11,120,5:98
11,121,5:98
11,122,5:98
11,139,5:98
11,140,5:98
11,141,5:98
11,147,5:98
11,148,5:162.1
11,159,5:44.9
11,160,5:24.2
11,165,5:44.5
11,166,5:44.13
11,177,5:24.2
11,178,5:44.9
11,207,5:98
11,214,5:65.2
11,215,5:98
11,241,5:98
11,242,5:4
11,249,5:98
11,12,6:98
11,13,6:4
11,14,6:4
11,15,6:4
11,16,6:4
11,17,6:4
11,18,6:4
11,19,6:98
11,20,6:98
11,21,6:109.4
11,22,6:109.4
11,23,6:109.4
11,24,6:109.4
11,25,6:109.4
11,26,6:109.4
11,27,6:109.4
11,28,6:109.4
11,29,6:109.4
11,30,6:109.4
11,31,6:109.4
11,32,6:109.4
11,33,6:109.4
11,34,6:109.4
11,35,6:109.4
11,36,6:109.4
11,37,6:109.4
11,38,6:109.4
11,39,6:109.4
11,40,6:109.4
11,41,6:109.4
11,42,6:109.4
11,43,6:109.4
11,44,6:109.4
11,45,6:109.4
11,46,6:4
11,47,6:4
11,48,6:4
11,49,6:4
11,50,6:4
11,51,6:4
11,52,6:4
11,53,6:4
11,54,6:98
11,55,6:109.4
11,56,6:109.4
11,57,6:109.4
11,58,6:109.4
11,59,6:109.4
11,60,6:109.4
11,61,6:109.4
11,62,6:109.4
11,63,6:109.4
11,64,6:109.4
11,65,6:109.4
11,66,6:109.4
11,67,6:109.4
11,68,6:109.4
11,69,6:109.4
11,70,6:109.4
11,71,6:109.4
11,72,6:109.4
11,73,6:109.4
11,74,6:109.4
11,75,6:109.4
11,76,6:109.4
11,77,6:109.4
11,78,6:109.4
11,79,6:109.4
11,80,6:109.4
11,81,6:109.4
11,82,6:109.4
11,84,6:114.2
11,93,6:44.13
11,94,6:44.5
11,101,6:114.3
11,113,6:162.1
11,114,6:89
11,120,6:98
11,121,6:98
11,122,6:98
11,139,6:98
11,140,6:98
11,141,6:98
11,147,6:89
11,148,6:162.1
11,160,6:114.2
11,167,6:44.5
11,168,6:44.13
11,177,6:114.3
11,179,6:109.4
11,180,6:109.4
11,181,6:109.4
11,182,6:109.4
11,183,6:109.4
11,184,6:109.4
11,185,6:109.4
11,186,6:109.4
11,187,6:109.4
11,188,6:109.4
11,189,6:109.4
11,190,6:109.4
11,191,6:109.4
11,192,6:109.4
11,193,6:109.4
11,194,6:109.4
11,195,6:109.4
11,196,6:109.4
11,197,6:109.4
11,198,6:109.4
11,199,6:109.4
11,200,6:109.4
11,201,6:109.4
11,202,6:109.4
11,203,6:109.4
11,204,6:109.4
11,205,6:109.4
11,206,6:109.4
11,207,6:98
11,208,6:4
11,209,6:4
11,210,6:4
11,211,6:4
11,212,6:4
11,213,6:4
11,214,6:65.2
11,215,6:4
11,216,6:109.4
11,217,6:109.4
11,218,6:109.4
11,219,6:109.4
11,220,6:109.4
11,221,6:109.4
11,222,6:109.4
11,223,6:109.4
11,224,6:109.4
11,225,6:109.4
11,226,6:109.4
11,227,6:109.4
11,228,6:109.4
11,229,6:109.4
11,230,6:109.4
11,231,6:109.4
11,232,6:109.4
11,233,6:109.4
11,234,6:109.4
11,235,6:109.4
11,236,6:109.4
11,237,6:109.4
11,238,6:109.4
11,239,6:109.4
11,240,6:109.4
11,241,6:98
11,242,6:98
11,243,6:4
11,244,6:4
11,245,6:4
11,246,6:4
11,247,6:4
11,248,6:4
11,249,6:98
11,12,7:44.1
11,13,7:17.9
11,19,7:98
11,20,7:109.3
11,21,7:24.2
11,23,7:24.2
11,25,7:24.2
11,27,7:24.2
11,29,7:24.2
11,31,7:24.2
11,33,7:24.2
11,35,7:24.2
11,37,7:24.2
11,39,7:24.2
11,41,7:24.2
11,43,7:24.2
11,45,7:24.2
11,46,7:98
11,54,7:98
11,55,7:98
11,56,7:24.2
11,58,7:24.2
11,60,7:24.2
11,62,7:24.2
11,64,7:24.2
11,66,7:24.2
11,68,7:24.2
11,70,7:24.2
11,72,7:24.2
11,74,7:24.2
11,76,7:24.2
11,78,7:24.2
11,80,7:24.2
11,82,7:24.2
11,83,7:44.9
11,84,7:114.6
11,91,7:44.13
11,92,7:44.5
11,101,7:114.7
11,102,7:44.9
11,113,7:162.1
11,114,7:89
11,120,7:98
11,121,7:98
11,122,7:98
11,139,7:98
11,140,7:98
11,141,7:98
11,147,7:89
11,148,7:162.1
11,159,7:44.9
11,160,7:114.6
11,169,7:44.5
11,170,7:44.13
11,177,7:114.7
11,178,7:44.9
11,179,7:24.2
11,181,7:24.2
11,183,7:24.2
11,185,7:24.2
11,187,7:24.2
11,189,7:24.2
11,191,7:24.2
11,193,7:24.2
11,195,7:24.2
11,197,7:24.2
11,199,7:24.2
11,201,7:24.2
11,203,7:24.2
11,205,7:24.2
11,206,7:98
11,207,7:98
11,214,7:65.2
11,215,7:98
11,216,7:24.2
11,218,7:24.2
11,220,7:24.2
11,222,7:24.2
11,224,7:24.2
11,226,7:24.2
11,228,7:24.2
11,230,7:24.2
11,232,7:24.2
11,234,7:24.2
11,236,7:24.2
11,238,7:24.2
11,240,7:24.2
11,241,7:109.2
11,242,7:98
11,248,7:17.9
11,249,7:44.1
11,12,8:44.9
11,13,8:98
11,19,8:98
11,21,8:98
11,23,8:98
11,25,8:98
11,27,8:98
11,29,8:98
11,31,8:98
11,33,8:98
11,35,8:98
11,37,8:98
11,39,8:98
11,41,8:98
11,43,8:98
11,45,8:98
11,46,8:98
11,54,8:98
11,55,8:98
11,56,8:98
11,58,8:98
11,60,8:98
11,62,8:98
11,64,8:98
11,66,8:98
11,68,8:98
11,70,8:98
11,72,8:98
11,74,8:98
11,76,8:98
11,78,8:98
11,80,8:98
11,82,8:98
11,84,8:4
11,89,8:44.13
11,90,8:44.5
11,101,8:4
11,113,8:24.1
11,114,8:98
11,120,8:98
11,121,8:98
11,122,8:98
11,139,8:98
11,140,8:98
11,141,8:98
11,147,8:98
11,148,8:24.1
11,160,8:4
11,171,8:44.5
11,172,8:44.13
11,177,8:4
11,179,8:98
11,181,8:98
11,183,8:98
11,185,8:98
11,187,8:98
11,189,8:98
11,191,8:98
11,193,8:98
11,195,8:98
11,197,8:98
11,199,8:98
11,201,8:98
11,203,8:98
11,205,8:98
11,206,8:98
11,207,8:98
11,214,8:65.2
11,215,8:98
11,216,8:98
11,218,8:98
11,220,8:98
11,222,8:98
11,224,8:98
11,226,8:98
11,228,8:98
11,230,8:98
11,232,8:98
11,234,8:98
11,236,8:98
11,238,8:98
11,240,8:98
11,242,8:98
11,248,8:98
11,249,8:44.9
11,12,9:44.1
11,13,9:98
11,19,9:4
11,20,9:98
11,21,9:67
11,22,9:109.4
11,23,9:67
11,24,9:109.4
11,25,9:67
11,26,9:109.4
11,27,9:67
11,28,9:109.4
11,29,9:67
11,30,9:109.4
11,31,9:67
11,32,9:109.4
11,33,9:67
11,34,9:109.4
11,35,9:67
11,36,9:109.4
11,37,9:67
11,38,9:109.4
11,39,9:67
11,40,9:109.4
11,41,9:67
11,42,9:109.4
11,43,9:67
11,44,9:109.4
11,45,9:67
11,46,9:98
11,54,9:98
11,55,9:109.4
11,56,9:67
11,57,9:109.4
11,58,9:67
11,59,9:109.4
11,60,9:67
11,61,9:109.4
11,62,9:67
11,63,9:109.4
11,64,9:67
11,65,9:109.4
11,66,9:67
11,67,9:109.4
11,68,9:67
11,69,9:109.4
11,70,9:67
11,71,9:109.4
11,72,9:67
11,73,9:109.4
11,74,9:67
11,75,9:109.4
11,76,9:67
11,77,9:109.4
11,78,9:67
11,79,9:109.4
11,80,9:67
11,81,9:109.4
11,82,9:67
11,83,9:44.8
11,84,9:43
11,87,9:44.13
11,88,9:44.5
11,101,9:43
11,102,9:44.8
11,113,9:98
11,114,9:98
11,120,9:98
11,121,9:98
11,122,9:98
11,139,9:98
11,140,9:98
11,141,9:98
11,147,9:98
11,148,9:98
11,159,9:44.8
11,160,9:43
11,173,9:44.5
11,174,9:44.13
11,177,9:43
11,178,9:44.8
11,179,9:67
11,180,9:109.4
11,181,9:67
11,182,9:109.4
11,183,9:67
11,184,9:109.4
11,185,9:67
11,186,9:109.4
11,187,9:67
11,188,9:109.4
11,189,9:67
11,190,9:109.4
11,191,9:67
11,192,9:109.4
11,193,9:67
11,194,9:109.4
11,195,9:67
11,196,9:109.4
11,197,9:67
11,198,9:109.4
11,199,9:67
11,200,9:109.4
11,201,9:67
11,202,9:109.4
11,203,9:67
11,204,9:109.4
11,205,9:67
11,206,9:109.4
11,207,9:98
11,214,9:65.2
11,215,9:98
11,216,9:67
11,217,9:109.4
11,218,9:67
11,219,9:109.4
11,220,9:67
11,221,9:109.4
11,222,9:67
11,223,9:109.4
11,224,9:67
11,225,9:109.4
11,226,9:67
11,227,9:109.4
11,228,9:67
11,229,9:109.4
11,230,9:67
11,231,9:109.4
11,232,9:67
11,233,9:109.4
11,234,9:67
11,235,9:109.4
11,236,9:67
11,237,9:109.4
11,238,9:67
11,239,9:109.4
11,240,9:67
11,241,9:98
11,242,9:4
11,248,9:98
11,249,9:44.1
11,12,10:85
11,13,10:17.1
11,19,10:17.1
11,20,10:98
11,22,10:98
11,24,10:98
11,26,10:98
11,28,10:98
11,30,10:98
11,32,10:98
11,34,10:98
11,36,10:98
11,38,10:98
11,40,10:98
11,42,10:98
11,44,10:98
11,46,10:98
11,54,10:98
11,55,10:98
11,57,10:98
11,59,10:98
11,61,10:98
11,63,10:98
11,65,10:98
11,67,10:98
11,69,10:98
11,71,10:98
11,73,10:98
11,75,10:98
11,77,10:98
11,79,10:98
11,81,10:98
11,83,10:98
11,84,10:162.1
11,85,10:44.13
11,86,10:44.5
11,101,10:162.1
11,113,10:162.1
11,114,10:98
11,120,10:98
11,121,10:98
11,122,10:98
11,124,10:77.1
11,126,10:77.1
11,128,10:77.1
11,130,10:77.1
11,131,10:77.1
11,133,10:77.1
11,135,10:77.1
11,137,10:77.1
11,139,10:98
11,140,10:98
11,141,10:98
11,147,10:98
11,148,10:162.1
11,160,10:162.1
11,175,10:44.5
11,176,10:44.13
11,177,10:162.1
11,178,10:98
11,180,10:98
11,182,10:98
11,184,10:98
11,186,10:98
11,188,10:98
11,190,10:98
11,192,10:98
11,194,10:98
11,196,10:98
11,198,10:98
11,200,10:98
11,202,10:98
11,204,10:98
11,206,10:98
11,207,10:98
11,214,10:65.2
11,215,10:98
11,217,10:98
11,219,10:98
11,221,10:98
11,223,10:98
11,225,10:98
11,227,10:98
11,229,10:98
11,231,10:98
11,233,10:98
11,235,10:98
11,237,10:98
11,239,10:98
11,241,10:98
11,242,10:17.1
11,248,10:17.1
11,249,10:85
11,12,11:44.9
11,13,11:17.1
11,19,11:17.1
11,20,11:98
11,21,11:85
11,22,11:98
11,23,11:85
11,24,11:98
11,25,11:85
11,26,11:98
11,27,11:85
11,28,11:98
11,29,11:85
11,30,11:98
11,31,11:85
11,32,11:98
11,33,11:85
11,34,11:98
11,35,11:85
11,36,11:98
11,37,11:85
11,38,11:98
11,39,11:85
11,40,11:98
11,41,11:85
11,42,11:98
11,43,11:85
11,44,11:98
11,45,11:85
11,46,11:98
11,54,11:98
11,55,11:98
11,56,11:85
11,57,11:98
11,58,11:85
11,59,11:98
11,60,11:85
11,61,11:98
11,62,11:85
11,63,11:98
11,64,11:85
11,65,11:98
11,66,11:85
11,67,11:98
11,68,11:85
11,69,11:98
11,70,11:85
11,71,11:98
11,72,11:85
11,73,11:98
11,74,11:85
11,75,11:98
11,76,11:85
11,77,11:98
11,78,11:85
11,79,11:98
11,80,11:85
11,81,11:98
11,82,11:85
11,83,11:98
11,84,11:43.5
11,101,11:43.5
11,113,11:98
11,114,11:98
11,120,11:98
11,121,11:98
11,122,11:98
11,139,11:98
11,140,11:98
11,141,11:98
11,147,11:98
11,148,11:98
11,160,11:43.5
11,177,11:43.5
11,178,11:98
11,179,11:85
11,180,11:98
11,181,11:85
11,182,11:98
11,183,11:85
11,184,11:98
11,185,11:85
11,186,11:98
11,187,11:85
11,188,11:98
11,189,11:85
11,190,11:98
11,191,11:85
11,192,11:98
11,193,11:85
11,194,11:98
11,195,11:85
11,196,11:98
11,197,11:85
11,198,11:98
11,199,11:85
11,200,11:98
11,201,11:85
11,202,11:98
11,203,11:85
11,204,11:98
11,205,11:85
11,206,11:98
11,207,11:98
11,213,11:65.5
11,214,11:65.2
11,215,11:98
11,216,11:85
11,217,11:98
11,218,11:85
11,219,11:98
11,220,11:85
11,221,11:98
11,222,11:85
11,223,11:98
11,224,11:85
11,225,11:98
11,226,11:85
11,227,11:98
11,228,11:85
11,229,11:98
11,230,11:85
11,231,11:98
11,232,11:85
11,233,11:98
11,234,11:85
11,235,11:98
11,236,11:85
11,237,11:98
11,238,11:85
11,239,11:98
11,240,11:85
11,241,11:98
11,242,11:17.1
11,248,11:17.1
11,249,11:44.9
11,12,12:98
11,13,12:98
11,14,12:98
11,15,12:4
11,16,12:4
11,17,12:4
11,18,12:4
11,19,12:98
11,20,12:109.7
11,21,12:98
11,22,12:98
11,23,12:98
11,24,12:98
11,25,12:98
11,26,12:98
11,27,12:98
11,28,12:98
11,29,12:98
11,30,12:98
11,31,12:98
11,32,12:98
11,33,12:98
11,34,12:98
11,35,12:98
11,36,12:98
11,37,12:98
11,38,12:98
11,39,12:98
11,40,12:98
11,41,12:98
11,42,12:98
11,43,12:98
11,44,12:98
11,45,12:98
11,46,12:98
11,47,12:98
11,48,12:98
11,49,12:98
11,50,12:98
11,51,12:98
11,52,12:98
11,53,12:98
11,54,12:98
11,55,12:98
11,56,12:98
11,57,12:98
11,58,12:98
11,59,12:98
11,60,12:98
11,61,12:98
11,62,12:98
11,63,12:98
11,64,12:98
11,65,12:98
11,66,12:98
11,67,12:98
11,68,12:98
11,69,12:98
11,70,12:98
11,71,12:98
11,72,12:98
11,73,12:98
11,74,12:98
11,75,12:98
11,76,12:98
11,77,12:98
11,78,12:98
11,79,12:98
11,80,12:98
11,81,12:98
11,82,12:98
11,83,12:109.4
11,84,12:98
11,85,12:162.5
11,86,12:162.5
11,90,12:24.1
11,91,12:44.5
11,92,12:44.5
11,93,12:44.5
11,94,12:44.5
11,95,12:44.5
11,96,12:44.5
11,97,12:44.5
11,98,12:44.5
11,99,12:162.5
11,100,12:162.5
11,101,12:98
11,102,12:109.7
11,103,12:109.4
11,111,12:109.4
11,112,12:109.6
11,113,12:98
11,114,12:44.13
11,115,12:44.13
11,120,12:98
11,121,12:98
11,122,12:98
11,139,12:98
11,140,12:98
11,141,12:98
11,146,12:44.13
11,147,12:44.13
11,148,12:98
11,149,12:109.7
11,150,12:109.4
11,158,12:109.4
11,159,12:109.6
11,160,12:98
11,161,12:162.5
11,162,12:162.5
11,163,12:44.5
11,164,12:44.5
11,165,12:44.5
11,166,12:44.5
11,167,12:44.5
11,168,12:44.5
11,169,12:44.5
11,170,12:44.5
11,171,12:24.1
11,175,12:162.5
11,176,12:162.5
11,177,12:98
11,178,12:109.4
11,179,12:98
11,180,12:98
11,181,12:98
11,182,12:98
11,183,12:98
11,184,12:98
11,185,12:98
11,186,12:98
11,187,12:98
11,188,12:98
11,189,12:98
11,190,12:98
11,191,12:98
11,192,12:98
11,193,12:98
11,194,12:98
11,195,12:98
11,196,12:98
11,197,12:98
11,198,12:98
11,199,12:98
11,200,12:98
11,201,12:98
11,202,12:98
11,203,12:98
11,204,12:98
11,205,12:98
11,206,12:98
11,207,12:98
11,208,12:98
11,209,12:98
11,210,12:98
11,211,12:98
11,212,12:98
11,213,12:98
11,214,12:65.2
11,215,12:98
11,216,12:98
11,217,12:98
11,218,12:98
11,219,12:98
11,220,12:98
11,221,12:98
11,222,12:98
11,223,12:98
11,224,12:98
11,225,12:98
11,226,12:98
11,227,12:98
11,228,12:98
11,229,12:98
11,230,12:98
11,231,12:98
11,232,12:98
11,233,12:98
11,234,12:98
11,235,12:98
11,236,12:98
11,237,12:98
11,238,12:98
11,239,12:98
11,240,12:98
11,241,12:109.6
11,242,12:98
11,243,12:4
11,244,12:4
11,245,12:4
11,246,12:4
11,247,12:98
11,248,12:98
11,249,12:98
11,83,13:85
11,84,13:85
11,85,13:128
11,86,13:128
11,99,13:128.3
11,100,13:128
11,101,13:85
11,102,13:85
11,112,13:109.2
11,113,13:24.2
11,116,13:17.5
11,120,13:98
11,121,13:98
11,122,13:98
11,138,13:98
11,139,13:98
11,140,13:98
11,141,13:98
11,145,13:17.5
11,148,13:24.2
11,149,13:109.3
11,159,13:85
11,160,13:85
11,161,13:128
11,162,13:128.2
11,175,13:128
11,176,13:128
11,177,13:85
11,178,13:85
11,84,14:85
11,85,14:128.4
11,86,14:128.6
11,87,14:109.5
11,88,14:109.5
11,89,14:109.5
11,96,14:109.5
11,97,14:109.5
11,98,14:109.5
11,99,14:128.7
11,100,14:128.4
11,101,14:85
11,113,14:24.2
11,120,14:98
11,121,14:98
11,122,14:98
11,123,14:98
11,138,14:98
11,139,14:98
11,140,14:98
11,141,14:98
11,148,14:24.2
11,160,14:85
11,161,14:128.4
11,162,14:128.6
11,163,14:109.5
11,164,14:109.5
11,165,14:109.5
11,172,14:109.5
11,173,14:109.5
11,174,14:109.5
11,175,14:128.7
11,176,14:128.4
11,177,14:85
11,84,15:44.13
11,85,15:44.13
11,86,15:44.13
11,87,15:98
11,88,15:98
11,89,15:98
11,96,15:98
11,97,15:98
11,98,15:98
11,99,15:44.13
11,100,15:44.13
11,101,15:44.13
11,113,15:24.2
11,120,15:98
11,121,15:98
11,122,15:98
11,123,15:98
11,125,15:77.1
11,127,15:77.1
11,129,15:77.1
11,132,15:77.1
11,134,15:77.1
11,136,15:77.1
11,137,15:98
11,138,15:98
11,139,15:98
11,140,15:98
11,141,15:98
11,148,15:24.2
11,160,15:44.13
11,161,15:44.13
11,162,15:44.13
11,163,15:98
11,164,15:98
11,165,15:98
11,172,15:98
11,173,15:98
11,174,15:98
11,175,15:44.13
11,176,15:44.13
11,177,15:44.13
11,11,16:109.2
11,21,16:109.3
11,45,16:109.2
11,55,16:109.3
11,87,16:162.1
11,88,16:162.1
11,89,16:162.1
11,90,16:109.5
11,91,16:109.5
11,92,16:109.5
11,93,16:109.5
11,94,16:109.5
11,95,16:109.5
11,96,16:162.1
11,97,16:162.1
11,98,16:162.1
11,113,16:98
11,120,16:98
11,121,16:98
11,122,16:98
11,123,16:98
11,124,16:98
11,137,16:98
11,138,16:98
11,139,16:98
11,140,16:98
11,141,16:98
11,148,16:98
11,163,16:162.1
11,164,16:162.1
11,165,16:162.1
11,166,16:109.5
11,167,16:109.5
11,168,16:109.5
11,169,16:109.5
11,170,16:109.5
11,171,16:109.5
11,172,16:162.1
11,173,16:162.1
11,174,16:162.1
11,206,16:109.2
11,216,16:109.3
11,240,16:109.2
11,250,16:109.3
11,12,17:109.2
11,20,17:109.3
11,46,17:109.2
11,54,17:109.3
11,84,17:44.13
11,85,17:44.13
11,86,17:44.13
11,87,17:43.5
11,88,17:43.5
11,89,17:43.5
11,90,17:98
11,91,17:98
11,92,17:98
11,93,17:98
11,94,17:98
11,95,17:98
11,96,17:43.5
11,97,17:43.5
11,98,17:43.5
11,99,17:44.13
11,100,17:44.13
11,101,17:44.13
11,113,17:98
11,120,17:98
11,121,17:98
11,122,17:98
11,123,17:98
11,124,17:98
11,125,17:98
11,136,17:98
11,137,17:98
11,138,17:98
11,139,17:98
11,140,17:98
11,141,17:98
11,148,17:98
11,160,17:44.13
11,161,17:44.13
11,162,17:44.13
11,163,17:43.5
11,164,17:43.5
11,165,17:43.5
11,166,17:98
11,167,17:98
11,168,17:98
11,169,17:98
11,170,17:98
11,171,17:98
11,172,17:43.5
11,173,17:43.5
11,174,17:43.5
11,175,17:44.13
11,176,17:44.13
11,177,17:44.13
11,207,17:109.2
11,215,17:109.3
11,241,17:109.2
11,249,17:109.3
11,13,18:109
11,14,18:109
11,15,18:109
11,16,18:109
11,17,18:109
11,18,18:109
11,19,18:109.3
11,47,18:109.2
11,53,18:109.3
11,113,18:162.1
11,120,18:98
11,121,18:98
11,122,18:98
11,123,18:98
11,124,18:98
11,125,18:98
11,126,18:98
11,135,18:98
11,136,18:98
11,137,18:98
11,138,18:98
11,139,18:98
11,140,18:98
11,141,18:98
11,148,18:162.1
11,208,18:109.2
11,214,18:109.3
11,242,18:109.2
11,243,18:109
11,244,18:109
11,245,18:109
11,246,18:109
11,247,18:109
11,248,18:109
11,48,19:109
11,49,19:109
11,50,19:109
11,51,19:109
11,52,19:109
11,113,19:98
11,120,19:98
11,121,19:98
11,122,19:98
11,123,19:98
11,124,19:98
11,125,19:98
11,126,19:98
11,127,19:98
11,128,19:98
11,129,19:98
11,130,19:98
11,131,19:98
11,132,19:98
11,133,19:98
11,134,19:98
11,135,19:98
11,136,19:98
11,137,19:98
11,138,19:98
11,139,19:98
11,140,19:98
11,141,19:98
11,148,19:98
11,209,19:109
11,210,19:109
11,211,19:109
11,212,19:109
11,213,19:109
11,113,20:98
11,120,20:98
11,121,20:98
11,122,20:98
11,123,20:98
11,124,20:98
11,125,20:98
11,126,20:98
11,127,20:98
11,128,20:98
11,129,20:98
11,130,20:98
11,131,20:98
11,132,20:98
11,133,20:98
11,134,20:98
11,135,20:98
11,136,20:98
11,137,20:98
11,138,20:98
11,139,20:98
11,140,20:98
11,141,20:98
11,148,20:98
11,90,21:44.13
11,91,21:44.13
11,92,21:44.13
11,93,21:44.13
11,94,21:44.13
11,95,21:44.13
11,112,21:109.4
11,113,21:98
11,114,21:98
11,115,21:98
11,116,21:98
11,117,21:98
11,118,21:98
11,119,21:98
11,120,21:98
11,121,21:98
11,122,21:98
11,123,21:98
11,124,21:98
11,125,21:98
11,126,21:98
11,127,21:98
11,128,21:98
11,129,21:98
11,130,21:98
11,131,21:98
11,132,21:98
11,133,21:98
11,134,21:98
11,135,21:98
11,136,21:98
11,137,21:98
11,138,21:98
11,139,21:98
11,140,21:98
11,141,21:98
11,142,21:98
11,143,21:98
11,144,21:98
11,145,21:98
11,146,21:98
11,147,21:98
11,148,21:98
11,149,21:109.7
11,166,21:44.13
11,167,21:44.13
11,168,21:44.13
11,169,21:44.13
11,170,21:44.13
11,171,21:44.13
11,90,22:109
11,91,22:109
11,92,22:109
11,93,22:109
11,94,22:109
11,95,22:109.3
11,116,22:98
11,117,22:98
11,118,22:98
11,119,22:98
11,120,22:98
11,141,22:98
11,142,22:98
11,143,22:98
11,144,22:98
11,148,22:98
11,166,22:109.2
11,167,22:109
11,168,22:109
11,169,22:109
11,170,22:109
11,171,22:109
11,91,26:44.9
11,92,26:44.9
11,93,26:44.9
11,94,26:44.9
11,167,26:44.9
11,168,26:44.9
11,169,26:44.9
11,170,26:44.9
11,91,28:98
11,92,28:98
11,93,28:98
11,94,28:98
11,167,28:98
11,168,28:98
11,169,28:98
11,170,28:98
11,87,29:109.6
11,88,29:109.4
11,89,29:109.4
11,90,29:109.6
11,91,29:98
11,92,29:98
11,93,29:98
11,94,29:98
11,95,29:109.4
11,96,29:109.4
11,97,29:109.4
11,98,29:109.7
11,163,29:109.6
11,164,29:109.4
11,165,29:109.4
11,166,29:109.4
11,167,29:98
11,168,29:98
11,169,29:98
11,170,29:98
11,171,29:109.7
11,172,29:109.4
11,173,29:109.4
11,174,29:109.7
11,91,30:162.1
11,94,30:162.1
11,167,30:162.1
11,170,30:162.1
11,91,31:162.1
11,94,31:162.1
11,167,31:162.1
11,170,31:162.1
11,91,32:162.1
11,94,32:162.1
11,167,32:162.1
11,170,32:162.1
11,92,33:162.9
11,93,33:162.9
11,168,33:162.9
11,169,33:162.9
11,91,35:44.13
11,92,35:44.13
11,93,35:44.13
11,94,35:44.13
11,167,35:44.13
11,168,35:44.13
11,169,35:44.13
11,170,35:44.13
12,0,0:24
12,1,0:24
12,2,0:24
12,3,0:24
12,4,0:24
12,5,0:24
12,6,0:24
12,7,0:24
12,8,0:24
12,9,0:24
12,10,0:24
12,11,0:24
12,12,0:98
12,13,0:24
12,14,0:98
12,15,0:98
12,16,0:98
12,17,0:98
12,18,0:98
12,19,0:24
12,20,0:24
12,21,0:24
12,22,0:24
12,23,0:24
12,24,0:24
12,25,0:24
12,26,0:24
12,27,0:24
12,28,0:24
12,29,0:24
12,30,0:24
12,31,0:24
12,32,0:24
12,33,0:24
12,34,0:24
12,35,0:24
12,36,0:24
12,37,0:24
12,38,0:24
12,39,0:98
12,40,0:98
12,41,0:98
12,42,0:98
12,43,0:98
12,44,0:98
12,45,0:98
12,46,0:98
12,47,0:98
12,48,0:98
12,49,0:98
12,50,0:98
12,51,0:98
12,52,0:98
12,53,0:98
12,54,0:98
12,55,0:24
12,56,0:24
12,57,0:24
12,58,0:24
12,59,0:24
12,60,0:24
12,61,0:24
12,62,0:24
12,63,0:24
12,64,0:24
12,65,0:24
12,66,0:24
12,67,0:24
12,68,0:24
12,69,0:24
12,70,0:24
12,71,0:24
12,72,0:24
12,73,0:24
12,74,0:98
12,75,0:98
12,76,0:98
12,77,0:98
12,78,0:98
12,79,0:98
12,80,0:98
12,81,0:98
12,82,0:98
12,83,0:98
12,84,0:98
12,85,0:98
12,86,0:98
12,87,0:98
12,88,0:98
12,89,0:98
12,90,0:98
12,91,0:98
12,92,0:98
12,93,0:98
12,94,0:98
12,95,0:98
12,96,0:98
12,97,0:98
12,98,0:98
12,99,0:98
12,100,0:98
12,101,0:98
12,102,0:98
12,103,0:98
12,104,0:98
12,105,0:98
12,106,0:98
12,107,0:98
12,108,0:98
12,109,0:98
12,110,0:98
12,111,0:98
12,112,0:98
12,113,0:98
12,114,0:98
12,115,0:98
12,116,0:98
12,117,0:98
12,118,0:98
12,119,0:98
12,120,0:98
12,121,0:98
12,122,0:98
12,123,0:98
12,124,0:4
12,125,0:98
12,126,0:98.2
12,127,0:98
12,128,0:98
12,129,0:13
12,130,0:4
12,131,0:98
12,132,0:13
12,133,0:98
12,134,0:98
12,135,0:4
12,136,0:98
12,137,0:13
12,138,0:98
12,139,0:98
12,140,0:98
12,141,0:98
12,142,0:98
12,143,0:98
12,144,0:98.2
12,145,0:98
12,146,0:98.2
12,147,0:98
12,148,0:98
12,149,0:98
12,150,0:98
12,151,0:98
12,152,0:98
12,153,0:98
12,154,0:98
12,155,0:98
12,156,0:98
12,157,0:98
12,158,0:98
12,159,0:98
12,160,0:98
12,161,0:98
12,162,0:98
12,163,0:98
12,164,0:98
12,165,0:98
12,166,0:98
12,167,0:98
12,168,0:98
12,169,0:98
12,170,0:98
12,171,0:98
12,172,0:98
12,173,0:98
