[META]
version=2.0
spawnSunlight=True
spawnDarkness=True
spawnWater=False
spawnLava=False
underFill=False
randomRotation=True
dig=True
tree=False
branch=False
needsFoundation=True
rarity=30
collisionPercentage=5
spawnElevationMin=0
spawnElevationMax=200
branchLimit=6
spawnInBiome=All
[DATA]
0,0,0:1
0,1,0:1
0,2,0:1
0,3,0:1
0,4,0:1
0,5,0:1
0,6,0:1
0,7,0:1
0,8,0:1
0,9,0:1
0,10,0:1
0,11,0:1
0,12,0:1
0,13,0:1
0,14,0:1
0,15,0:1
0,16,0:1
0,17,0:1
0,18,0:1
0,19,0:1
0,20,0:1
0,21,0:1
0,22,0:1
0,23,0:1
0,24,0:1
0,25,0:1
0,26,0:1
0,27,0:1
0,28,0:1
0,29,0:1
0,30,0:1
0,31,0:1
0,32,0:1
0,33,0:1
0,34,0:1
0,35,0:1
0,36,0:1
0,0,1:1
0,1,1:1
0,2,1:1
0,3,1:1
0,4,1:1
0,5,1:1
0,6,1:1
0,7,1:1
0,8,1:1
0,9,1:1
0,10,1:1
0,11,1:1
0,12,1:1
0,13,1:1
0,14,1:1
0,15,1:1
0,16,1:1
0,17,1:1
0,18,1:1
0,19,1:1
0,20,1:1
0,21,1:1
0,22,1:1
0,23,1:1
0,24,1:1
0,25,1:1
0,26,1:1
0,27,1:1
0,28,1:1
0,29,1:1
0,30,1:1
0,31,1:1
0,32,1:1
0,33,1:1
0,34,1:1
0,35,1:1
0,36,1:1
0,0,2:1
0,1,2:3
0,2,2:3
0,3,2:3
0,4,2:1
0,5,2:1
0,6,2:1
0,7,2:1
0,8,2:1
0,9,2:1
0,10,2:1
0,11,2:1
0,12,2:1
0,13,2:1
0,14,2:1
0,15,2:1
0,16,2:1
0,17,2:1
0,18,2:1
0,19,2:1
0,20,2:1
0,21,2:1
0,22,2:1
0,23,2:1
0,24,2:1
0,25,2:1
0,26,2:1
0,27,2:1
0,28,2:1
0,29,2:1
0,30,2:1
0,31,2:1
0,32,2:1
0,33,2:1
0,34,2:1
0,35,2:1
0,36,2:1
0,0,3:3
0,1,3:3
0,2,3:3
0,3,3:3
0,4,3:3
0,5,3:3
0,6,3:1
0,7,3:1
0,8,3:1
0,9,3:1
0,10,3:1
0,11,3:1
0,12,3:1
0,13,3:1
0,14,3:1
0,15,3:1
0,16,3:1
0,17,3:1
0,18,3:1
0,19,3:1
0,20,3:1
0,21,3:1
0,22,3:1
0,23,3:1
0,24,3:1
0,25,3:1
0,26,3:1
0,27,3:1
0,28,3:1
0,29,3:1
0,30,3:1
0,31,3:3
0,32,3:3
0,33,3:3
0,34,3:3
0,35,3:3
0,36,3:1
0,0,4:3
0,1,4:3
0,2,4:3
0,3,4:3
0,4,4:3
0,5,4:3
0,6,4:3
0,7,4:3
0,8,4:1
0,9,4:1
0,10,4:1
0,11,4:1
0,12,4:1
0,13,4:1
0,14,4:1
0,15,4:13
0,16,4:13
0,17,4:13
0,18,4:1
0,19,4:1
0,20,4:1
0,21,4:1
0,22,4:1
0,23,4:1
0,24,4:1
0,25,4:1
0,26,4:1
0,27,4:1
0,28,4:1
0,29,4:1
0,30,4:1
0,31,4:3
0,32,4:3
0,33,4:3
0,34,4:3
0,35,4:3
0,36,4:1
0,0,5:3
0,1,5:3
0,2,5:3
0,3,5:3
0,4,5:3
0,5,5:3
0,6,5:3
0,7,5:3
0,8,5:3
0,9,5:1
0,10,5:1
0,11,5:1
0,12,5:1
0,13,5:13
0,14,5:13
0,15,5:13
0,16,5:13
0,17,5:13
0,18,5:1
0,19,5:1
0,20,5:1
0,21,5:1
0,22,5:1
0,23,5:1
0,24,5:1
0,25,5:1
0,26,5:1
0,27,5:1
0,28,5:1
0,29,5:1
0,30,5:1
0,31,5:3
0,32,5:3
0,33,5:3
0,34,5:3
0,35,5:3
0,36,5:1
0,0,6:3
0,1,6:3
0,2,6:3
0,3,6:3
0,4,6:3
0,5,6:3
0,6,6:3
0,7,6:12
0,8,6:12
0,9,6:1
0,10,6:1
0,11,6:1
0,12,6:1
0,13,6:13
0,14,6:13
0,15,6:13
0,16,6:13
0,17,6:13
0,18,6:1
0,19,6:1
0,20,6:1
0,21,6:1
0,22,6:1
0,23,6:1
0,24,6:1
0,25,6:1
0,26,6:1
0,27,6:1
0,28,6:1
0,29,6:1
0,30,6:1
0,31,6:1
0,32,6:3
0,33,6:3
0,34,6:3
0,35,6:1
0,36,6:1
0,0,7:2
0,1,7:2
0,2,7:2
0,3,7:2
0,4,7:2
0,5,7:2
0,6,7:2
0,7,7:2
0,8,7:2
0,9,7:2
0,10,7:2
0,11,7:2
0,12,7:2
0,13,7:2
0,14,7:2
0,15,7:98
0,16,7:98
0,17,7:98
0,18,7:98
0,19,7:98
0,20,7:98
0,21,7:98
0,22,7:2
0,23,7:2
0,24,7:2
0,25,7:2
0,26,7:2
0,27,7:2
0,28,7:2
0,29,7:2
0,30,7:2
0,31,7:2
0,32,7:2
0,33,7:2
0,34,7:2
0,35,7:2
0,36,7:2
0,1,8:31.1
0,3,8:31.1
0,4,8:31.1
0,5,8:31.1
0,10,8:31.1
0,11,8:31.1
0,12,8:31.1
0,14,8:44
0,22,8:44
0,29,8:31.1
0,30,8:31.1
0,31,8:31.1
0,32,8:31.1
0,34,8:31.1
0,36,8:37
1,0,0:1
1,1,0:1
1,2,0:1
1,3,0:1
1,4,0:1
1,5,0:1
1,6,0:1
1,7,0:1
1,8,0:1
1,9,0:1
1,10,0:1
1,11,0:1
1,12,0:1
1,13,0:1
1,14,0:1
1,15,0:1
1,16,0:1
1,17,0:1
1,18,0:1
1,19,0:1
1,20,0:1
1,21,0:1
1,22,0:1
1,23,0:1
1,24,0:1
1,25,0:1
1,26,0:1
1,27,0:1
1,28,0:1
1,29,0:1
1,30,0:1
1,31,0:1
1,32,0:1
1,33,0:1
1,34,0:1
1,35,0:1
1,36,0:1
1,0,1:1
1,1,1:1
1,2,1:1
1,3,1:1
1,4,1:1
1,5,1:1
1,6,1:1
1,7,1:1
1,8,1:1
1,9,1:1
1,10,1:1
1,11,1:1
1,12,1:1
1,13,1:1
1,14,1:1
1,15,1:1
1,16,1:1
1,17,1:1
1,18,1:1
1,19,1:1
1,20,1:1
1,21,1:1
1,22,1:1
1,23,1:1
1,24,1:1
1,25,1:1
1,26,1:1
1,27,1:1
1,28,1:1
1,29,1:1
1,30,1:1
1,31,1:1
1,32,1:1
1,33,1:1
1,34,1:1
1,35,1:1
1,36,1:1
1,0,2:1
1,1,2:1
1,2,2:1
1,3,2:1
1,4,2:1
1,5,2:1
1,6,2:1
1,7,2:1
1,8,2:1
1,9,2:1
1,10,2:1
1,11,2:1
1,12,2:1
1,13,2:1
1,14,2:1
1,15,2:1
1,16,2:1
1,17,2:1
1,18,2:1
1,19,2:1
1,20,2:1
1,21,2:1
1,22,2:1
1,23,2:1
1,24,2:1
1,25,2:1
1,26,2:1
1,27,2:1
1,28,2:1
1,29,2:1
1,30,2:1
1,31,2:1
1,32,2:1
1,33,2:1
1,34,2:1
1,35,2:1
1,36,2:1
1,0,3:3
1,1,3:3
1,2,3:3
1,3,3:3
1,4,3:3
1,5,3:1
1,6,3:1
1,7,3:1
1,8,3:1
1,9,3:1
1,10,3:1
1,11,3:1
1,12,3:1
1,13,3:1
1,14,3:1
1,15,3:1
1,16,3:1
1,17,3:1
1,18,3:1
1,19,3:1
1,20,3:1
1,21,3:1
1,22,3:1
1,23,3:1
1,24,3:1
1,25,3:1
1,26,3:1
1,27,3:1
1,28,3:1
1,29,3:1
1,30,3:1
1,31,3:1
1,32,3:1
1,33,3:1
1,34,3:1
1,35,3:1
1,36,3:1
1,0,4:3
1,1,4:3
1,2,4:3
1,3,4:3
1,4,4:3
1,5,4:3
1,6,4:1
1,7,4:1
1,8,4:1
1,9,4:1
1,10,4:1
1,11,4:1
1,12,4:1
1,13,4:1
1,14,4:1
1,15,4:13
1,16,4:13
1,17,4:13
1,18,4:1
1,19,4:1
1,20,4:1
1,21,4:1
1,22,4:1
1,23,4:1
1,24,4:1
1,25,4:1
1,26,4:1
1,27,4:1
1,28,4:1
1,29,4:1
1,30,4:1
1,31,4:1
1,32,4:3
1,33,4:3
1,34,4:3
1,35,4:3
1,36,4:1
1,0,5:3
1,1,5:3
1,2,5:3
1,3,5:3
1,4,5:3
1,5,5:3
1,6,5:3
1,7,5:1
1,8,5:1
1,9,5:1
1,10,5:1
1,11,5:1
1,12,5:1
1,13,5:1
1,14,5:13
1,15,5:13
1,16,5:13
1,17,5:13
1,18,5:13
1,19,5:1
1,20,5:1
1,21,5:1
1,22,5:1
1,23,5:1
1,24,5:1
1,25,5:1
1,26,5:1
1,27,5:1
1,28,5:1
1,29,5:1
1,30,5:1
1,31,5:1
1,32,5:1
1,33,5:3
1,34,5:3
1,35,5:3
1,36,5:1
1,0,6:3
1,1,6:3
1,2,6:3
1,3,6:3
1,4,6:3
1,5,6:3
1,6,6:12
1,7,6:12
1,8,6:1
1,9,6:1
1,10,6:1
1,11,6:1
1,12,6:1
1,13,6:1
1,14,6:13
1,15,6:13
1,16,6:13
1,17,6:13
1,18,6:13
1,19,6:1
1,20,6:1
1,21,6:1
1,22,6:1
1,23,6:1
1,24,6:1
1,25,6:1
1,26,6:1
1,27,6:1
1,28,6:1
1,29,6:1
1,30,6:1
1,31,6:1
1,32,6:1
1,33,6:1
1,34,6:1
1,35,6:1
1,36,6:1
1,0,7:2
1,1,7:2
1,2,7:2
1,3,7:2
1,4,7:2
1,5,7:2
1,6,7:2
1,7,7:2
1,8,7:2
1,9,7:2
1,10,7:2
1,11,7:2
1,12,7:2
1,13,7:2
1,14,7:3
1,15,7:98
1,16,7:98
1,17,7:98
1,18,7:98
1,19,7:98
1,20,7:98
1,21,7:98
1,22,7:3
1,23,7:2
1,24,7:2
1,25,7:2
1,26,7:2
1,27,7:2
1,28,7:2
1,29,7:2
1,30,7:2
1,31,7:2
1,32,7:2
1,33,7:2
1,34,7:2
1,35,7:2
1,36,7:2
1,1,8:31.1
1,4,8:31.1
1,5,8:31.1
1,6,8:31.1
1,11,8:31.1
1,12,8:31.1
1,13,8:31.1
1,14,8:43
1,15,8:50.3
1,21,8:50.4
1,22,8:43
1,25,8:31.1
1,30,8:31.1
1,31,8:31.1
1,32,8:37
1,35,8:31.1
1,36,8:31.1
2,0,0:1
2,1,0:1
2,2,0:1
2,3,0:1
2,4,0:1
2,5,0:1
2,6,0:1
2,7,0:1
2,8,0:1
2,9,0:1
2,10,0:1
2,11,0:1
2,12,0:1
2,13,0:1
2,14,0:1
2,15,0:1
2,16,0:1
2,17,0:1
2,18,0:1
2,19,0:1
2,20,0:1
2,21,0:1
2,22,0:1
2,23,0:1
2,24,0:1
2,25,0:1
2,26,0:1
2,27,0:1
2,28,0:1
2,29,0:1
2,30,0:1
2,31,0:1
2,32,0:1
2,33,0:1
2,34,0:1
2,35,0:1
2,36,0:1
2,0,1:1
2,1,1:1
2,2,1:1
2,3,1:1
2,4,1:1
2,5,1:1
2,6,1:1
2,7,1:1
2,8,1:1
2,9,1:1
2,10,1:1
2,11,1:1
2,12,1:1
2,13,1:1
2,14,1:1
2,15,1:1
2,16,1:1
2,17,1:1
2,18,1:1
2,19,1:1
2,20,1:1
2,21,1:1
2,22,1:1
2,23,1:1
2,24,1:1
2,25,1:1
2,26,1:1
2,27,1:1
2,28,1:1
2,29,1:1
2,30,1:1
2,31,1:1
2,32,1:1
2,33,1:1
2,34,1:1
2,35,1:1
2,36,1:1
2,0,2:1
2,1,2:1
2,2,2:1
2,3,2:1
2,4,2:1
2,5,2:1
2,6,2:1
2,7,2:1
2,8,2:1
2,9,2:1
2,10,2:1
2,11,2:1
2,12,2:1
2,13,2:1
2,14,2:1
2,15,2:1
2,16,2:1
2,17,2:1
2,18,2:1
2,19,2:1
2,20,2:1
2,21,2:1
2,22,2:1
2,23,2:1
2,24,2:1
2,25,2:1
2,26,2:1
2,27,2:1
2,28,2:1
2,29,2:1
2,30,2:1
2,31,2:1
2,32,2:1
2,33,2:1
2,34,2:1
2,35,2:1
2,36,2:1
2,0,3:1
2,1,3:3
2,2,3:3
2,3,3:3
2,4,3:1
2,5,3:1
2,6,3:1
2,7,3:1
2,8,3:1
2,9,3:1
2,10,3:1
2,11,3:1
2,12,3:1
2,13,3:1
2,14,3:1
2,15,3:1
2,16,3:1
2,17,3:1
2,18,3:1
2,19,3:1
2,20,3:1
2,21,3:1
2,22,3:1
2,23,3:1
2,24,3:1
2,25,3:1
2,26,3:1
2,27,3:1
2,28,3:1
2,29,3:1
2,30,3:1
2,31,3:1
2,32,3:1
2,33,3:1
2,34,3:1
2,35,3:1
2,36,3:1
2,0,4:3
2,1,4:3
2,2,4:3
2,3,4:3
2,4,4:3
2,5,4:1
2,6,4:1
2,7,4:1
2,8,4:1
2,9,4:1
2,10,4:1
2,11,4:1
2,12,4:1
2,13,4:1
2,14,4:1
2,15,4:13
2,16,4:13
2,17,4:13
2,18,4:13
2,19,4:13
2,20,4:1
2,21,4:1
2,22,4:1
2,23,4:1
2,24,4:1
2,25,4:1
2,26,4:1
2,27,4:1
2,28,4:1
2,29,4:1
2,30,4:1
2,31,4:1
2,32,4:1
2,33,4:1
2,34,4:1
2,35,4:1
2,36,4:1
2,0,5:3
2,1,5:3
2,2,5:3
2,3,5:3
2,4,5:3
2,5,5:3
2,6,5:1
2,7,5:1
2,8,5:1
2,9,5:1
2,10,5:1
2,11,5:1
2,12,5:1
2,13,5:1
2,14,5:13
2,15,5:13
2,16,5:13
2,17,5:13
2,18,5:13
2,19,5:13
2,20,5:13
2,21,5:1
2,22,5:1
2,23,5:1
2,24,5:1
2,25,5:1
2,26,5:1
2,27,5:1
2,28,5:1
2,29,5:1
2,30,5:1
2,31,5:1
2,32,5:1
2,33,5:1
2,34,5:1
2,35,5:1
2,36,5:1
2,0,6:3
2,1,6:3
2,2,6:3
2,3,6:3
2,4,6:3
2,5,6:3
2,6,6:3
2,7,6:1
2,8,6:1
2,9,6:1
2,10,6:1
2,11,6:1
2,12,6:1
2,13,6:1
2,14,6:13
2,15,6:13
2,17,6:13
2,18,6:13
2,19,6:13
2,20,6:13
2,21,6:1
2,22,6:1
2,23,6:1
2,24,6:1
2,25,6:1
2,26,6:1
2,27,6:1
2,28,6:1
2,29,6:1
2,30,6:1
2,31,6:1
2,32,6:1
2,33,6:1
2,34,6:1
2,35,6:3
2,36,6:1
2,0,7:2
2,1,7:2
2,2,7:2
2,3,7:2
2,4,7:2
2,5,7:2
2,6,7:98
2,7,7:98
2,8,7:98
2,9,7:98
2,10,7:98
2,11,7:2
2,12,7:2
2,13,7:2
2,14,7:3
2,15,7:98
2,16,7:98
2,17,7:98
2,18,7:98
2,19,7:98
2,20,7:98
2,21,7:98
2,22,7:3
2,23,7:2
2,24,7:2
2,25,7:2
2,26,7:98
2,27,7:98
2,28,7:98
2,29,7:98
2,30,7:98
2,31,7:2
2,32,7:2
2,33,7:2
2,34,7:2
2,35,7:2
2,36,7:2
2,0,8:31.1
2,1,8:38
2,11,8:31.1
2,12,8:31.1
2,14,8:44
2,22,8:44
2,25,8:31.1
2,31,8:31.1
2,32,8:31.1
2,33,8:31.1
2,34,8:31.1
2,33,10:18.2
2,34,10:18.2
2,35,10:18.2
2,36,10:18.2
2,32,11:18.2
2,33,11:18.2
2,34,11:18.2
2,35,11:18.2
2,36,11:18.2
3,0,0:1
3,1,0:1
3,2,0:1
3,3,0:1
3,4,0:1
3,5,0:1
3,6,0:1
3,7,0:1
3,8,0:1
3,9,0:1
3,10,0:1
3,11,0:1
3,12,0:1
3,13,0:1
3,14,0:1
3,15,0:1
3,16,0:1
3,17,0:1
3,18,0:1
3,19,0:1
3,20,0:1
3,21,0:1
3,22,0:1
3,23,0:1
3,24,0:1
3,25,0:1
3,26,0:1
3,27,0:1
3,28,0:1
3,29,0:1
3,30,0:1
3,31,0:1
3,32,0:1
3,33,0:1
3,34,0:1
3,35,0:13
3,36,0:1
3,0,1:1
3,1,1:1
3,2,1:1
3,3,1:1
3,4,1:1
3,5,1:1
3,6,1:1
3,7,1:1
3,8,1:1
3,9,1:1
3,10,1:1
3,11,1:1
3,12,1:1
3,13,1:1
3,14,1:1
3,15,1:1
3,16,1:1
3,17,1:1
3,18,1:1
3,19,1:1
3,20,1:1
3,21,1:1
3,22,1:1
3,23,1:1
3,24,1:1
3,25,1:1
3,26,1:1
3,27,1:1
3,28,1:1
3,29,1:1
3,30,1:1
3,31,1:1
3,32,1:1
3,33,1:1
3,34,1:1
3,35,1:13
3,36,1:1
3,0,2:1
3,1,2:1
3,2,2:1
3,3,2:1
3,4,2:1
3,5,2:1
3,6,2:1
3,7,2:1
3,8,2:1
3,9,2:1
3,10,2:1
3,11,2:1
3,12,2:1
3,13,2:1
3,14,2:1
3,15,2:1
3,16,2:1
3,17,2:1
3,18,2:1
3,19,2:1
3,20,2:1
3,21,2:1
3,22,2:1
3,23,2:1
3,24,2:1
3,25,2:1
3,26,2:1
3,27,2:1
3,28,2:1
3,29,2:1
3,30,2:1
3,31,2:1
3,32,2:1
3,33,2:1
3,34,2:1
3,35,2:13
3,36,2:1
3,0,3:3
3,1,3:3
3,2,3:3
3,3,3:3
3,4,3:1
3,5,3:1
3,6,3:1
3,7,3:1
3,8,3:1
3,9,3:1
3,10,3:1
3,11,3:1
3,12,3:1
3,13,3:1
3,14,3:1
3,15,3:1
3,16,3:1
3,17,3:1
3,18,3:1
3,19,3:1
3,20,3:1
3,21,3:1
3,22,3:1
3,23,3:1
3,24,3:1
3,25,3:1
3,26,3:1
3,27,3:1
3,28,3:1
3,29,3:1
3,30,3:1
3,31,3:1
3,32,3:1
3,33,3:1
3,34,3:1
3,35,3:3
3,36,3:1
3,0,4:3
3,1,4:3
3,2,4:3
3,3,4:3
3,4,4:3
3,5,4:1
3,6,4:1
3,7,4:1
3,8,4:1
3,9,4:1
3,10,4:1
3,11,4:1
3,12,4:1
3,13,4:1
3,14,4:1
3,15,4:1
3,16,4:1
3,17,4:13
3,18,4:13
3,19,4:13
3,20,4:1
3,21,4:1
3,22,4:1
3,23,4:1
3,24,4:1
3,25,4:1
3,26,4:1
3,27,4:1
3,28,4:1
3,29,4:1
3,30,4:1
3,31,4:1
3,32,4:1
3,33,4:1
3,34,4:1
3,35,4:3
3,36,4:1
3,0,5:3
3,1,5:3
3,2,5:3
3,3,5:3
3,4,5:3
3,5,5:3
3,6,5:1
3,7,5:1
3,8,5:1
3,9,5:1
3,10,5:1
3,11,5:1
3,12,5:1
3,13,5:1
3,14,5:1
3,15,5:13
3,16,5:13
3,17,5:13
3,18,5:13
3,19,5:13
3,20,5:13
3,21,5:1
3,22,5:1
3,23,5:1
3,24,5:1
3,25,5:1
3,26,5:1
3,27,5:1
3,28,5:1
3,29,5:1
3,30,5:1
3,31,5:1
3,32,5:1
3,33,5:1
3,34,5:1
3,35,5:3
3,36,5:1
3,0,6:3
3,1,6:3
3,2,6:3
3,3,6:3
3,4,6:3
3,5,6:3
3,6,6:3
3,7,6:1
3,8,6:1
3,9,6:1
3,10,6:1
3,11,6:1
3,12,6:1
3,13,6:1
3,14,6:1
3,15,6:13
3,16,6:13
3,17,6:13
3,18,6:13
3,19,6:13
3,20,6:13
3,21,6:1
3,22,6:1
3,23,6:1
3,24,6:1
3,25,6:1
3,26,6:1
3,27,6:1
3,28,6:1
3,29,6:1
3,30,6:1
3,31,6:1
3,32,6:1
3,33,6:1
3,34,6:1
3,35,6:3
3,36,6:1
3,0,7:2
3,1,7:2
3,2,7:2
3,3,7:2
3,4,7:2
3,5,7:2
3,6,7:98
3,7,7:9
3,8,7:9
3,9,7:9
3,10,7:98
3,11,7:2
3,12,7:2
3,13,7:2
3,14,7:2
3,15,7:98
3,16,7:98
3,17,7:98
3,18,7:98
3,19,7:98
3,20,7:98
3,21,7:98
3,22,7:2
3,23,7:2
3,24,7:2
3,25,7:2
3,26,7:98
3,27,7:9
3,28,7:9
3,29,7:9
3,30,7:98
3,31,7:2
3,32,7:2
3,33,7:2
3,34,7:2
3,35,7:2
3,36,7:2
3,0,8:37
3,1,8:31.1
3,2,8:31.1
3,8,8:9.9
3,11,8:31.1
3,13,8:31.1
3,14,8:44
3,22,8:44
3,24,8:31.1
3,25,8:31.1
3,28,8:9.9
3,32,8:31.1
3,33,8:31.1
3,34,8:44.3
3,36,8:31.1
3,8,9:9.9
3,28,9:9.9
3,8,10:9.1
3,28,10:9.1
3,32,10:18.2
3,33,10:18.2
3,34,10:18.2
3,35,10:18.2
3,36,10:18.2
3,32,11:18.2
3,33,11:18.2
3,34,11:18.2
3,35,11:18.2
3,36,11:18.2
3,34,12:18.2
3,34,13:18.2
4,0,0:1
4,1,0:1
4,2,0:1
4,3,0:1
4,4,0:1
4,5,0:1
4,6,0:1
4,7,0:1
4,8,0:1
4,9,0:1
4,10,0:1
4,11,0:1
4,12,0:1
4,13,0:1
4,14,0:1
4,15,0:1
4,16,0:1
4,17,0:1
4,18,0:1
4,19,0:1
4,20,0:1
4,21,0:1
4,22,0:1
4,23,0:1
4,24,0:1
4,25,0:1
4,26,0:1
4,27,0:1
4,28,0:1
4,29,0:1
4,30,0:1
4,31,0:1
4,32,0:1
4,33,0:1
4,34,0:1
4,35,0:1
4,36,0:1
4,0,1:1
4,1,1:1
4,2,1:1
4,3,1:1
4,4,1:1
4,5,1:1
4,6,1:1
4,7,1:1
4,8,1:1
4,9,1:1
4,10,1:1
4,11,1:1
4,12,1:1
4,13,1:1
4,14,1:1
4,15,1:1
4,16,1:1
4,17,1:1
4,18,1:1
4,19,1:1
4,20,1:1
4,21,1:1
4,22,1:1
4,23,1:1
4,24,1:1
4,25,1:1
4,26,1:1
4,27,1:1
4,28,1:1
4,29,1:1
4,30,1:1
4,31,1:1
4,32,1:1
4,33,1:1
4,34,1:1
4,35,1:1
4,36,1:1
4,0,2:1
4,1,2:1
4,2,2:1
4,3,2:1
4,4,2:1
4,5,2:1
4,6,2:1
4,7,2:1
4,8,2:1
4,9,2:1
4,10,2:1
4,11,2:1
4,12,2:1
4,13,2:1
4,14,2:1
4,15,2:1
4,16,2:1
4,17,2:1
4,18,2:1
4,19,2:1
4,20,2:1
4,21,2:1
4,22,2:1
4,23,2:1
4,24,2:1
4,25,2:1
4,26,2:1
4,27,2:1
4,28,2:1
4,29,2:1
4,30,2:1
4,31,2:1
4,32,2:1
4,33,2:1
4,34,2:1
4,35,2:1
4,36,2:1
4,0,3:3
4,1,3:3
4,2,3:3
4,3,3:3
4,4,3:1
4,5,3:1
4,6,3:1
4,7,3:1
4,8,3:1
4,9,3:1
4,10,3:1
4,11,3:1
4,12,3:1
4,13,3:1
4,14,3:1
4,15,3:1
4,16,3:1
4,17,3:1
4,18,3:1
4,19,3:1
4,20,3:1
4,21,3:1
4,22,3:1
4,23,3:1
4,24,3:1
4,25,3:1
4,26,3:1
4,27,3:1
4,28,3:1
4,29,3:1
4,30,3:1
4,31,3:1
4,32,3:1
4,33,3:1
4,34,3:1
4,35,3:1
4,36,3:1
4,0,4:3
4,1,4:3
4,2,4:3
4,3,4:3
4,4,4:3
4,5,4:1
4,6,4:1
4,7,4:1
4,8,4:1
4,9,4:1
4,10,4:1
4,11,4:1
4,12,4:1
4,13,4:1
4,14,4:1
4,15,4:1
4,16,4:1
4,17,4:1
4,18,4:1
4,19,4:13
4,20,4:1
4,21,4:1
4,22,4:1
4,23,4:1
4,24,4:1
4,25,4:1
4,26,4:1
4,27,4:1
4,28,4:1
4,29,4:1
4,30,4:1
4,31,4:1
4,32,4:1
4,33,4:1
4,34,4:1
4,35,4:1
4,36,4:1
4,0,5:3
4,1,5:3
4,2,5:3
4,3,5:3
4,4,5:3
4,5,5:3
4,6,5:1
4,7,5:1
4,8,5:1
4,9,5:1
4,10,5:1
4,11,5:1
4,12,5:1
4,13,5:1
4,14,5:1
4,15,5:1
4,16,5:1
4,17,5:1
4,18,5:13
4,19,5:13
4,20,5:13
4,21,5:1
4,22,5:1
4,23,5:1
4,24,5:1
4,25,5:1
4,26,5:1
4,27,5:1
4,28,5:1
4,29,5:1
4,30,5:1
4,31,5:1
4,32,5:1
4,33,5:1
4,34,5:1
4,35,5:1
4,36,5:1
4,0,6:3
4,1,6:3
4,2,6:3
4,3,6:3
4,4,6:3
4,5,6:3
4,6,6:3
4,7,6:1
4,8,6:1
4,9,6:1
4,10,6:1
4,11,6:1
4,12,6:1
4,13,6:1
4,14,6:1
4,15,6:1
4,16,6:1
4,17,6:1
4,18,6:13
4,19,6:13
4,20,6:13
4,21,6:1
4,22,6:1
4,23,6:1
4,24,6:1
4,25,6:1
4,26,6:1
4,27,6:1
4,28,6:1
4,29,6:1
4,30,6:1
4,31,6:1
4,32,6:1
4,33,6:1
4,34,6:1
4,35,6:1
4,36,6:1
4,0,7:2
4,1,7:2
4,2,7:2
4,3,7:2
4,4,7:2
4,5,7:2
4,6,7:98
4,7,7:9
4,8,7:9
4,9,7:9
4,10,7:98
4,11,7:2
4,12,7:2
4,13,7:2
4,14,7:3
4,15,7:98
4,16,7:98
4,17,7:98
4,18,7:98
4,19,7:98
4,20,7:98
4,21,7:98
4,22,7:3
4,23,7:2
4,24,7:2
4,25,7:2
4,26,7:98
4,27,7:9
4,28,7:9
4,29,7:9
4,30,7:98
4,31,7:2
4,32,7:2
4,33,7:2
4,34,7:3
4,35,7:2
4,36,7:2
4,0,8:31.1
4,1,8:31.1
4,2,8:31.1
4,3,8:31.1
4,7,8:9.9
4,8,8:9.8
4,9,8:9.9
4,11,8:31.1
4,12,8:31.1
4,14,8:43
4,15,8:50.3
4,21,8:50.4
4,22,8:43
4,24,8:31.1
4,25,8:31.1
4,27,8:9.9
4,28,8:9.8
4,29,8:9.9
4,33,8:44.3
4,34,8:17.2
4,35,8:44.3
4,7,9:9.9
4,8,9:9.8
4,9,9:9.9
4,27,9:9.9
4,28,9:9.8
4,29,9:9.9
4,34,9:17.2
4,7,10:9.1
4,8,10:9
4,9,10:9.1
4,27,10:9.1
4,28,10:9
4,29,10:9.1
4,32,10:18.2
4,33,10:18.2
4,34,10:17.2
4,35,10:18.2
4,36,10:18.2
4,32,11:18.2
4,33,11:18.2
4,34,11:17.2
4,35,11:18.2
4,36,11:18.2
4,33,12:18.2
4,34,12:17.2
4,35,12:18.2
4,33,13:18.2
4,34,13:18.2
4,35,13:18.2
5,0,0:1
5,1,0:1
5,2,0:1
5,3,0:15
5,4,0:1
5,5,0:1
5,6,0:1
5,7,0:1
5,8,0:1
5,9,0:1
5,10,0:1
5,11,0:1
5,12,0:1
5,13,0:1
5,14,0:1
5,15,0:1
5,16,0:1
5,17,0:1
5,18,0:1
5,19,0:1
5,20,0:1
5,21,0:1
5,22,0:1
5,23,0:1
5,24,0:1
5,25,0:1
5,26,0:1
5,27,0:1
5,28,0:1
5,29,0:1
5,30,0:1
5,31,0:1
5,32,0:1
5,33,0:1
5,34,0:1
5,35,0:1
5,36,0:1
5,0,1:1
5,1,1:1
5,2,1:1
5,3,1:15
5,4,1:1
5,5,1:1
5,6,1:1
5,7,1:1
5,8,1:1
5,9,1:1
5,10,1:1
5,11,1:1
5,12,1:1
5,13,1:1
5,14,1:1
5,15,1:1
5,16,1:1
5,17,1:1
5,18,1:1
5,19,1:1
5,20,1:1
5,21,1:1
5,22,1:1
5,23,1:1
5,24,1:1
5,25,1:1
5,26,1:1
5,27,1:1
5,28,1:1
5,29,1:1
5,30,1:1
5,31,1:1
5,32,1:1
5,33,1:1
5,34,1:1
5,35,1:1
5,36,1:1
5,0,2:1
5,1,2:1
5,2,2:1
5,3,2:1
5,4,2:1
5,5,2:1
5,6,2:1
5,7,2:1
5,8,2:1
5,9,2:1
5,10,2:1
5,11,2:1
5,12,2:1
5,13,2:1
5,14,2:1
5,15,2:1
5,16,2:1
5,17,2:1
5,18,2:1
5,19,2:1
5,20,2:1
5,21,2:1
5,22,2:1
5,23,2:1
5,24,2:1
5,25,2:1
5,26,2:1
5,27,2:1
5,28,2:1
5,29,2:1
5,30,2:1
5,31,2:1
5,32,2:1
5,33,2:1
5,34,2:1
5,35,2:1
5,36,2:1
5,0,3:3
5,1,3:3
5,2,3:3
5,3,3:1
5,4,3:1
5,5,3:1
5,6,3:1
5,7,3:1
5,8,3:1
5,9,3:1
5,10,3:1
5,11,3:1
5,12,3:1
5,13,3:1
5,14,3:1
5,15,3:1
5,16,3:1
5,17,3:1
5,18,3:1
5,19,3:1
5,20,3:1
5,21,3:1
5,22,3:1
5,23,3:1
5,24,3:1
5,25,3:1
5,26,3:1
5,27,3:1
5,28,3:1
5,29,3:1
5,30,3:1
5,31,3:1
5,32,3:1
5,33,3:1
5,34,3:1
5,35,3:1
5,36,3:1
5,0,4:3
5,1,4:3
5,2,4:3
5,3,4:3
5,4,4:3
5,5,4:1
5,6,4:1
5,7,4:1
5,8,4:1
5,9,4:1
5,10,4:1
5,11,4:1
5,12,4:1
5,13,4:1
5,14,4:1
5,15,4:1
5,16,4:1
5,17,4:1
5,18,4:1
5,19,4:1
5,20,4:1
5,21,4:1
5,22,4:1
5,23,4:1
5,24,4:1
5,25,4:1
5,26,4:1
5,27,4:1
5,28,4:1
5,29,4:1
5,30,4:1
5,31,4:1
5,32,4:1
5,33,4:1
5,34,4:1
5,35,4:1
5,36,4:1
5,0,5:3
5,1,5:3
5,2,5:3
5,3,5:3
5,4,5:3
5,5,5:3
5,6,5:1
5,7,5:1
5,8,5:1
5,9,5:1
5,10,5:1
5,11,5:1
5,12,5:1
5,13,5:1
5,14,5:1
5,15,5:1
5,16,5:1
5,17,5:1
5,18,5:1
5,19,5:1
5,20,5:1
5,21,5:1
5,22,5:1
5,23,5:1
5,24,5:1
5,25,5:1
5,26,5:1
5,27,5:1
5,28,5:1
5,29,5:1
5,30,5:1
5,31,5:1
5,32,5:1
5,33,5:1
5,34,5:1
5,35,5:1
5,36,5:1
5,0,6:3
5,1,6:3
5,2,6:3
5,3,6:3
5,4,6:3
5,5,6:3
5,6,6:1
5,7,6:1
5,8,6:1
5,9,6:1
5,10,6:1
5,11,6:1
5,12,6:1
5,13,6:1
5,14,6:1
5,15,6:1
5,16,6:1
5,17,6:1
5,18,6:1
5,19,6:1
5,20,6:1
5,21,6:1
5,22,6:1
5,23,6:1
5,24,6:1
5,25,6:1
5,26,6:1
5,27,6:1
5,28,6:1
5,29,6:1
5,30,6:1
5,31,6:1
5,32,6:1
5,33,6:1
5,34,6:1
5,35,6:1
5,36,6:1
5,0,7:2
5,1,7:2
5,2,7:2
5,3,7:2
5,4,7:2
5,5,7:2
5,6,7:98
5,7,7:9
5,8,7:9
5,9,7:9
5,10,7:98
5,11,7:2
5,12,7:2
5,13,7:2
5,14,7:2
5,15,7:98
5,16,7:98
5,17,7:98
5,18,7:98
5,19,7:98
5,20,7:98
5,21,7:98
5,22,7:2
5,23,7:2
5,24,7:2
5,25,7:2
5,26,7:98
5,27,7:9
5,28,7:9
5,29,7:9
5,30,7:98
5,31,7:2
5,32,7:2
5,33,7:2
5,34,7:2
5,35,7:2
5,36,7:2
5,0,8:31.1
5,1,8:31.1
5,3,8:31.1
5,4,8:37
5,5,8:31.1
5,8,8:9.9
5,14,8:44
5,22,8:44
5,25,8:31.1
5,28,8:9.9
5,31,8:31.1
5,32,8:31.1
5,33,8:31.1
5,34,8:44.3
5,35,8:31.1
5,8,9:9.9
5,28,9:9.9
5,8,10:9.1
5,28,10:9.1
5,32,10:18.2
5,33,10:18.2
5,34,10:18.2
5,35,10:18.2
5,36,10:18.2
5,32,11:18.2
5,33,11:18.2
5,34,11:18.2
5,35,11:18.2
5,36,11:18.2
5,33,12:18.2
5,34,12:18.2
5,34,13:18.2
6,0,0:13
6,1,0:13
6,2,0:13
6,3,0:15
6,4,0:16
6,5,0:16
6,6,0:1
6,7,0:1
6,8,0:1
6,9,0:1
6,10,0:1
6,11,0:1
6,12,0:1
6,13,0:1
6,14,0:1
6,15,0:1
6,16,0:1
6,17,0:1
6,18,0:1
6,19,0:1
6,20,0:1
6,21,0:1
6,22,0:1
6,23,0:3
6,24,0:3
6,25,0:1
6,26,0:1
6,27,0:1
6,28,0:1
6,29,0:1
6,30,0:1
6,31,0:1
6,32,0:1
6,33,0:1
6,34,0:1
6,35,0:1
6,36,0:1
6,0,1:1
6,1,1:1
6,2,1:1
6,3,1:15
6,4,1:16
6,5,1:16
6,6,1:1
6,7,1:1
6,8,1:1
6,9,1:1
6,10,1:1
6,11,1:1
6,12,1:1
6,13,1:1
6,14,1:1
6,15,1:1
6,16,1:1
6,17,1:1
6,18,1:1
6,19,1:1
6,20,1:1
6,21,1:1
6,22,1:1
6,23,1:1
6,24,1:1
6,25,1:1
6,26,1:1
6,27,1:1
6,28,1:1
6,29,1:1
6,30,1:1
6,31,1:1
6,32,1:1
6,33,1:1
6,34,1:1
6,35,1:1
6,36,1:1
6,0,2:1
6,1,2:1
6,2,2:1
6,3,2:1
6,4,2:1
6,5,2:1
6,6,2:1
6,7,2:1
6,8,2:1
6,9,2:1
6,10,2:1
6,11,2:1
6,12,2:1
6,13,2:1
6,14,2:1
6,15,2:1
6,16,2:1
6,17,2:1
6,18,2:1
6,19,2:1
6,20,2:1
6,21,2:1
6,22,2:1
6,23,2:1
6,24,2:1
6,25,2:1
6,26,2:1
6,27,2:1
6,28,2:1
6,29,2:1
6,30,2:1
6,31,2:1
6,32,2:1
6,33,2:1
6,34,2:1
6,35,2:1
6,36,2:1
6,0,3:3
6,1,3:3
6,2,3:1
6,3,3:1
6,4,3:1
6,5,3:1
6,6,3:1
6,7,3:1
6,8,3:1
6,9,3:1
6,10,3:1
6,11,3:1
6,12,3:1
6,13,3:1
6,14,3:1
6,15,3:1
6,16,3:1
6,17,3:1
6,18,3:1
6,19,3:1
6,20,3:1
6,21,3:1
6,22,3:1
6,23,3:1
6,24,3:1
6,25,3:1
6,26,3:1
6,27,3:1
6,28,3:1
6,29,3:1
6,30,3:1
6,31,3:1
6,32,3:1
6,33,3:1
6,34,3:1
6,35,3:1
6,36,3:1
6,0,4:3
6,1,4:3
6,2,4:3
6,3,4:3
6,4,4:1
6,5,4:1
6,6,4:1
6,7,4:1
6,8,4:1
6,9,4:1
6,10,4:1
6,11,4:1
6,12,4:1
6,13,4:1
6,14,4:1
6,15,4:1
6,16,4:1
6,17,4:1
6,18,4:1
6,19,4:1
6,20,4:1
6,21,4:1
6,22,4:1
6,23,4:1
6,24,4:1
6,25,4:1
6,26,4:1
6,27,4:1
6,28,4:1
6,29,4:1
6,30,4:1
6,31,4:1
6,32,4:1
6,33,4:1
6,34,4:1
6,35,4:1
6,36,4:1
6,0,5:3
6,1,5:3
6,2,5:3
6,3,5:3
6,4,5:3
6,5,5:1
6,6,5:1
6,7,5:1
6,8,5:1
6,9,5:1
6,10,5:1
6,11,5:1
6,12,5:1
6,13,5:1
6,14,5:1
6,15,5:1
6,16,5:1
6,17,5:1
6,18,5:1
6,19,5:1
6,20,5:1
6,21,5:1
6,22,5:1
6,23,5:1
6,24,5:1
6,25,5:1
6,26,5:1
6,27,5:1
6,28,5:1
6,29,5:1
6,30,5:1
6,31,5:1
6,32,5:1
6,33,5:1
6,34,5:1
6,35,5:1
6,36,5:1
6,0,6:3
6,1,6:3
6,2,6:3
6,3,6:3
6,4,6:3
6,5,6:3
6,6,6:1
6,7,6:1
6,8,6:1
6,9,6:1
6,10,6:1
6,11,6:1
6,12,6:1
6,13,6:1
6,14,6:1
6,15,6:1
6,16,6:1
6,17,6:1
6,18,6:1
6,19,6:1
6,20,6:1
6,21,6:1
6,22,6:1
6,23,6:1
6,24,6:1
6,25,6:1
6,26,6:1
6,27,6:1
6,28,6:1
6,29,6:1
6,30,6:1
6,31,6:1
6,32,6:1
6,33,6:1
6,34,6:1
6,35,6:1
6,36,6:1
6,0,7:2
6,1,7:2
6,2,7:2
6,3,7:2
6,4,7:2
6,5,7:2
6,6,7:98
6,7,7:98
6,8,7:98
6,9,7:98
6,10,7:98
6,11,7:2
6,12,7:2
6,13,7:2
6,14,7:2
6,15,7:98
6,16,7:98
6,17,7:98
6,18,7:98
6,19,7:98
6,20,7:98
6,21,7:98
6,22,7:2
6,23,7:2
6,24,7:2
6,25,7:2
6,26,7:98
6,27,7:98
6,28,7:98
6,29,7:98
6,30,7:98
6,31,7:2
6,32,7:2
6,33,7:2
6,34,7:2
6,35,7:2
6,36,7:2
6,1,8:31.1
6,2,8:31.1
6,4,8:31.1
6,11,8:31.1
6,12,8:31.1
6,14,8:44
6,22,8:44
6,25,8:31.1
6,33,8:37
6,34,8:31.1
6,35,8:31.1
6,36,8:31.1
6,32,10:18.2
6,33,10:18.2
6,34,10:18.2
6,35,10:18.2
6,36,10:18.2
6,32,11:18.2
6,33,11:18.2
6,34,11:18.2
6,35,11:18.2
7,0,0:13
7,1,0:13
7,2,0:13
7,3,0:13
7,4,0:16
7,5,0:13
7,6,0:16
7,7,0:1
7,8,0:1
7,9,0:1
7,10,0:1
7,11,0:1
7,12,0:1
7,13,0:1
7,14,0:1
7,15,0:1
7,16,0:1
7,17,0:1
7,18,0:1
7,19,0:1
7,20,0:1
7,21,0:1
7,22,0:3
7,23,0:3
7,24,0:3
7,25,0:3
7,26,0:3
7,27,0:3
7,28,0:1
7,29,0:1
7,30,0:1
7,31,0:1
7,32,0:1
7,33,0:1
7,34,0:1
7,35,0:1
7,36,0:1
7,0,1:1
7,1,1:13
7,2,1:13
7,3,1:1
7,4,1:16
7,5,1:16
7,6,1:16
7,7,1:1
7,8,1:1
7,9,1:1
7,10,1:1
7,11,1:1
7,12,1:1
7,13,1:1
7,14,1:1
7,15,1:1
7,16,1:1
7,17,1:1
7,18,1:1
7,19,1:1
7,20,1:1
7,21,1:1
7,22,1:1
7,23,1:1
7,24,1:1
7,25,1:1
7,26,1:1
7,27,1:1
7,28,1:1
7,29,1:1
7,30,1:1
7,31,1:1
7,32,1:1
7,33,1:1
7,34,1:1
7,35,1:1
7,36,1:1
7,0,2:1
7,1,2:1
7,2,2:1
7,3,2:1
7,4,2:1
7,5,2:1
7,6,2:1
7,7,2:1
7,8,2:1
7,9,2:1
7,10,2:1
7,11,2:1
7,12,2:1
7,13,2:1
7,14,2:1
7,15,2:1
7,16,2:1
7,17,2:1
7,18,2:1
7,19,2:1
7,20,2:1
7,21,2:1
7,22,2:1
7,23,2:1
7,24,2:1
7,25,2:1
7,26,2:1
7,27,2:1
7,28,2:1
7,29,2:1
7,30,2:1
7,31,2:1
7,32,2:1
7,33,2:1
7,34,2:1
7,35,2:1
7,36,2:1
7,0,3:3
7,1,3:3
7,2,3:1
7,3,3:1
7,4,3:1
7,5,3:1
7,6,3:1
7,7,3:1
7,8,3:1
7,9,3:1
7,10,3:1
7,11,3:1
7,12,3:1
7,13,3:1
7,14,3:1
7,15,3:1
7,16,3:1
7,17,3:1
7,18,3:1
7,19,3:1
7,20,3:1
7,21,3:1
7,22,3:1
7,23,3:1
7,24,3:1
7,25,3:1
7,26,3:1
7,27,3:1
7,28,3:1
7,29,3:1
7,30,3:1
7,31,3:1
7,32,3:1
7,33,3:1
7,34,3:1
7,35,3:1
7,36,3:1
7,0,4:3
7,1,4:3
7,2,4:3
7,3,4:1
7,4,4:1
7,5,4:1
7,6,4:1
7,7,4:1
7,8,4:1
7,9,4:1
7,10,4:1
7,11,4:1
7,12,4:1
7,13,4:1
7,14,4:1
7,15,4:1
7,16,4:1
7,17,4:1
7,18,4:1
7,19,4:1
7,20,4:1
7,21,4:1
7,22,4:1
7,23,4:1
7,24,4:1
7,25,4:1
7,26,4:1
7,27,4:1
7,28,4:1
7,29,4:1
7,30,4:1
7,31,4:1
7,32,4:1
7,33,4:1
7,34,4:1
7,35,4:1
7,36,4:1
7,0,5:3
7,1,5:3
7,2,5:3
7,3,5:3
7,4,5:1
7,5,5:1
7,6,5:1
7,7,5:1
7,8,5:1
7,9,5:1
7,10,5:1
7,11,5:1
7,12,5:1
7,13,5:1
7,14,5:1
7,15,5:1
7,16,5:1
7,17,5:1
7,18,5:1
7,19,5:1
7,20,5:1
7,21,5:1
7,22,5:1
7,23,5:1
7,24,5:1
7,25,5:1
7,26,5:1
7,27,5:1
7,28,5:1
7,29,5:1
7,30,5:1
7,31,5:1
7,32,5:1
7,33,5:1
7,34,5:1
7,35,5:1
7,36,5:1
7,0,6:3
7,1,6:3
7,2,6:3
7,3,6:3
7,4,6:3
7,5,6:1
7,6,6:1
7,7,6:1
7,8,6:1
7,9,6:1
7,10,6:1
7,11,6:1
7,12,6:1
7,13,6:1
7,14,6:1
7,15,6:1
7,16,6:1
7,17,6:1
7,18,6:1
7,19,6:1
7,20,6:1
7,21,6:1
7,22,6:1
7,23,6:1
7,24,6:1
7,25,6:1
7,26,6:1
7,27,6:1
7,28,6:1
7,29,6:1
7,30,6:1
7,31,6:1
7,32,6:1
7,33,6:1
7,34,6:1
7,35,6:1
7,36,6:1
7,0,7:2
7,1,7:2
7,2,7:2
7,3,7:2
7,4,7:2
7,5,7:2
7,6,7:2
7,7,7:2
7,8,7:2
7,9,7:2
7,10,7:2
7,11,7:2
7,12,7:2
7,13,7:2
7,14,7:3
7,15,7:98
7,16,7:98
7,17,7:98
7,18,7:98
7,19,7:98
7,20,7:98
7,21,7:98
7,22,7:3
7,23,7:2
7,24,7:2
7,25,7:2
7,26,7:2
7,27,7:2
7,28,7:2
7,29,7:2
7,30,7:2
7,31,7:2
7,32,7:2
7,33,7:2
7,34,7:2
7,35,7:2
7,36,7:2
7,0,8:31.1
7,1,8:31.1
7,2,8:31.1
7,3,8:31.1
7,4,8:31.1
7,6,8:31.1
7,7,8:31.1
7,8,8:31.1
7,14,8:43
7,15,8:50.3
7,21,8:50.4
7,22,8:43
7,26,8:31.1
7,30,8:31.1
7,31,8:31.1
7,33,8:31.1
7,34,8:31.1
7,35,8:31.1
7,36,8:31.1
8,0,0:13
8,1,0:13
8,2,0:13
8,3,0:13
8,4,0:13
8,5,0:13
8,6,0:13
8,7,0:16
8,8,0:1
8,9,0:1
8,10,0:1
8,11,0:1
8,12,0:1
8,13,0:1
8,14,0:1
8,15,0:1
8,16,0:1
8,17,0:1
8,18,0:1
8,19,0:1
8,20,0:1
8,21,0:1
8,22,0:3
8,23,0:3
8,24,0:3
8,25,0:3
8,26,0:3
8,27,0:3
8,28,0:1
8,29,0:1
8,30,0:1
8,31,0:1
8,32,0:1
8,33,0:1
8,34,0:1
8,35,0:1
8,36,0:1
8,0,1:1
8,1,1:13
8,2,1:13
8,3,1:1
8,4,1:1
8,5,1:16
8,6,1:16
8,7,1:16
8,8,1:1
8,9,1:1
8,10,1:1
8,11,1:1
8,12,1:1
8,13,1:1
8,14,1:1
8,15,1:1
8,16,1:1
8,17,1:1
8,18,1:1
8,19,1:1
8,20,1:1
8,21,1:1
8,22,1:1
8,23,1:1
8,24,1:1
8,25,1:1
8,26,1:3
8,27,1:1
8,28,1:1
8,29,1:1
8,30,1:1
8,31,1:1
8,32,1:1
8,33,1:1
8,34,1:1
8,35,1:1
8,36,1:1
8,0,2:1
8,1,2:1
8,2,2:1
8,3,2:1
8,4,2:1
8,5,2:1
8,6,2:1
8,7,2:1
8,8,2:1
8,9,2:1
8,10,2:1
8,11,2:1
8,12,2:1
8,13,2:1
8,14,2:1
8,15,2:1
8,16,2:1
8,17,2:1
8,18,2:1
8,19,2:1
8,20,2:1
8,21,2:1
8,22,2:1
8,23,2:1
8,24,2:1
8,25,2:1
8,26,2:1
8,27,2:1
8,28,2:1
8,29,2:1
8,30,2:1
8,31,2:1
8,32,2:1
8,33,2:1
8,34,2:1
8,35,2:1
8,36,2:1
8,0,3:3
8,1,3:16
8,2,3:16
8,3,3:16
8,4,3:1
8,5,3:1
8,6,3:1
8,7,3:1
8,8,3:1
8,9,3:1
8,10,3:1
8,11,3:1
8,12,3:1
8,13,3:1
8,14,3:1
8,15,3:1
8,16,3:1
8,17,3:1
8,18,3:1
8,19,3:1
8,20,3:1
8,21,3:1
8,22,3:1
8,23,3:1
8,24,3:1
8,25,3:1
8,26,3:1
8,27,3:1
8,28,3:1
8,29,3:1
8,30,3:1
8,31,3:1
8,32,3:1
8,33,3:1
8,34,3:1
8,35,3:1
8,36,3:1
8,0,4:3
8,1,4:3
8,2,4:3
8,3,4:16
8,4,4:1
8,5,4:1
8,6,4:1
8,7,4:1
8,8,4:1
8,9,4:1
8,10,4:1
8,11,4:1
8,12,4:1
8,13,4:1
8,14,4:1
8,15,4:1
8,16,4:1
8,17,4:1
8,18,4:1
8,19,4:1
8,20,4:1
8,21,4:1
8,22,4:1
8,23,4:1
8,24,4:1
8,25,4:1
8,26,4:1
8,27,4:1
8,28,4:1
8,29,4:1
8,30,4:1
8,31,4:1
8,32,4:1
8,33,4:1
8,34,4:1
8,35,4:1
8,36,4:1
8,0,5:3
8,1,5:3
8,2,5:3
8,3,5:3
8,4,5:1
8,5,5:1
8,6,5:1
8,7,5:1
8,8,5:1
8,9,5:1
8,10,5:1
8,11,5:1
8,12,5:1
8,13,5:1
8,14,5:1
8,15,5:1
8,16,5:1
8,17,5:1
8,18,5:1
8,19,5:1
8,20,5:1
8,21,5:1
8,22,5:1
8,23,5:1
8,24,5:1
8,25,5:1
8,26,5:1
8,27,5:1
8,28,5:1
8,29,5:1
8,30,5:1
8,31,5:1
8,32,5:1
8,33,5:1
8,34,5:1
8,35,5:1
8,36,5:1
8,0,6:3
8,1,6:3
8,2,6:3
8,3,6:3
8,4,6:3
8,5,6:1
8,6,6:1
8,7,6:1
8,8,6:1
8,9,6:1
8,10,6:1
8,11,6:1
8,12,6:1
8,13,6:1
8,14,6:1
8,15,6:1
8,16,6:1
8,17,6:1
8,18,6:1
8,19,6:1
8,20,6:1
8,21,6:1
8,22,6:1
8,23,6:1
8,24,6:1
8,25,6:1
8,26,6:1
8,27,6:1
8,28,6:1
8,29,6:1
8,30,6:1
8,31,6:1
8,32,6:1
8,33,6:1
8,34,6:1
8,35,6:1
8,36,6:1
8,0,7:2
8,1,7:2
8,2,7:2
8,3,7:2
8,4,7:2
8,5,7:2
8,6,7:2
8,7,7:2
8,8,7:2
8,9,7:2
8,10,7:2
8,11,7:2
8,12,7:2
8,13,7:2
8,14,7:2
8,15,7:98
8,16,7:98
8,17,7:98
8,18,7:98
8,19,7:98
8,20,7:98
8,21,7:98
8,22,7:2
8,23,7:2
8,24,7:2
8,25,7:2
8,26,7:2
8,27,7:2
8,28,7:2
8,29,7:2
8,30,7:2
8,31,7:2
8,32,7:2
8,33,7:2
8,34,7:2
8,35,7:2
8,36,7:2
8,0,8:31.1
8,1,8:31.1
8,2,8:31.1
8,5,8:31.1
8,6,8:31.1
8,7,8:31.1
8,8,8:31.1
8,10,8:31.1
8,11,8:31.1
8,12,8:31.1
8,14,8:44
8,22,8:44
8,26,8:31.1
8,27,8:31.1
8,28,8:31.1
8,30,8:31.1
8,31,8:31.1
8,32,8:31.1
8,33,8:31.1
8,34,8:31.1
8,35,8:31.1
8,36,8:31.1
9,0,0:13
9,1,0:13
9,2,0:13
9,3,0:13
9,4,0:13
9,5,0:13
9,6,0:13
9,7,0:16
9,8,0:1
9,9,0:1
9,10,0:1
9,11,0:1
9,12,0:1
9,13,0:1
9,14,0:1
9,15,0:1
9,16,0:1
9,17,0:1
9,18,0:1
9,19,0:1
9,20,0:1
9,21,0:1
9,22,0:1
9,23,0:1
9,24,0:3
9,25,0:3
9,26,0:3
9,27,0:3
9,28,0:3
9,29,0:1
9,30,0:1
9,31,0:1
9,32,0:1
9,33,0:1
9,34,0:1
9,35,0:1
9,36,0:1
9,0,1:1
9,1,1:1
9,2,1:1
9,3,1:1
9,4,1:1
9,5,1:1
9,6,1:16
9,7,1:16
9,8,1:1
9,9,1:1
9,10,1:1
9,11,1:1
9,12,1:1
9,13,1:1
9,14,1:1
9,15,1:1
9,16,1:1
9,17,1:1
9,18,1:1
9,19,1:1
9,20,1:1
9,21,1:1
9,22,1:1
9,23,1:1
9,24,1:1
9,25,1:1
9,26,1:1
9,27,1:1
9,28,1:1
9,29,1:1
9,30,1:1
9,31,1:1
9,32,1:1
9,33,1:1
9,34,1:1
9,35,1:1
9,36,1:1
9,0,2:1
9,1,2:1
9,2,2:1
9,3,2:1
9,4,2:1
9,5,2:1
9,6,2:1
9,7,2:1
9,8,2:1
9,9,2:1
9,10,2:1
9,11,2:1
9,12,2:1
9,13,2:1
9,14,2:1
9,15,2:1
9,16,2:1
9,17,2:1
9,18,2:1
9,19,2:1
9,20,2:1
9,21,2:1
9,22,2:1
9,23,2:1
9,24,2:1
9,25,2:1
9,26,2:1
9,27,2:1
9,28,2:1
9,29,2:1
9,30,2:1
9,31,2:1
9,32,2:1
9,33,2:1
9,34,2:1
9,35,2:1
9,36,2:1
9,0,3:3
9,1,3:16
9,2,3:1
9,3,3:1
9,4,3:1
9,5,3:1
9,6,3:1
9,7,3:1
9,8,3:1
9,9,3:1
9,10,3:1
9,11,3:1
9,12,3:1
9,13,3:1
9,14,3:1
9,15,3:1
9,16,3:1
9,17,3:1
9,18,3:1
9,19,3:1
9,20,3:1
9,21,3:1
9,22,3:1
9,23,3:1
9,24,3:1
9,25,3:1
9,26,3:1
9,27,3:1
9,28,3:1
9,29,3:1
9,30,3:1
9,31,3:1
9,32,3:1
9,33,3:1
9,34,3:1
9,35,3:1
9,36,3:1
9,0,4:3
9,1,4:3
9,2,4:3
9,3,4:1
9,4,4:1
9,5,4:1
9,6,4:1
9,7,4:1
9,8,4:1
9,9,4:1
9,10,4:1
9,11,4:1
9,12,4:1
9,13,4:1
9,14,4:1
9,15,4:1
9,16,4:1
9,17,4:1
9,18,4:1
9,19,4:1
9,20,4:1
9,21,4:1
9,22,4:1
9,23,4:1
9,24,4:1
9,25,4:1
9,26,4:1
9,27,4:1
9,28,4:1
9,29,4:1
9,30,4:1
9,31,4:1
9,32,4:1
9,33,4:1
9,34,4:1
9,35,4:1
9,36,4:1
9,0,5:3
9,1,5:3
9,2,5:3
9,3,5:3
9,4,5:1
9,5,5:1
9,6,5:1
9,7,5:1
9,8,5:1
9,9,5:1
9,10,5:1
9,11,5:1
9,12,5:1
9,13,5:1
9,14,5:1
9,15,5:1
9,16,5:1
9,17,5:1
9,18,5:1
9,19,5:1
9,20,5:1
9,21,5:1
9,22,5:1
9,23,5:1
9,24,5:1
9,25,5:1
9,26,5:1
9,27,5:1
9,28,5:1
9,29,5:1
9,30,5:1
9,31,5:1
9,32,5:1
9,33,5:1
9,34,5:1
9,35,5:1
9,36,5:1
9,0,6:3
9,1,6:3
9,2,6:3
9,3,6:3
9,4,6:1
9,5,6:1
9,6,6:1
9,7,6:1
9,8,6:1
9,9,6:1
9,10,6:1
9,11,6:1
9,12,6:1
9,13,6:1
9,14,6:1
9,15,6:1
9,16,6:1
9,17,6:1
9,18,6:1
9,19,6:1
9,20,6:1
9,21,6:1
9,22,6:1
9,23,6:1
9,24,6:1
9,25,6:1
9,26,6:1
9,27,6:1
9,28,6:1
9,29,6:1
9,30,6:1
9,31,6:1
9,32,6:1
9,33,6:1
9,34,6:1
9,35,6:1
9,36,6:1
9,0,7:2
9,1,7:2
9,2,7:2
9,3,7:2
9,4,7:2
9,5,7:2
9,6,7:2
9,7,7:2
9,8,7:2
9,9,7:2
9,10,7:2
9,11,7:2
9,12,7:2
9,13,7:2
9,14,7:2
9,15,7:98
9,16,7:98
9,17,7:98
9,18,7:98
9,19,7:98
9,20,7:98
9,21,7:98
9,23,7:2
9,24,7:2
9,25,7:2
9,26,7:2
9,27,7:2
9,28,7:2
9,29,7:2
9,30,7:2
9,31,7:2
9,32,7:2
9,33,7:2
9,34,7:2
9,35,7:2
9,36,7:2
9,1,8:31.1
9,3,8:31.1
9,5,8:31.1
9,6,8:31.1
9,7,8:31.1
9,8,8:37
9,9,8:31.1
9,11,8:31.1
9,12,8:31.1
9,13,8:31.1
9,14,8:44
9,22,8:44
9,27,8:31.1
9,29,8:31.1
9,30,8:31.1
9,31,8:31.1
9,32,8:31.1
9,33,8:31.1
9,34,8:31.1
9,35,8:31.1
10,0,0:1
10,1,0:1
10,2,0:1
10,3,0:1
10,4,0:1
10,5,0:1
10,6,0:1
10,7,0:1
10,8,0:1
10,9,0:1
10,10,0:1
10,11,0:1
10,12,0:1
10,13,0:1
10,14,0:1
10,15,0:1
10,16,0:1
10,17,0:1
10,18,0:1
10,19,0:1
10,20,0:1
10,21,0:1
10,22,0:1
10,23,0:1
10,24,0:1
10,25,0:3
10,26,0:3
10,27,0:1
10,28,0:1
10,29,0:1
10,30,0:1
10,31,0:1
10,32,0:1
10,33,0:1
10,34,0:1
10,35,0:1
10,36,0:1
10,0,1:1
10,1,1:1
10,2,1:1
10,3,1:1
10,4,1:1
10,5,1:1
10,6,1:1
10,7,1:1
10,8,1:1
10,9,1:1
10,10,1:1
10,11,1:1
10,12,1:1
10,13,1:1
10,14,1:1
10,15,1:1
10,16,1:1
10,17,1:1
10,18,1:1
10,19,1:1
10,20,1:1
10,21,1:1
10,22,1:1
10,23,1:1
10,24,1:1
10,25,1:1
10,26,1:1
10,27,1:1
10,28,1:1
10,29,1:1
10,30,1:1
10,31,1:1
10,32,1:1
10,33,1:1
10,34,1:1
10,35,1:1
10,36,1:1
10,0,2:1
10,1,2:1
10,2,2:1
10,3,2:1
10,4,2:1
10,5,2:1
10,6,2:1
10,7,2:1
10,8,2:1
10,9,2:1
10,10,2:1
10,11,2:1
10,12,2:1
10,13,2:1
10,14,2:1
10,15,2:1
10,16,2:1
10,17,2:1
10,18,2:1
10,19,2:1
10,20,2:1
10,21,2:1
10,22,2:1
10,23,2:1
10,24,2:1
10,25,2:1
10,26,2:1
10,27,2:1
10,28,2:1
10,29,2:1
10,30,2:1
10,31,2:1
10,32,2:1
10,33,2:1
10,34,2:1
10,35,2:1
10,36,2:1
10,0,3:1
10,1,3:1
10,2,3:1
10,3,3:1
10,4,3:1
10,5,3:1
10,6,3:1
10,7,3:1
10,8,3:1
10,9,3:1
10,10,3:1
10,11,3:1
10,12,3:1
10,13,3:1
10,14,3:1
10,15,3:1
10,16,3:1
10,17,3:1
10,18,3:1
10,19,3:1
10,20,3:1
10,21,3:1
10,22,3:1
10,23,3:1
10,24,3:1
10,25,3:1
10,26,3:1
10,27,3:1
10,28,3:1
10,29,3:1
10,30,3:1
10,31,3:1
10,32,3:1
10,33,3:1
10,34,3:1
10,35,3:1
10,36,3:1
10,0,4:3
10,1,4:3
10,2,4:1
10,3,4:1
10,4,4:1
10,5,4:1
10,6,4:1
10,7,4:1
10,8,4:1
10,9,4:1
10,10,4:1
10,11,4:1
10,12,4:1
10,13,4:1
10,14,4:1
10,15,4:1
10,16,4:1
10,17,4:1
10,18,4:1
10,19,4:1
10,20,4:1
10,21,4:1
10,22,4:1
10,23,4:1
10,24,4:1
10,25,4:1
10,26,4:1
10,27,4:1
10,28,4:1
10,29,4:1
10,30,4:1
10,31,4:1
10,32,4:1
10,33,4:1
10,34,4:1
10,35,4:1
10,36,4:1
10,0,5:3
10,1,5:3
10,2,5:3
10,3,5:1
10,4,5:1
10,5,5:1
10,6,5:1
10,7,5:1
10,8,5:1
10,9,5:1
10,10,5:1
10,11,5:1
10,12,5:1
10,13,5:1
10,14,5:1
10,15,5:1
10,16,5:1
10,17,5:1
10,18,5:1
10,19,5:1
10,20,5:1
10,21,5:1
10,22,5:1
10,23,5:1
10,24,5:1
10,25,5:1
10,26,5:1
10,27,5:1
10,28,5:1
10,29,5:1
10,30,5:1
10,31,5:1
10,32,5:1
10,33,5:1
10,34,5:1
10,35,5:1
10,36,5:1
10,0,6:3
10,1,6:3
10,2,6:3
10,3,6:3
10,4,6:1
10,5,6:1
10,6,6:1
10,7,6:1
10,8,6:1
10,9,6:1
10,10,6:1
10,11,6:1
10,12,6:1
10,13,6:1
10,14,6:1
10,15,6:1
10,16,6:1
10,17,6:1
10,18,6:1
10,19,6:1
10,20,6:1
10,21,6:1
10,22,6:1
10,23,6:1
10,24,6:1
10,25,6:1
10,26,6:1
10,27,6:1
10,28,6:1
10,29,6:1
10,30,6:1
10,31,6:1
10,32,6:1
10,33,6:1
10,34,6:1
10,35,6:1
10,36,6:1
10,0,7:2
10,1,7:2
10,2,7:2
10,3,7:2
10,4,7:2
10,5,7:2
10,6,7:2
10,7,7:2
10,8,7:2
10,9,7:2
10,10,7:2
10,11,7:2
10,12,7:2
10,13,7:2
10,14,7:2
10,15,7:98
10,16,7:98
10,17,7:98
10,18,7:98
10,19,7:98
10,20,7:98
10,21,7:98
10,23,7:2
10,24,7:2
10,25,7:2
10,26,7:2
10,27,7:2
10,28,7:2
10,29,7:2
10,30,7:2
10,31,7:2
10,32,7:2
10,33,7:2
10,34,7:2
10,35,7:2
10,36,7:2
10,2,8:31.1
10,5,8:31.1
10,6,8:31.1
10,7,8:31.1
10,8,8:31.1
10,12,8:31.1
10,14,8:44
10,22,8:44
10,24,8:31.1
10,25,8:31.1
10,26,8:31.1
10,27,8:31.1
10,28,8:31.1
10,29,8:31.1
10,30,8:31.1
10,31,8:31.1
10,32,8:31.1
10,33,8:31.1
10,34,8:31.1
10,36,8:31.1
11,0,0:1
11,1,0:1
11,2,0:1
11,3,0:1
11,4,0:1
11,5,0:1
11,6,0:1
11,7,0:1
11,8,0:1
11,9,0:1
11,10,0:1
11,11,0:1
11,12,0:3
11,13,0:3
11,14,0:3
11,15,0:1
11,16,0:1
11,17,0:1
11,18,0:1
11,19,0:1
11,20,0:1
11,21,0:1
11,22,0:1
11,23,0:1
11,24,0:1
11,25,0:1
11,26,0:1
11,27,0:1
11,28,0:1
11,29,0:1
11,30,0:1
11,31,0:1
11,32,0:1
11,33,0:13
11,34,0:13
11,35,0:13
11,36,0:1
11,0,1:1
11,1,1:1
11,2,1:1
11,3,1:1
11,4,1:1
11,5,1:1
11,6,1:1
11,7,1:1
11,8,1:1
11,9,1:1
11,10,1:1
11,11,1:1
11,12,1:1
11,13,1:1
11,14,1:1
11,15,1:1
11,16,1:1
11,17,1:1
11,18,1:1
11,19,1:1
11,20,1:1
11,21,1:1
11,22,1:1
11,23,1:1
11,24,1:1
11,25,1:1
11,26,1:1
11,27,1:1
11,28,1:1
11,29,1:1
11,30,1:1
11,31,1:1
11,32,1:1
11,33,1:13
11,34,1:13
11,35,1:13
11,36,1:1
11,0,2:1
11,1,2:1
11,2,2:1
11,3,2:1
11,4,2:1
11,5,2:1
11,6,2:1
11,7,2:1
11,8,2:1
11,9,2:1
11,10,2:1
11,11,2:1
11,12,2:1
11,13,2:1
11,14,2:1
11,15,2:1
11,16,2:1
11,17,2:1
11,18,2:1
11,19,2:1
11,20,2:1
11,21,2:1
11,22,2:1
11,23,2:1
11,24,2:1
11,25,2:1
11,26,2:1
11,27,2:1
11,28,2:1
11,29,2:1
11,30,2:1
11,31,2:1
11,32,2:1
11,33,2:1
11,34,2:1
11,35,2:1
11,36,2:1
11,0,3:1
11,1,3:1
11,2,3:1
11,3,3:1
11,4,3:1
11,5,3:1
11,6,3:1
11,7,3:1
11,8,3:1
11,9,3:1
11,10,3:1
11,11,3:1
11,12,3:1
11,13,3:1
11,14,3:1
11,15,3:1
11,16,3:1
11,17,3:1
11,18,3:1
11,19,3:1
11,20,3:1
11,21,3:1
11,22,3:1
11,23,3:1
11,24,3:1
11,25,3:1
11,26,3:1
11,27,3:1
11,28,3:1
11,29,3:1
11,30,3:1
11,31,3:1
11,32,3:1
11,33,3:1
11,34,3:1
11,35,3:1
11,36,3:1
11,0,4:3
11,1,4:3
11,2,4:1
11,3,4:1
11,4,4:1
11,5,4:1
11,6,4:1
11,7,4:1
11,8,4:1
11,9,4:1
11,10,4:1
11,11,4:1
11,12,4:1
11,13,4:1
11,14,4:1
11,15,4:1
11,16,4:1
11,17,4:1
11,18,4:1
11,19,4:1
11,20,4:1
11,21,4:1
11,22,4:1
11,23,4:1
11,24,4:1
11,25,4:1
11,26,4:1
11,27,4:1
11,28,4:1
11,29,4:1
11,30,4:1
11,31,4:1
11,32,4:1
11,33,4:1
11,34,4:1
11,35,4:1
11,36,4:1
11,0,5:3
11,1,5:3
11,2,5:3
11,3,5:3
11,4,5:1
11,5,5:1
11,6,5:1
11,7,5:1
11,8,5:1
11,9,5:1
11,10,5:1
11,11,5:1
11,12,5:1
11,13,5:1
11,14,5:1
11,15,5:1
11,16,5:1
11,17,5:1
11,18,5:1
11,19,5:1
11,20,5:1
11,21,5:1
11,22,5:1
11,23,5:1
11,24,5:1
11,25,5:1
11,26,5:1
11,27,5:1
11,28,5:1
11,29,5:1
11,30,5:1
11,31,5:1
11,32,5:1
11,33,5:1
11,34,5:1
11,35,5:1
11,36,5:1
11,0,6:3
11,1,6:3
11,2,6:3
11,3,6:3
11,4,6:1
11,5,6:1
11,6,6:1
11,7,6:1
11,8,6:1
11,9,6:1
11,10,6:1
11,11,6:1
11,12,6:1
11,13,6:1
11,14,6:1
11,15,6:1
11,16,6:1
11,17,6:1
11,18,6:1
11,19,6:1
11,20,6:1
11,21,6:1
11,22,6:1
11,23,6:1
11,24,6:1
11,25,6:1
11,26,6:1
11,27,6:1
11,28,6:1
11,29,6:1
11,30,6:1
11,31,6:1
11,32,6:1
11,33,6:1
11,34,6:1
11,35,6:1
11,36,6:1
11,0,7:2
11,1,7:2
11,2,7:2
11,3,7:2
11,4,7:2
11,5,7:2
11,6,7:2
11,7,7:2
11,8,7:2
11,9,7:2
11,10,7:2
11,11,7:2
11,12,7:2
11,13,7:2
11,14,7:3
11,15,7:98
11,16,7:98
11,17,7:98
11,18,7:98
11,19,7:98
11,20,7:98
11,21,7:98
11,22,7:3
11,23,7:2
11,24,7:2
11,25,7:2
11,26,7:2
11,27,7:2
11,28,7:2
11,29,7:2
11,30,7:2
11,31,7:2
11,32,7:2
11,33,7:2
11,34,7:2
11,35,7:2
11,36,7:2
11,1,8:31.1
11,4,8:31.1
11,7,8:31.1
11,8,8:31.1
11,9,8:31.1
11,14,8:44
11,22,8:44
11,24,8:31.1
11,25,8:31.1
11,28,8:31.1
11,29,8:31.1
11,30,8:31.1
11,31,8:31.1
11,33,8:31.1
11,34,8:31.1
11,3,9:50.2
11,8,9:50.2
11,13,9:50.2
11,23,9:50.2
11,28,9:50.2
11,33,9:50.2
11,14,11:50.2
11,22,11:50.2
11,15,12:50.2
11,21,12:50.2
11,3,13:50.2
11,13,13:50.2
11,16,13:50.2
11,20,13:50.2
11,23,13:50.2
11,28,13:50.2
11,33,13:50.2
11,18,14:50.2
11,1,16:43
11,2,16:43
11,3,16:44
11,4,16:43
11,5,16:44
11,6,16:44
11,7,16:43
11,8,16:44
11,9,16:44
11,10,16:43
11,11,16:44
11,12,16:44
11,13,16:43
11,14,16:44
11,15,16:44
11,16,16:43
11,17,16:44
11,18,16:44
11,19,16:43
11,20,16:44
11,21,16:44
11,22,16:43
11,23,16:44
11,24,16:44
11,25,16:43
11,26,16:44
11,27,16:44
11,28,16:43
11,29,16:44
11,30,16:44
11,31,16:43
11,32,16:44
11,33,16:44
11,34,16:43
11,35,16:43
11,1,17:44
11,2,17:44
11,4,17:44
11,7,17:44
11,10,17:44
11,13,17:44
11,16,17:44
11,19,17:44
11,22,17:44
11,25,17:44
11,28,17:44
11,31,17:44
11,34,17:44
11,35,17:44
12,0,0:1
12,1,0:1
12,2,0:1
12,3,0:1
12,4,0:1
12,5,0:1
12,6,0:1
12,7,0:1
12,8,0:1
12,9,0:1
12,10,0:1
12,11,0:1
12,12,0:1
12,13,0:1
12,14,0:3
12,15,0:1
12,16,0:1
12,17,0:1
12,18,0:1
12,19,0:1
12,20,0:1
12,21,0:1
12,22,0:1
12,23,0:1
12,24,0:1
12,25,0:1
12,26,0:1
12,27,0:1
12,28,0:1
12,29,0:1
12,30,0:1
12,31,0:1
12,32,0:1
12,33,0:13
12,34,0:13
12,35,0:13
12,36,0:1
12,0,1:1
12,1,1:1
12,2,1:1
12,3,1:1
12,4,1:1
12,5,1:1
12,6,1:1
12,7,1:1
12,8,1:1
12,9,1:1
12,10,1:1
12,11,1:1
12,12,1:1
12,13,1:1
12,14,1:1
12,15,1:1
12,16,1:1
12,17,1:1
12,18,1:1
12,19,1:1
12,20,1:1
12,21,1:1
12,22,1:1
12,23,1:1
12,24,1:1
12,25,1:1
12,26,1:1
12,27,1:1
12,28,1:1
12,29,1:1
12,30,1:1
12,31,1:1
12,32,1:1
12,33,1:13
12,34,1:13
12,35,1:13
12,36,1:1
12,0,2:1
12,1,2:1
12,2,2:1
12,3,2:1
12,4,2:1
12,5,2:1
12,6,2:1
12,7,2:1
12,8,2:1
12,9,2:1
12,10,2:1
12,11,2:1
12,12,2:1
12,13,2:1
12,14,2:1
12,15,2:1
12,16,2:1
12,17,2:1
12,18,2:1
12,19,2:1
12,20,2:1
12,21,2:1
12,22,2:1
12,23,2:1
12,24,2:1
12,25,2:1
12,26,2:1
12,27,2:1
12,28,2:1
12,29,2:1
12,30,2:1
12,31,2:1
12,32,2:1
12,33,2:13
12,34,2:13
12,35,2:13
12,36,2:1
12,0,3:1
12,1,3:1
12,2,3:1
12,3,3:1
12,4,3:1
12,5,3:1
12,6,3:1
12,7,3:1
12,8,3:1
12,9,3:1
12,10,3:1
12,11,3:1
12,12,3:1
12,13,3:1
12,14,3:1
12,15,3:1
12,16,3:1
12,17,3:1
12,18,3:1
12,19,3:1
12,20,3:1
12,21,3:1
12,22,3:1
12,23,3:1
12,24,3:1
12,25,3:1
12,26,3:1
12,27,3:1
12,28,3:1
12,29,3:1
12,30,3:1
12,31,3:1
12,32,3:1
12,33,3:1
12,34,3:1
12,35,3:1
12,36,3:1
12,0,4:3
12,1,4:3
12,2,4:1
12,3,4:1
12,4,4:1
12,5,4:1
12,6,4:1
12,7,4:1
12,8,4:1
12,9,4:1
12,10,4:1
12,11,4:1
12,12,4:1
12,13,4:1
12,14,4:1
12,15,4:1
12,16,4:1
12,17,4:1
12,18,4:1
12,19,4:1
12,20,4:1
12,21,4:1
12,22,4:1
12,23,4:1
12,24,4:1
12,25,4:1
12,26,4:1
12,27,4:1
12,28,4:1
12,29,4:1
12,30,4:1
12,31,4:1
12,32,4:1
12,33,4:1
12,34,4:1
12,35,4:1
12,36,4:1
12,0,5:3
12,1,5:3
12,2,5:3
12,3,5:3
12,4,5:1
12,5,5:1
12,6,5:1
12,7,5:1
12,8,5:1
12,9,5:1
12,10,5:1
12,11,5:1
12,12,5:1
12,13,5:1
12,14,5:1
12,15,5:1
12,16,5:1
12,17,5:1
12,18,5:1
12,19,5:1
12,20,5:1
12,21,5:1
12,22,5:1
12,23,5:1
12,24,5:1
12,25,5:1
12,26,5:1
12,27,5:1
12,28,5:1
12,29,5:1
12,30,5:1
12,31,5:1
12,32,5:1
12,33,5:1
12,34,5:1
12,35,5:1
12,36,5:1
12,0,6:3
12,1,6:3
12,2,6:3
12,3,6:3
12,4,6:1
12,5,6:1
12,6,6:1
12,7,6:1
12,8,6:1
12,9,6:1
12,10,6:1
12,11,6:1
12,12,6:1
12,13,6:1
12,14,6:1
12,15,6:1
12,16,6:1
12,17,6:1
12,18,6:1
12,19,6:1
12,20,6:1
12,21,6:1
12,22,6:1
12,23,6:1
12,24,6:1
12,25,6:1
12,26,6:1
12,27,6:1
12,28,6:1
12,29,6:1
12,30,6:1
12,31,6:1
12,32,6:1
12,33,6:1
12,34,6:1
12,35,6:1
12,36,6:1
12,0,7:2
12,1,7:2
12,2,7:4
12,3,7:4
12,4,7:4
12,5,7:4
12,6,7:4
12,7,7:4
12,8,7:3
12,9,7:4
12,10,7:4
12,11,7:4
12,12,7:4
12,13,7:3
12,14,7:3
12,15,7:98
12,16,7:98
12,17,7:98
12,18,7:98
12,19,7:98
12,20,7:98
12,21,7:98
12,22,7:3
12,23,7:3
12,24,7:4
12,25,7:4
12,26,7:4
12,27,7:4
12,28,7:4
12,29,7:4
12,30,7:4
12,31,7:4
12,32,7:4
12,33,7:4
12,34,7:3
12,35,7:2
12,36,7:2
12,1,8:31.1
12,2,8:1
12,3,8:1
12,8,8:1
12,13,8:1
12,14,8:17
12,22,8:17
12,23,8:1
12,28,8:1
12,33,8:1
12,34,8:1
12,2,9:1
12,3,9:1
12,8,9:1
12,13,9:1
12,14,9:17
12,22,9:17
12,23,9:1
12,28,9:1
12,33,9:1
12,34,9:1
12,2,10:1
12,3,10:1
12,4,10:1
12,7,10:1
12,8,10:1
12,9,10:1
12,12,10:1
12,13,10:1
12,14,10:17
12,22,10:17
12,23,10:1
12,24,10:1
12,27,10:1
12,28,10:1
12,29,10:1
12,32,10:1
12,33,10:1
12,34,10:1
12,2,11:1
12,3,11:1
12,4,11:1
12,5,11:1
12,6,11:1
12,7,11:1
12,8,11:1
12,9,11:1
12,10,11:1
12,11,11:1
12,12,11:1
12,13,11:1
12,14,11:17
12,22,11:17
12,23,11:1
12,24,11:1
12,25,11:1
12,26,11:1
12,27,11:1
12,28,11:1
12,29,11:1
12,30,11:1
12,31,11:1
12,32,11:1
12,33,11:1
12,34,11:1
12,2,12:1
12,3,12:1
12,8,12:1
12,13,12:1
12,14,12:17
12,15,12:17
12,21,12:17
12,22,12:17
12,23,12:1
12,28,12:1
12,33,12:1
12,34,12:1
12,2,13:1
12,3,13:1
12,8,13:1
12,13,13:1
12,14,13:1
12,15,13:17
12,16,13:17
12,20,13:17
12,21,13:17
12,22,13:1
12,23,13:1
12,28,13:1
12,33,13:1
12,34,13:1
12,2,14:1
12,3,14:1
12,4,14:1
12,7,14:1
12,8,14:1
12,9,14:1
12,12,14:1
12,13,14:1
12,14,14:1
12,15,14:1
12,16,14:17
12,17,14:17
12,18,14:17
12,19,14:17
12,20,14:17
12,21,14:1
12,22,14:1
12,23,14:1
12,24,14:1
12,27,14:1
12,28,14:1
12,29,14:1
12,32,14:1
12,33,14:1
12,34,14:1
12,2,15:1
12,3,15:1
12,4,15:1
12,5,15:1
12,6,15:1
12,7,15:1
12,8,15:1
12,9,15:1
12,10,15:1
12,11,15:1
12,12,15:1
12,13,15:1
12,14,15:1
12,15,15:1
12,16,15:1
12,17,15:1
12,18,15:1
12,19,15:1
12,20,15:1
12,21,15:1
12,22,15:1
12,23,15:1
12,24,15:1
12,25,15:1
12,26,15:1
12,27,15:1
12,28,15:1
12,29,15:1
12,30,15:1
12,31,15:1
12,32,15:1
12,33,15:1
12,34,15:1
12,1,16:43
12,2,16:43
12,3,16:44
12,4,16:44
12,5,16:44
12,6,16:44
12,7,16:44
12,8,16:44
12,9,16:44
12,10,16:44
12,11,16:44
12,12,16:44
12,13,16:44
12,14,16:44
12,15,16:44
12,16,16:44
12,17,16:44
12,18,16:44
12,19,16:44
12,20,16:44
12,21,16:44
12,22,16:44
12,23,16:44
12,24,16:44
12,25,16:44
12,26,16:44
12,27,16:44
12,28,16:44
12,29,16:44
12,30,16:44
12,31,16:44
12,32,16:44
12,33,16:44
12,34,16:43
12,35,16:43
12,1,17:44
12,2,17:44
12,34,17:44
12,35,17:44
13,0,0:1
13,1,0:1
13,2,0:1
13,3,0:1
13,4,0:1
13,5,0:1
13,6,0:1
13,7,0:1
13,8,0:1
13,9,0:1
13,10,0:1
13,11,0:1
13,12,0:1
13,13,0:1
13,14,0:1
13,15,0:1
13,16,0:1
13,17,0:1
13,18,0:1
13,19,0:1
13,20,0:1
13,21,0:1
13,22,0:1
13,23,0:1
13,24,0:1
13,25,0:1
13,26,0:1
13,27,0:1
13,28,0:1
13,29,0:15
13,30,0:1
13,31,0:1
13,32,0:13
13,33,0:13
13,34,0:13
13,35,0:13
13,36,0:13
13,0,1:1
13,1,1:1
13,2,1:1
13,3,1:1
13,4,1:1
13,5,1:1
13,6,1:1
13,7,1:1
13,8,1:1
13,9,1:1
13,10,1:1
13,11,1:1
13,12,1:1
13,13,1:1
13,14,1:1
13,15,1:1
13,16,1:1
13,17,1:1
13,18,1:1
13,19,1:1
13,20,1:1
13,21,1:1
13,22,1:1
13,23,1:1
13,24,1:1
13,25,1:1
13,26,1:1
13,27,1:1
13,28,1:15
13,29,1:15
13,30,1:1
13,31,1:1
13,32,1:13
13,33,1:13
13,34,1:13
13,35,1:13
13,36,1:13
13,0,2:1
13,1,2:1
13,2,2:1
13,3,2:1
13,4,2:1
13,5,2:1
13,6,2:1
13,7,2:1
13,8,2:1
13,9,2:1
13,10,2:1
13,11,2:1
13,12,2:1
13,13,2:1
13,14,2:1
13,15,2:1
13,16,2:1
13,17,2:1
13,18,2:1
13,19,2:1
13,20,2:1
13,21,2:1
13,22,2:1
13,23,2:1
13,24,2:1
13,25,2:1
13,26,2:1
13,27,2:1
13,28,2:1
13,29,2:1
13,30,2:1
13,31,2:1
13,32,2:1
13,33,2:13
13,34,2:13
13,35,2:13
13,36,2:1
13,0,3:1
13,1,3:1
13,2,3:1
13,3,3:1
13,4,3:1
13,5,3:1
13,6,3:1
13,7,3:1
13,8,3:1
13,9,3:1
13,10,3:1
13,11,3:1
13,12,3:1
13,13,3:1
13,14,3:1
13,15,3:1
13,16,3:1
13,17,3:1
13,18,3:1
13,19,3:1
13,20,3:1
13,21,3:1
13,22,3:1
13,23,3:1
13,24,3:1
13,25,3:1
13,26,3:1
13,27,3:1
13,28,3:1
13,29,3:1
13,30,3:1
13,31,3:1
13,32,3:1
13,33,3:1
13,34,3:1
13,35,3:1
13,36,3:1
13,0,4:3
13,1,4:3
13,2,4:3
13,3,4:1
13,4,4:1
13,5,4:1
13,6,4:1
13,7,4:1
13,8,4:1
13,9,4:1
13,10,4:1
13,11,4:1
13,12,4:1
13,13,4:1
13,14,4:1
13,15,4:3
13,16,4:3
13,17,4:3
13,18,4:3
13,19,4:3
13,20,4:1
13,21,4:1
13,22,4:1
13,23,4:1
13,24,4:1
13,25,4:1
13,26,4:1
13,27,4:1
13,28,4:1
13,29,4:1
13,30,4:1
13,31,4:1
13,32,4:1
13,33,4:1
13,34,4:1
13,35,4:1
13,36,4:1
13,0,5:3
13,1,5:3
13,2,5:3
13,3,5:3
13,4,5:1
13,5,5:1
13,6,5:1
13,7,5:1
13,8,5:1
13,9,5:1
13,10,5:1
13,11,5:1
13,12,5:1
13,13,5:1
13,14,5:1
13,15,5:3
13,16,5:3
13,17,5:3
13,18,5:3
13,19,5:3
13,20,5:1
13,21,5:1
13,22,5:1
13,23,5:1
13,24,5:1
13,25,5:1
13,26,5:1
13,27,5:1
13,28,5:1
13,29,5:1
13,30,5:1
13,31,5:1
13,32,5:1
13,33,5:1
13,34,5:1
13,35,5:1
13,36,5:1
13,0,6:3
13,1,6:3
13,2,6:3
13,3,6:3
13,4,6:1
13,5,6:1
13,6,6:1
13,7,6:1
13,8,6:1
13,9,6:1
13,10,6:1
13,11,6:1
13,12,6:1
13,13,6:1
13,14,6:1
13,15,6:1
13,16,6:1
13,17,6:3
13,18,6:3
13,19,6:1
13,20,6:1
13,21,6:1
13,22,6:1
13,23,6:1
13,24,6:1
13,25,6:1
13,26,6:1
13,27,6:1
13,28,6:1
13,29,6:1
13,30,6:1
13,31,6:1
13,32,6:1
13,33,6:1
13,34,6:1
13,35,6:1
13,36,6:1
13,0,7:2
13,1,7:2
13,2,7:4
13,3,7:4
13,4,7:4
13,5,7:4
13,6,7:4
13,7,7:4
13,8,7:3
13,9,7:4
13,10,7:4
13,11,7:4
13,12,7:4
13,13,7:3
13,14,7:3
13,15,7:98
13,16,7:98
13,17,7:98
13,18,7:98
13,19,7:98
13,20,7:98
13,21,7:98
13,22,7:3
13,23,7:3
13,24,7:4
13,25,7:4
13,26,7:4
13,27,7:4
13,28,7:4
13,29,7:4
13,30,7:4
13,31,7:4
13,32,7:4
13,33,7:4
13,34,7:3
13,35,7:2
13,36,7:2
13,2,8:1
13,3,8:1
13,8,8:1
13,13,8:1
13,14,8:17
13,22,8:17
13,23,8:1
13,28,8:1
13,33,8:1
13,34,8:1
13,35,8:31.1
13,1,9:50.4
13,2,9:1
13,3,9:1
13,8,9:1
13,13,9:1
13,14,9:17
13,22,9:17
13,23,9:1
13,28,9:1
13,33,9:1
13,34,9:1
13,35,9:50.3
13,2,10:1
13,3,10:1
13,4,10:1
13,7,10:1
13,8,10:1
13,9,10:1
13,12,10:1
13,13,10:1
13,14,10:17
13,22,10:17
13,23,10:1
13,24,10:1
13,27,10:1
13,28,10:1
13,29,10:1
13,32,10:1
13,33,10:1
13,34,10:1
13,2,11:1
13,3,11:1
13,4,11:1
13,5,11:1
13,6,11:1
13,7,11:1
13,8,11:1
13,9,11:1
13,10,11:1
13,11,11:1
13,12,11:1
13,13,11:1
13,14,11:17
13,22,11:17
13,23,11:1
13,24,11:1
13,25,11:1
13,26,11:1
13,27,11:1
13,28,11:1
13,29,11:1
13,30,11:1
13,31,11:1
13,32,11:1
13,33,11:1
13,34,11:1
13,2,12:1
13,3,12:1
13,8,12:1
13,13,12:1
13,14,12:17
13,15,12:17
13,16,12:50.3
13,20,12:50.4
13,21,12:17
13,22,12:17
13,23,12:1
13,28,12:1
13,33,12:1
13,34,12:1
13,1,13:50.4
13,2,13:1
13,3,13:1
13,4,13:50.3
13,8,13:1
13,13,13:1
13,14,13:1
13,15,13:17
13,16,13:17
13,17,13:50.3
13,19,13:50.4
13,20,13:17
13,21,13:17
13,22,13:1
13,23,13:1
13,28,13:1
13,32,13:50.4
13,33,13:1
13,34,13:1
13,35,13:50.3
13,2,14:1
13,3,14:1
13,4,14:1
13,7,14:1
13,8,14:1
13,9,14:1
13,12,14:1
13,13,14:1
13,14,14:1
13,15,14:1
13,16,14:17
13,17,14:17
13,18,14:17
13,19,14:17
13,20,14:17
13,21,14:1
13,22,14:1
13,23,14:1
13,24,14:1
13,27,14:1
13,28,14:1
13,29,14:1
13,32,14:1
13,33,14:1
13,34,14:1
13,2,15:1
13,3,15:1
13,4,15:1
13,5,15:1
13,6,15:1
13,7,15:1
13,8,15:1
13,9,15:1
13,10,15:1
13,11,15:1
13,12,15:1
13,13,15:1
13,14,15:1
13,15,15:1
13,16,15:1
13,17,15:1
13,18,15:1
13,19,15:1
13,20,15:1
13,21,15:1
13,22,15:1
13,23,15:1
13,24,15:1
13,25,15:1
13,26,15:1
13,27,15:1
13,28,15:1
13,29,15:1
13,30,15:1
13,31,15:1
13,32,15:1
13,33,15:1
13,34,15:1
13,1,16:44
13,2,16:44
13,34,16:44
13,35,16:44
14,0,0:1
14,1,0:1
14,2,0:1
14,3,0:1
14,4,0:1
14,5,0:1
14,6,0:1
14,7,0:13
14,8,0:1
14,9,0:1
14,10,0:1
14,11,0:1
14,12,0:1
14,13,0:1
14,14,0:1
14,15,0:1
14,16,0:1
14,17,0:1
14,18,0:1
14,19,0:1
14,20,0:1
14,21,0:1
14,22,0:1
14,23,0:1
14,24,0:1
14,25,0:1
14,26,0:1
14,27,0:1
14,28,0:1
14,29,0:1
14,30,0:1
14,31,0:1
14,32,0:13
14,33,0:13
14,34,0:13
14,35,0:13
14,36,0:13
14,0,1:1
14,1,1:1
14,2,1:1
14,3,1:1
14,4,1:1
14,5,1:1
14,6,1:1
14,7,1:1
14,8,1:1
14,9,1:1
14,10,1:1
14,11,1:1
14,12,1:1
14,13,1:1
14,14,1:1
14,15,1:1
14,16,1:1
14,17,1:1
14,18,1:1
14,19,1:1
14,20,1:1
14,21,1:1
14,22,1:1
14,23,1:1
14,24,1:1
14,25,1:1
14,26,1:1
14,27,1:1
14,28,1:1
14,29,1:1
14,30,1:1
14,31,1:1
14,32,1:13
14,33,1:13
14,34,1:13
14,35,1:13
14,36,1:13
14,0,2:1
14,1,2:1
14,2,2:1
14,3,2:1
14,4,2:1
14,5,2:1
14,6,2:1
14,7,2:1
14,8,2:1
14,9,2:1
14,10,2:1
14,11,2:1
14,12,2:1
14,13,2:1
14,14,2:1
14,15,2:1
14,16,2:1
14,17,2:1
14,18,2:1
14,19,2:1
14,20,2:1
14,21,2:1
14,22,2:1
14,23,2:1
14,24,2:1
14,25,2:1
14,26,2:1
14,27,2:1
14,28,2:15
14,29,2:15
14,30,2:1
14,31,2:1
14,32,2:13
14,33,2:13
14,34,2:13
14,35,2:13
14,36,2:1
14,0,3:1
14,1,3:1
14,2,3:1
14,3,3:1
14,4,3:1
14,5,3:1
14,6,3:1
14,7,3:1
14,8,3:1
14,9,3:1
14,10,3:1
14,11,3:1
14,12,3:1
14,13,3:1
14,14,3:1
14,15,3:1
14,16,3:3
14,17,3:3
14,18,3:3
14,19,3:3
14,20,3:1
14,21,3:1
14,22,3:1
14,23,3:1
14,24,3:1
14,25,3:1
14,26,3:1
14,27,3:1
14,28,3:15
14,29,3:1
14,30,3:1
14,31,3:1
14,32,3:1
14,33,3:1
14,34,3:1
14,35,3:1
14,36,3:1
14,0,4:3
14,1,4:3
14,2,4:3
14,3,4:1
14,4,4:1
14,5,4:1
14,6,4:1
14,7,4:1
14,8,4:1
14,9,4:1
14,10,4:1
14,11,4:1
14,12,4:1
14,13,4:1
14,14,4:1
14,15,4:3
14,16,4:3
14,17,4:3
14,18,4:3
14,19,4:3
14,20,4:3
14,21,4:1
14,22,4:1
14,23,4:1
14,24,4:1
14,25,4:1
14,26,4:1
14,27,4:1
14,28,4:1
14,29,4:1
14,30,4:1
14,31,4:1
14,32,4:1
14,33,4:1
14,34,4:1
14,35,4:1
14,36,4:1
14,0,5:3
14,1,5:3
14,2,5:3
14,3,5:3
14,4,5:1
14,5,5:1
14,6,5:1
14,7,5:1
14,8,5:1
14,9,5:1
14,10,5:1
14,11,5:1
14,12,5:1
14,13,5:1
14,14,5:1
14,15,5:3
14,16,5:3
14,17,5:3
14,18,5:3
14,19,5:3
14,20,5:3
14,21,5:1
14,22,5:1
14,23,5:1
14,24,5:1
14,25,5:1
14,26,5:1
14,27,5:1
14,28,5:1
14,29,5:1
14,30,5:1
14,31,5:1
14,32,5:1
14,33,5:1
14,34,5:1
14,35,5:1
14,36,5:1
14,0,6:3
14,1,6:3
14,2,6:3
14,3,6:3
14,4,6:1
14,5,6:1
14,6,6:1
14,7,6:1
14,8,6:1
14,9,6:1
14,10,6:1
14,11,6:1
14,12,6:1
14,13,6:1
14,14,6:1
14,15,6:1
14,16,6:3
14,17,6:3
14,18,6:3
14,19,6:3
14,20,6:3
14,21,6:1
14,22,6:1
14,23,6:1
14,24,6:1
14,25,6:1
14,26,6:1
14,27,6:1
14,28,6:1
14,29,6:1
14,30,6:1
14,31,6:1
14,32,6:1
14,33,6:1
14,34,6:1
14,35,6:1
14,36,6:1
14,0,7:2
14,1,7:2
14,2,7:4
14,3,7:4
14,4,7:98
14,5,7:98
14,6,7:98
14,7,7:98
14,8,7:98
14,9,7:98
14,10,7:98
14,11,7:98
14,12,7:98
14,13,7:98
14,14,7:98
14,15,7:98
14,16,7:98
14,17,7:98
14,18,7:98
14,19,7:98
14,20,7:98
14,21,7:98
14,22,7:98
14,23,7:98
14,24,7:98
14,25,7:98
14,26,7:98
14,27,7:98
14,28,7:98
14,29,7:98
14,30,7:98
14,31,7:98
14,32,7:98
14,33,7:4
14,34,7:4
14,35,7:2
14,36,7:2
14,36,8:31.1
14,2,10:1
14,3,10:1
14,33,10:1
14,34,10:1
14,2,11:1
14,3,11:1
14,4,11:1
14,5,11:1
14,6,11:1
14,7,11:1
14,8,11:1
14,9,11:1
14,10,11:1
14,11,11:1
14,12,11:1
14,13,11:1
14,14,11:17
14,22,11:17
14,23,11:1
14,24,11:1
14,25,11:1
14,26,11:1
14,27,11:1
14,28,11:1
14,29,11:1
14,30,11:1
14,31,11:1
14,32,11:1
14,33,11:1
14,34,11:1
14,14,12:17
14,15,12:17
14,21,12:17
14,22,12:17
14,3,13:50.1
14,8,13:50.1
14,13,13:50.1
14,15,13:17
14,16,13:17
14,20,13:17
14,21,13:17
14,33,13:50.1
14,2,14:1
14,3,14:1
14,16,14:17
14,17,14:17
14,18,14:17
14,19,14:17
14,20,14:17
14,33,14:1
14,34,14:1
14,2,15:1
14,3,15:1
14,33,15:1
14,34,15:1
14,1,16:44
14,2,16:44
14,34,16:44
14,35,16:44
15,0,0:1
15,1,0:1
15,2,0:1
15,3,0:1
15,4,0:1
15,5,0:1
15,6,0:13
15,7,0:13
15,8,0:13
15,9,0:1
15,10,0:1
15,11,0:1
15,12,0:1
15,13,0:1
15,14,0:1
15,15,0:1
15,16,0:1
15,17,0:1
15,18,0:1
15,19,0:1
15,20,0:1
15,21,0:1
15,22,0:1
15,23,0:1
15,24,0:1
15,25,0:1
15,26,0:1
15,27,0:1
15,28,0:1
15,29,0:1
15,30,0:1
15,31,0:1
15,32,0:13
15,33,0:13
15,34,0:13
15,35,0:13
15,36,0:1
15,0,1:1
15,1,1:1
15,2,1:1
15,3,1:1
15,4,1:1
15,5,1:1
15,6,1:1
15,7,1:1
15,8,1:1
15,9,1:1
15,10,1:1
15,11,1:1
15,12,1:1
15,13,1:1
15,14,1:1
15,15,1:1
15,16,1:1
15,17,1:1
15,18,1:1
15,19,1:1
15,20,1:1
15,21,1:1
15,22,1:1
15,23,1:1
15,24,1:1
15,25,1:1
15,26,1:1
15,27,1:1
15,28,1:1
15,29,1:1
15,30,1:1
15,31,1:1
15,32,1:13
15,33,1:13
15,34,1:13
15,35,1:13
15,36,1:1
15,0,2:1
15,1,2:1
15,2,2:1
15,3,2:1
15,4,2:1
15,5,2:1
15,6,2:1
15,7,2:1
15,8,2:1
15,9,2:1
15,10,2:1
15,11,2:1
15,12,2:1
15,13,2:1
15,14,2:1
15,15,2:1
15,16,2:1
15,17,2:1
15,18,2:1
15,19,2:1
15,20,2:1
15,21,2:1
15,22,2:1
15,23,2:1
15,24,2:1
15,25,2:1
15,26,2:1
15,27,2:1
15,28,2:1
15,29,2:1
15,30,2:1
15,31,2:1
15,32,2:13
15,33,2:13
15,34,2:13
15,35,2:13
15,36,2:1
15,0,3:1
15,1,3:1
15,2,3:1
15,3,3:1
15,4,3:1
15,5,3:1
15,6,3:1
15,7,3:1
15,8,3:1
15,9,3:1
15,10,3:1
15,11,3:1
15,12,3:1
15,13,3:1
15,14,3:1
15,15,3:1
15,16,3:1
15,17,3:3
15,18,3:3
15,19,3:3
15,20,3:3
15,21,3:1
15,22,3:1
15,23,3:1
15,24,3:1
15,25,3:1
15,26,3:1
15,27,3:1
15,28,3:1
15,29,3:1
15,30,3:1
15,31,3:1
15,32,3:1
15,33,3:1
15,34,3:1
15,35,3:1
15,36,3:1
15,0,4:3
15,1,4:3
15,2,4:3
15,3,4:3
15,4,4:1
15,5,4:1
15,6,4:1
15,7,4:1
15,8,4:1
15,9,4:1
15,10,4:1
15,11,4:1
15,12,4:1
15,13,4:1
15,14,4:1
15,15,4:1
15,16,4:3
15,17,4:3
15,18,4:3
15,19,4:3
15,20,4:3
15,21,4:3
15,22,4:1
15,23,4:1
15,24,4:1
15,25,4:1
15,26,4:1
15,27,4:1
15,28,4:1
15,29,4:1
15,30,4:1
15,31,4:1
15,32,4:1
15,33,4:1
15,34,4:1
15,35,4:1
15,36,4:1
15,0,5:3
15,1,5:3
15,2,5:3
15,3,5:3
15,4,5:1
15,5,5:1
15,6,5:1
15,7,5:1
15,8,5:1
15,9,5:1
15,10,5:1
15,11,5:1
15,12,5:1
15,13,5:1
15,14,5:1
15,15,5:1
15,16,5:3
15,17,5:3
15,18,5:3
15,19,5:3
15,20,5:3
15,21,5:3
15,22,5:3
15,23,5:1
15,24,5:1
15,25,5:1
15,26,5:1
15,27,5:1
15,28,5:1
15,29,5:1
15,30,5:1
15,31,5:1
15,32,5:1
15,33,5:1
15,34,5:1
15,35,5:1
15,36,5:1
15,0,6:3
15,1,6:3
15,2,6:3
15,3,6:3
15,4,6:1
15,5,6:1
15,6,6:1
15,7,6:1
15,8,6:1
15,9,6:1
15,10,6:1
15,11,6:1
15,12,6:1
15,13,6:1
15,14,6:1
15,15,6:1
15,16,6:3
15,17,6:3
15,18,6:3
15,19,6:3
15,20,6:3
15,21,6:3
15,22,6:1
15,23,6:1
15,24,6:1
15,25,6:1
15,26,6:1
15,27,6:1
15,28,6:1
15,29,6:1
15,30,6:1
15,31,6:1
15,32,6:1
15,33,6:1
15,34,6:1
15,35,6:1
15,36,6:1
15,0,7:2
15,1,7:2
15,2,7:4
15,3,7:4
15,4,7:98
15,5,7:98
15,6,7:98
15,7,7:98
15,8,7:98
15,9,7:98
15,10,7:98
15,11,7:98
15,12,7:98
15,13,7:98
15,14,7:98
15,15,7:98
15,16,7:98
15,17,7:98
15,18,7:98
15,19,7:98
15,20,7:98
15,21,7:98
15,22,7:98
15,23,7:98
15,24,7:98
15,25,7:98
15,26,7:98
15,27,7:98
15,28,7:98
15,29,7:98
15,30,7:98
15,31,7:98
15,32,7:98
15,33,7:4
15,34,7:4
15,35,7:2
15,36,7:2
15,13,8:65.4
15,23,8:65.4
15,35,8:31.1
15,12,9:50.2
15,13,9:65.4
15,23,9:65.4
15,24,9:50.2
15,5,10:1
15,6,10:1
15,7,10:1
15,8,10:1
15,9,10:1
15,10,10:1
15,11,10:1
15,12,10:1
15,13,10:65.4
15,23,10:65.4
15,24,10:1
15,25,10:1
15,26,10:1
15,27,10:1
15,28,10:1
15,29,10:1
15,30,10:1
15,31,10:1
15,2,11:1
15,3,11:1
15,4,11:1
15,13,11:65.4
15,14,11:17
15,22,11:17
15,23,11:65.4
15,32,11:1
15,33,11:1
15,34,11:1
15,14,12:17
15,15,12:17
15,16,12:50.3
15,20,12:50.4
15,21,12:17
15,22,12:17
15,15,13:17
15,16,13:17
15,17,13:50.3
15,19,13:50.4
15,20,13:17
15,21,13:17
15,16,14:17
15,17,14:17
15,18,14:17
15,19,14:17
15,20,14:17
15,2,15:1
15,3,15:1
15,17,15:50.5
15,19,15:50.5
15,33,15:1
15,34,15:1
15,1,16:43
15,2,16:44
15,34,16:44
15,35,16:44
15,1,17:44
16,0,0:1
16,1,0:1
16,2,0:1
16,3,0:1
16,4,0:1
16,5,0:13
16,6,0:13
16,7,0:13
16,8,0:13
16,9,0:1
16,10,0:1
16,11,0:1
16,12,0:1
16,13,0:1
16,14,0:1
16,15,0:1
16,16,0:1
16,17,0:1
16,18,0:1
16,19,0:1
16,20,0:1
16,21,0:1
16,22,0:1
16,23,0:1
16,24,0:1
16,25,0:1
16,26,0:1
16,27,0:1
16,28,0:1
16,29,0:1
16,30,0:1
16,31,0:13
16,32,0:13
16,33,0:13
16,34,0:13
16,35,0:13
16,36,0:1
16,0,1:1
16,1,1:1
16,2,1:1
16,3,1:1
16,4,1:1
16,5,1:1
16,6,1:1
16,7,1:13
16,8,1:1
16,9,1:1
16,10,1:1
16,11,1:1
16,12,1:1
16,13,1:1
16,14,1:1
16,15,1:1
16,16,1:1
16,17,1:1
16,18,1:1
16,19,1:1
16,20,1:1
16,21,1:1
16,22,1:1
16,23,1:1
16,24,1:1
16,25,1:1
16,26,1:1
16,27,1:1
16,28,1:1
16,29,1:1
16,30,1:1
16,31,1:13
16,32,1:13
16,33,1:13
16,34,1:13
16,35,1:13
16,36,1:1
16,0,2:1
16,1,2:1
16,2,2:1
16,3,2:1
16,4,2:1
16,5,2:1
16,6,2:1
16,7,2:1
16,8,2:1
16,9,2:1
16,10,2:1
16,11,2:1
16,12,2:1
16,13,2:1
16,14,2:1
16,15,2:1
16,16,2:1
16,17,2:1
16,18,2:1
16,19,2:1
16,20,2:1
16,21,2:1
16,22,2:1
16,23,2:1
16,24,2:1
16,25,2:1
16,26,2:1
16,27,2:1
16,28,2:1
16,29,2:1
16,30,2:1
16,31,2:1
16,32,2:13
16,33,2:13
16,34,2:13
16,35,2:1
16,36,2:1
16,0,3:1
16,1,3:1
16,2,3:1
16,3,3:1
16,4,3:1
16,5,3:1
16,6,3:1
16,7,3:1
16,8,3:1
16,9,3:1
16,10,3:1
16,11,3:1
16,12,3:1
16,13,3:1
16,14,3:1
16,15,3:1
16,16,3:1
16,17,3:1
16,18,3:3
16,19,3:3
16,20,3:1
16,21,3:1
16,22,3:1
16,23,3:1
16,24,3:1
16,25,3:1
16,26,3:1
16,27,3:1
16,28,3:1
16,29,3:1
16,30,3:1
16,31,3:1
16,32,3:1
16,33,3:1
16,34,3:1
16,35,3:1
16,36,3:1
16,0,4:3
16,1,4:3
16,2,4:3
16,3,4:3
16,4,4:1
16,5,4:1
16,6,4:1
16,7,4:1
16,8,4:1
16,9,4:1
16,10,4:1
16,11,4:1
16,12,4:1
16,13,4:1
16,14,4:1
16,15,4:1
16,16,4:1
16,17,4:3
16,18,4:3
16,19,4:3
16,20,4:3
16,21,4:3
16,22,4:3
16,23,4:1
16,24,4:1
16,25,4:1
16,26,4:1
16,27,4:1
16,28,4:1
16,29,4:1
16,30,4:1
16,31,4:1
16,32,4:1
16,33,4:1
16,34,4:1
16,35,4:1
16,36,4:1
16,0,5:3
16,1,5:3
16,2,5:3
16,3,5:3
16,4,5:1
16,5,5:1
16,6,5:1
16,7,5:1
16,8,5:1
16,9,5:1
16,10,5:1
16,11,5:1
16,12,5:1
16,13,5:1
16,14,5:1
16,15,5:1
16,16,5:1
16,17,5:3
16,18,5:3
16,19,5:3
16,20,5:3
16,21,5:3
16,22,5:3
16,23,5:3
16,24,5:1
16,25,5:1
16,26,5:1
16,27,5:1
16,28,5:1
16,29,5:1
16,30,5:1
16,31,5:1
16,32,5:1
16,33,5:1
16,34,5:1
16,35,5:1
16,36,5:1
16,0,6:3
16,1,6:3
16,2,6:3
16,3,6:3
16,4,6:3
16,5,6:1
16,6,6:1
16,7,6:1
16,8,6:1
16,9,6:1
16,10,6:1
16,11,6:1
16,12,6:1
16,13,6:1
16,14,6:1
16,15,6:1
16,16,6:1
16,17,6:3
16,18,6:3
16,19,6:3
16,20,6:3
16,21,6:3
16,22,6:3
16,23,6:3
16,24,6:1
16,25,6:1
16,26,6:1
16,27,6:1
16,28,6:1
16,29,6:1
16,30,6:1
16,31,6:1
16,32,6:1
16,33,6:1
16,34,6:1
16,35,6:1
16,36,6:1
16,0,7:2
16,1,7:2
16,2,7:4
16,3,7:4
16,4,7:98
16,5,7:98
16,6,7:3
16,7,7:3
16,8,7:3
16,9,7:3
16,10,7:3
16,11,7:3
16,12,7:3
16,13,7:3
16,14,7:3
16,15,7:98
16,16,7:98
16,17,7:98
16,18,7:98
16,19,7:98
16,20,7:98
16,21,7:98
16,22,7:3
16,23,7:3
16,24,7:3
16,25,7:3
16,26,7:3
16,27,7:3
16,28,7:3
16,29,7:3
16,30,7:3
16,31,7:98
16,32,7:98
16,33,7:4
16,34,7:4
16,35,7:2
16,36,7:2
16,6,8:1
16,7,8:1
16,8,8:1
16,9,8:1
16,10,8:1
16,11,8:1
16,12,8:1
16,13,8:1
16,14,8:17
16,22,8:17
16,23,8:1
16,24,8:1
16,25,8:1
16,26,8:1
16,27,8:1
16,28,8:1
16,29,8:1
16,30,8:1
16,35,8:31.1
16,36,8:38
16,6,9:1
16,7,9:1
16,8,9:1
16,9,9:1
16,10,9:1
16,11,9:1
16,12,9:1
16,13,9:1
16,14,9:17
16,22,9:17
16,23,9:1
16,24,9:1
16,25,9:1
16,26,9:1
16,27,9:1
16,28,9:1
16,29,9:1
16,30,9:1
16,5,10:1
16,13,10:1
16,14,10:17
16,22,10:17
16,23,10:1
16,31,10:1
16,2,11:1
16,3,11:1
16,4,11:1
16,13,11:1
16,14,11:17
16,22,11:17
16,23,11:1
16,32,11:1
16,33,11:1
16,34,11:1
16,14,12:17
16,15,12:17
16,21,12:17
16,22,12:17
16,15,13:17
16,16,13:17
16,20,13:17
16,21,13:17
16,16,14:17
16,17,14:17
16,18,14:17
16,19,14:17
16,20,14:17
16,2,15:1
16,3,15:1
16,33,15:1
16,34,15:1
16,1,16:44
16,2,16:44
16,34,16:44
16,35,16:43
16,35,17:44
17,0,0:1
17,1,0:1
17,2,0:1
17,3,0:1
17,4,0:1
17,5,0:13
17,6,0:13
17,7,0:13
17,8,0:13
17,9,0:1
17,10,0:1
17,11,0:1
17,12,0:1
17,13,0:1
17,14,0:1
17,15,0:13
17,16,0:13
17,17,0:13
17,18,0:3
17,19,0:3
17,20,0:3
17,21,0:3
17,22,0:1
17,23,0:1
17,24,0:1
17,25,0:1
17,26,0:1
17,27,0:1
17,28,0:1
17,29,0:1
17,30,0:1
17,31,0:13
17,32,0:13
17,33,0:13
17,34,0:13
17,35,0:1
17,36,0:1
17,0,1:1
17,1,1:1
17,2,1:1
17,3,1:1
17,4,1:1
17,5,1:1
17,6,1:13
17,7,1:13
17,8,1:1
17,9,1:1
17,10,1:1
17,11,1:1
17,12,1:1
17,13,1:1
17,14,1:1
17,15,1:1
17,16,1:1
17,17,1:3
17,18,1:3
17,19,1:3
17,20,1:3
17,21,1:3
17,22,1:1
17,23,1:1
17,24,1:1
17,25,1:1
17,26,1:1
17,27,1:1
17,28,1:1
17,29,1:1
17,30,1:1
17,31,1:13
17,32,1:13
17,33,1:13
17,34,1:13
17,35,1:1
17,36,1:1
17,0,2:1
17,1,2:1
17,2,2:1
17,3,2:1
17,4,2:1
17,5,2:1
17,6,2:1
17,7,2:1
17,8,2:1
17,9,2:1
17,10,2:1
17,11,2:1
17,12,2:1
17,13,2:1
17,14,2:1
17,15,2:1
17,16,2:1
17,17,2:1
17,18,2:1
17,19,2:1
17,20,2:1
17,21,2:1
17,22,2:1
17,23,2:1
17,24,2:1
17,25,2:1
17,26,2:1
17,27,2:1
17,28,2:1
17,29,2:1
17,30,2:15
17,31,2:15
17,32,2:13
17,33,2:13
17,34,2:13
17,35,2:1
17,36,2:1
17,0,3:1
17,1,3:1
17,2,3:1
17,3,3:1
17,4,3:1
17,5,3:1
17,6,3:1
17,7,3:1
17,8,3:1
17,9,3:1
17,10,3:1
17,11,3:1
17,12,3:1
17,13,3:1
17,14,3:1
17,15,3:1
17,16,3:1
17,17,3:1
17,18,3:1
17,19,3:1
17,20,3:1
17,21,3:1
17,22,3:1
17,23,3:1
17,24,3:1
17,25,3:1
17,26,3:1
17,27,3:1
17,28,3:1
17,29,3:1
17,30,3:15
17,31,3:15
17,32,3:1
17,33,3:1
17,34,3:1
17,35,3:1
17,36,3:1
17,0,4:3
17,1,4:3
17,2,4:3
17,3,4:3
17,4,4:1
17,5,4:1
17,6,4:1
17,7,4:1
17,8,4:1
17,9,4:1
17,10,4:1
17,11,4:1
17,12,4:1
17,13,4:1
17,14,4:1
17,15,4:1
17,16,4:1
17,17,4:1
17,18,4:3
17,19,4:3
17,20,4:3
17,21,4:3
17,22,4:3
17,23,4:3
17,24,4:1
17,25,4:1
17,26,4:1
17,27,4:1
17,28,4:1
17,29,4:1
17,30,4:1
17,31,4:1
17,32,4:1
17,33,4:1
17,34,4:1
17,35,4:1
17,36,4:1
17,0,5:3
17,1,5:3
17,2,5:3
17,3,5:3
17,4,5:3
17,5,5:1
17,6,5:1
17,7,5:1
17,8,5:1
17,9,5:1
17,10,5:1
17,11,5:1
17,12,5:1
17,13,5:1
17,14,5:1
17,15,5:1
17,16,5:1
17,17,5:1
17,18,5:3
17,19,5:3
17,20,5:3
17,21,5:3
17,22,5:3
17,23,5:3
17,24,5:3
17,25,5:1
17,26,5:1
17,27,5:1
17,28,5:1
17,29,5:1
17,30,5:1
17,31,5:1
17,32,5:1
17,33,5:1
17,34,5:1
17,35,5:1
17,36,5:1
17,0,6:3
17,1,6:3
17,2,6:3
17,3,6:3
17,4,6:3
17,5,6:1
17,6,6:1
17,7,6:1
17,10,6:1
17,11,6:1
17,12,6:1
17,13,6:1
17,14,6:1
17,15,6:1
17,16,6:1
17,17,6:1
17,18,6:3
17,19,6:3
17,20,6:3
17,21,6:3
17,22,6:3
17,23,6:3
17,24,6:3
17,25,6:1
17,26,6:1
17,27,6:1
17,28,6:1
17,29,6:1
17,30,6:1
17,31,6:1
17,32,6:1
17,33,6:1
17,34,6:1
17,35,6:1
17,36,6:1
17,0,7:2
17,1,7:2
17,2,7:4
17,3,7:4
17,4,7:98
17,5,7:98
17,6,7:3
17,7,7:4
17,8,7:4
17,9,7:4
17,10,7:4
17,11,7:4
17,12,7:4
17,13,7:4
17,14,7:4
17,15,7:98
17,16,7:98
17,17,7:98
17,18,7:98
17,19,7:98
17,20,7:98
17,21,7:98
17,22,7:4
17,23,7:4
17,24,7:4
17,25,7:4
17,26,7:4
17,27,7:4
17,28,7:4
17,29,7:4
17,30,7:3
17,31,7:98
17,32,7:98
17,33,7:4
17,34,7:4
17,35,7:2
17,36,7:2
17,1,8:31.1
17,6,8:1
17,30,8:1
17,35,8:31.1
17,36,8:31.1
17,6,9:1
17,7,9:50.3
17,8,9:50.1
17,10,9:50.1
17,12,9:50.1
17,24,9:50.1
17,26,9:50.1
17,28,9:50.1
17,29,9:50.4
17,30,9:1
17,2,10:1
17,3,10:1
17,5,10:1
17,14,10:50.1
17,22,10:50.1
17,31,10:1
17,33,10:1
17,34,10:1
17,2,11:1
17,3,11:1
17,4,11:1
17,32,11:1
17,33,11:1
17,34,11:1
17,2,14:1
17,3,14:1
17,33,14:1
17,34,14:1
17,2,15:1
17,3,15:1
17,33,15:1
17,34,15:1
17,1,16:44
17,2,16:44
17,34,16:44
17,35,16:44
18,0,0:1
18,1,0:1
18,2,0:1
18,3,0:1
18,4,0:1
18,5,0:13
18,6,0:13
18,7,0:13
18,8,0:13
18,9,0:1
18,10,0:1
18,11,0:1
18,12,0:13
18,13,0:13
18,14,0:13
18,15,0:13
18,16,0:13
18,17,0:13
18,18,0:13
18,19,0:3
18,20,0:3
18,21,0:3
18,22,0:1
18,23,0:1
18,24,0:1
18,25,0:1
18,26,0:1
18,27,0:1
18,28,0:1
18,29,0:1
18,30,0:1
18,31,0:13
18,32,0:13
18,33,0:13
18,34,0:13
18,35,0:1
18,36,0:1
18,0,1:1
18,1,1:1
18,2,1:1
18,3,1:1
18,4,1:1
18,5,1:1
18,6,1:13
18,7,1:13
18,8,1:1
18,9,1:1
18,10,1:1
18,11,1:1
18,12,1:1
18,13,1:13
18,14,1:13
18,15,1:13
18,16,1:13
18,17,1:13
18,18,1:3
18,19,1:3
18,20,1:3
18,21,1:3
18,22,1:1
18,23,1:1
18,24,1:1
18,25,1:1
18,26,1:1
18,27,1:1
18,28,1:1
18,29,1:1
18,30,1:1
18,31,1:13
18,32,1:13
18,33,1:13
18,34,1:13
18,35,1:1
18,36,1:1
18,0,2:1
18,1,2:1
18,2,2:1
18,3,2:1
18,4,2:1
18,5,2:1
18,6,2:1
18,7,2:1
18,8,2:1
18,9,2:1
18,10,2:1
18,11,2:1
18,12,2:1
18,13,2:1
18,14,2:1
18,15,2:1
18,16,2:3
18,17,2:3
18,18,2:3
18,19,2:3
18,20,2:1
18,21,2:1
18,22,2:1
18,23,2:1
18,24,2:1
18,25,2:1
18,26,2:1
18,27,2:1
18,28,2:1
18,29,2:1
18,30,2:1
18,31,2:1
18,32,2:13
18,33,2:13
18,34,2:1
18,35,2:1
18,36,2:1
18,0,3:1
18,1,3:1
18,2,3:1
18,3,3:3
18,4,3:1
18,5,3:1
18,6,3:1
18,7,3:1
18,8,3:1
18,9,3:1
18,10,3:1
18,11,3:1
18,12,3:1
18,13,3:1
18,14,3:1
18,15,3:1
18,16,3:1
18,17,3:1
18,18,3:1
18,19,3:1
18,20,3:1
18,21,3:1
18,22,3:1
18,23,3:1
18,24,3:1
18,25,3:1
18,26,3:1
18,27,3:1
18,28,3:1
18,29,3:1
18,30,3:1
18,31,3:1
18,32,3:1
18,33,3:1
18,34,3:1
18,35,3:1
18,36,3:1
18,0,4:3
18,1,4:3
18,2,4:3
18,3,4:3
18,4,4:3
18,5,4:1
18,6,4:1
18,7,4:1
18,8,4:1
18,9,4:1
18,10,4:1
18,11,4:1
18,12,4:1
18,13,4:1
18,14,4:1
18,15,4:1
18,16,4:1
18,17,4:1
18,18,4:1
18,19,4:1
18,20,4:1
18,21,4:1
18,22,4:1
18,23,4:1
18,24,4:1
18,25,4:1
18,26,4:1
18,27,4:1
18,28,4:1
18,29,4:1
18,30,4:1
18,31,4:1
18,32,4:1
18,33,4:1
18,34,4:1
18,35,4:1
18,36,4:1
18,0,5:3
18,1,5:3
18,2,5:3
18,3,5:3
18,4,5:3
18,5,5:1
18,6,5:1
18,7,5:1
18,8,5:1
18,9,5:1
18,10,5:1
18,11,5:1
18,12,5:1
18,13,5:1
18,14,5:1
18,15,5:1
18,16,5:1
18,17,5:1
18,18,5:1
18,19,5:1
18,20,5:1
18,21,5:1
18,22,5:3
18,23,5:3
18,24,5:1
18,25,5:1
18,26,5:1
18,27,5:1
18,28,5:1
18,29,5:1
18,30,5:1
18,31,5:1
18,32,5:1
18,33,5:1
18,34,5:1
18,35,5:1
18,36,5:1
18,0,6:3
18,1,6:3
18,2,6:3
18,3,6:3
18,4,6:3
18,5,6:3
18,6,6:1
18,7,6:1
18,9,6:1
18,10,6:1
18,11,6:1
18,12,6:1
18,13,6:1
18,14,6:1
18,15,6:1
18,16,6:1
18,17,6:1
18,18,6:1
18,19,6:1
18,20,6:1
18,21,6:1
18,22,6:3
18,23,6:3
18,24,6:1
18,25,6:1
18,26,6:1
18,27,6:1
18,28,6:1
18,29,6:1
18,30,6:1
18,31,6:1
18,32,6:1
18,33,6:1
18,34,6:1
18,35,6:1
18,36,6:1
18,0,7:2
18,1,7:2
18,2,7:4
18,3,7:4
18,4,7:98
18,5,7:98
18,6,7:3
18,7,7:4
18,8,7:4
18,9,7:4
18,10,7:4
18,11,7:4
18,12,7:4
18,13,7:4
18,14,7:4
18,15,7:98
18,16,7:98
18,17,7:98
18,18,7:98
18,19,7:98
18,20,7:98
18,21,7:98
18,22,7:4
18,23,7:4
18,24,7:4
18,25,7:4
18,26,7:4
18,27,7:4
18,28,7:4
18,29,7:4
18,30,7:3
18,31,7:98
18,32,7:98
18,33,7:3
18,34,7:3
18,35,7:2
18,36,7:2
18,1,8:38
18,2,8:1
18,3,8:1
18,6,8:1
18,30,8:1
18,33,8:1
18,34,8:1
18,36,8:31.1
18,1,9:50.4
18,2,9:1
18,3,9:1
18,6,9:1
18,30,9:1
18,33,9:1
18,34,9:1
18,35,9:50.3
18,2,10:1
18,3,10:1
18,5,10:1
18,31,10:1
18,33,10:1
18,34,10:1
18,2,11:1
18,3,11:1
18,4,11:1
18,32,11:1
18,33,11:1
18,34,11:1
18,2,12:1
18,3,12:1
18,33,12:1
18,34,12:1
18,1,13:50.4
18,2,13:1
18,3,13:1
18,4,13:50.3
18,32,13:50.4
18,33,13:1
18,34,13:1
18,35,13:50.3
18,2,14:1
18,3,14:1
18,33,14:1
18,34,14:1
18,2,15:1
18,3,15:1
18,33,15:1
18,34,15:1
18,1,16:43
18,2,16:44
18,34,16:44
18,35,16:44
18,1,17:44
19,0,0:1
19,1,0:1
19,2,0:1
19,3,0:1
19,4,0:1
19,5,0:13
19,6,0:13
19,7,0:13
19,8,0:1
19,9,0:1
19,10,0:1
19,11,0:13
19,12,0:13
19,13,0:13
19,14,0:13
19,15,0:13
19,16,0:13
19,17,0:13
19,18,0:13
19,19,0:3
19,20,0:3
19,21,0:1
19,22,0:1
19,23,0:1
19,24,0:1
19,25,0:1
19,26,0:1
19,27,0:1
19,28,0:1
19,29,0:1
19,30,0:1
19,31,0:1
19,32,0:13
19,33,0:13
19,34,0:1
19,35,0:1
19,36,0:1
19,0,1:1
19,1,1:1
19,2,1:1
19,3,1:1
19,4,1:1
19,5,1:1
19,6,1:1
19,7,1:1
19,8,1:1
19,9,1:1
19,10,1:1
19,11,1:1
19,12,1:13
19,13,1:13
19,14,1:13
19,15,1:13
19,16,1:13
19,17,1:13
19,18,1:3
19,19,1:3
19,20,1:3
19,21,1:1
19,22,1:1
19,23,1:1
19,24,1:1
19,25,1:1
19,26,1:1
19,27,1:1
19,28,1:1
19,29,1:1
19,30,1:1
19,31,1:1
19,32,1:13
19,33,1:13
19,34,1:1
19,35,1:1
19,36,1:1
19,0,2:1
19,1,2:1
19,2,2:1
19,3,2:1
19,4,2:1
19,5,2:1
19,6,2:1
19,7,2:1
19,8,2:1
19,9,2:1
19,10,2:1
19,11,2:1
19,12,2:1
19,13,2:1
19,14,2:1
19,15,2:1
19,16,2:1
19,17,2:1
19,18,2:1
19,19,2:1
19,20,2:1
19,21,2:1
19,22,2:1
19,23,2:1
19,24,2:1
19,25,2:1
19,26,2:1
19,27,2:1
19,28,2:1
19,29,2:1
19,30,2:1
19,31,2:1
19,32,2:1
19,33,2:1
19,34,2:1
19,35,2:1
19,36,2:1
19,0,3:1
19,1,3:1
19,2,3:1
19,3,3:3
19,4,3:1
19,5,3:1
19,6,3:1
19,7,3:1
19,8,3:1
19,9,3:1
19,10,3:1
19,11,3:1
19,12,3:1
19,13,3:1
19,14,3:1
19,15,3:1
19,16,3:1
19,17,3:1
19,18,3:1
19,19,3:1
19,20,3:1
19,21,3:1
19,22,3:1
19,23,3:1
19,24,3:1
19,25,3:1
19,26,3:1
19,27,3:1
19,28,3:1
19,29,3:1
19,30,3:1
19,31,3:1
19,32,3:1
19,33,3:1
19,34,3:1
19,35,3:1
19,36,3:1
19,0,4:3
19,1,4:3
19,2,4:3
19,3,4:3
19,4,4:3
19,5,4:1
19,6,4:1
19,7,4:1
19,8,4:1
19,9,4:1
19,10,4:1
19,11,4:1
19,12,4:1
19,13,4:1
19,14,4:1
19,15,4:1
19,16,4:1
19,17,4:1
19,18,4:1
19,19,4:1
19,20,4:1
19,21,4:1
19,22,4:1
19,23,4:1
19,24,4:1
19,25,4:1
19,26,4:1
19,27,4:1
19,28,4:1
19,29,4:1
19,30,4:1
19,31,4:1
19,32,4:1
19,33,4:1
19,34,4:1
19,35,4:1
19,36,4:1
19,0,5:3
19,1,5:3
19,2,5:3
19,3,5:3
19,4,5:3
19,5,5:3
19,6,5:1
19,7,5:1
19,8,5:1
19,9,5:1
19,10,5:1
19,11,5:1
19,12,5:1
19,13,5:1
19,14,5:1
19,15,5:1
19,16,5:1
19,17,5:1
19,18,5:1
19,19,5:1
19,20,5:1
19,21,5:1
19,22,5:1
19,23,5:1
19,24,5:1
19,25,5:1
19,26,5:1
19,27,5:1
19,28,5:1
19,29,5:1
19,30,5:1
19,31,5:1
19,32,5:1
19,33,5:1
19,34,5:1
19,35,5:1
19,36,5:1
19,0,6:3
19,1,6:3
19,2,6:3
19,3,6:3
19,4,6:3
19,5,6:3
19,6,6:1
19,7,6:1
19,8,6:1
19,9,6:1
19,10,6:1
19,11,6:1
19,12,6:1
19,13,6:1
19,14,6:1
19,15,6:1
19,16,6:1
19,17,6:1
19,18,6:1
19,19,6:1
19,20,6:1
19,21,6:1
19,22,6:1
19,23,6:1
19,24,6:1
19,25,6:1
19,26,6:1
19,27,6:1
19,28,6:1
19,29,6:1
19,30,6:1
19,31,6:1
19,32,6:1
19,33,6:1
19,34,6:1
19,35,6:1
19,36,6:1
19,0,7:2
19,1,7:2
19,2,7:4
19,3,7:4
19,4,7:98
19,5,7:98
19,6,7:3
19,7,7:4
19,8,7:4
19,9,7:4
19,10,7:4
19,11,7:4
19,12,7:4
19,13,7:4
19,14,7:4
19,15,7:4
19,16,7:4
19,17,7:4
19,18,7:4
19,19,7:4
19,20,7:4
19,21,7:4
19,22,7:4
19,23,7:4
19,24,7:4
19,25,7:4
19,26,7:4
19,27,7:4
19,28,7:4
19,29,7:4
19,30,7:3
19,31,7:98
19,32,7:98
19,33,7:4
19,34,7:4
19,35,7:2
19,36,7:2
19,1,8:31.1
19,6,8:1
19,30,8:1
19,6,9:1
19,7,9:50.3
19,29,9:50.4
19,30,9:1
19,2,10:1
19,3,10:1
19,5,10:1
19,31,10:1
19,33,10:1
19,34,10:1
19,2,11:1
19,3,11:1
19,4,11:1
19,32,11:1
19,33,11:1
19,34,11:1
19,2,14:1
19,3,14:1
19,33,14:1
19,34,14:1
19,2,15:1
19,3,15:1
19,33,15:1
19,34,15:1
19,1,16:44
19,2,16:44
19,34,16:44
19,35,16:43
19,35,17:44
20,0,0:1
20,1,0:1
20,2,0:1
20,3,0:1
20,4,0:1
20,5,0:13
20,6,0:13
20,7,0:13
20,8,0:1
20,9,0:13
20,10,0:13
20,11,0:13
20,12,0:13
20,13,0:13
20,14,0:13
20,15,0:13
20,16,0:13
20,17,0:13
20,18,0:3
20,19,0:3
20,20,0:1
20,21,0:1
20,22,0:1
20,23,0:1
20,24,0:1
20,25,0:1
20,26,0:1
20,27,0:1
20,28,0:1
20,29,0:1
20,30,0:1
20,31,0:1
20,32,0:1
20,33,0:1
20,34,0:1
20,35,0:1
20,36,0:1
20,0,1:1
20,1,1:1
20,2,1:1
20,3,1:1
20,4,1:1
20,5,1:1
20,6,1:13
20,7,1:1
20,8,1:1
20,9,1:1
20,10,1:1
20,11,1:1
20,12,1:1
20,13,1:1
20,14,1:1
20,15,1:1
20,16,1:1
20,17,1:1
20,18,1:1
20,19,1:1
20,20,1:1
20,21,1:1
20,22,1:1
20,23,1:1
20,24,1:1
20,25,1:1
20,26,1:1
20,27,1:1
20,28,1:1
20,29,1:1
20,30,1:1
20,31,1:1
20,32,1:1
20,33,1:1
20,34,1:1
20,35,1:1
20,36,1:1
20,0,2:1
20,1,2:1
20,2,2:1
20,3,2:1
20,4,2:1
20,5,2:1
20,6,2:1
20,7,2:1
20,8,2:9
20,9,2:9
20,10,2:9
20,11,2:9
20,12,2:9
20,13,2:9
20,14,2:9
20,15,2:9
20,16,2:9
20,17,2:9
20,18,2:9
20,19,2:9
20,20,2:9
20,21,2:9
20,22,2:9
20,23,2:9
20,24,2:9
20,25,2:9
20,26,2:9
20,27,2:9
20,28,2:9
20,29,2:1
20,30,2:1
20,31,2:1
20,32,2:1
20,33,2:1
20,34,2:1
20,35,2:1
20,36,2:1
20,0,3:1
20,1,3:1
20,2,3:1
20,3,3:3
20,4,3:1
20,5,3:1
20,6,3:1
20,7,3:1
20,8,3:9
20,9,3:9
20,10,3:9.8
20,11,3:9
20,12,3:9.8
20,13,3:9
20,14,3:9.8
20,15,3:9.8
20,16,3:9.8
20,17,3:9.8
20,18,3:9.8
20,19,3:9.8
20,20,3:9.8
20,21,3:9.8
20,22,3:9.8
20,23,3:9.8
20,24,3:9
20,25,3:9
20,26,3:9
20,27,3:9
20,28,3:9
20,29,3:1
20,30,3:1
20,31,3:1
20,32,3:1
20,33,3:1
20,34,3:1
20,35,3:1
20,36,3:1
20,0,4:3
20,1,4:3
20,2,4:3
20,3,4:3
20,4,4:3
20,5,4:1
20,6,4:1
20,7,4:1
20,8,4:9
20,9,4:9
20,10,4:9
20,11,4:9
20,12,4:9
20,13,4:9
20,14,4:9
20,15,4:9
20,16,4:9
20,17,4:9
20,18,4:9
20,19,4:9
20,20,4:9
20,21,4:9
20,22,4:9
20,23,4:9
20,24,4:9
20,25,4:9
20,26,4:9
20,27,4:9
20,28,4:9
20,29,4:1
20,30,4:1
20,31,4:1
20,32,4:1
20,33,4:1
20,34,4:1
20,35,4:1
20,36,4:1
20,0,5:3
20,1,5:3
20,2,5:3
20,3,5:3
20,4,5:3
20,5,5:3
20,6,5:1
20,7,5:1
20,8,5:9
20,9,5:9
20,10,5:9
20,11,5:9
20,12,5:9
20,13,5:9
20,14,5:9
20,15,5:9
20,16,5:9
20,17,5:9
20,18,5:9
20,19,5:9
20,20,5:9
20,21,5:9
20,22,5:9
20,23,5:9
20,24,5:9
20,25,5:9
20,26,5:9
20,27,5:9
20,28,5:9
20,29,5:1
20,30,5:1
20,31,5:1
20,32,5:1
20,33,5:1
20,34,5:1
20,35,5:1
20,36,5:1
20,0,6:3
20,1,6:3
20,2,6:3
20,3,6:3
20,4,6:3
20,5,6:3
20,6,6:3
20,7,6:1
20,15,6:65.5
20,16,6:65.5
20,17,6:65.5
20,19,6:65.5
20,20,6:65.5
20,21,6:65.5
20,29,6:1
20,30,6:1
20,31,6:1
20,32,6:1
20,33,6:1
20,34,6:1
20,35,6:1
20,36,6:3
20,0,7:2
20,1,7:2
20,2,7:4
20,3,7:4
20,4,7:98
20,5,7:98
20,6,7:3
20,7,7:4
20,15,7:65.5
20,16,7:65.5
20,17,7:65.5
20,18,7:17
20,19,7:65.5
20,20,7:65.5
20,21,7:65.5
20,29,7:4
20,30,7:3
20,31,7:98
20,32,7:98
20,33,7:4
20,34,7:4
20,35,7:2
20,36,7:2
20,1,8:31.1
20,6,8:1
20,30,8:1
20,35,8:31.1
20,36,8:31.1
20,6,9:1
20,30,9:1
20,5,10:1
20,31,10:1
20,2,11:1
20,3,11:1
20,4,11:1
20,32,11:1
20,33,11:1
20,34,11:1
20,2,15:1
20,3,15:1
20,33,15:1
20,34,15:1
20,1,16:44
20,2,16:44
20,34,16:44
20,35,16:44
21,0,0:1
21,1,0:1
21,2,0:1
21,3,0:1
21,4,0:1
21,5,0:13
21,6,0:13
21,7,0:13
21,8,0:1
21,9,0:13
21,10,0:13
21,11,0:13
21,12,0:13
21,13,0:13
21,14,0:13
21,15,0:13
21,16,0:3
21,17,0:3
21,18,0:3
21,19,0:1
21,20,0:1
21,21,0:1
21,22,0:1
21,23,0:1
21,24,0:1
21,25,0:1
21,26,0:1
21,27,0:1
21,28,0:1
21,29,0:1
21,30,0:1
21,31,0:1
21,32,0:1
21,33,0:1
21,34,0:1
21,35,0:1
21,36,0:1
21,0,1:1
21,1,1:1
21,2,1:1
21,3,1:1
21,4,1:1
21,5,1:1
21,6,1:1
21,7,1:1
21,8,1:1
21,9,1:1
21,10,1:1
21,11,1:1
21,12,1:1
21,13,1:1
21,14,1:1
21,15,1:1
21,16,1:1
21,17,1:1
21,18,1:1
21,19,1:1
21,20,1:1
21,21,1:1
21,22,1:1
21,23,1:1
21,24,1:1
21,25,1:1
21,26,1:1
21,27,1:1
21,28,1:1
21,29,1:1
21,30,1:1
21,31,1:1
21,32,1:1
21,33,1:1
21,34,1:1
21,35,1:1
21,36,1:1
21,0,2:1
21,1,2:1
21,2,2:1
21,3,2:1
21,4,2:1
21,5,2:1
21,6,2:1
21,7,2:1
21,8,2:9
21,9,2:9
21,10,2:9
21,11,2:9
21,12,2:9
21,13,2:9
21,14,2:9
21,15,2:9
21,16,2:9
21,17,2:9
21,18,2:9
21,19,2:9
21,20,2:9
21,21,2:9
21,22,2:9
21,23,2:9
21,24,2:9
21,25,2:9
21,26,2:9
21,27,2:9
21,28,2:9
21,29,2:1
21,30,2:1
21,31,2:1
21,32,2:1
21,33,2:1
21,34,2:1
21,35,2:1
21,36,2:1
21,0,3:1
21,1,3:1
21,2,3:1
21,3,3:3
21,4,3:1
21,5,3:1
21,6,3:1
21,7,3:1
21,8,3:9
21,9,3:9
21,10,3:9
21,11,3:9
21,12,3:9
21,13,3:9
21,14,3:9
21,15,3:9
21,16,3:9
21,17,3:9
21,18,3:9
21,19,3:9
21,20,3:9
21,21,3:9
21,22,3:9
21,23,3:9
21,24,3:9
21,25,3:9
21,26,3:9
21,27,3:9
21,28,3:9
21,29,3:1
21,30,3:1
21,31,3:1
21,32,3:1
21,33,3:1
21,34,3:1
21,35,3:1
21,36,3:1
21,0,4:3
21,1,4:3
21,2,4:3
21,3,4:3
21,4,4:3
21,5,4:3
21,6,4:1
21,7,4:1
21,8,4:9
21,9,4:9
21,10,4:9
21,11,4:9
21,12,4:9
21,13,4:9
21,14,4:9
21,15,4:9
21,16,4:9
21,17,4:9
21,18,4:9
21,19,4:9
21,20,4:9
21,21,4:9
21,22,4:9
21,23,4:9
21,24,4:9
21,25,4:9
21,26,4:9
21,27,4:9
21,28,4:9
21,29,4:1
21,30,4:1
21,31,4:1
21,32,4:1
21,33,4:1
21,34,4:1
21,35,4:1
21,36,4:1
21,0,5:3
21,1,5:3
21,2,5:3
21,3,5:3
21,4,5:3
21,5,5:3
21,6,5:3
21,7,5:1
21,8,5:9
21,9,5:9
21,10,5:9
21,11,5:9
21,12,5:9
21,13,5:9
21,14,5:9
21,15,5:9
21,16,5:9
21,17,5:9
21,18,5:9
21,19,5:9
21,20,5:9
21,21,5:9
21,22,5:9
21,23,5:9
21,24,5:9
21,25,5:9
21,26,5:9
21,27,5:9
21,28,5:9
21,29,5:1
21,30,5:1
21,31,5:1
21,32,5:1
21,33,5:1
21,34,5:1
21,35,5:1
21,36,5:1
21,0,6:3
21,1,6:3
21,2,6:3
21,3,6:3
21,4,6:3
21,5,6:3
21,6,6:3
21,7,6:1
21,29,6:1
21,30,6:1
21,31,6:1
21,32,6:1
21,33,6:1
21,34,6:1
21,35,6:1
21,36,6:3
21,0,7:2
21,1,7:2
21,2,7:4
21,3,7:4
21,4,7:98
21,5,7:98
21,6,7:3
21,7,7:4
21,18,7:17
21,29,7:4
21,30,7:3
21,31,7:98
21,32,7:98
21,33,7:4
21,34,7:4
21,35,7:2
21,36,7:2
21,1,8:31.1
21,6,8:1
21,30,8:1
21,35,8:31.1
21,36,8:31.1
21,6,9:1
21,7,9:50.3
21,29,9:50.4
21,30,9:1
21,5,10:1
21,31,10:1
21,2,11:1
21,3,11:1
21,4,11:1
21,32,11:1
21,33,11:1
21,34,11:1
21,2,15:1
21,3,15:1
21,33,15:1
21,34,15:1
21,1,16:43
21,2,16:44
21,34,16:44
21,35,16:44
21,1,17:44
22,0,0:1
22,1,0:1
22,2,0:1
22,3,0:1
22,4,0:1
22,5,0:13
22,6,0:13
22,7,0:1
22,8,0:1
22,9,0:13
22,10,0:13
22,11,0:1
22,12,0:1
22,13,0:3
22,14,0:3
22,15,0:3
22,16,0:3
22,17,0:1
22,18,0:1
22,19,0:1
22,20,0:1
22,21,0:1
22,22,0:1
22,23,0:1
22,24,0:1
22,25,0:1
22,26,0:1
22,27,0:1
22,28,0:1
22,29,0:1
22,30,0:1
22,31,0:1
22,32,0:1
22,33,0:1
22,34,0:1
22,35,0:1
22,36,0:1
22,0,1:1
22,1,1:1
22,2,1:1
22,3,1:1
22,4,1:1
22,5,1:1
22,6,1:1
22,7,1:1
22,8,1:1
22,9,1:1
22,10,1:1
22,11,1:1
22,12,1:1
22,13,1:1
22,14,1:1
22,15,1:1
22,16,1:1
22,17,1:1
22,18,1:1
22,19,1:1
22,20,1:1
22,21,1:1
22,22,1:1
22,23,1:1
22,24,1:1
22,25,1:1
22,26,1:1
22,27,1:1
22,28,1:1
22,29,1:1
22,30,1:1
22,31,1:1
22,32,1:1
22,33,1:1
22,34,1:1
22,35,1:1
22,36,1:1
22,0,2:1
22,1,2:1
22,2,2:1
22,3,2:1
22,4,2:1
22,5,2:1
22,6,2:1
22,7,2:1
22,8,2:9
22,9,2:9
22,10,2:9
22,11,2:9
22,12,2:9
22,13,2:9
22,14,2:9
22,15,2:9
22,16,2:9
22,17,2:9
22,18,2:9
22,19,2:9
22,20,2:9
22,21,2:9
22,22,2:9
22,23,2:9
22,24,2:9
22,25,2:9
22,26,2:9
22,27,2:9
22,28,2:9
22,29,2:1
22,30,2:1
22,31,2:1
22,32,2:1
22,33,2:1
22,34,2:1
22,35,2:1
22,36,2:1
22,0,3:1
22,1,3:1
22,2,3:1
22,3,3:3
22,4,3:1
22,5,3:1
22,6,3:1
22,7,3:1
22,8,3:9
22,9,3:9
22,10,3:9
22,11,3:9
22,12,3:9
22,13,3:9
22,14,3:9
22,15,3:9
22,16,3:9
22,17,3:9
22,18,3:9
22,19,3:9
22,20,3:9
22,21,3:9
22,22,3:9
22,23,3:9
22,24,3:9
22,25,3:9
22,26,3:9
22,27,3:9
22,28,3:9
22,29,3:1
22,30,3:1
22,31,3:1
22,32,3:1
22,33,3:1
22,34,3:1
22,35,3:1
22,36,3:1
22,0,4:3
22,1,4:3
22,2,4:3
22,3,4:3
22,4,4:3
22,5,4:3
22,6,4:3
22,7,4:1
22,8,4:9
22,9,4:9
22,10,4:9
22,11,4:9
22,12,4:9
22,13,4:9
22,14,4:9
22,15,4:9
22,16,4:9
22,17,4:9
22,18,4:9
22,19,4:9
22,20,4:9
22,21,4:9
22,22,4:9
22,23,4:9
22,24,4:9
22,25,4:9
22,26,4:9
22,27,4:9
22,28,4:9
22,29,4:1
22,30,4:1
22,31,4:1
22,32,4:1
22,33,4:1
22,34,4:1
22,35,4:1
22,36,4:1
22,0,5:3
22,1,5:3
22,2,5:3
22,3,5:3
22,4,5:3
22,5,5:3
22,6,5:3
22,7,5:1
22,8,5:9
22,9,5:9
22,10,5:9
22,11,5:9
22,12,5:9
22,13,5:9
22,14,5:9
22,15,5:9
22,16,5:9
22,17,5:9
22,18,5:9
22,19,5:9
22,20,5:9
22,21,5:9
22,22,5:9
22,23,5:9
22,24,5:9
22,25,5:9
22,26,5:9
22,27,5:9
22,28,5:9
22,29,5:1
22,30,5:1
22,31,5:1
22,32,5:1
22,33,5:1
22,34,5:1
22,35,5:1
22,36,5:1
22,0,6:3
22,1,6:3
22,2,6:3
22,3,6:3
22,4,6:3
22,5,6:3
22,6,6:3
22,7,6:1
22,29,6:1
22,30,6:1
22,31,6:1
22,32,6:1
22,33,6:1
22,34,6:1
22,35,6:3
22,36,6:3
22,0,7:2
22,1,7:2
22,2,7:4
22,3,7:4
22,4,7:98
22,5,7:98
22,6,7:3
22,7,7:4
22,29,7:4
22,30,7:3
22,31,7:98
22,32,7:98
22,33,7:4
22,34,7:4
22,35,7:2
22,36,7:2
22,1,8:31.1
22,6,8:1
22,30,8:1
22,35,8:31.1
22,36,8:31.1
22,6,9:1
22,30,9:1
22,2,10:1
22,3,10:1
22,5,10:1
22,31,10:1
22,33,10:1
22,34,10:1
22,2,11:1
22,3,11:1
22,4,11:1
22,32,11:1
22,33,11:1
22,34,11:1
22,2,14:1
22,3,14:1
22,33,14:1
22,34,14:1
22,2,15:1
22,3,15:1
22,33,15:1
22,34,15:1
22,1,16:44
22,2,16:44
22,34,16:44
22,35,16:43
22,35,17:44
23,0,0:1
23,1,0:1
23,2,0:1
23,3,0:1
23,4,0:1
23,5,0:1
23,6,0:1
23,7,0:1
23,8,0:1
23,9,0:1
23,10,0:1
23,11,0:1
23,12,0:1
23,13,0:1
23,14,0:1
23,15,0:1
23,16,0:1
23,17,0:1
23,18,0:1
23,19,0:1
23,20,0:1
23,21,0:1
23,22,0:1
23,23,0:1
23,24,0:1
23,25,0:1
23,26,0:1
23,27,0:1
23,28,0:1
23,29,0:1
23,30,0:1
23,31,0:1
23,32,0:1
23,33,0:1
23,34,0:1
23,35,0:1
23,36,0:1
23,0,1:1
23,1,1:1
23,2,1:1
23,3,1:1
23,4,1:1
23,5,1:1
23,6,1:1
23,7,1:1
23,8,1:1
23,9,1:1
23,10,1:1
23,11,1:1
23,12,1:1
23,13,1:1
23,14,1:1
23,15,1:1
23,16,1:1
23,17,1:1
23,18,1:1
23,19,1:1
23,20,1:1
23,21,1:1
23,22,1:1
23,23,1:1
23,24,1:1
23,25,1:1
23,26,1:1
23,27,1:1
23,28,1:1
23,29,1:1
23,30,1:1
23,31,1:1
23,32,1:1
23,33,1:1
23,34,1:1
23,35,1:1
23,36,1:1
23,0,2:1
23,1,2:1
23,2,2:1
23,3,2:1
23,4,2:1
23,5,2:1
23,6,2:1
23,7,2:1
23,8,2:9
23,9,2:9
23,10,2:9
23,11,2:9
23,12,2:9
23,13,2:9
23,14,2:9
23,15,2:9
23,16,2:9
23,17,2:9
23,18,2:9
23,19,2:9
23,20,2:9
23,21,2:9
23,22,2:9
23,23,2:9
23,24,2:9
23,25,2:9
23,26,2:9
23,27,2:9
23,28,2:9
23,29,2:1
23,30,2:1
23,31,2:1
23,32,2:1
23,33,2:1
23,34,2:1
23,35,2:1
23,36,2:1
23,0,3:1
23,1,3:1
23,2,3:1
23,3,3:3
23,4,3:1
23,5,3:1
23,6,3:1
23,7,3:1
23,8,3:9
23,9,3:9
23,10,3:9
23,11,3:9
23,12,3:9
23,13,3:9
23,14,3:9
23,15,3:9
23,16,3:9
23,17,3:9
23,18,3:9
23,19,3:9
23,20,3:9
23,21,3:9
23,22,3:9
23,23,3:9
23,24,3:9
23,25,3:9
23,26,3:9
23,27,3:9
23,28,3:9
23,29,3:1
23,30,3:1
23,31,3:1
23,32,3:1
23,33,3:1
23,34,3:1
23,35,3:1
23,36,3:1
23,0,4:3
23,1,4:3
23,2,4:3
23,3,4:3
23,4,4:3
23,5,4:3
23,6,4:3
23,7,4:1
23,8,4:9
23,9,4:9
23,10,4:9
23,11,4:9
23,12,4:9
23,13,4:9
23,14,4:9
23,15,4:9
23,16,4:9
23,17,4:9
23,18,4:9
23,19,4:9
23,20,4:9
23,21,4:9
23,22,4:9
23,23,4:9
23,24,4:9
23,25,4:9
23,26,4:9
23,27,4:9
23,28,4:9
23,29,4:1
23,30,4:1
23,31,4:1
23,32,4:1
23,33,4:1
23,34,4:1
23,35,4:1
23,36,4:1
23,0,5:3
23,1,5:3
23,2,5:3
23,3,5:3
23,4,5:3
23,5,5:3
23,6,5:3
23,7,5:1
23,8,5:9
23,9,5:9
23,10,5:9
23,11,5:9
23,12,5:9
23,13,5:9
23,14,5:9
23,15,5:9
23,16,5:9
23,17,5:9
23,18,5:9
23,19,5:9
23,20,5:9
23,21,5:9
23,22,5:9
23,23,5:9
23,24,5:9
23,25,5:9
23,26,5:9
23,27,5:9
23,28,5:9
23,29,5:1
23,30,5:1
23,31,5:1
23,32,5:1
23,33,5:1
23,34,5:1
23,35,5:1
23,36,5:3
23,0,6:3
23,1,6:3
23,2,6:3
23,3,6:3
23,4,6:3
23,5,6:3
23,6,6:3
23,7,6:1
23,29,6:1
23,30,6:1
23,31,6:1
23,32,6:1
23,33,6:1
23,34,6:3
23,35,6:3
23,36,6:3
23,0,7:2
23,1,7:2
23,2,7:3
23,3,7:3
23,4,7:98
23,5,7:98
23,6,7:3
23,7,7:4
23,16,7:17
23,18,7:17
23,29,7:4
23,30,7:3
23,31,7:98
23,32,7:98
23,33,7:3
23,34,7:3
23,35,7:2
23,36,7:2
23,2,8:1
23,3,8:1
23,6,8:1
23,30,8:1
23,33,8:1
23,34,8:1
23,35,8:31.1
23,36,8:31.1
23,1,9:50.4
23,2,9:1
23,3,9:1
23,6,9:1
23,7,9:50.3
23,29,9:50.4
23,30,9:1
23,33,9:1
23,34,9:1
23,35,9:50.3
23,2,10:1
23,3,10:1
23,5,10:1
23,31,10:1
23,33,10:1
23,34,10:1
23,2,11:1
23,3,11:1
23,4,11:1
23,32,11:1
23,33,11:1
23,34,11:1
23,2,12:1
23,3,12:1
23,33,12:1
23,34,12:1
23,1,13:50.4
23,2,13:1
23,3,13:1
23,4,13:50.3
23,32,13:50.4
23,33,13:1
23,34,13:1
23,35,13:50.3
23,2,14:1
23,3,14:1
23,33,14:1
23,34,14:1
23,2,15:1
23,3,15:1
23,33,15:1
23,34,15:1
23,1,16:44
23,2,16:44
23,34,16:44
23,35,16:44
24,0,0:1
24,1,0:1
24,2,0:1
24,3,0:1
24,4,0:1
24,5,0:1
24,6,0:1
24,7,0:1
24,8,0:1
24,9,0:1
24,10,0:1
24,11,0:1
24,12,0:1
24,13,0:1
24,14,0:1
24,15,0:1
24,16,0:1
24,17,0:1
24,18,0:1
24,19,0:1
24,20,0:1
24,21,0:1
24,22,0:1
24,23,0:1
24,24,0:1
24,25,0:1
24,26,0:1
24,27,0:1
24,28,0:1
24,29,0:1
24,30,0:1
24,31,0:1
24,32,0:1
24,33,0:1
24,34,0:1
24,35,0:1
24,36,0:1
24,0,1:1
24,1,1:1
24,2,1:1
24,3,1:1
24,4,1:1
24,5,1:1
24,6,1:1
24,7,1:1
24,8,1:1
24,9,1:1
24,10,1:1
24,11,1:1
24,12,1:1
24,13,1:1
24,14,1:1
24,15,1:1
24,16,1:1
24,17,1:1
24,18,1:1
24,19,1:1
24,20,1:1
24,21,1:1
24,22,1:1
24,23,1:1
24,24,1:1
24,25,1:1
24,26,1:1
24,27,1:1
24,28,1:1
24,29,1:1
24,30,1:1
24,31,1:1
24,32,1:1
24,33,1:1
24,34,1:1
24,35,1:1
24,36,1:1
24,0,2:1
24,1,2:1
24,2,2:1
24,3,2:1
24,4,2:1
24,5,2:1
24,6,2:1
24,7,2:1
24,8,2:9
24,9,2:9
24,10,2:9
24,11,2:9
24,12,2:9
24,13,2:9
24,14,2:9
24,15,2:9
24,16,2:9
24,17,2:9
24,18,2:9
24,19,2:9
24,20,2:9
24,21,2:9
24,22,2:9
24,23,2:9
24,24,2:9
24,25,2:9
24,26,2:9
24,27,2:9
24,28,2:9
24,29,2:1
24,30,2:1
24,31,2:1
24,32,2:1
24,33,2:1
24,34,2:1
24,35,2:1
24,36,2:1
24,0,3:1
24,1,3:1
24,2,3:1
24,3,3:1
24,4,3:1
24,5,3:1
24,6,3:1
24,7,3:1
24,8,3:9
24,9,3:9
24,10,3:9
24,11,3:9
24,12,3:9
24,13,3:9
24,14,3:9
24,15,3:9
24,16,3:9
24,17,3:9
24,18,3:9
24,19,3:9
24,20,3:9
24,21,3:9
24,22,3:9
24,23,3:9
24,24,3:9
24,25,3:9
24,26,3:9
24,27,3:9
24,28,3:9
24,29,3:1
24,30,3:1
24,31,3:1
24,32,3:1
24,33,3:1
24,34,3:1
24,35,3:1
24,36,3:1
24,0,4:3
24,1,4:3
24,2,4:3
24,3,4:3
24,4,4:3
24,5,4:3
24,6,4:3
24,7,4:1
24,8,4:9
24,9,4:9
24,10,4:9
24,11,4:9
24,12,4:9
24,13,4:9
24,14,4:9
24,15,4:9
24,16,4:9
24,17,4:9
24,18,4:9
24,19,4:9
24,20,4:9
24,21,4:9
24,22,4:9
24,23,4:9
24,24,4:9
24,25,4:9
24,26,4:9
24,27,4:9
24,28,4:9
24,29,4:1
24,30,4:1
24,31,4:1
24,32,4:1
24,33,4:1
24,34,4:1
24,35,4:1
24,36,4:1
24,0,5:3
24,1,5:3
24,2,5:3
24,3,5:3
24,4,5:3
24,5,5:3
24,6,5:3
24,7,5:1
24,8,5:9
24,9,5:9
24,10,5:9
24,11,5:9
24,12,5:9
24,13,5:9
24,14,5:9
24,15,5:9
24,16,5:9
24,17,5:9
24,18,5:9
24,19,5:9
24,20,5:9
24,21,5:9
24,22,5:9
24,23,5:9
24,24,5:9
24,25,5:9
24,26,5:9
24,27,5:9
24,28,5:9
24,29,5:1
24,30,5:1
24,31,5:1
24,32,5:1
24,33,5:1
24,34,5:1
24,35,5:3
24,36,5:3
24,0,6:3
24,1,6:3
24,2,6:3
24,3,6:3
24,4,6:3
24,5,6:3
24,6,6:3
24,7,6:1
24,29,6:1
24,30,6:1
24,31,6:1
24,32,6:1
24,33,6:1
24,34,6:3
24,35,6:3
24,36,6:3
24,0,7:2
24,1,7:2
24,2,7:4
24,3,7:4
24,4,7:98
24,5,7:98
24,6,7:3
24,7,7:4
24,14,7:17
24,29,7:4
24,30,7:3
24,31,7:98
24,32,7:98
24,33,7:4
24,34,7:4
24,35,7:2
24,36,7:2
24,6,8:1
24,30,8:1
24,35,8:31.1
24,36,8:31.1
24,6,9:1
24,30,9:1
24,2,10:1
24,3,10:1
24,5,10:1
24,31,10:1
24,33,10:1
24,34,10:1
24,2,11:1
24,3,11:1
24,4,11:1
24,32,11:1
24,33,11:1
24,34,11:1
24,2,14:1
24,3,14:1
24,33,14:1
24,34,14:1
24,2,15:1
24,3,15:1
24,33,15:1
24,34,15:1
24,1,16:43
24,2,16:44
24,34,16:44
24,35,16:44
24,1,17:44
25,0,0:3
25,1,0:3
25,2,0:3
25,3,0:1
25,4,0:1
25,5,0:1
25,6,0:1
25,7,0:1
25,8,0:1
25,9,0:1
25,10,0:1
25,11,0:1
25,12,0:1
25,13,0:1
25,14,0:1
25,15,0:1
25,16,0:1
25,17,0:1
25,18,0:1
25,19,0:1
25,20,0:1
25,21,0:1
25,22,0:1
25,23,0:1
25,24,0:1
25,25,0:1
25,26,0:1
25,27,0:1
25,28,0:1
25,29,0:1
25,30,0:1
25,31,0:1
25,32,0:1
25,33,0:1
25,34,0:1
25,35,0:1
25,36,0:1
25,0,1:3
25,1,1:3
25,2,1:1
25,3,1:1
25,4,1:1
25,5,1:1
25,6,1:1
25,7,1:1
25,8,1:1
25,9,1:1
25,10,1:1
25,11,1:1
25,12,1:1
25,13,1:1
25,14,1:1
25,15,1:1
25,16,1:1
25,17,1:1
25,18,1:1
25,19,1:1
25,20,1:1
25,21,1:1
25,22,1:1
25,23,1:1
25,24,1:1
25,25,1:1
25,26,1:1
25,27,1:1
25,28,1:1
25,29,1:1
25,30,1:1
25,31,1:1
25,32,1:1
25,33,1:1
25,34,1:1
25,35,1:1
25,36,1:1
25,0,2:1
25,1,2:1
25,2,2:1
25,3,2:1
25,4,2:1
25,5,2:1
25,6,2:1
25,7,2:1
25,8,2:9
25,9,2:9
25,10,2:9
25,11,2:9
25,12,2:9
25,13,2:9
25,14,2:9
25,15,2:9
25,16,2:9
25,17,2:9
25,18,2:9
25,19,2:9
25,20,2:9
25,21,2:9
25,22,2:9
25,23,2:9
25,24,2:9
25,25,2:9
25,26,2:9
25,27,2:9
25,28,2:9
25,29,2:1
25,30,2:1
25,31,2:1
25,32,2:1
25,33,2:1
25,34,2:1
25,35,2:1
25,36,2:1
25,0,3:1
25,1,3:1
25,2,3:1
25,3,3:1
25,4,3:1
25,5,3:1
25,6,3:1
25,7,3:1
25,8,3:9
25,9,3:9
25,10,3:9
25,11,3:9
25,12,3:9
25,13,3:9
25,14,3:9
25,15,3:9
25,16,3:9
25,17,3:9
25,18,3:9
25,19,3:9
25,20,3:9
25,21,3:9
25,22,3:9
25,23,3:9
25,24,3:9
25,25,3:9
25,26,3:9
25,27,3:9
25,28,3:9
25,29,3:1
25,30,3:1
25,31,3:1
25,32,3:1
25,33,3:1
25,34,3:1
25,35,3:1
25,36,3:1
25,0,4:3
25,1,4:3
25,2,4:3
25,3,4:3
25,4,4:3
25,5,4:3
25,6,4:3
25,7,4:1
25,8,4:9
25,9,4:9
25,10,4:9
25,11,4:9
25,12,4:9
25,13,4:9
25,14,4:9
25,15,4:9
25,16,4:9
25,17,4:9
25,18,4:9
25,19,4:9
25,20,4:9
25,21,4:9
25,22,4:9
25,23,4:9
25,24,4:9
25,25,4:9
25,26,4:9
25,27,4:9
25,28,4:9
25,29,4:1
25,30,4:1
25,31,4:1
25,32,4:1
25,33,4:1
25,34,4:1
25,35,4:1
25,36,4:1
25,0,5:3
25,1,5:3
25,2,5:3
25,3,5:3
25,4,5:3
25,5,5:3
25,6,5:3
25,7,5:1
25,8,5:9
25,9,5:9
25,10,5:9
25,11,5:9
25,12,5:9
25,13,5:9
25,14,5:9
25,15,5:9
25,16,5:9
25,17,5:9
25,18,5:9
25,19,5:9
25,20,5:9
25,21,5:9
25,22,5:9
25,23,5:9
25,24,5:9
25,25,5:9
25,26,5:9
25,27,5:9
25,28,5:9
25,29,5:1
25,30,5:1
25,31,5:1
25,32,5:1
25,33,5:1
25,34,5:3
25,35,5:3
25,36,5:3
25,0,6:3
25,1,6:3
25,2,6:3
25,3,6:3
25,4,6:3
25,5,6:3
25,6,6:3
25,7,6:1
25,29,6:1
25,30,6:1
25,31,6:1
25,32,6:1
25,33,6:3
25,34,6:3
25,35,6:3
25,36,6:3
25,0,7:2
25,1,7:2
25,2,7:4
25,3,7:4
25,4,7:98
25,5,7:98
25,6,7:3
25,7,7:4
25,29,7:4
25,30,7:3
25,31,7:98
25,32,7:98
25,33,7:4
25,34,7:4
25,35,7:2
25,36,7:2
25,6,8:1
25,30,8:1
25,35,8:31.1
25,36,8:31.1
25,6,9:1
25,7,9:50.3
25,29,9:50.4
25,30,9:1
25,5,10:1
25,31,10:1
25,2,11:1
25,3,11:1
25,4,11:1
25,32,11:1
25,33,11:1
25,34,11:1
25,2,15:1
25,3,15:1
25,33,15:1
25,34,15:1
25,1,16:44
25,2,16:44
25,34,16:44
25,35,16:43
25,35,17:44
26,0,0:3
26,1,0:3
26,2,0:3
26,3,0:3
26,4,0:3
26,5,0:1
26,6,0:1
26,7,0:1
26,8,0:1
26,9,0:1
26,10,0:1
26,11,0:1
26,12,0:1
26,13,0:1
26,14,0:1
26,15,0:1
26,16,0:1
26,17,0:1
26,18,0:1
26,19,0:1
26,20,0:1
26,21,0:1
26,22,0:1
26,23,0:1
26,24,0:1
26,25,0:1
26,26,0:1
26,27,0:1
26,28,0:1
26,29,0:1
26,30,0:1
26,31,0:1
26,32,0:1
26,33,0:1
26,34,0:1
26,35,0:1
26,36,0:1
26,0,1:3
26,1,1:3
26,2,1:3
26,3,1:3
26,4,1:1
26,5,1:1
26,6,1:1
26,7,1:1
26,8,1:1
26,9,1:1
26,10,1:1
26,11,1:1
26,12,1:1
26,13,1:1
26,14,1:1
26,15,1:1
26,16,1:1
26,17,1:1
26,18,1:1
26,19,1:1
26,20,1:1
26,21,1:1
26,22,1:1
26,23,1:1
26,24,1:1
26,25,1:1
26,26,1:1
26,27,1:1
26,28,1:1
26,29,1:1
26,30,1:1
26,31,1:1
26,32,1:1
26,33,1:1
26,34,1:1
26,35,1:1
26,36,1:1
26,0,2:1
26,1,2:1
26,2,2:1
26,3,2:1
26,4,2:1
26,5,2:1
26,6,2:1
26,7,2:1
26,8,2:9
26,9,2:9
26,10,2:9
26,11,2:9
26,12,2:9
26,13,2:9
26,14,2:9
26,15,2:9
26,16,2:9
26,17,2:9
26,18,2:9
26,19,2:9
26,20,2:9
26,21,2:9
26,22,2:9
26,23,2:9
26,24,2:9
26,25,2:9
26,26,2:9
26,27,2:9
26,28,2:9
26,29,2:1
26,30,2:1
26,31,2:1
26,32,2:1
26,33,2:1
26,34,2:1
26,35,2:1
26,36,2:1
26,0,3:1
26,1,3:1
26,2,3:1
26,3,3:1
26,4,3:1
26,5,3:1
26,6,3:1
26,7,3:1
26,8,3:9
26,9,3:9
26,10,3:9
26,11,3:9
26,12,3:9
26,13,3:9
26,14,3:9
26,15,3:9
26,16,3:9
26,17,3:9
26,18,3:9
26,19,3:9
26,20,3:9
26,21,3:9
26,22,3:9
26,23,3:9
26,24,3:9
26,25,3:9
26,26,3:9
26,27,3:9
26,28,3:9
26,29,3:1
26,30,3:1
26,31,3:1
26,32,3:1
26,33,3:1
26,34,3:1
26,35,3:1
26,36,3:1
26,0,4:3
26,1,4:3
26,2,4:3
26,3,4:3
26,4,4:3
26,5,4:3
26,6,4:3
26,7,4:1
26,8,4:9
26,9,4:9
26,10,4:9
26,11,4:9
26,12,4:9
26,13,4:9
26,14,4:9
26,15,4:9
26,16,4:9
26,17,4:9
26,18,4:9
26,19,4:9
26,20,4:9
26,21,4:9
26,22,4:9
26,23,4:9
26,24,4:9
26,25,4:9
26,26,4:9
26,27,4:9
26,28,4:9
26,29,4:1
26,30,4:1
26,31,4:1
26,32,4:1
26,33,4:1
26,34,4:1
26,35,4:1
26,36,4:3
26,0,5:3
26,1,5:3
26,2,5:3
26,3,5:3
26,4,5:3
26,5,5:3
26,6,5:3
26,7,5:1
26,8,5:9
26,9,5:9
26,10,5:9
26,11,5:9
26,12,5:9
26,13,5:9
26,14,5:9
26,15,5:9
26,16,5:9
26,17,5:9
26,18,5:9
26,19,5:9
26,20,5:9
26,21,5:9
26,22,5:9
26,23,5:9
26,24,5:9
26,25,5:9
26,26,5:9
26,27,5:9
26,28,5:9
26,29,5:1
26,30,5:1
26,31,5:1
26,32,5:1
26,33,5:3
26,34,5:3
26,35,5:3
26,36,5:3
26,0,6:3
26,1,6:3
26,2,6:3
26,3,6:3
26,4,6:3
26,5,6:3
26,6,6:3
26,7,6:1
26,29,6:1
26,30,6:1
26,31,6:1
26,32,6:3
26,33,6:3
26,34,6:3
26,35,6:3
26,36,6:3
26,0,7:2
26,1,7:2
26,2,7:4
26,3,7:4
26,4,7:98
26,5,7:98
26,6,7:3
26,7,7:4
26,11,7:17
26,24,7:17
26,29,7:4
26,30,7:3
26,31,7:98
26,32,7:98
26,33,7:4
26,34,7:4
26,35,7:2
26,36,7:2
26,1,8:31.1
26,6,8:1
26,30,8:1
26,6,9:1
26,30,9:1
26,5,10:1
26,31,10:1
26,2,11:1
26,3,11:1
26,4,11:1
26,32,11:1
26,33,11:1
26,34,11:1
26,2,15:1
26,3,15:1
26,33,15:1
26,34,15:1
26,1,16:44
26,2,16:44
26,34,16:44
26,35,16:44
27,0,0:3
27,1,0:3
27,2,0:3
27,3,0:3
27,4,0:3
27,5,0:3
27,6,0:1
27,7,0:1
27,8,0:1
27,9,0:1
27,10,0:1
27,11,0:1
27,12,0:1
27,13,0:1
27,14,0:1
27,15,0:1
27,16,0:1
27,17,0:1
27,18,0:1
27,19,0:1
27,20,0:1
27,21,0:1
27,22,0:1
27,23,0:1
27,24,0:1
27,25,0:1
27,26,0:1
27,27,0:1
27,28,0:1
27,29,0:1
27,30,0:1
27,31,0:1
27,32,0:1
27,33,0:1
27,34,0:1
27,35,0:1
27,36,0:1
27,0,1:3
27,1,1:3
27,2,1:3
27,3,1:3
27,4,1:3
27,5,1:1
27,6,1:1
27,7,1:1
27,8,1:1
27,9,1:1
27,10,1:1
27,11,1:1
27,12,1:1
27,13,1:1
27,14,1:1
27,15,1:1
27,16,1:1
27,17,1:1
27,18,1:1
27,19,1:1
27,20,1:1
27,21,1:1
27,22,1:1
27,23,1:1
27,24,1:1
27,25,1:1
27,26,1:1
27,27,1:1
27,28,1:1
27,29,1:1
27,30,1:1
27,31,1:1
27,32,1:1
27,33,1:1
27,34,1:1
27,35,1:1
27,36,1:1
27,0,2:1
27,1,2:3
27,2,2:3
27,3,2:1
27,4,2:1
27,5,2:1
27,6,2:1
27,7,2:1
27,8,2:9
27,9,2:9
27,10,2:9
27,11,2:9
27,12,2:9
27,13,2:9
27,14,2:9
27,15,2:9
27,16,2:9
27,17,2:9
27,18,2:9
27,19,2:9
27,20,2:9
27,21,2:9
27,22,2:9
27,23,2:9
27,24,2:9
27,25,2:9
27,26,2:9
27,27,2:9
27,28,2:9
27,29,2:1
27,30,2:1
27,31,2:1
27,32,2:1
27,33,2:1
27,34,2:1
27,35,2:1
27,36,2:1
27,0,3:1
27,1,3:1
27,2,3:1
27,3,3:1
27,4,3:1
27,5,3:1
27,6,3:1
27,7,3:1
27,8,3:9
27,9,3:9
27,10,3:9
27,11,3:9
27,12,3:9
27,13,3:9
27,14,3:9
27,15,3:9
27,16,3:9
27,17,3:9
27,18,3:9
27,19,3:9
27,20,3:9
27,21,3:9
27,22,3:9
27,23,3:9
27,24,3:9
27,25,3:9
27,26,3:9
27,27,3:9
27,28,3:9
27,29,3:1
27,30,3:1
27,31,3:1
27,32,3:1
27,33,3:1
27,34,3:1
27,35,3:1
27,36,3:1
27,0,4:3
27,1,4:3
27,2,4:3
27,3,4:3
27,4,4:3
27,5,4:3
27,6,4:3
27,7,4:1
27,8,4:9
27,9,4:9
27,10,4:9
27,11,4:9
27,12,4:9
27,13,4:9
27,14,4:9
27,15,4:9
27,16,4:9
27,17,4:9
27,18,4:9
27,19,4:9
27,20,4:9
27,21,4:9
27,22,4:9
27,23,4:9
27,24,4:9
27,25,4:9
27,26,4:9
27,27,4:9
27,28,4:9
27,29,4:1
27,30,4:1
27,31,4:1
27,32,4:1
27,33,4:1
27,34,4:1
27,35,4:3
27,36,4:3
27,0,5:3
27,1,5:3
27,2,5:3
27,3,5:3
27,4,5:3
27,5,5:3
27,6,5:3
27,7,5:1
27,8,5:9
27,9,5:9
27,10,5:9
27,11,5:9
27,12,5:9
27,13,5:9
27,14,5:9
27,15,5:9
27,16,5:9
27,17,5:9
27,18,5:9
27,19,5:9
27,20,5:9
27,21,5:9
27,22,5:9.1
27,23,5:9
27,24,5:9
27,25,5:9
27,26,5:9
27,27,5:9
27,28,5:9
27,29,5:1
27,30,5:1
27,31,5:1
27,32,5:3
27,33,5:3
27,34,5:3
27,35,5:3
27,36,5:3
27,0,6:3
27,1,6:3
27,2,6:3
27,3,6:3
27,4,6:3
27,5,6:3
27,6,6:3
27,7,6:1
27,22,6:17
27,29,6:1
27,30,6:3
27,31,6:3
27,32,6:3
27,33,6:3
27,34,6:3
27,35,6:3
27,36,6:3
27,0,7:2
27,1,7:2
27,2,7:4
27,3,7:4
27,4,7:98
27,5,7:98
27,6,7:3
27,7,7:4
27,29,7:4
27,30,7:3
27,31,7:98
27,32,7:98
27,33,7:4
27,34,7:4
27,35,7:2
27,36,7:2
27,1,8:31.1
27,6,8:1
27,30,8:1
27,6,9:1
27,7,9:50.3
27,29,9:50.4
27,30,9:1
27,2,10:1
27,3,10:1
27,5,10:1
27,31,10:1
27,33,10:1
27,34,10:1
27,2,11:1
27,3,11:1
27,4,11:1
27,32,11:1
27,33,11:1
27,34,11:1
27,2,14:1
27,3,14:1
27,33,14:1
27,34,14:1
27,2,15:1
27,3,15:1
27,33,15:1
27,34,15:1
27,1,16:43
27,2,16:44
27,34,16:44
27,35,16:44
27,1,17:44
28,0,0:3
28,1,0:3
28,2,0:3
28,3,0:3
28,4,0:3
28,5,0:3
28,6,0:3
28,7,0:1
28,8,0:1
28,9,0:1
28,10,0:1
28,11,0:1
28,12,0:1
28,13,0:1
28,14,0:1
28,15,0:1
28,16,0:1
28,17,0:1
28,18,0:1
28,19,0:1
28,20,0:1
28,21,0:1
28,22,0:1
28,23,0:1
28,24,0:1
28,25,0:1
28,26,0:1
28,27,0:1
28,28,0:1
28,29,0:1
28,30,0:1
28,31,0:1
28,32,0:1
28,33,0:1
28,34,0:1
28,35,0:1
28,36,0:16
28,0,1:3
28,1,1:3
28,2,1:3
28,3,1:3
28,4,1:3
28,5,1:3
28,6,1:3
28,7,1:1
28,8,1:1
28,9,1:1
28,10,1:1
28,11,1:1
28,12,1:1
28,13,1:1
28,14,1:1
28,15,1:1
28,16,1:1
28,17,1:1
28,18,1:1
28,19,1:1
28,20,1:1
28,21,1:1
28,22,1:1
28,23,1:1
28,24,1:1
28,25,1:1
28,26,1:1
28,27,1:1
28,28,1:1
28,29,1:1
28,30,1:1
28,31,1:1
28,32,1:1
28,33,1:1
28,34,1:1
28,35,1:1
28,36,1:1
28,0,2:1
28,1,2:1
28,2,2:1
28,3,2:3
28,4,2:3
28,5,2:1
28,6,2:1
28,7,2:1
28,8,2:9
28,9,2:9
28,10,2:9
28,11,2:9
28,12,2:9
28,13,2:9
28,14,2:9
28,15,2:9
28,16,2:9
28,17,2:9
28,18,2:9
28,19,2:9
28,20,2:9
28,21,2:9
28,22,2:9
28,23,2:9
28,24,2:9
28,25,2:9
28,26,2:9
28,27,2:9
28,28,2:9
28,29,2:1
28,30,2:1
28,31,2:1
28,32,2:1
28,33,2:1
28,34,2:1
28,35,2:1
28,36,2:1
28,0,3:1
28,1,3:1
28,2,3:1
28,3,3:1
28,4,3:1
28,5,3:1
28,6,3:1
28,7,3:1
28,8,3:9
28,9,3:9
28,10,3:9
28,11,3:9
28,12,3:9
28,13,3:9
28,14,3:9
28,15,3:9
28,16,3:9
28,17,3:9
28,18,3:9
28,19,3:9
28,20,3:9
28,21,3:9
28,22,3:9
28,23,3:9
28,24,3:9
28,25,3:9
28,26,3:9
28,27,3:9
28,28,3:9
28,29,3:1
28,30,3:1
28,31,3:1
28,32,3:1
28,33,3:1
28,34,3:1
28,35,3:1
28,36,3:1
28,0,4:3
28,1,4:3
28,2,4:3
28,3,4:3
28,4,4:3
28,5,4:3
28,6,4:3
28,7,4:1
28,8,4:9
28,9,4:9
28,10,4:9
28,11,4:9
28,12,4:9
28,13,4:9
28,14,4:9
28,15,4:9
28,16,4:9
28,17,4:9
28,18,4:9
28,19,4:9
28,20,4:9
28,21,4:9
28,22,4:9
28,23,4:9
28,24,4:9
28,25,4:9
28,26,4:9
28,27,4:9
28,28,4:9
28,29,4:1
28,30,4:1
28,31,4:1
28,32,4:1
28,33,4:3
28,34,4:3
28,35,4:3
28,36,4:3
28,0,5:3
28,1,5:3
28,2,5:3
28,3,5:3
28,4,5:3
28,5,5:3
28,6,5:3
28,7,5:1
28,8,5:9
28,9,5:9
28,10,5:9
28,11,5:9
28,12,5:9
28,13,5:9
28,14,5:9
28,15,5:9
28,16,5:9
28,17,5:9
28,18,5:9
28,19,5:9
28,20,5:9
28,21,5:9
28,22,5:9
28,23,5:9
28,24,5:9
28,25,5:9
28,26,5:9
28,27,5:9
28,28,5:9
28,29,5:1
28,30,5:3
28,31,5:3
28,32,5:3
28,33,5:3
28,34,5:3
28,35,5:3
28,36,5:3
28,0,6:3
28,1,6:3
28,2,6:3
28,3,6:3
28,4,6:3
28,5,6:3
28,6,6:3
28,7,6:1
28,29,6:1
28,30,6:3
28,31,6:3
28,32,6:3
28,33,6:3
28,34,6:3
28,35,6:3
28,36,6:3
28,0,7:2
28,1,7:2
28,2,7:3
28,3,7:3
28,4,7:98
28,5,7:98
28,6,7:3
28,7,7:4
28,29,7:4
28,30,7:3
28,31,7:98
28,32,7:98
28,33,7:3
28,34,7:3
28,35,7:2
28,36,7:2
28,2,8:1
28,3,8:1
28,6,8:1
28,30,8:1
28,33,8:1
28,34,8:1
28,36,8:31.1
28,1,9:50.4
28,2,9:1
28,3,9:1
28,6,9:1
28,30,9:1
28,33,9:1
28,34,9:1
28,35,9:50.3
28,2,10:1
28,3,10:1
28,5,10:1
28,31,10:1
28,33,10:1
28,34,10:1
28,2,11:1
28,3,11:1
28,4,11:1
28,32,11:1
28,33,11:1
28,34,11:1
28,2,12:1
28,3,12:1
28,33,12:1
28,34,12:1
28,1,13:50.4
28,2,13:1
28,3,13:1
28,4,13:50.3
28,32,13:50.4
28,33,13:1
28,34,13:1
28,35,13:50.3
28,2,14:1
28,3,14:1
28,33,14:1
28,34,14:1
28,2,15:1
28,3,15:1
28,33,15:1
28,34,15:1
28,1,16:44
28,2,16:44
28,34,16:44
28,35,16:43
28,35,17:44
29,0,0:1
29,1,0:3
29,2,0:3
29,3,0:3
29,4,0:3
29,5,0:3
29,6,0:3
29,7,0:1
29,8,0:1
29,9,0:1
29,10,0:1
29,11,0:1
29,12,0:1
29,13,0:1
29,14,0:1
29,15,0:1
29,16,0:1
29,17,0:1
29,18,0:1
29,19,0:1
29,20,0:1
29,21,0:1
29,22,0:1
29,23,0:1
29,24,0:1
29,25,0:1
29,26,0:1
29,27,0:1
29,28,0:1
29,29,0:1
29,30,0:1
29,31,0:1
29,32,0:1
29,33,0:1
29,34,0:1
29,35,0:1
29,36,0:1
29,0,1:1
29,1,1:1
29,2,1:3
29,3,1:3
29,4,1:3
29,5,1:3
29,6,1:3
29,7,1:1
29,8,1:1
29,9,1:1
29,10,1:1
29,11,1:1
29,12,1:1
29,13,1:1
29,14,1:1
29,15,1:1
29,16,1:1
29,17,1:1
29,18,1:1
29,19,1:1
29,20,1:1
29,21,1:1
29,22,1:1
29,23,1:1
29,24,1:1
29,25,1:1
29,26,1:1
29,27,1:1
29,28,1:1
29,29,1:1
29,30,1:1
29,31,1:1
29,32,1:1
29,33,1:1
29,34,1:1
29,35,1:1
29,36,1:1
29,0,2:1
29,1,2:1
29,2,2:1
29,3,2:1
29,4,2:1
29,5,2:3
29,6,2:1
29,7,2:1
29,8,2:9
29,9,2:9
29,10,2:9
29,11,2:9
29,12,2:9
29,13,2:9
29,14,2:9
29,15,2:9
29,16,2:9
29,17,2:9
29,18,2:9
29,19,2:9
29,20,2:9
29,21,2:9
29,22,2:9
29,23,2:9
29,24,2:9
29,25,2:9
29,26,2:9
29,27,2:9
29,28,2:9
29,29,2:1
29,30,2:1
29,31,2:1
29,32,2:1
29,33,2:1
29,34,2:1
29,35,2:1
29,36,2:1
29,0,3:1
29,1,3:1
29,2,3:1
29,3,3:1
29,4,3:1
29,5,3:1
29,6,3:1
29,7,3:1
29,8,3:9
29,9,3:9
29,10,3:9
29,11,3:9
29,12,3:9
29,13,3:9
29,14,3:9
29,15,3:9
29,16,3:9
29,17,3:9
29,18,3:9
29,19,3:9
29,20,3:9
29,21,3:9
29,22,3:9
29,23,3:9
29,24,3:9
29,25,3:9
29,26,3:9
29,27,3:9
29,28,3:9
29,29,3:1
29,30,3:1
29,31,3:1
29,32,3:1
29,33,3:1
29,34,3:1
29,35,3:1
29,36,3:1
29,0,4:3
29,1,4:3
29,2,4:3
29,3,4:3
29,4,4:3
29,5,4:3
29,6,4:3
29,7,4:1
29,8,4:9
29,9,4:9
29,10,4:9
29,11,4:9
29,12,4:9
29,13,4:9
29,14,4:9
29,15,4:9
29,16,4:9
29,17,4:9
29,18,4:9
29,19,4:9
29,20,4:9
29,21,4:9
29,22,4:9
29,23,4:9
29,24,4:9
29,25,4:9
29,26,4:9
29,27,4:9
29,28,4:9
29,29,4:1
29,30,4:3
29,31,4:3
29,32,4:3
29,33,4:3
29,34,4:3
29,35,4:3
29,36,4:3
29,0,5:3
29,1,5:3
29,2,5:3
29,3,5:3
29,4,5:3
29,5,5:3
29,6,5:3
29,7,5:1
29,8,5:9
29,9,5:9
29,10,5:9
29,11,5:9
29,12,5:9
29,13,5:9
29,14,5:9
29,15,5:9
29,16,5:9
29,17,5:9
29,18,5:9
29,19,5:9
29,20,5:9
29,21,5:9
29,22,5:9
29,23,5:9
29,24,5:9
29,25,5:9
29,26,5:9
29,27,5:9
29,28,5:9
29,29,5:1
29,30,5:3
29,31,5:3
29,32,5:3
29,33,5:3
29,34,5:3
29,35,5:3
29,36,5:3
29,0,6:3
29,1,6:3
29,2,6:3
29,3,6:3
29,4,6:3
29,5,6:3
29,6,6:3
29,7,6:1
29,29,6:1
29,30,6:3
29,31,6:3
29,32,6:3
29,33,6:3
29,34,6:3
29,35,6:3
29,36,6:3
29,0,7:2
29,1,7:2
29,2,7:4
29,3,7:4
29,4,7:98
29,5,7:98
29,6,7:3
29,7,7:4
29,11,7:17
29,15,7:17
29,18,7:17
29,20,7:17
29,25,7:17
29,26,7:17
29,29,7:4
29,30,7:3
29,31,7:98
29,32,7:98
29,33,7:4
29,34,7:4
29,35,7:2
29,36,7:2
29,6,8:1
29,26,8:17
29,30,8:1
29,6,9:1
29,7,9:50.3
29,26,9:17
29,29,9:50.4
29,30,9:1
29,2,10:1
29,3,10:1
29,5,10:1
29,31,10:1
29,33,10:1
29,34,10:1
29,2,11:1
29,3,11:1
29,4,11:1
29,32,11:1
29,33,11:1
29,34,11:1
29,2,14:1
29,3,14:1
29,33,14:1
29,34,14:1
29,2,15:1
29,3,15:1
29,33,15:1
29,34,15:1
29,1,16:44
29,2,16:44
29,34,16:44
29,35,16:44
30,0,0:1
30,1,0:1
30,2,0:16
30,3,0:3
30,4,0:3
30,5,0:3
30,6,0:3
30,7,0:1
30,8,0:1
30,9,0:1
30,10,0:1
30,11,0:1
30,12,0:1
30,13,0:1
30,14,0:1
30,15,0:1
30,16,0:1
30,17,0:1
30,18,0:1
30,19,0:1
30,20,0:1
30,21,0:1
30,22,0:1
30,23,0:1
30,24,0:1
30,25,0:1
30,26,0:1
30,27,0:1
30,28,0:1
30,29,0:1
30,30,0:1
30,31,0:1
30,32,0:1
30,33,0:1
30,34,0:1
30,35,0:1
30,36,0:1
30,0,1:1
30,1,1:1
30,2,1:16
30,3,1:16
30,4,1:3
30,5,1:3
30,6,1:3
30,7,1:1
30,8,1:1
30,9,1:1
30,10,1:1
30,11,1:1
30,12,1:1
30,13,1:1
30,14,1:1
30,15,1:1
30,16,1:1
30,17,1:1
30,18,1:1
30,19,1:1
30,20,1:1
30,21,1:1
30,22,1:1
30,23,1:1
30,24,1:1
30,25,1:1
30,26,1:1
30,27,1:1
30,28,1:1
30,29,1:1
30,30,1:1
30,31,1:1
30,32,1:1
30,33,1:1
30,34,1:1
30,35,1:1
30,36,1:1
30,0,2:1
30,1,2:1
30,2,2:1
30,3,2:1
30,4,2:1
30,5,2:1
30,6,2:1
30,7,2:1
30,8,2:9
30,9,2:9
30,10,2:9
30,11,2:9
30,12,2:9
30,13,2:9
30,14,2:9
30,15,2:9
30,16,2:9
30,17,2:9
30,18,2:9
30,19,2:9
30,20,2:9
30,21,2:9
30,22,2:9
30,23,2:9
30,24,2:9
30,25,2:9
30,26,2:9
30,27,2:9
30,28,2:9
30,29,2:1
30,30,2:1
30,31,2:1
30,32,2:1
30,33,2:1
30,34,2:1
30,35,2:1
30,36,2:1
30,0,3:1
30,1,3:1
30,2,3:1
30,3,3:1
30,4,3:1
30,5,3:1
30,6,3:1
30,7,3:1
30,8,3:9
30,9,3:9
30,10,3:9
30,11,3:9
30,12,3:9
30,13,3:9
30,14,3:9
30,15,3:9
30,16,3:9
30,17,3:9
30,18,3:9
30,19,3:9
30,20,3:9
30,21,3:9
30,22,3:9
30,23,3:9
30,24,3:9
30,25,3:9
30,26,3:9
30,27,3:9
30,28,3:9
30,29,3:1
30,30,3:3
30,31,3:3
30,32,3:3
30,33,3:3
30,34,3:1
30,35,3:1
30,36,3:1
30,0,4:3
30,1,4:3
30,2,4:3
30,3,4:3
30,4,4:3
30,5,4:3
30,6,4:3
30,7,4:1
30,8,4:9
30,9,4:9
30,10,4:9
30,11,4:9
30,12,4:9
30,13,4:9
30,14,4:9
30,15,4:9
30,16,4:9
30,17,4:9
30,18,4:9
30,19,4:9
30,20,4:9
30,21,4:9
30,22,4:9
30,23,4:9
30,24,4:9
30,25,4:9
30,26,4:9
30,27,4:9
30,28,4:9
30,29,4:1
30,30,4:3
30,31,4:3
30,32,4:3
30,33,4:3
30,34,4:3
30,35,4:3
30,36,4:3
30,0,5:3
30,1,5:3
30,2,5:3
30,3,5:3
30,4,5:3
30,5,5:3
30,6,5:3
30,7,5:1
30,8,5:9
30,9,5:9
30,10,5:9
30,11,5:9
30,12,5:9
30,13,5:9
30,14,5:9
30,15,5:9
30,16,5:9
30,17,5:9
30,18,5:9
30,19,5:9
30,20,5:9
30,21,5:9
30,22,5:9
30,23,5:9
30,24,5:9
30,25,5:9
30,26,5:9
30,27,5:9
30,28,5:9
30,29,5:1
30,30,5:3
30,31,5:3
30,32,5:3
30,33,5:3
30,34,5:3
30,35,5:3
30,36,5:3
30,0,6:3
30,1,6:3
30,2,6:3
30,3,6:3
30,4,6:3
30,5,6:3
30,6,6:3
30,7,6:1
30,29,6:1
30,30,6:3
30,31,6:3
30,32,6:3
30,33,6:3
30,34,6:3
30,35,6:3
30,36,6:3
30,0,7:2
30,1,7:2
30,2,7:4
30,3,7:4
30,4,7:98
30,5,7:98
30,6,7:3
30,7,7:4
30,29,7:4
30,30,7:3
30,31,7:98
30,32,7:98
30,33,7:4
30,34,7:4
30,35,7:2
30,36,7:2
30,6,8:1
30,25,8:17
30,30,8:1
30,36,8:31.1
30,6,9:1
30,30,9:1
30,5,10:1
30,31,10:1
30,2,11:1
30,3,11:1
30,4,11:1
30,17,11:17
30,19,11:17
30,32,11:1
30,33,11:1
30,34,11:1
30,21,12:17
30,22,12:17
30,23,12:17
30,24,12:17
30,26,12:17
30,2,15:1
30,3,15:1
30,17,15:17
30,18,15:17
30,19,15:17
30,20,15:17
30,21,15:17
30,22,15:17
30,33,15:1
30,34,15:1
30,1,16:43
30,2,16:44
30,17,16:85
30,18,16:85
30,19,16:85
30,20,16:85
30,21,16:85
30,22,16:85
30,34,16:44
30,35,16:44
30,1,17:44
30,17,17:50.5
30,21,17:50.5
31,0,0:1
31,1,0:1
31,2,0:1
31,3,0:16
31,4,0:3
31,5,0:3
31,6,0:1
31,7,0:1
31,8,0:1
31,9,0:1
31,10,0:1
31,11,0:1
31,12,0:1
31,13,0:1
31,14,0:1
31,15,0:1
31,16,0:1
31,17,0:1
31,18,0:1
31,19,0:1
31,20,0:1
31,21,0:1
31,22,0:1
31,23,0:1
31,24,0:1
31,25,0:1
31,26,0:1
31,27,0:1
31,28,0:1
31,29,0:1
31,30,0:1
31,31,0:1
31,32,0:1
31,33,0:1
31,34,0:1
31,35,0:1
31,36,0:1
31,0,1:1
31,1,1:1
31,2,1:1
31,3,1:16
31,4,1:16
31,5,1:1
31,6,1:1
31,7,1:1
31,8,1:1
31,9,1:1
31,10,1:1
31,11,1:1
31,12,1:1
31,13,1:1
31,14,1:1
31,15,1:1
31,16,1:1
31,17,1:1
31,18,1:1
31,19,1:1
31,20,1:1
31,21,1:1
31,22,1:1
31,23,1:1
31,24,1:1
31,25,1:1
31,26,1:1
31,27,1:1
31,28,1:1
31,29,1:1
31,30,1:1
31,31,1:1
31,32,1:1
31,33,1:1
31,34,1:1
31,35,1:1
31,36,1:1
31,0,2:1
31,1,2:1
31,2,2:1
31,3,2:1
31,4,2:1
31,5,2:1
31,6,2:1
31,7,2:1
31,8,2:9
31,9,2:9
31,10,2:9
31,11,2:9
31,12,2:9
31,13,2:9
31,14,2:9
31,15,2:9
31,16,2:9
31,17,2:9
31,18,2:9
31,19,2:9
31,20,2:9
31,21,2:9
31,22,2:9
31,23,2:9
31,24,2:9
31,25,2:9
31,26,2:9
31,27,2:9
31,28,2:9
31,29,2:1
31,30,2:1
31,31,2:1
31,32,2:1
31,33,2:1
31,34,2:1
31,35,2:1
31,36,2:1
31,0,3:1
31,1,3:1
31,2,3:1
31,3,3:1
31,4,3:1
31,5,3:1
31,6,3:1
31,7,3:1
31,8,3:9
31,9,3:9
31,10,3:9
31,11,3:9
31,12,3:9
31,13,3:9
31,14,3:9
31,15,3:9
31,16,3:9
31,17,3:9
31,18,3:9
31,19,3:9
31,20,3:9
31,21,3:9
31,22,3:9
31,23,3:9
31,24,3:9
31,25,3:9
31,26,3:9
31,27,3:9
31,28,3:9
31,29,3:1
31,30,3:3
31,31,3:3
31,32,3:3
31,33,3:1
31,34,3:1
31,35,3:1
31,36,3:1
31,0,4:3
31,1,4:3
31,2,4:3
31,3,4:3
31,4,4:3
