[META]
version=2.0
spawnSunlight=True
spawnDarkness=True
spawnWater=False
spawnLava=False
underFill=False
randomRotation=True
dig=True
tree=False
branch=False
needsFoundation=True
rarity=30
collisionPercentage=5
spawnElevationMin=0
spawnElevationMax=200
branchLimit=6
spawnInBiome=All
[DATA]
0,0,0:42
0,1,0:42
0,2,0:42
0,3,0:42
0,4,0:42
0,5,0:42
0,6,0:42
0,7,0:42
0,8,0:42
0,9,0:42
0,10,0:42
0,4,1:109
0,5,1:109
0,6,1:109
1,0,0:2
1,1,0:2
1,2,0:2
1,3,0:3
1,4,0:3
1,5,0:3
1,6,0:3
1,7,0:3
1,8,0:2
1,9,0:2
1,10,0:2
1,3,1:42
1,4,1:42
1,5,1:42
1,6,1:42
1,7,1:42
1,3,2:109.3
1,4,2:70
1,6,2:70
1,7,2:109.2
1,5,4:68.4
2,0,0:3
2,1,0:3
2,2,0:3
2,3,0:3
2,4,0:3
2,5,0:3
2,6,0:3
2,7,0:3
2,8,0:3
2,9,0:3
2,10,0:3
2,0,1:1
2,1,1:1
2,2,1:1
2,3,1:1
2,4,1:1
2,5,1:1
2,6,1:1
2,7,1:1
2,8,1:1
2,9,1:1
2,10,1:1
2,0,2:1
2,1,2:98
2,2,2:102
2,3,2:89
2,4,2:71
2,5,2:57
2,6,2:71
2,7,2:89
2,8,2:102
2,9,2:98
2,10,2:1
2,0,3:1
2,1,3:98
2,2,3:102
2,3,3:89
2,4,3:71.9
2,5,3:57
2,6,3:71.8
2,7,3:89
2,8,3:102
2,9,3:98
2,10,3:1
2,0,4:1
2,1,4:98
2,2,4:102
2,3,4:89
2,4,4:41
2,5,4:57
2,6,4:41
2,7,4:89
2,8,4:102
2,9,4:98
2,10,4:1
2,0,5:1
2,1,5:98
2,2,5:102
2,3,5:89
2,4,5:89
2,5,5:89
2,6,5:89
2,7,5:89
2,8,5:102
2,9,5:98
2,10,5:1
2,0,6:1
2,1,6:98
2,2,6:109.7
2,3,6:44.13
2,4,6:44.13
2,5,6:44.13
2,6,6:44.13
2,7,6:44.13
2,8,6:109.6
2,9,6:98
2,10,6:1
2,0,7:1
2,1,7:98
2,2,7:98
2,3,7:98
2,4,7:41
2,5,7:41
2,6,7:41
2,7,7:98
2,8,7:98
2,9,7:98
2,10,7:1
2,0,8:1
2,1,8:98
2,2,8:98
2,3,8:41
2,4,8:102
2,5,8:102
2,6,8:102
2,7,8:41
2,8,8:98
2,9,8:98
2,10,8:1
2,0,9:1
2,1,9:98
2,2,9:98
2,3,9:41
2,4,9:102
2,5,9:102
2,6,9:102
2,7,9:41
2,8,9:98
2,9,9:98
2,10,9:1
2,0,10:1
2,1,10:98
2,2,10:98
2,3,10:41
2,4,10:102
2,5,10:102
2,6,10:102
2,7,10:41
2,8,10:98
2,9,10:98
2,10,10:1
2,0,11:1
2,1,11:98
2,2,11:98
2,3,11:98
2,4,11:41
2,5,11:41
2,6,11:41
2,7,11:98
2,8,11:98
2,9,11:98
2,10,11:1
2,0,12:1
2,1,12:98
2,2,12:98
2,3,12:98
2,4,12:98
2,5,12:98
2,6,12:98
2,7,12:98
2,8,12:98
2,9,12:98
2,10,12:1
2,0,13:1
2,1,13:98
2,2,13:98
2,3,13:98
2,4,13:98
2,5,13:98
2,6,13:98
2,7,13:98
2,8,13:98
2,9,13:98
2,10,13:1
2,0,14:1
2,1,14:98
2,2,14:102
2,3,14:98
2,4,14:102
2,5,14:102
2,6,14:102
2,7,14:98
2,8,14:102
2,9,14:98
2,10,14:1
2,0,15:1
2,1,15:98
2,2,15:98
2,3,15:98
2,4,15:98
2,5,15:98
2,6,15:98
2,7,15:98
2,8,15:98
2,9,15:98
2,10,15:1
2,0,16:1
2,1,16:98
2,2,16:89
2,3,16:98
2,4,16:89
2,5,16:89
2,6,16:89
2,7,16:98
2,8,16:89
2,9,16:98
2,10,16:1
2,0,17:1
2,1,17:98
2,2,17:98
2,3,17:98
2,4,17:98
2,5,17:98
2,6,17:98
2,7,17:98
2,8,17:98
2,9,17:98
2,10,17:1
2,0,18:1
2,1,18:98
2,2,18:102
2,3,18:98
2,4,18:102
2,5,18:102
2,6,18:102
2,7,18:98
2,8,18:102
2,9,18:98
2,10,18:1
2,0,19:1
2,1,19:98
2,2,19:98
2,3,19:98
2,4,19:98
2,5,19:98
2,6,19:98
2,7,19:98
2,8,19:98
2,9,19:98
2,10,19:1
2,0,20:1
2,1,20:98
2,2,20:89
2,3,20:98
2,4,20:89
2,5,20:89
2,6,20:89
2,7,20:98
2,8,20:89
2,9,20:98
2,10,20:1
2,0,21:1
2,1,21:98
2,2,21:98
2,3,21:98
2,4,21:98
2,5,21:98
2,6,21:98
2,7,21:98
2,8,21:98
2,9,21:98
2,10,21:1
2,0,22:1
2,1,22:98
2,2,22:102
2,3,22:98
2,4,22:102
2,5,22:102
2,6,22:102
2,7,22:98
2,8,22:102
2,9,22:98
2,10,22:1
2,0,23:1
2,1,23:98
2,2,23:98
2,3,23:98
2,4,23:98
2,5,23:98
2,6,23:98
2,7,23:98
2,8,23:98
2,9,23:98
2,10,23:1
2,0,24:1
2,1,24:98
2,2,24:89
2,3,24:98
2,4,24:89
2,5,24:89
2,6,24:89
2,7,24:98
2,8,24:89
2,9,24:98
2,10,24:1
2,0,25:1
2,1,25:98
2,2,25:98
2,3,25:98
2,4,25:98
2,5,25:98
2,6,25:98
2,7,25:98
2,8,25:98
2,9,25:98
2,10,25:1
2,0,26:1
2,1,26:98
2,2,26:102
2,3,26:98
2,4,26:102
2,5,26:102
2,6,26:102
2,7,26:98
2,8,26:102
2,9,26:98
2,10,26:1
2,0,27:1
2,1,27:98
2,2,27:98
2,3,27:98
2,4,27:102
2,5,27:102
2,6,27:102
2,7,27:98
2,8,27:98
2,9,27:98
2,10,27:1
2,0,28:1
2,1,28:98
2,2,28:89
2,3,28:98
2,4,28:89
2,5,28:102
2,6,28:89
2,7,28:98
2,8,28:89
2,9,28:98
2,10,28:1
2,0,29:1
2,1,29:98
2,2,29:98
2,3,29:98
2,4,29:98
2,5,29:98
2,6,29:98
2,7,29:98
2,8,29:98
2,9,29:98
2,10,29:1
2,0,30:1
2,1,30:98
2,2,30:102
2,3,30:98
2,4,30:102
2,5,30:102
2,6,30:102
2,7,30:98
2,8,30:102
2,9,30:98
2,10,30:1
2,0,31:1
2,1,31:98
2,2,31:98
2,3,31:98
2,4,31:98
2,5,31:98
2,6,31:98
2,7,31:98
2,8,31:98
2,9,31:98
2,10,31:1
2,0,32:1
2,1,32:98
2,2,32:89
2,3,32:98
2,4,32:89
2,5,32:89
2,6,32:89
2,7,32:98
2,8,32:89
2,9,32:98
2,10,32:1
2,0,33:1
2,1,33:98
2,2,33:98
2,3,33:98
2,4,33:98
2,5,33:98
2,6,33:98
2,7,33:98
2,8,33:98
2,9,33:98
2,10,33:1
2,0,34:1
2,1,34:98
2,2,34:102
2,3,34:98
2,4,34:102
2,5,34:102
2,6,34:102
2,7,34:98
2,8,34:102
2,9,34:98
2,10,34:1
2,0,35:1
2,1,35:98
2,2,35:98
2,3,35:98
2,4,35:98
2,5,35:98
2,6,35:98
2,7,35:98
2,8,35:98
2,9,35:98
2,10,35:1
2,0,36:1
2,1,36:89
2,2,36:89
2,3,36:89
2,4,36:89
2,5,36:89
2,6,36:89
2,7,36:89
2,8,36:89
2,9,36:89
2,10,36:1
2,0,37:1
2,1,37:102
2,2,37:102
2,3,37:102
2,4,37:102
2,5,37:102
2,6,37:102
2,7,37:102
2,8,37:102
2,9,37:102
2,10,37:1
2,0,38:89
2,1,38:1
2,2,38:1
2,3,38:1
2,4,38:1
2,5,38:1
2,6,38:1
2,7,38:1
2,8,38:1
2,9,38:1
2,10,38:89
3,0,0:3
3,1,0:89
3,2,0:98
3,3,0:98
3,4,0:98
3,5,0:98
3,6,0:98
3,7,0:98
3,8,0:98
3,9,0:89
3,10,0:3
3,0,1:1
3,4,1:98
3,5,1:98
3,6,1:98
3,10,1:1
3,0,2:98
3,4,2:70
3,6,2:70
3,10,2:98
3,0,3:98
3,10,3:98
3,0,4:98
3,10,4:98
3,0,5:98
3,10,5:98
3,0,6:98
3,10,6:98
3,0,7:98
3,10,7:98
3,0,8:98
3,10,8:98
3,0,9:98
3,10,9:98
3,0,10:98
3,10,10:98
3,0,11:98
3,10,11:98
3,0,12:98
3,10,12:98
3,0,13:98
3,10,13:98
3,0,14:98
3,10,14:98
3,0,15:98
3,10,15:98
3,0,16:98
3,1,16:98
3,2,16:98
3,3,16:98
3,4,16:98
3,5,16:98
3,6,16:98
3,7,16:98
3,8,16:98
3,9,16:98
3,10,16:98
3,0,17:98
3,1,17:57
3,2,17:57
3,3,17:57
3,4,17:57
3,5,17:57
3,6,17:57
3,7,17:57
3,8,17:57
3,9,17:57
3,10,17:98
3,0,18:98
3,1,18:57
3,2,18:44
3,3,18:57
3,4,18:44
3,5,18:53.1
3,6,18:44
3,7,18:57
3,8,18:44
3,9,18:57
3,10,18:98
3,0,19:98
3,1,19:57
3,2,19:57
3,3,19:57
3,4,19:133
3,5,19:68.5
3,6,19:133
3,7,19:57
3,8,19:57
3,9,19:57
3,10,19:98
3,0,20:98
3,1,20:133
3,2,20:133
3,3,20:133
3,4,20:42
3,6,20:42
3,7,20:133
3,8,20:133
3,9,20:133
3,10,20:98
3,0,21:98
3,4,21:44
3,5,21:42
3,6,21:44
3,10,21:98
3,0,22:98
3,10,22:98
3,0,23:98
3,10,23:98
3,0,24:98
3,10,24:98
3,0,25:98
3,1,25:96.11
3,2,25:98
3,3,25:98
3,4,25:98
3,5,25:98
3,6,25:98
3,7,25:98
3,8,25:98
3,9,25:98
3,10,25:98
3,0,26:98
3,3,26:53.2
3,4,26:54.5
3,5,26:53.1
3,6,26:54.5
3,7,26:53.3
3,10,26:98
3,0,27:98
3,5,27:68.5
3,10,27:98
3,0,28:98
3,10,28:98
3,0,29:98
3,10,29:98
3,0,30:98
3,10,30:98
3,0,31:98
3,10,31:98
3,0,32:98
3,10,32:98
3,0,33:98
3,10,33:98
3,0,34:98
3,10,34:98
3,0,35:98
3,10,35:98
3,0,36:89
3,10,36:89
3,0,37:102
3,10,37:102
3,0,38:1
3,10,38:1
3,1,39:1
3,2,39:1
3,3,39:1
3,4,39:1
3,5,39:1
3,6,39:1
3,7,39:1
3,8,39:1
3,9,39:1
4,0,0:3
4,1,0:98
4,2,0:98
4,3,0:98
4,4,0:98
4,5,0:98
4,6,0:98
4,7,0:98
4,8,0:98
4,9,0:98
4,10,0:3
4,0,1:1
4,4,1:109.1
4,5,1:109.1
4,6,1:109.1
4,10,1:1
4,0,2:89
4,10,2:89
4,0,3:89
4,10,3:89
4,0,4:89
4,10,4:89
4,0,5:89
4,10,5:89
4,0,6:89
4,10,6:89
4,0,7:89
4,10,7:89
4,0,8:89
4,10,8:89
4,0,9:89
4,10,9:89
4,0,10:89
4,10,10:89
4,0,11:89
4,10,11:89
4,0,12:89
4,10,12:89
4,0,13:89
4,10,13:89
4,0,14:89
4,10,14:89
4,0,15:89
4,10,15:89
4,0,16:89
4,1,16:98
4,2,16:98
4,3,16:98
4,4,16:98
4,5,16:98
4,6,16:98
4,7,16:98
4,8,16:98
4,9,16:98
4,10,16:89
4,0,17:89
4,1,17:41
4,2,17:41
4,3,17:57
4,4,17:57
4,5,17:57
4,6,17:57
4,7,17:57
4,8,17:41
4,9,17:41
4,10,17:89
4,0,18:89
4,1,18:44
4,2,18:44
4,3,18:44
4,7,18:44
4,8,18:44
4,9,18:44
4,10,18:89
4,0,19:89
4,10,19:89
4,0,20:89
4,10,20:89
4,0,21:89
4,5,21:68.5
4,10,21:89
4,0,22:89
4,10,22:89
4,0,23:89
4,10,23:89
4,0,24:89
4,10,24:89
4,0,25:89
4,1,25:98
4,2,25:98
4,3,25:98
4,4,25:98
4,5,25:98
4,6,25:98
4,7,25:98
4,8,25:98
4,9,25:98
4,10,25:89
4,0,26:89
4,3,26:53.2
4,7,26:53.3
4,10,26:89
4,0,27:89
4,10,27:89
4,0,28:89
4,10,28:98
4,0,29:98
4,10,29:98
4,0,30:98
4,10,30:89
4,0,31:89
4,10,31:98
4,0,32:98
4,10,32:98
4,0,33:98
4,10,33:98
4,0,34:98
4,10,34:98
4,0,35:98
4,10,35:98
4,0,36:89
4,10,36:89
4,0,37:102
4,10,37:102
4,0,38:1
4,10,38:1
4,1,39:1
4,9,39:1
4,2,40:1
4,3,40:1
4,4,40:1
4,5,40:1
4,6,40:1
4,7,40:1
4,8,40:1
5,0,0:3
5,1,0:98
5,2,0:98
5,3,0:89
5,4,0:98
5,5,0:98
5,6,0:98
5,7,0:89
5,8,0:98
5,9,0:98
5,10,0:3
5,0,1:1
5,10,1:1
5,0,2:98
5,10,2:98
5,0,3:98
5,10,3:98
5,0,4:98
5,10,4:98
5,0,5:98
5,10,5:98
5,0,6:98
5,10,6:98
5,0,7:98
5,10,7:98
5,0,8:98
5,10,8:98
5,0,9:98
5,10,9:98
5,0,10:98
5,10,10:98
5,0,11:98
5,10,11:98
5,0,12:98
5,10,12:98
5,0,13:98
5,10,13:98
5,0,14:98
5,10,14:98
5,0,15:98
5,10,15:98
5,0,16:98
5,1,16:98
5,2,16:98
5,3,16:98
5,4,16:98
5,5,16:98
5,6,16:98
5,7,16:98
5,8,16:98
5,9,16:98
5,10,16:98
5,0,17:98
5,1,17:44
5,2,17:44
5,3,17:44
5,4,17:44
5,5,17:44
5,6,17:44
5,7,17:44
5,8,17:44
5,9,17:44
5,10,17:98
5,0,18:98
5,10,18:98
5,0,19:98
5,10,19:98
5,0,20:98
5,10,20:98
5,0,21:98
5,10,21:98
5,0,22:98
5,10,22:98
5,0,23:98
5,10,23:98
5,0,24:98
5,10,24:98
5,0,25:98
5,1,25:98
5,2,25:98
5,3,25:98
5,4,25:98
5,5,25:98
5,6,25:98
5,7,25:98
5,8,25:98
5,9,25:98
5,10,25:98
5,0,26:98
5,3,26:53.2
5,4,26:126.8
5,5,26:126.8
5,6,26:126.8
5,7,26:53.3
5,10,26:89
5,0,27:89
5,10,27:89
5,0,28:89
5,10,28:89
5,0,29:89
5,10,29:89
5,0,30:89
5,10,30:89
5,0,31:89
5,10,31:89
5,0,32:89
5,10,32:98
5,0,33:98
5,10,33:98
5,0,34:98
5,10,34:98
5,0,35:98
5,10,35:98
5,0,36:89
5,10,36:89
5,0,37:102
5,10,37:102
5,0,38:1
5,10,38:1
5,1,39:1
5,9,39:1
5,2,40:1
5,8,40:1
5,3,41:1
5,4,41:1
5,5,41:1
5,6,41:1
5,7,41:1
6,0,0:3
6,1,0:98
6,2,0:98
6,3,0:98
6,4,0:98
6,5,0:98
6,6,0:98
6,7,0:98
6,8,0:98
6,9,0:98
6,10,0:3
6,0,1:1
6,10,1:1
6,0,2:98
6,10,2:98
6,0,3:98
6,10,3:98
6,0,4:98
6,10,4:98
6,0,5:98
6,10,5:98
6,0,6:98
6,10,6:98
6,0,7:98
6,10,7:98
6,0,8:98
6,10,8:98
6,0,9:98
6,10,9:98
6,0,10:98
6,10,10:98
6,0,11:98
6,10,11:98
6,0,12:98
6,10,12:98
6,0,13:98
6,10,13:98
6,0,14:98
6,10,14:98
6,0,15:98
6,10,15:98
6,0,16:98
6,1,16:98
6,2,16:98
6,3,16:98
6,4,16:98
6,5,16:98
6,6,16:98
6,7,16:98
6,8,16:98
6,9,16:98
6,10,16:98
6,0,17:98
6,10,17:98
6,0,18:98
6,10,18:98
6,0,19:98
6,10,19:98
6,0,20:98
6,10,20:98
6,0,21:98
6,10,21:98
6,0,22:98
6,10,22:98
6,0,23:98
6,10,23:98
6,0,24:98
6,10,24:98
6,0,25:98
6,1,25:98
6,2,25:98
6,3,25:98
6,4,25:98
6,5,25:98
6,6,25:98
6,7,25:98
6,8,25:98
6,9,25:98
6,10,25:98
6,0,26:98
6,5,26:68.5
6,10,26:98
6,0,27:98
6,10,27:89
6,0,28:89
6,10,28:98
6,0,29:98
6,10,29:98
6,0,30:98
6,10,30:98
6,0,31:98
6,10,31:98
6,0,32:98
6,10,32:98
6,0,33:98
6,10,33:98
6,0,34:98
6,10,34:98
6,0,35:98
6,10,35:98
6,0,36:89
6,10,36:89
6,0,37:102
6,10,37:102
6,0,38:1
6,10,38:1
6,1,39:1
6,9,39:1
6,2,40:1
6,8,40:1
6,3,41:1
6,7,41:1
6,4,42:1
6,5,42:1
6,6,42:1
7,0,0:3
7,1,0:98
7,2,0:98
7,3,0:98
7,4,0:98
7,5,0:98
7,6,0:98
7,7,0:98
7,8,0:98
7,9,0:98
7,10,0:3
7,0,1:1
7,10,1:1
7,0,2:89
7,10,2:89
7,0,3:89
7,10,3:89
7,0,4:89
7,10,4:89
7,0,5:89
7,10,5:89
7,0,6:89
7,10,6:89
7,0,7:89
7,10,7:89
7,0,8:89
7,10,8:89
7,0,9:89
7,10,9:89
7,0,10:89
7,10,10:89
7,0,11:89
7,10,11:89
7,0,12:89
7,10,12:89
7,0,13:89
7,10,13:89
7,0,14:89
7,10,14:89
7,0,15:89
7,10,15:89
7,0,16:89
7,1,16:98
7,2,16:98
7,3,16:98
7,4,16:98
7,5,16:98
7,6,16:98
7,7,16:98
7,8,16:98
7,9,16:98
7,10,16:89
7,0,17:89
7,10,17:89
7,0,18:89
7,10,18:89
7,0,19:89
7,10,19:89
7,0,20:89
7,10,20:89
7,0,21:89
7,10,21:89
7,0,22:89
7,10,22:89
7,0,23:89
7,10,23:89
7,0,24:89
7,10,24:89
7,0,25:89
7,1,25:98
7,2,25:98
7,3,25:98
7,4,25:98
7,5,25:98
7,6,25:98
7,7,25:98
7,8,25:98
7,9,25:98
7,10,25:89
7,0,26:89
7,10,26:89
7,0,27:89
7,10,27:89
7,0,28:89
7,10,28:89
7,0,29:89
7,10,29:89
7,0,30:89
7,10,30:89
7,0,31:89
7,10,31:89
7,0,32:89
7,10,32:89
7,0,33:89
7,10,33:89
7,0,34:89
7,10,34:89
7,0,35:89
7,10,35:89
7,0,36:89
7,10,36:89
7,0,37:102
7,10,37:102
7,0,38:1
7,10,38:1
7,1,39:1
7,9,39:1
7,2,40:1
7,8,40:1
7,3,41:1
7,7,41:1
7,4,42:1
7,5,42:89
7,6,42:1
8,0,0:3
8,1,0:98
8,2,0:98
8,3,0:89
8,4,0:98
8,5,0:89
8,6,0:98
8,7,0:89
8,8,0:98
8,9,0:98
8,10,0:3
8,0,1:1
8,10,1:1
8,0,2:102
8,10,2:102
8,0,3:102
8,10,3:102
8,0,4:102
8,10,4:102
8,0,5:102
8,10,5:102
8,0,6:102
8,10,6:102
8,0,7:102
8,10,7:102
8,0,8:102
8,10,8:102
8,0,9:102
8,10,9:102
8,0,10:102
8,10,10:102
8,0,11:102
8,10,11:102
8,0,12:102
8,10,12:102
8,0,13:102
8,10,13:102
8,0,14:102
8,10,14:102
8,0,15:102
8,10,15:102
8,0,16:102
8,1,16:98
8,2,16:98
8,3,16:98
8,4,16:98
8,5,16:98
8,6,16:98
8,7,16:98
8,8,16:98
8,9,16:98
8,10,16:102
8,0,17:102
8,10,17:102
8,0,18:102
8,10,18:102
8,0,19:102
8,10,19:102
8,0,20:102
8,10,20:102
8,0,21:102
8,10,21:102
8,0,22:102
8,10,22:102
8,0,23:102
8,10,23:102
8,0,24:102
8,10,24:102
8,0,25:102
8,1,25:102
8,2,25:102
8,3,25:102
8,4,25:102
8,5,25:102
8,6,25:102
8,7,25:102
8,8,25:102
8,9,25:102
8,10,25:102
8,0,26:102
8,10,26:102
8,0,27:102
8,10,27:102
8,0,28:102
8,10,28:102
8,0,29:102
8,10,29:102
8,0,30:102
8,10,30:102
8,0,31:102
8,10,31:102
8,0,32:102
8,10,32:102
8,0,33:102
8,10,33:102
8,0,34:102
8,10,34:102
8,0,35:102
8,10,35:102
8,0,36:89
8,10,36:89
8,0,37:102
8,10,37:102
8,0,38:1
8,10,38:1
8,1,39:1
8,9,39:1
8,2,40:1
8,8,40:1
8,3,41:1
8,7,41:1
8,4,42:1
8,5,42:96.10
8,6,42:1
9,0,0:3
9,1,0:98
9,2,0:98
9,3,0:98
9,4,0:98
9,5,0:98
9,6,0:98
9,7,0:98
9,8,0:98
9,9,0:98
9,10,0:3
9,0,1:1
9,10,1:1
9,0,2:89
9,10,2:89
9,0,3:89
9,10,3:89
9,0,4:89
9,10,4:89
9,0,5:89
9,10,5:89
9,0,6:89
9,10,6:89
9,0,7:89
9,10,7:89
9,0,8:89
9,10,8:89
9,0,9:89
9,10,9:89
9,0,10:89
9,10,10:89
9,0,11:89
9,10,11:89
9,0,12:89
9,10,12:89
9,0,13:89
9,10,13:89
9,0,14:89
9,10,14:89
9,0,15:89
9,10,15:89
9,0,16:89
9,1,16:98
9,2,16:98
9,3,16:98
9,4,16:98
9,5,16:98
9,6,16:98
9,7,16:98
9,8,16:98
9,9,16:98
9,10,16:89
9,0,17:89
9,10,17:89
9,0,18:89
9,10,18:89
9,0,19:89
9,10,19:89
9,0,20:89
9,10,20:89
9,0,21:89
9,10,21:89
9,0,22:89
9,10,22:89
9,0,23:89
9,10,23:89
9,0,24:89
9,10,24:89
9,0,25:89
9,1,25:98
9,2,25:98
9,3,25:98
9,4,25:98
9,5,25:98
9,6,25:98
9,7,25:98
9,8,25:98
9,9,25:98
9,10,25:89
9,0,26:89
9,10,26:89
9,0,27:89
9,10,27:89
9,0,28:89
9,10,28:89
9,0,29:89
9,10,29:89
9,0,30:89
9,10,30:89
9,0,31:89
9,10,31:89
9,0,32:89
9,10,32:89
9,0,33:89
9,10,33:89
9,0,34:89
9,10,34:89
9,0,35:89
9,10,35:89
9,0,36:89
9,10,36:89
9,0,37:102
9,10,37:102
9,0,38:1
9,10,38:1
9,1,39:1
9,9,39:1
9,2,40:1
9,8,40:1
9,3,41:1
9,7,41:1
9,4,42:1
9,5,42:89
9,6,42:1
10,0,0:3
10,1,0:98
10,2,0:98
10,3,0:98
10,4,0:98
10,5,0:98
10,6,0:98
10,7,0:98
10,8,0:98
10,9,0:98
10,10,0:3
10,0,1:1
10,10,1:1
10,0,2:98
10,10,2:98
10,0,3:98
10,10,3:98
10,0,4:98
10,10,4:98
10,0,5:98
10,10,5:98
10,0,6:98
10,10,6:98
10,0,7:98
10,10,7:98
10,0,8:98
10,10,8:98
10,0,9:98
10,10,9:98
10,0,10:98
10,10,10:98
10,0,11:98
10,10,11:98
10,0,12:98
10,10,12:98
10,0,13:98
10,10,13:98
10,0,14:98
10,10,14:98
10,0,15:98
10,10,15:98
10,0,16:98
10,1,16:98
10,2,16:98
10,3,16:98
10,4,16:98
10,5,16:98
10,6,16:98
10,7,16:98
10,8,16:98
10,9,16:98
10,10,16:98
10,0,17:98
10,10,17:98
10,0,18:98
10,10,18:98
10,0,19:98
10,10,19:98
10,0,20:98
10,10,20:98
10,0,21:98
10,10,21:98
10,0,22:98
10,10,22:98
10,0,23:98
10,10,23:98
10,0,24:98
10,10,24:98
10,0,25:98
10,1,25:98
10,2,25:98
10,3,25:98
10,4,25:98
10,6,25:98
10,7,25:98
10,8,25:98
10,9,25:98
10,10,25:98
10,0,26:98
10,10,26:98
10,0,27:98
10,10,27:89
10,0,28:89
10,10,28:98
10,0,29:98
10,10,29:98
10,0,30:98
10,10,30:98
10,0,31:98
10,10,31:98
10,0,32:98
10,10,32:98
10,0,33:98
10,10,33:98
10,0,34:98
10,10,34:98
10,0,35:98
10,10,35:98
10,0,36:89
10,10,36:89
10,0,37:102
10,10,37:102
10,0,38:1
10,10,38:1
10,1,39:1
10,9,39:1
10,2,40:1
10,8,40:1
10,3,41:1
10,7,41:1
10,4,42:1
10,5,42:1
10,6,42:1
11,0,0:3
11,1,0:98
11,2,0:98
11,3,0:89
11,4,0:98
11,5,0:98
11,6,0:98
11,7,0:89
11,8,0:98
11,9,0:98
11,10,0:3
11,0,1:1
11,10,1:1
11,0,2:98
11,10,2:98
11,0,3:98
11,10,3:98
11,0,4:98
11,10,4:98
11,0,5:98
11,10,5:98
11,0,6:98
11,10,6:98
11,0,7:98
11,10,7:98
11,0,8:98
11,10,8:98
11,0,9:98
11,10,9:98
11,0,10:98
11,10,10:98
11,0,11:98
11,10,11:98
11,0,12:98
11,10,12:98
11,0,13:98
11,10,13:98
11,0,14:98
11,10,14:98
11,0,15:98
11,10,15:98
11,0,16:98
11,1,16:98
11,2,16:98
11,3,16:98
11,4,16:98
11,5,16:98
11,6,16:98
11,7,16:98
11,8,16:98
11,9,16:98
11,10,16:98
11,0,17:98
11,10,17:98
11,0,18:98
11,10,18:98
11,0,19:98
11,10,19:98
11,0,20:98
11,10,20:98
11,0,21:98
11,10,21:98
11,0,22:98
11,10,22:98
11,0,23:98
11,10,23:98
11,0,24:98
11,10,24:98
11,0,25:98
11,1,25:98
11,2,25:98
11,3,25:98
11,4,25:98
11,5,25:98
11,6,25:98
11,7,25:98
11,8,25:98
11,9,25:98
11,10,25:98
11,0,26:98
11,10,26:89
11,0,27:89
11,10,27:89
11,0,28:89
11,10,28:89
11,0,29:89
11,10,29:89
11,0,30:89
11,10,30:89
11,0,31:89
11,10,31:89
11,0,32:89
11,10,32:98
11,0,33:98
11,10,33:98
11,0,34:98
11,10,34:98
11,0,35:98
11,10,35:98
11,0,36:89
11,10,36:89
11,0,37:102
11,10,37:102
11,0,38:1
11,10,38:1
11,1,39:1
11,9,39:1
11,2,40:1
11,8,40:1
11,3,41:1
11,4,41:1
11,5,41:1
11,6,41:1
11,7,41:1
12,0,0:3
12,1,0:98
12,2,0:98
12,3,0:98
12,4,0:98
12,5,0:98
12,6,0:98
12,7,0:98
12,8,0:98
12,9,0:98
12,10,0:3
12,0,1:1
12,9,1:70
12,10,1:1
12,0,2:89
12,10,2:89
12,0,3:89
12,10,3:89
12,0,4:89
12,10,4:89
12,0,5:89
12,10,5:89
12,0,6:89
12,10,6:89
12,0,7:89
12,10,7:89
12,0,8:89
12,10,8:89
12,0,9:89
12,10,9:89
12,0,10:89
12,10,10:89
12,0,11:89
12,10,11:89
12,0,12:89
12,10,12:89
12,0,13:89
12,10,13:89
12,0,14:89
12,10,14:89
12,0,15:89
12,10,15:89
12,0,16:89
12,1,16:98
12,2,16:98
12,3,16:98
12,4,16:98
12,5,16:98
12,6,16:98
12,7,16:98
12,8,16:98
12,9,16:98
12,10,16:89
12,0,17:89
12,10,17:89
12,0,18:89
12,10,18:89
12,0,19:89
12,10,19:89
12,0,20:89
12,10,20:89
12,0,21:89
12,10,21:89
12,0,22:89
12,10,22:89
12,0,23:89
12,10,23:89
12,0,24:89
12,10,24:89
12,0,25:89
12,1,25:98
12,2,25:98
12,3,25:98
12,4,25:98
12,5,25:98
12,6,25:98
12,7,25:98
12,8,25:98
12,9,25:98
12,10,25:89
12,0,26:89
12,1,26:70
12,10,26:89
12,0,27:89
12,10,27:89
12,0,28:89
12,10,28:98
12,0,29:98
12,10,29:98
12,0,30:98
12,10,30:89
12,0,31:89
12,10,31:98
12,0,32:98
12,10,32:98
12,0,33:98
12,10,33:98
12,0,34:98
12,10,34:98
12,0,35:98
12,10,35:98
12,0,36:89
12,10,36:89
12,0,37:102
12,10,37:102
12,0,38:1
12,10,38:1
12,1,39:1
12,9,39:1
12,2,40:1
12,3,40:1
12,4,40:1
12,5,40:1
12,6,40:1
12,7,40:1
12,8,40:1
13,0,0:3
13,1,0:89
13,2,0:98
13,3,0:98
13,4,0:98
13,5,0:89
13,6,0:98
13,7,0:98
13,8,0:98
13,9,0:89
13,10,0:3
13,0,1:1
13,2,1:26.10
13,3,1:26.2
13,9,1:137
13,10,1:1
13,0,2:98
13,10,2:98
13,0,3:98
13,10,3:98
13,0,4:98
13,10,4:98
13,0,5:98
13,10,5:98
13,0,6:98
13,10,6:98
13,0,7:98
13,10,7:98
13,0,8:98
13,10,8:98
13,0,9:98
13,10,9:98
13,0,10:98
13,10,10:98
13,0,11:98
13,10,11:98
13,0,12:98
13,10,12:98
13,0,13:98
13,10,13:98
13,0,14:98
13,10,14:98
13,0,15:98
13,10,15:98
13,0,16:98
13,1,16:98
13,2,16:98
13,3,16:98
13,4,16:98
13,5,16:98
13,6,16:98
13,7,16:98
13,8,16:98
13,9,16:98
13,10,16:98
13,0,17:98
13,1,17:137
13,2,17:70
13,8,17:70
13,9,17:137
13,10,17:98
13,0,18:98
13,10,18:98
13,0,19:98
13,10,19:98
13,0,20:98
13,10,20:98
13,0,21:98
13,10,21:98
13,0,22:98
13,10,22:98
13,0,23:98
13,10,23:98
13,0,24:98
13,10,24:98
13,0,25:98
13,1,25:98
13,2,25:98
13,3,25:102
13,4,25:98
13,5,25:102
13,6,25:98
13,7,25:102
13,8,25:98
13,9,25:98
13,10,25:98
13,0,26:98
13,1,26:137
13,10,26:98
13,0,27:98
13,10,27:98
13,0,28:98
13,10,28:98
13,0,29:98
13,10,29:98
13,0,30:98
13,10,30:98
13,0,31:98
13,10,31:98
13,0,32:98
13,10,32:98
13,0,33:98
13,10,33:98
13,0,34:98
13,10,34:98
13,0,35:98
13,10,35:98
13,0,36:89
13,10,36:89
13,0,37:102
13,10,37:102
13,0,38:1
13,10,38:1
13,1,39:1
13,2,39:1
13,3,39:1
13,4,39:1
13,5,39:1
13,6,39:1
13,7,39:1
13,8,39:1
13,9,39:1
14,0,0:3
14,1,0:3
14,2,0:3
14,3,0:3
14,4,0:3
14,5,0:3
14,6,0:3
14,7,0:3
14,8,0:3
14,9,0:3
14,10,0:3
14,0,1:1
14,1,1:1
14,2,1:1
14,3,1:1
14,4,1:1
14,5,1:1
14,6,1:1
14,7,1:1
14,8,1:1
14,9,1:1
14,10,1:1
14,0,2:1
14,1,2:89
14,2,2:98
14,3,2:102
14,4,2:98
14,5,2:102
14,6,2:98
14,7,2:102
14,8,2:98
14,9,2:89
14,10,2:1
14,0,3:1
14,1,3:89
14,2,3:98
14,3,3:102
14,4,3:98
14,5,3:102
14,6,3:98
14,7,3:102
14,8,3:98
14,9,3:89
14,10,3:1
14,0,4:1
14,1,4:89
14,2,4:98
14,3,4:102
14,4,4:98
14,5,4:102
14,6,4:98
14,7,4:102
14,8,4:98
14,9,4:89
14,10,4:1
14,0,5:1
14,1,5:89
14,2,5:98
14,3,5:102
14,4,5:98
14,5,5:102
14,6,5:98
14,7,5:102
14,8,5:98
14,9,5:89
14,10,5:1
14,0,6:1
14,1,6:89
14,2,6:98
14,3,6:102
14,4,6:98
14,5,6:102
14,6,6:98
14,7,6:102
14,8,6:98
14,9,6:89
14,10,6:1
14,0,7:1
14,1,7:89
14,2,7:98
14,3,7:102
14,4,7:98
14,5,7:102
14,6,7:98
14,7,7:102
14,8,7:98
14,9,7:89
14,10,7:1
14,0,8:1
14,1,8:89
14,2,8:98
14,3,8:102
14,4,8:98
14,5,8:102
14,6,8:98
14,7,8:102
14,8,8:98
14,9,8:89
14,10,8:1
14,0,9:1
14,1,9:89
14,2,9:98
14,3,9:102
14,4,9:98
14,5,9:102
14,6,9:98
14,7,9:102
14,8,9:98
14,9,9:89
14,10,9:1
14,0,10:1
14,1,10:89
14,2,10:98
14,3,10:102
14,4,10:98
14,5,10:102
14,6,10:98
14,7,10:102
14,8,10:98
14,9,10:89
14,10,10:1
14,0,11:1
14,1,11:89
14,2,11:98
14,3,11:102
14,4,11:98
14,5,11:102
14,6,11:98
14,7,11:102
14,8,11:98
14,9,11:89
14,10,11:1
14,0,12:1
14,1,12:89
14,2,12:98
14,3,12:102
14,4,12:98
14,5,12:102
14,6,12:98
14,7,12:102
14,8,12:98
14,9,12:89
14,10,12:1
14,0,13:1
14,1,13:89
14,2,13:98
14,3,13:102
14,4,13:98
14,5,13:102
14,6,13:98
14,7,13:102
14,8,13:98
14,9,13:89
14,10,13:1
14,0,14:1
14,1,14:89
14,2,14:98
14,3,14:102
14,4,14:98
14,5,14:102
14,6,14:98
14,7,14:102
14,8,14:98
14,9,14:89
14,10,14:1
14,0,15:1
14,1,15:89
14,2,15:98
14,3,15:102
14,4,15:98
14,5,15:102
14,6,15:98
14,7,15:102
14,8,15:98
14,9,15:89
14,10,15:1
14,0,16:1
14,1,16:89
14,2,16:98
14,3,16:102
14,4,16:98
14,5,16:102
14,6,16:98
14,7,16:102
14,8,16:98
14,9,16:89
14,10,16:1
14,0,17:1
14,1,17:89
14,2,17:98
14,3,17:102
14,4,17:98
14,5,17:102
14,6,17:98
14,7,17:102
14,8,17:98
14,9,17:89
14,10,17:1
14,0,18:1
14,1,18:89
14,2,18:98
14,3,18:102
14,4,18:98
14,5,18:102
14,6,18:98
14,7,18:102
14,8,18:98
14,9,18:89
14,10,18:1
14,0,19:1
14,1,19:89
14,2,19:98
14,3,19:102
14,4,19:98
14,5,19:102
14,6,19:98
14,7,19:102
14,8,19:98
14,9,19:89
14,10,19:1
14,0,20:1
14,1,20:89
14,2,20:98
14,3,20:102
14,4,20:98
14,5,20:102
14,6,20:98
14,7,20:102
14,8,20:98
14,9,20:89
14,10,20:1
14,0,21:1
14,1,21:89
14,2,21:98
14,3,21:102
14,4,21:98
14,5,21:102
14,6,21:98
14,7,21:102
14,8,21:98
14,9,21:89
14,10,21:1
14,0,22:1
14,1,22:89
14,2,22:98
14,3,22:102
14,4,22:98
14,5,22:102
14,6,22:98
14,7,22:102
14,8,22:98
14,9,22:89
14,10,22:1
14,0,23:1
14,1,23:89
14,2,23:98
14,3,23:102
14,4,23:98
14,5,23:102
14,6,23:98
14,7,23:102
14,8,23:98
14,9,23:89
14,10,23:1
14,0,24:1
14,1,24:89
14,2,24:98
14,3,24:102
14,4,24:98
14,5,24:102
14,6,24:98
14,7,24:102
14,8,24:98
14,9,24:89
14,10,24:1
14,0,25:1
14,1,25:89
14,2,25:98
14,3,25:102
14,4,25:98
14,5,25:102
14,6,25:98
14,7,25:102
14,8,25:98
14,9,25:89
14,10,25:1
14,0,26:1
14,1,26:89
14,2,26:98
14,3,26:102
14,4,26:98
14,5,26:102
14,6,26:98
14,7,26:102
14,8,26:98
14,9,26:89
14,10,26:1
14,0,27:1
14,1,27:89
14,2,27:98
14,3,27:102
14,4,27:102
14,5,27:102
14,6,27:102
14,7,27:102
14,8,27:98
14,9,27:89
14,10,27:1
14,0,28:1
14,1,28:89
14,2,28:98
14,3,28:98
14,4,28:98
14,5,28:102
14,6,28:98
14,7,28:98
14,8,28:98
14,9,28:89
14,10,28:1
14,0,29:1
14,1,29:98
14,2,29:89
14,3,29:98
14,4,29:98
14,5,29:102
14,6,29:98
14,7,29:98
14,8,29:89
14,9,29:98
14,10,29:1
14,0,30:1
14,1,30:98
14,2,30:98
14,3,30:89
14,4,30:98
14,5,30:102
14,6,30:98
14,7,30:89
14,8,30:98
14,9,30:98
14,10,30:1
14,0,31:1
14,1,31:98
14,2,31:98
14,3,31:89
14,4,31:98
14,5,31:102
14,6,31:98
14,7,31:89
14,8,31:98
14,9,31:98
14,10,31:1
14,0,32:1
14,1,32:98
14,2,32:98
14,3,32:89
14,4,32:98
14,5,32:102
14,6,32:98
14,7,32:89
14,8,32:98
14,9,32:98
14,10,32:1
14,0,33:1
14,1,33:98
14,2,33:98
14,3,33:89
14,4,33:98
14,5,33:102
14,6,33:98
14,7,33:89
14,8,33:98
14,9,33:98
14,10,33:1
14,0,34:1
14,1,34:98
14,2,34:98
14,3,34:89
14,4,34:98
14,5,34:102
14,6,34:98
14,7,34:89
14,8,34:98
14,9,34:98
14,10,34:1
14,0,35:1
14,1,35:98
14,2,35:98
14,3,35:89
14,4,35:98
14,5,35:102
14,6,35:98
14,7,35:89
14,8,35:98
14,9,35:98
14,10,35:1
14,0,36:1
14,1,36:89
14,2,36:89
14,3,36:89
14,4,36:89
14,5,36:89
14,6,36:89
14,7,36:89
14,8,36:89
14,9,36:89
14,10,36:1
14,0,37:1
14,1,37:102
14,2,37:102
14,3,37:102
14,4,37:102
14,5,37:102
14,6,37:102
14,7,37:102
14,8,37:102
14,9,37:102
14,10,37:1
14,0,38:89
14,1,38:1
14,2,38:1
14,3,38:1
14,4,38:1
14,5,38:1
14,6,38:1
14,7,38:1
14,8,38:1
14,9,38:1
14,10,38:89
